DEBUG 2024-01-10 00:10:12,017 base Exception while resolving variable 'company_name' in template 'basecamp/html_email-inquiry-response-p2p.html'.
Traceback (most recent call last):
  File "/home/horeb/github/easygo/venv/lib/python3.11/site-packages/django/template/base.py", line 880, in _resolve_lookup
    current = current[bit]
              ~~~~~~~^^^^^
  File "/home/horeb/github/easygo/venv/lib/python3.11/site-packages/django/template/context.py", line 83, in __getitem__
    raise KeyError(key)
KeyError: 'company_name'

During handling of the above exception, another exception occurred:

Traceback (most recent call last):
  File "/home/horeb/github/easygo/venv/lib/python3.11/site-packages/django/template/base.py", line 886, in _resolve_lookup
    if isinstance(current, BaseContext) and getattr(
                                            ^^^^^^^^
AttributeError: type object 'Context' has no attribute 'company_name'

During handling of the above exception, another exception occurred:

Traceback (most recent call last):
  File "/home/horeb/github/easygo/venv/lib/python3.11/site-packages/django/template/base.py", line 896, in _resolve_lookup
    current = current[int(bit)]
                      ^^^^^^^^
ValueError: invalid literal for int() with base 10: 'company_name'

During handling of the above exception, another exception occurred:

Traceback (most recent call last):
  File "/home/horeb/github/easygo/venv/lib/python3.11/site-packages/django/template/base.py", line 903, in _resolve_lookup
    raise VariableDoesNotExist(
django.template.base.VariableDoesNotExist: Failed lookup for key [company_name] in [{'True': True, 'False': False, 'None': None}, {'name': 'Debbie Mathias', 'contact': '0414288990', 'email': 'scorpio2148@outlook.com', 'flight_date': datetime.date(2023, 11, 3), 'pickup_time': '08:00', 'flight_number': '8 McIntosh Street, Kings Park, 2148', 'street': 'Overseas Passenger Terminal', 'no_of_passenger': '2', 'no_of_baggage': '2 x checkin, 2 x carry', 'return_flight_date': datetime.date(2023, 11, 10), 'return_flight_number': 'Overseas Passenger Terminal', 'return_pickup_time': '08:30', 'message': '', 'price': '300', 'notice': '', 'private_ride': False}]
DEBUG 2024-01-10 00:10:12,029 base Exception while resolving variable 'company_name' in template 'basecamp/html_email-inquiry-response-p2p.html'.
Traceback (most recent call last):
  File "/home/horeb/github/easygo/venv/lib/python3.11/site-packages/django/template/base.py", line 880, in _resolve_lookup
    current = current[bit]
              ~~~~~~~^^^^^
  File "/home/horeb/github/easygo/venv/lib/python3.11/site-packages/django/template/context.py", line 83, in __getitem__
    raise KeyError(key)
KeyError: 'company_name'

During handling of the above exception, another exception occurred:

Traceback (most recent call last):
  File "/home/horeb/github/easygo/venv/lib/python3.11/site-packages/django/template/base.py", line 886, in _resolve_lookup
    if isinstance(current, BaseContext) and getattr(
                                            ^^^^^^^^
AttributeError: type object 'Context' has no attribute 'company_name'

During handling of the above exception, another exception occurred:

Traceback (most recent call last):
  File "/home/horeb/github/easygo/venv/lib/python3.11/site-packages/django/template/base.py", line 896, in _resolve_lookup
    current = current[int(bit)]
                      ^^^^^^^^
ValueError: invalid literal for int() with base 10: 'company_name'

During handling of the above exception, another exception occurred:

Traceback (most recent call last):
  File "/home/horeb/github/easygo/venv/lib/python3.11/site-packages/django/template/base.py", line 903, in _resolve_lookup
    raise VariableDoesNotExist(
django.template.base.VariableDoesNotExist: Failed lookup for key [company_name] in [{'True': True, 'False': False, 'None': None}, {'name': 'Steven CHRISTIE', 'contact': '0422184319', 'email': 'ezi2c@hotmail.com', 'flight_date': datetime.date(2023, 9, 30), 'pickup_time': '12:01', 'flight_number': '13 Maple Grove, Kellyville Ridge', 'street': 'WHITE BAY CRUISE TERMINAL', 'no_of_passenger': '4', 'no_of_baggage': '6', 'return_flight_date': datetime.date(2023, 10, 9), 'return_flight_number': 'CIRCULAR QUAY CRUISE TERMINAL', 'return_pickup_time': '07:30', 'message': 'Hello, \r\nCould you please supply a quote for transport for a family of Four with luggage from Kellyville Ridge (P/C 2155)\r\nWe will require Drop Off & Pick Up please from our P&O Cruise which departs in the evening from the White Bay Cruise Terminal on the 30th September, 2023 & returns early in the morning on the 9th October, 2023 at the Circular Quay Cruise Terminal, with return transport to our residence.\r\nThank you\r\nRegards\r\nSteven CHRISTIE \r\nMob: 0422184319', 'price': '360', 'notice': '', 'private_ride': False}]
DEBUG 2024-01-10 00:10:12,043 base Exception while resolving variable 'company_name' in template 'basecamp/html_email-inquiry-response-p2p.html'.
Traceback (most recent call last):
  File "/home/horeb/github/easygo/venv/lib/python3.11/site-packages/django/template/base.py", line 880, in _resolve_lookup
    current = current[bit]
              ~~~~~~~^^^^^
  File "/home/horeb/github/easygo/venv/lib/python3.11/site-packages/django/template/context.py", line 83, in __getitem__
    raise KeyError(key)
KeyError: 'company_name'

During handling of the above exception, another exception occurred:

Traceback (most recent call last):
  File "/home/horeb/github/easygo/venv/lib/python3.11/site-packages/django/template/base.py", line 886, in _resolve_lookup
    if isinstance(current, BaseContext) and getattr(
                                            ^^^^^^^^
AttributeError: type object 'Context' has no attribute 'company_name'

During handling of the above exception, another exception occurred:

Traceback (most recent call last):
  File "/home/horeb/github/easygo/venv/lib/python3.11/site-packages/django/template/base.py", line 896, in _resolve_lookup
    current = current[int(bit)]
                      ^^^^^^^^
ValueError: invalid literal for int() with base 10: 'company_name'

During handling of the above exception, another exception occurred:

Traceback (most recent call last):
  File "/home/horeb/github/easygo/venv/lib/python3.11/site-packages/django/template/base.py", line 903, in _resolve_lookup
    raise VariableDoesNotExist(
django.template.base.VariableDoesNotExist: Failed lookup for key [company_name] in [{'True': True, 'False': False, 'None': None}, {'name': 'James', 'contact': '0448474448', 'email': 'james.walker22email@gmail.com', 'flight_date': datetime.date(2023, 11, 17), 'pickup_time': '05:45', 'flight_number': '20 Anglo Street', 'street': 'Sydney Domestic Airport', 'no_of_passenger': '7', 'no_of_baggage': '8 bags', 'return_flight_date': datetime.date(2023, 11, 24), 'return_flight_number': 'Sydney Domestic', 'return_pickup_time': '17:00', 'message': 'Shuttle to Sydney Domestic 7 people plus bags on the way there. Only 5 people needed for the return pickup. Please quote separately.', 'price': '240', 'notice': '', 'private_ride': False}]
DEBUG 2024-01-10 00:10:12,047 base Exception while resolving variable 'company_name' in template 'basecamp/html_email-inquiry-response-p2p.html'.
Traceback (most recent call last):
  File "/home/horeb/github/easygo/venv/lib/python3.11/site-packages/django/template/base.py", line 880, in _resolve_lookup
    current = current[bit]
              ~~~~~~~^^^^^
  File "/home/horeb/github/easygo/venv/lib/python3.11/site-packages/django/template/context.py", line 83, in __getitem__
    raise KeyError(key)
KeyError: 'company_name'

During handling of the above exception, another exception occurred:

Traceback (most recent call last):
  File "/home/horeb/github/easygo/venv/lib/python3.11/site-packages/django/template/base.py", line 886, in _resolve_lookup
    if isinstance(current, BaseContext) and getattr(
                                            ^^^^^^^^
AttributeError: type object 'Context' has no attribute 'company_name'

During handling of the above exception, another exception occurred:

Traceback (most recent call last):
  File "/home/horeb/github/easygo/venv/lib/python3.11/site-packages/django/template/base.py", line 896, in _resolve_lookup
    current = current[int(bit)]
                      ^^^^^^^^
ValueError: invalid literal for int() with base 10: 'company_name'

During handling of the above exception, another exception occurred:

Traceback (most recent call last):
  File "/home/horeb/github/easygo/venv/lib/python3.11/site-packages/django/template/base.py", line 903, in _resolve_lookup
    raise VariableDoesNotExist(
django.template.base.VariableDoesNotExist: Failed lookup for key [company_name] in [{'True': True, 'False': False, 'None': None}, {'name': 'E Ning Liew', 'contact': '+6597317991', 'email': 'eningliew@gmail.com', 'flight_date': datetime.date(2023, 10, 11), 'pickup_time': '16:00', 'flight_number': '17 Nelson Street Thornleigh 2120', 'street': 'Circular Quay Wharf 6 (to reach by 5pm)', 'no_of_passenger': '11', 'no_of_baggage': '0', 'return_flight_date': datetime.date(2023, 10, 7), 'return_flight_number': 'Circular Quay', 'return_pickup_time': '21:00', 'message': 'Hi Peter,\r\nJerry Liew here, submitting the booking for 11 Oct. Return trip will be from Circular Quay back to 17 Nelson Street Thornleigh 2021', 'price': '350', 'notice': '', 'private_ride': False}]
DEBUG 2024-01-10 00:10:12,051 base Exception while resolving variable 'company_name' in template 'basecamp/html_email-inquiry-response-p2p.html'.
Traceback (most recent call last):
  File "/home/horeb/github/easygo/venv/lib/python3.11/site-packages/django/template/base.py", line 880, in _resolve_lookup
    current = current[bit]
              ~~~~~~~^^^^^
  File "/home/horeb/github/easygo/venv/lib/python3.11/site-packages/django/template/context.py", line 83, in __getitem__
    raise KeyError(key)
KeyError: 'company_name'

During handling of the above exception, another exception occurred:

Traceback (most recent call last):
  File "/home/horeb/github/easygo/venv/lib/python3.11/site-packages/django/template/base.py", line 886, in _resolve_lookup
    if isinstance(current, BaseContext) and getattr(
                                            ^^^^^^^^
AttributeError: type object 'Context' has no attribute 'company_name'

During handling of the above exception, another exception occurred:

Traceback (most recent call last):
  File "/home/horeb/github/easygo/venv/lib/python3.11/site-packages/django/template/base.py", line 896, in _resolve_lookup
    current = current[int(bit)]
                      ^^^^^^^^
ValueError: invalid literal for int() with base 10: 'company_name'

During handling of the above exception, another exception occurred:

Traceback (most recent call last):
  File "/home/horeb/github/easygo/venv/lib/python3.11/site-packages/django/template/base.py", line 903, in _resolve_lookup
    raise VariableDoesNotExist(
django.template.base.VariableDoesNotExist: Failed lookup for key [company_name] in [{'True': True, 'False': False, 'None': None}, {'name': 'Phil Sanders', 'contact': '+61417677036', 'email': 'philsanders1953@gmail.com', 'flight_date': datetime.date(2023, 12, 3), 'pickup_time': '09:30', 'flight_number': 'Normanhurst', 'street': 'White Bay Cruise Terminal', 'no_of_passenger': '4', 'no_of_baggage': '4 suitcases, 4 hand luggage', 'return_flight_date': datetime.date(2023, 12, 11), 'return_flight_number': 'Circular Quay', 'return_pickup_time': '10:00', 'message': '', 'price': '260', 'notice': '', 'private_ride': False}]
DEBUG 2024-01-10 00:10:12,056 base Exception while resolving variable 'company_name' in template 'basecamp/html_email-inquiry-response-p2p.html'.
Traceback (most recent call last):
  File "/home/horeb/github/easygo/venv/lib/python3.11/site-packages/django/template/base.py", line 880, in _resolve_lookup
    current = current[bit]
              ~~~~~~~^^^^^
  File "/home/horeb/github/easygo/venv/lib/python3.11/site-packages/django/template/context.py", line 83, in __getitem__
    raise KeyError(key)
KeyError: 'company_name'

During handling of the above exception, another exception occurred:

Traceback (most recent call last):
  File "/home/horeb/github/easygo/venv/lib/python3.11/site-packages/django/template/base.py", line 886, in _resolve_lookup
    if isinstance(current, BaseContext) and getattr(
                                            ^^^^^^^^
AttributeError: type object 'Context' has no attribute 'company_name'

During handling of the above exception, another exception occurred:

Traceback (most recent call last):
  File "/home/horeb/github/easygo/venv/lib/python3.11/site-packages/django/template/base.py", line 896, in _resolve_lookup
    current = current[int(bit)]
                      ^^^^^^^^
ValueError: invalid literal for int() with base 10: 'company_name'

During handling of the above exception, another exception occurred:

Traceback (most recent call last):
  File "/home/horeb/github/easygo/venv/lib/python3.11/site-packages/django/template/base.py", line 903, in _resolve_lookup
    raise VariableDoesNotExist(
django.template.base.VariableDoesNotExist: Failed lookup for key [company_name] in [{'True': True, 'False': False, 'None': None}, {'name': 'Greg Townend', 'contact': '0414572472', 'email': 'gtownend@gmail.com', 'flight_date': datetime.date(2023, 12, 1), 'pickup_time': '11:00', 'flight_number': '25A Good Street Westmead', 'street': 'Sydney cruise terminal', 'no_of_passenger': '2', 'no_of_baggage': '2', 'return_flight_date': datetime.date(2023, 12, 8), 'return_flight_number': 'Sydney cruise terminal', 'return_pickup_time': '08:00', 'message': '', 'price': '240 (inc tolls)', 'notice': 'This cost is for a return trip', 'private_ride': False}]
DEBUG 2024-01-10 00:10:12,060 base Exception while resolving variable 'company_name' in template 'basecamp/html_email-inquiry-response-p2p.html'.
Traceback (most recent call last):
  File "/home/horeb/github/easygo/venv/lib/python3.11/site-packages/django/template/base.py", line 880, in _resolve_lookup
    current = current[bit]
              ~~~~~~~^^^^^
  File "/home/horeb/github/easygo/venv/lib/python3.11/site-packages/django/template/context.py", line 83, in __getitem__
    raise KeyError(key)
KeyError: 'company_name'

During handling of the above exception, another exception occurred:

Traceback (most recent call last):
  File "/home/horeb/github/easygo/venv/lib/python3.11/site-packages/django/template/base.py", line 886, in _resolve_lookup
    if isinstance(current, BaseContext) and getattr(
                                            ^^^^^^^^
AttributeError: type object 'Context' has no attribute 'company_name'

During handling of the above exception, another exception occurred:

Traceback (most recent call last):
  File "/home/horeb/github/easygo/venv/lib/python3.11/site-packages/django/template/base.py", line 896, in _resolve_lookup
    current = current[int(bit)]
                      ^^^^^^^^
ValueError: invalid literal for int() with base 10: 'company_name'

During handling of the above exception, another exception occurred:

Traceback (most recent call last):
  File "/home/horeb/github/easygo/venv/lib/python3.11/site-packages/django/template/base.py", line 903, in _resolve_lookup
    raise VariableDoesNotExist(
django.template.base.VariableDoesNotExist: Failed lookup for key [company_name] in [{'True': True, 'False': False, 'None': None}, {'name': 'Ben Smith', 'contact': '0432546913', 'email': 'benandbecsmith@gmail.com', 'flight_date': datetime.date(2023, 12, 3), 'pickup_time': '09:30', 'flight_number': 'Jasmine Road Normanhurst (outside Normanhurst boys near bottom of the hill)', 'street': 'White bay cruise terminal', 'no_of_passenger': '8', 'no_of_baggage': 'x8 bags, x8 hand luggage/backpacks', 'return_flight_date': datetime.date(2023, 11, 20), 'return_flight_number': None, 'return_pickup_time': None, 'message': 'x8 passengers - ONE WAY TRIP - NO RETURN JOURNEY Pick up - from Jasmine road Normanhurst (outside Normanhurst boys) \r\nDrop off - White bay cruise terminal.\r\n\r\nx2 car seats for x1 five year old, x1 (large) two-year-old.\r\nx6 adults/teenagers\r\n\r\nMy parents and inlaws are also being picked up by you at the same time and location. (booking Phillip Sanders)', 'price': '160', 'notice': '', 'private_ride': False}]
DEBUG 2024-01-10 00:10:12,067 base Exception while resolving variable 'company_name' in template 'basecamp/html_email-inquiry-response-p2p.html'.
Traceback (most recent call last):
  File "/home/horeb/github/easygo/venv/lib/python3.11/site-packages/django/template/base.py", line 880, in _resolve_lookup
    current = current[bit]
              ~~~~~~~^^^^^
  File "/home/horeb/github/easygo/venv/lib/python3.11/site-packages/django/template/context.py", line 83, in __getitem__
    raise KeyError(key)
KeyError: 'company_name'

During handling of the above exception, another exception occurred:

Traceback (most recent call last):
  File "/home/horeb/github/easygo/venv/lib/python3.11/site-packages/django/template/base.py", line 886, in _resolve_lookup
    if isinstance(current, BaseContext) and getattr(
                                            ^^^^^^^^
AttributeError: type object 'Context' has no attribute 'company_name'

During handling of the above exception, another exception occurred:

Traceback (most recent call last):
  File "/home/horeb/github/easygo/venv/lib/python3.11/site-packages/django/template/base.py", line 896, in _resolve_lookup
    current = current[int(bit)]
                      ^^^^^^^^
ValueError: invalid literal for int() with base 10: 'company_name'

During handling of the above exception, another exception occurred:

Traceback (most recent call last):
  File "/home/horeb/github/easygo/venv/lib/python3.11/site-packages/django/template/base.py", line 903, in _resolve_lookup
    raise VariableDoesNotExist(
django.template.base.VariableDoesNotExist: Failed lookup for key [company_name] in [{'True': True, 'False': False, 'None': None}, {'name': 'Farshid Kazemi', 'contact': '0497702201', 'email': 'Kazemieng@yahoo.com', 'flight_date': datetime.date(2023, 12, 3), 'pickup_time': '13:00', 'flight_number': '81-83 Kissing Point Road Dundas 2117', 'street': 'White Bay Cruise Terminal James Craig Road Rozelle', 'no_of_passenger': '3', 'no_of_baggage': '4', 'return_flight_date': datetime.date(2023, 12, 11), 'return_flight_number': 'Circular quay to Dundas', 'return_pickup_time': '07:00', 'message': 'Pickup@1pm', 'price': '200', 'notice': '', 'private_ride': False}]
DEBUG 2024-01-10 00:10:12,071 base Exception while resolving variable 'company_name' in template 'basecamp/html_email-inquiry-response-p2p.html'.
Traceback (most recent call last):
  File "/home/horeb/github/easygo/venv/lib/python3.11/site-packages/django/template/base.py", line 880, in _resolve_lookup
    current = current[bit]
              ~~~~~~~^^^^^
  File "/home/horeb/github/easygo/venv/lib/python3.11/site-packages/django/template/context.py", line 83, in __getitem__
    raise KeyError(key)
KeyError: 'company_name'

During handling of the above exception, another exception occurred:

Traceback (most recent call last):
  File "/home/horeb/github/easygo/venv/lib/python3.11/site-packages/django/template/base.py", line 886, in _resolve_lookup
    if isinstance(current, BaseContext) and getattr(
                                            ^^^^^^^^
AttributeError: type object 'Context' has no attribute 'company_name'

During handling of the above exception, another exception occurred:

Traceback (most recent call last):
  File "/home/horeb/github/easygo/venv/lib/python3.11/site-packages/django/template/base.py", line 896, in _resolve_lookup
    current = current[int(bit)]
                      ^^^^^^^^
ValueError: invalid literal for int() with base 10: 'company_name'

During handling of the above exception, another exception occurred:

Traceback (most recent call last):
  File "/home/horeb/github/easygo/venv/lib/python3.11/site-packages/django/template/base.py", line 903, in _resolve_lookup
    raise VariableDoesNotExist(
django.template.base.VariableDoesNotExist: Failed lookup for key [company_name] in [{'True': True, 'False': False, 'None': None}, {'name': 'JOANNA FUNNELL', 'contact': 'TBN', 'email': 'joannafun1970@hotmail.com', 'flight_date': datetime.date(2024, 1, 19), 'pickup_time': '11:30', 'flight_number': 'castle hill', 'street': 'circular quay', 'no_of_passenger': '4', 'no_of_baggage': '4', 'return_flight_date': datetime.date(2024, 1, 27), 'return_flight_number': 'circular quay', 'return_pickup_time': '08:30', 'message': '', 'price': '280', 'notice': '', 'private_ride': False}]
WARNING 2024-01-10 00:16:24,355 log Not Found: /wp-content/themes/purevision/scripts/admin/uploadify/uploadify.css
WARNING 2024-01-10 00:25:47,153 log Not Found: /robots.txt
WARNING 2024-01-10 00:28:18,296 log Not Found: /shop/fr/product/moncler-bryone-down-jacket-pour-femme-rouge/
ERROR 2024-01-10 00:34:14,587 log Internal Server Error: /horeb_yhwh/blog/post/2909/change/
Traceback (most recent call last):
  File "/home/horeb/github/easygo/venv/lib/python3.11/site-packages/django/db/backends/utils.py", line 89, in _execute
    return self.cursor.execute(sql, params)
           ^^^^^^^^^^^^^^^^^^^^^^^^^^^^^^^^
  File "/home/horeb/github/easygo/venv/lib/python3.11/site-packages/django/db/backends/sqlite3/base.py", line 328, in execute
    return super().execute(query, params)
           ^^^^^^^^^^^^^^^^^^^^^^^^^^^^^^
sqlite3.IntegrityError: NOT NULL constraint failed: blog_post.email1

The above exception was the direct cause of the following exception:

Traceback (most recent call last):
  File "/home/horeb/github/easygo/venv/lib/python3.11/site-packages/django/core/handlers/exception.py", line 55, in inner
    response = get_response(request)
               ^^^^^^^^^^^^^^^^^^^^^
  File "/home/horeb/github/easygo/venv/lib/python3.11/site-packages/django/core/handlers/base.py", line 197, in _get_response
    response = wrapped_callback(request, *callback_args, **callback_kwargs)
               ^^^^^^^^^^^^^^^^^^^^^^^^^^^^^^^^^^^^^^^^^^^^^^^^^^^^^^^^^^^^
  File "/home/horeb/github/easygo/venv/lib/python3.11/site-packages/django/contrib/admin/options.py", line 688, in wrapper
    return self.admin_site.admin_view(view)(*args, **kwargs)
           ^^^^^^^^^^^^^^^^^^^^^^^^^^^^^^^^^^^^^^^^^^^^^^^^^
  File "/home/horeb/github/easygo/venv/lib/python3.11/site-packages/django/utils/decorators.py", line 134, in _wrapper_view
    response = view_func(request, *args, **kwargs)
               ^^^^^^^^^^^^^^^^^^^^^^^^^^^^^^^^^^^
  File "/home/horeb/github/easygo/venv/lib/python3.11/site-packages/django/views/decorators/cache.py", line 62, in _wrapper_view_func
    response = view_func(request, *args, **kwargs)
               ^^^^^^^^^^^^^^^^^^^^^^^^^^^^^^^^^^^
  File "/home/horeb/github/easygo/venv/lib/python3.11/site-packages/django/contrib/admin/sites.py", line 242, in inner
    return view(request, *args, **kwargs)
           ^^^^^^^^^^^^^^^^^^^^^^^^^^^^^^
  File "/home/horeb/github/easygo/venv/lib/python3.11/site-packages/django/contrib/admin/options.py", line 1889, in change_view
    return self.changeform_view(request, object_id, form_url, extra_context)
           ^^^^^^^^^^^^^^^^^^^^^^^^^^^^^^^^^^^^^^^^^^^^^^^^^^^^^^^^^^^^^^^^^
  File "/home/horeb/github/easygo/venv/lib/python3.11/site-packages/django/utils/decorators.py", line 46, in _wrapper
    return bound_method(*args, **kwargs)
           ^^^^^^^^^^^^^^^^^^^^^^^^^^^^^
  File "/home/horeb/github/easygo/venv/lib/python3.11/site-packages/django/utils/decorators.py", line 134, in _wrapper_view
    response = view_func(request, *args, **kwargs)
               ^^^^^^^^^^^^^^^^^^^^^^^^^^^^^^^^^^^
  File "/home/horeb/github/easygo/venv/lib/python3.11/site-packages/django/contrib/admin/options.py", line 1747, in changeform_view
    return self._changeform_view(request, object_id, form_url, extra_context)
           ^^^^^^^^^^^^^^^^^^^^^^^^^^^^^^^^^^^^^^^^^^^^^^^^^^^^^^^^^^^^^^^^^^
  File "/home/horeb/github/easygo/venv/lib/python3.11/site-packages/django/contrib/admin/options.py", line 1798, in _changeform_view
    self.save_model(request, new_object, form, not add)
  File "/home/horeb/github/easygo/venv/lib/python3.11/site-packages/django/contrib/admin/options.py", line 1227, in save_model
    obj.save()
  File "/home/horeb/github/easygo/venv/lib/python3.11/site-packages/django/db/models/base.py", line 814, in save
    self.save_base(
  File "/home/horeb/github/easygo/venv/lib/python3.11/site-packages/django/db/models/base.py", line 877, in save_base
    updated = self._save_table(
              ^^^^^^^^^^^^^^^^^
  File "/home/horeb/github/easygo/venv/lib/python3.11/site-packages/django/db/models/base.py", line 990, in _save_table
    updated = self._do_update(
              ^^^^^^^^^^^^^^^^
  File "/home/horeb/github/easygo/venv/lib/python3.11/site-packages/django/db/models/base.py", line 1054, in _do_update
    return filtered._update(values) > 0
           ^^^^^^^^^^^^^^^^^^^^^^^^
  File "/home/horeb/github/easygo/venv/lib/python3.11/site-packages/django/db/models/query.py", line 1231, in _update
    return query.get_compiler(self.db).execute_sql(CURSOR)
           ^^^^^^^^^^^^^^^^^^^^^^^^^^^^^^^^^^^^^^^^^^^^^^^
  File "/home/horeb/github/easygo/venv/lib/python3.11/site-packages/django/db/models/sql/compiler.py", line 1984, in execute_sql
    cursor = super().execute_sql(result_type)
             ^^^^^^^^^^^^^^^^^^^^^^^^^^^^^^^^
  File "/home/horeb/github/easygo/venv/lib/python3.11/site-packages/django/db/models/sql/compiler.py", line 1562, in execute_sql
    cursor.execute(sql, params)
  File "/home/horeb/github/easygo/venv/lib/python3.11/site-packages/django/db/backends/utils.py", line 67, in execute
    return self._execute_with_wrappers(
           ^^^^^^^^^^^^^^^^^^^^^^^^^^^^
  File "/home/horeb/github/easygo/venv/lib/python3.11/site-packages/django/db/backends/utils.py", line 80, in _execute_with_wrappers
    return executor(sql, params, many, context)
           ^^^^^^^^^^^^^^^^^^^^^^^^^^^^^^^^^^^^
  File "/home/horeb/github/easygo/venv/lib/python3.11/site-packages/django/db/backends/utils.py", line 84, in _execute
    with self.db.wrap_database_errors:
  File "/home/horeb/github/easygo/venv/lib/python3.11/site-packages/django/db/utils.py", line 91, in __exit__
    raise dj_exc_value.with_traceback(traceback) from exc_value
  File "/home/horeb/github/easygo/venv/lib/python3.11/site-packages/django/db/backends/utils.py", line 89, in _execute
    return self.cursor.execute(sql, params)
           ^^^^^^^^^^^^^^^^^^^^^^^^^^^^^^^^
  File "/home/horeb/github/easygo/venv/lib/python3.11/site-packages/django/db/backends/sqlite3/base.py", line 328, in execute
    return super().execute(query, params)
           ^^^^^^^^^^^^^^^^^^^^^^^^^^^^^^
django.db.utils.IntegrityError: NOT NULL constraint failed: blog_post.email1
