WARNING 2024-01-30 06:30:01,617 log Not Found: /style.php
WARNING 2024-01-30 06:51:58,747 log Not Found: /product/moncler-coat-men-hooded-fur-collar-blue/
WARNING 2024-01-30 07:56:11,428 log Not Found: /.well-known/traffic-advice
WARNING 2024-01-30 07:56:11,432 log Not Found: /.well-known/traffic-advice
WARNING 2024-01-30 07:56:30,475 log Not Found: //wp-includes/wlwmanifest.xml
WARNING 2024-01-30 07:56:30,880 log Not Found: //xmlrpc.php
WARNING 2024-01-30 07:56:31,708 log Not Found: //blog/wp-includes/wlwmanifest.xml
WARNING 2024-01-30 07:56:32,132 log Not Found: //web/wp-includes/wlwmanifest.xml
WARNING 2024-01-30 07:56:32,575 log Not Found: //wordpress/wp-includes/wlwmanifest.xml
WARNING 2024-01-30 07:56:33,002 log Not Found: //website/wp-includes/wlwmanifest.xml
WARNING 2024-01-30 07:56:33,405 log Not Found: //wp/wp-includes/wlwmanifest.xml
WARNING 2024-01-30 07:56:33,795 log Not Found: //news/wp-includes/wlwmanifest.xml
WARNING 2024-01-30 07:56:34,157 log Not Found: //2020/wp-includes/wlwmanifest.xml
WARNING 2024-01-30 07:56:34,503 log Not Found: //2019/wp-includes/wlwmanifest.xml
WARNING 2024-01-30 07:56:34,875 log Not Found: //shop/wp-includes/wlwmanifest.xml
WARNING 2024-01-30 07:56:35,217 log Not Found: //wp1/wp-includes/wlwmanifest.xml
WARNING 2024-01-30 07:56:35,577 log Not Found: //test/wp-includes/wlwmanifest.xml
WARNING 2024-01-30 07:56:35,958 log Not Found: //wp2/wp-includes/wlwmanifest.xml
WARNING 2024-01-30 07:56:36,350 log Not Found: //site/wp-includes/wlwmanifest.xml
WARNING 2024-01-30 07:56:36,741 log Not Found: //cms/wp-includes/wlwmanifest.xml
WARNING 2024-01-30 07:56:37,075 log Not Found: //sito/wp-includes/wlwmanifest.xml
WARNING 2024-01-30 07:57:22,734 log Not Found: /shop/product/kids-moncler-vest-boy-gray/
WARNING 2024-01-30 08:45:07,550 log Not Found: /robots.txt
WARNING 2024-01-30 08:45:53,725 log Not Found: /shop/nn/product/moncler-down-coat-menn-midt-lengde-med-hett-kaffe/
WARNING 2024-01-30 09:12:36,070 log Not Found: /ads.txt
WARNING 2024-01-30 09:50:26,172 log Not Found: /.git/config
WARNING 2024-01-30 10:00:00,763 log Not Found: /robots.txt
DEBUG 2024-01-30 10:04:21,017 base Exception while resolving variable 'subtitle' in template 'admin_honeypot/login.html'.
Traceback (most recent call last):
  File "/home/horeb/github/easygo/venv/lib/python3.11/site-packages/django/template/base.py", line 880, in _resolve_lookup
    current = current[bit]
              ~~~~~~~^^^^^
  File "/home/horeb/github/easygo/venv/lib/python3.11/site-packages/django/template/context.py", line 83, in __getitem__
    raise KeyError(key)
KeyError: 'subtitle'

During handling of the above exception, another exception occurred:

Traceback (most recent call last):
  File "/home/horeb/github/easygo/venv/lib/python3.11/site-packages/django/template/base.py", line 886, in _resolve_lookup
    if isinstance(current, BaseContext) and getattr(
                                            ^^^^^^^^
AttributeError: type object 'RequestContext' has no attribute 'subtitle'

During handling of the above exception, another exception occurred:

Traceback (most recent call last):
  File "/home/horeb/github/easygo/venv/lib/python3.11/site-packages/django/template/base.py", line 896, in _resolve_lookup
    current = current[int(bit)]
                      ^^^^^^^^
ValueError: invalid literal for int() with base 10: 'subtitle'

During handling of the above exception, another exception occurred:

Traceback (most recent call last):
  File "/home/horeb/github/easygo/venv/lib/python3.11/site-packages/django/template/base.py", line 903, in _resolve_lookup
    raise VariableDoesNotExist(
django.template.base.VariableDoesNotExist: Failed lookup for key [subtitle] in [{'True': True, 'False': False, 'None': None}, {'csrf_token': <SimpleLazyObject: <function csrf.<locals>._get_val at 0x7fb7b45ed8a0>>, 'request': <WSGIRequest: GET '/admin/login/?next=/admin/'>, 'user': <SimpleLazyObject: <function AuthenticationMiddleware.process_request.<locals>.<lambda> at 0x7fb7b45ed580>>, 'perms': PermWrapper(<SimpleLazyObject: <function AuthenticationMiddleware.process_request.<locals>.<lambda> at 0x7fb7b45ed580>>), 'messages': <FallbackStorage: request=<WSGIRequest: GET '/admin/login/?next=/admin/'>>, 'DEFAULT_MESSAGE_LEVELS': {'DEBUG': 10, 'INFO': 20, 'SUCCESS': 25, 'WARNING': 30, 'ERROR': 40}}, {}, {'form': <HoneypotLoginForm bound=False, valid=Unknown, fields=(username;password)>, 'view': <admin_honeypot.views.AdminHoneypot object at 0x7fb7b4311410>, 'app_path': '/admin/login/?next=/admin/', 'next': '/admin/', 'title': 'Log in', 'LANGUAGE_CODE': 'en-us', 'LANGUAGE_BIDI': False}, {'block': <Block Node: title. Contents: [<IfNode>, <Variable Node: title>, <TextNode: ' | '>, <Variable Node: site_title|default:_('Django site admin')>]>}]
DEBUG 2024-01-30 10:04:21,019 base Exception while resolving variable 'site_title' in template 'admin_honeypot/login.html'.
Traceback (most recent call last):
  File "/home/horeb/github/easygo/venv/lib/python3.11/site-packages/django/template/base.py", line 880, in _resolve_lookup
    current = current[bit]
              ~~~~~~~^^^^^
  File "/home/horeb/github/easygo/venv/lib/python3.11/site-packages/django/template/context.py", line 83, in __getitem__
    raise KeyError(key)
KeyError: 'site_title'

During handling of the above exception, another exception occurred:

Traceback (most recent call last):
  File "/home/horeb/github/easygo/venv/lib/python3.11/site-packages/django/template/base.py", line 886, in _resolve_lookup
    if isinstance(current, BaseContext) and getattr(
                                            ^^^^^^^^
AttributeError: type object 'RequestContext' has no attribute 'site_title'

During handling of the above exception, another exception occurred:

Traceback (most recent call last):
  File "/home/horeb/github/easygo/venv/lib/python3.11/site-packages/django/template/base.py", line 896, in _resolve_lookup
    current = current[int(bit)]
                      ^^^^^^^^
ValueError: invalid literal for int() with base 10: 'site_title'

During handling of the above exception, another exception occurred:

Traceback (most recent call last):
  File "/home/horeb/github/easygo/venv/lib/python3.11/site-packages/django/template/base.py", line 903, in _resolve_lookup
    raise VariableDoesNotExist(
django.template.base.VariableDoesNotExist: Failed lookup for key [site_title] in [{'True': True, 'False': False, 'None': None}, {'csrf_token': <SimpleLazyObject: <function csrf.<locals>._get_val at 0x7fb7b45ed8a0>>, 'request': <WSGIRequest: GET '/admin/login/?next=/admin/'>, 'user': <SimpleLazyObject: <function AuthenticationMiddleware.process_request.<locals>.<lambda> at 0x7fb7b45ed580>>, 'perms': PermWrapper(<SimpleLazyObject: <function AuthenticationMiddleware.process_request.<locals>.<lambda> at 0x7fb7b45ed580>>), 'messages': <FallbackStorage: request=<WSGIRequest: GET '/admin/login/?next=/admin/'>>, 'DEFAULT_MESSAGE_LEVELS': {'DEBUG': 10, 'INFO': 20, 'SUCCESS': 25, 'WARNING': 30, 'ERROR': 40}}, {}, {'form': <HoneypotLoginForm bound=False, valid=Unknown, fields=(username;password)>, 'view': <admin_honeypot.views.AdminHoneypot object at 0x7fb7b4311410>, 'app_path': '/admin/login/?next=/admin/', 'next': '/admin/', 'title': 'Log in', 'LANGUAGE_CODE': 'en-us', 'LANGUAGE_BIDI': False}, {'block': <Block Node: title. Contents: [<IfNode>, <Variable Node: title>, <TextNode: ' | '>, <Variable Node: site_title|default:_('Django site admin')>]>}]
DEBUG 2024-01-30 10:04:21,020 base Exception while resolving variable 'is_popup' in template 'admin_honeypot/login.html'.
Traceback (most recent call last):
  File "/home/horeb/github/easygo/venv/lib/python3.11/site-packages/django/template/base.py", line 880, in _resolve_lookup
    current = current[bit]
              ~~~~~~~^^^^^
  File "/home/horeb/github/easygo/venv/lib/python3.11/site-packages/django/template/context.py", line 83, in __getitem__
    raise KeyError(key)
KeyError: 'is_popup'

During handling of the above exception, another exception occurred:

Traceback (most recent call last):
  File "/home/horeb/github/easygo/venv/lib/python3.11/site-packages/django/template/base.py", line 886, in _resolve_lookup
    if isinstance(current, BaseContext) and getattr(
                                            ^^^^^^^^
AttributeError: type object 'RequestContext' has no attribute 'is_popup'

During handling of the above exception, another exception occurred:

Traceback (most recent call last):
  File "/home/horeb/github/easygo/venv/lib/python3.11/site-packages/django/template/base.py", line 896, in _resolve_lookup
    current = current[int(bit)]
                      ^^^^^^^^
ValueError: invalid literal for int() with base 10: 'is_popup'

During handling of the above exception, another exception occurred:

Traceback (most recent call last):
  File "/home/horeb/github/easygo/venv/lib/python3.11/site-packages/django/template/base.py", line 903, in _resolve_lookup
    raise VariableDoesNotExist(
django.template.base.VariableDoesNotExist: Failed lookup for key [is_popup] in [{'True': True, 'False': False, 'None': None}, {'csrf_token': <SimpleLazyObject: <function csrf.<locals>._get_val at 0x7fb7b45ed8a0>>, 'request': <WSGIRequest: GET '/admin/login/?next=/admin/'>, 'user': <SimpleLazyObject: <function AuthenticationMiddleware.process_request.<locals>.<lambda> at 0x7fb7b45ed580>>, 'perms': PermWrapper(<SimpleLazyObject: <function AuthenticationMiddleware.process_request.<locals>.<lambda> at 0x7fb7b45ed580>>), 'messages': <FallbackStorage: request=<WSGIRequest: GET '/admin/login/?next=/admin/'>>, 'DEFAULT_MESSAGE_LEVELS': {'DEBUG': 10, 'INFO': 20, 'SUCCESS': 25, 'WARNING': 30, 'ERROR': 40}}, {}, {'form': <HoneypotLoginForm bound=False, valid=Unknown, fields=(username;password)>, 'view': <admin_honeypot.views.AdminHoneypot object at 0x7fb7b4311410>, 'app_path': '/admin/login/?next=/admin/', 'next': '/admin/', 'title': 'Log in', 'LANGUAGE_CODE': 'en-us', 'LANGUAGE_BIDI': False}]
DEBUG 2024-01-30 10:04:21,020 base Exception while resolving variable 'is_nav_sidebar_enabled' in template 'admin_honeypot/login.html'.
Traceback (most recent call last):
  File "/home/horeb/github/easygo/venv/lib/python3.11/site-packages/django/template/base.py", line 880, in _resolve_lookup
    current = current[bit]
              ~~~~~~~^^^^^
  File "/home/horeb/github/easygo/venv/lib/python3.11/site-packages/django/template/context.py", line 83, in __getitem__
    raise KeyError(key)
KeyError: 'is_nav_sidebar_enabled'

During handling of the above exception, another exception occurred:

Traceback (most recent call last):
  File "/home/horeb/github/easygo/venv/lib/python3.11/site-packages/django/template/base.py", line 886, in _resolve_lookup
    if isinstance(current, BaseContext) and getattr(
                                            ^^^^^^^^
AttributeError: type object 'RequestContext' has no attribute 'is_nav_sidebar_enabled'

During handling of the above exception, another exception occurred:

Traceback (most recent call last):
  File "/home/horeb/github/easygo/venv/lib/python3.11/site-packages/django/template/base.py", line 896, in _resolve_lookup
    current = current[int(bit)]
                      ^^^^^^^^
ValueError: invalid literal for int() with base 10: 'is_nav_sidebar_enabled'

During handling of the above exception, another exception occurred:

Traceback (most recent call last):
  File "/home/horeb/github/easygo/venv/lib/python3.11/site-packages/django/template/base.py", line 903, in _resolve_lookup
    raise VariableDoesNotExist(
django.template.base.VariableDoesNotExist: Failed lookup for key [is_nav_sidebar_enabled] in [{'True': True, 'False': False, 'None': None}, {'csrf_token': <SimpleLazyObject: <function csrf.<locals>._get_val at 0x7fb7b45ed8a0>>, 'request': <WSGIRequest: GET '/admin/login/?next=/admin/'>, 'user': <SimpleLazyObject: <function AuthenticationMiddleware.process_request.<locals>.<lambda> at 0x7fb7b45ed580>>, 'perms': PermWrapper(<SimpleLazyObject: <function AuthenticationMiddleware.process_request.<locals>.<lambda> at 0x7fb7b45ed580>>), 'messages': <FallbackStorage: request=<WSGIRequest: GET '/admin/login/?next=/admin/'>>, 'DEFAULT_MESSAGE_LEVELS': {'DEBUG': 10, 'INFO': 20, 'SUCCESS': 25, 'WARNING': 30, 'ERROR': 40}}, {}, {'form': <HoneypotLoginForm bound=False, valid=Unknown, fields=(username;password)>, 'view': <admin_honeypot.views.AdminHoneypot object at 0x7fb7b4311410>, 'app_path': '/admin/login/?next=/admin/', 'next': '/admin/', 'title': 'Log in', 'LANGUAGE_CODE': 'en-us', 'LANGUAGE_BIDI': False}]
DEBUG 2024-01-30 10:04:21,021 base Exception while resolving variable 'is_popup' in template 'admin_honeypot/login.html'.
Traceback (most recent call last):
  File "/home/horeb/github/easygo/venv/lib/python3.11/site-packages/django/template/base.py", line 880, in _resolve_lookup
    current = current[bit]
              ~~~~~~~^^^^^
  File "/home/horeb/github/easygo/venv/lib/python3.11/site-packages/django/template/context.py", line 83, in __getitem__
    raise KeyError(key)
KeyError: 'is_popup'

During handling of the above exception, another exception occurred:

Traceback (most recent call last):
  File "/home/horeb/github/easygo/venv/lib/python3.11/site-packages/django/template/base.py", line 886, in _resolve_lookup
    if isinstance(current, BaseContext) and getattr(
                                            ^^^^^^^^
AttributeError: type object 'RequestContext' has no attribute 'is_popup'

During handling of the above exception, another exception occurred:

Traceback (most recent call last):
  File "/home/horeb/github/easygo/venv/lib/python3.11/site-packages/django/template/base.py", line 896, in _resolve_lookup
    current = current[int(bit)]
                      ^^^^^^^^
ValueError: invalid literal for int() with base 10: 'is_popup'

During handling of the above exception, another exception occurred:

Traceback (most recent call last):
  File "/home/horeb/github/easygo/venv/lib/python3.11/site-packages/django/template/base.py", line 903, in _resolve_lookup
    raise VariableDoesNotExist(
django.template.base.VariableDoesNotExist: Failed lookup for key [is_popup] in [{'True': True, 'False': False, 'None': None}, {'csrf_token': <SimpleLazyObject: <function csrf.<locals>._get_val at 0x7fb7b45ed8a0>>, 'request': <WSGIRequest: GET '/admin/login/?next=/admin/'>, 'user': <SimpleLazyObject: <function AuthenticationMiddleware.process_request.<locals>.<lambda> at 0x7fb7b45ed580>>, 'perms': PermWrapper(<SimpleLazyObject: <function AuthenticationMiddleware.process_request.<locals>.<lambda> at 0x7fb7b45ed580>>), 'messages': <FallbackStorage: request=<WSGIRequest: GET '/admin/login/?next=/admin/'>>, 'DEFAULT_MESSAGE_LEVELS': {'DEBUG': 10, 'INFO': 20, 'SUCCESS': 25, 'WARNING': 30, 'ERROR': 40}}, {}, {'form': <HoneypotLoginForm bound=False, valid=Unknown, fields=(username;password)>, 'view': <admin_honeypot.views.AdminHoneypot object at 0x7fb7b4311410>, 'app_path': '/admin/login/?next=/admin/', 'next': '/admin/', 'title': 'Log in', 'LANGUAGE_CODE': 'en-us', 'LANGUAGE_BIDI': False}]
DEBUG 2024-01-30 10:04:21,023 base Exception while resolving variable 'is_popup' in template 'admin_honeypot/login.html'.
Traceback (most recent call last):
  File "/home/horeb/github/easygo/venv/lib/python3.11/site-packages/django/template/base.py", line 880, in _resolve_lookup
    current = current[bit]
              ~~~~~~~^^^^^
  File "/home/horeb/github/easygo/venv/lib/python3.11/site-packages/django/template/context.py", line 83, in __getitem__
    raise KeyError(key)
KeyError: 'is_popup'

During handling of the above exception, another exception occurred:

Traceback (most recent call last):
  File "/home/horeb/github/easygo/venv/lib/python3.11/site-packages/django/template/base.py", line 886, in _resolve_lookup
    if isinstance(current, BaseContext) and getattr(
                                            ^^^^^^^^
AttributeError: type object 'RequestContext' has no attribute 'is_popup'

During handling of the above exception, another exception occurred:

Traceback (most recent call last):
  File "/home/horeb/github/easygo/venv/lib/python3.11/site-packages/django/template/base.py", line 896, in _resolve_lookup
    current = current[int(bit)]
                      ^^^^^^^^
ValueError: invalid literal for int() with base 10: 'is_popup'

During handling of the above exception, another exception occurred:

Traceback (most recent call last):
  File "/home/horeb/github/easygo/venv/lib/python3.11/site-packages/django/template/base.py", line 903, in _resolve_lookup
    raise VariableDoesNotExist(
django.template.base.VariableDoesNotExist: Failed lookup for key [is_popup] in [{'True': True, 'False': False, 'None': None}, {'csrf_token': <SimpleLazyObject: <function csrf.<locals>._get_val at 0x7fb7b45ed8a0>>, 'request': <WSGIRequest: GET '/admin/login/?next=/admin/'>, 'user': <SimpleLazyObject: <function AuthenticationMiddleware.process_request.<locals>.<lambda> at 0x7fb7b45ed580>>, 'perms': PermWrapper(<SimpleLazyObject: <function AuthenticationMiddleware.process_request.<locals>.<lambda> at 0x7fb7b45ed580>>), 'messages': <FallbackStorage: request=<WSGIRequest: GET '/admin/login/?next=/admin/'>>, 'DEFAULT_MESSAGE_LEVELS': {'DEBUG': 10, 'INFO': 20, 'SUCCESS': 25, 'WARNING': 30, 'ERROR': 40}}, {}, {'form': <HoneypotLoginForm bound=False, valid=Unknown, fields=(username;password)>, 'view': <admin_honeypot.views.AdminHoneypot object at 0x7fb7b4311410>, 'app_path': '/admin/login/?next=/admin/', 'next': '/admin/', 'title': 'Log in', 'LANGUAGE_CODE': 'en-us', 'LANGUAGE_BIDI': False}]
DEBUG 2024-01-30 10:04:21,023 base Exception while resolving variable 'site_header' in template 'admin_honeypot/login.html'.
Traceback (most recent call last):
  File "/home/horeb/github/easygo/venv/lib/python3.11/site-packages/django/template/base.py", line 880, in _resolve_lookup
    current = current[bit]
              ~~~~~~~^^^^^
  File "/home/horeb/github/easygo/venv/lib/python3.11/site-packages/django/template/context.py", line 83, in __getitem__
    raise KeyError(key)
KeyError: 'site_header'

During handling of the above exception, another exception occurred:

Traceback (most recent call last):
  File "/home/horeb/github/easygo/venv/lib/python3.11/site-packages/django/template/base.py", line 886, in _resolve_lookup
    if isinstance(current, BaseContext) and getattr(
                                            ^^^^^^^^
AttributeError: type object 'RequestContext' has no attribute 'site_header'

During handling of the above exception, another exception occurred:

Traceback (most recent call last):
  File "/home/horeb/github/easygo/venv/lib/python3.11/site-packages/django/template/base.py", line 896, in _resolve_lookup
    current = current[int(bit)]
                      ^^^^^^^^
ValueError: invalid literal for int() with base 10: 'site_header'

During handling of the above exception, another exception occurred:

Traceback (most recent call last):
  File "/home/horeb/github/easygo/venv/lib/python3.11/site-packages/django/template/base.py", line 903, in _resolve_lookup
    raise VariableDoesNotExist(
django.template.base.VariableDoesNotExist: Failed lookup for key [site_header] in [{'True': True, 'False': False, 'None': None}, {'csrf_token': <SimpleLazyObject: <function csrf.<locals>._get_val at 0x7fb7b45ed8a0>>, 'request': <WSGIRequest: GET '/admin/login/?next=/admin/'>, 'user': <SimpleLazyObject: <function AuthenticationMiddleware.process_request.<locals>.<lambda> at 0x7fb7b45ed580>>, 'perms': PermWrapper(<SimpleLazyObject: <function AuthenticationMiddleware.process_request.<locals>.<lambda> at 0x7fb7b45ed580>>), 'messages': <FallbackStorage: request=<WSGIRequest: GET '/admin/login/?next=/admin/'>>, 'DEFAULT_MESSAGE_LEVELS': {'DEBUG': 10, 'INFO': 20, 'SUCCESS': 25, 'WARNING': 30, 'ERROR': 40}}, {}, {'form': <HoneypotLoginForm bound=False, valid=Unknown, fields=(username;password)>, 'view': <admin_honeypot.views.AdminHoneypot object at 0x7fb7b4311410>, 'app_path': '/admin/login/?next=/admin/', 'next': '/admin/', 'title': 'Log in', 'LANGUAGE_CODE': 'en-us', 'LANGUAGE_BIDI': False}, {'block': <Block Node: header. Contents: [<TextNode: '\n    <div id="header">\n  '>, <Block Node: branding. Contents: []>, <TextNode: '\n        </div>\n        '>, <Block Node: usertools. Contents: [<TextNode: '\n        '>, <IfNode>, <TextNode: '\n        '>]>, <TextNode: '\n        '>, <Block Node: nav-global. Contents: []>, <TextNode: '\n    </div>\n    '>]>}, {'block': <Block Node: branding. Contents: [<TextNode: '\n<h1 id="site-name"><a hr'>, <URLNode view_name=''admin_honeypot:index'' args=[] kwargs={} as=None>, <TextNode: '">'>, <Variable Node: site_header|default:_('Django administration')>, <TextNode: '</a></h1>\n'>]>}]
DEBUG 2024-01-30 10:04:21,024 base Exception while resolving variable 'is_popup' in template 'admin_honeypot/login.html'.
Traceback (most recent call last):
  File "/home/horeb/github/easygo/venv/lib/python3.11/site-packages/django/template/base.py", line 880, in _resolve_lookup
    current = current[bit]
              ~~~~~~~^^^^^
  File "/home/horeb/github/easygo/venv/lib/python3.11/site-packages/django/template/context.py", line 83, in __getitem__
    raise KeyError(key)
KeyError: 'is_popup'

During handling of the above exception, another exception occurred:

Traceback (most recent call last):
  File "/home/horeb/github/easygo/venv/lib/python3.11/site-packages/django/template/base.py", line 886, in _resolve_lookup
    if isinstance(current, BaseContext) and getattr(
                                            ^^^^^^^^
AttributeError: type object 'RequestContext' has no attribute 'is_popup'

During handling of the above exception, another exception occurred:

Traceback (most recent call last):
  File "/home/horeb/github/easygo/venv/lib/python3.11/site-packages/django/template/base.py", line 896, in _resolve_lookup
    current = current[int(bit)]
                      ^^^^^^^^
ValueError: invalid literal for int() with base 10: 'is_popup'

During handling of the above exception, another exception occurred:

Traceback (most recent call last):
  File "/home/horeb/github/easygo/venv/lib/python3.11/site-packages/django/template/base.py", line 903, in _resolve_lookup
    raise VariableDoesNotExist(
django.template.base.VariableDoesNotExist: Failed lookup for key [is_popup] in [{'True': True, 'False': False, 'None': None}, {'csrf_token': <SimpleLazyObject: <function csrf.<locals>._get_val at 0x7fb7b45ed8a0>>, 'request': <WSGIRequest: GET '/admin/login/?next=/admin/'>, 'user': <SimpleLazyObject: <function AuthenticationMiddleware.process_request.<locals>.<lambda> at 0x7fb7b45ed580>>, 'perms': PermWrapper(<SimpleLazyObject: <function AuthenticationMiddleware.process_request.<locals>.<lambda> at 0x7fb7b45ed580>>), 'messages': <FallbackStorage: request=<WSGIRequest: GET '/admin/login/?next=/admin/'>>, 'DEFAULT_MESSAGE_LEVELS': {'DEBUG': 10, 'INFO': 20, 'SUCCESS': 25, 'WARNING': 30, 'ERROR': 40}}, {}, {'form': <HoneypotLoginForm bound=False, valid=Unknown, fields=(username;password)>, 'view': <admin_honeypot.views.AdminHoneypot object at 0x7fb7b4311410>, 'app_path': '/admin/login/?next=/admin/', 'next': '/admin/', 'title': 'Log in', 'LANGUAGE_CODE': 'en-us', 'LANGUAGE_BIDI': False}]
DEBUG 2024-01-30 10:04:21,024 base Exception while resolving variable 'is_nav_sidebar_enabled' in template 'admin_honeypot/login.html'.
Traceback (most recent call last):
  File "/home/horeb/github/easygo/venv/lib/python3.11/site-packages/django/template/base.py", line 880, in _resolve_lookup
    current = current[bit]
              ~~~~~~~^^^^^
  File "/home/horeb/github/easygo/venv/lib/python3.11/site-packages/django/template/context.py", line 83, in __getitem__
    raise KeyError(key)
KeyError: 'is_nav_sidebar_enabled'

During handling of the above exception, another exception occurred:

Traceback (most recent call last):
  File "/home/horeb/github/easygo/venv/lib/python3.11/site-packages/django/template/base.py", line 886, in _resolve_lookup
    if isinstance(current, BaseContext) and getattr(
                                            ^^^^^^^^
AttributeError: type object 'RequestContext' has no attribute 'is_nav_sidebar_enabled'

During handling of the above exception, another exception occurred:

Traceback (most recent call last):
  File "/home/horeb/github/easygo/venv/lib/python3.11/site-packages/django/template/base.py", line 896, in _resolve_lookup
    current = current[int(bit)]
                      ^^^^^^^^
ValueError: invalid literal for int() with base 10: 'is_nav_sidebar_enabled'

During handling of the above exception, another exception occurred:

Traceback (most recent call last):
  File "/home/horeb/github/easygo/venv/lib/python3.11/site-packages/django/template/base.py", line 903, in _resolve_lookup
    raise VariableDoesNotExist(
django.template.base.VariableDoesNotExist: Failed lookup for key [is_nav_sidebar_enabled] in [{'True': True, 'False': False, 'None': None}, {'csrf_token': <SimpleLazyObject: <function csrf.<locals>._get_val at 0x7fb7b45ed8a0>>, 'request': <WSGIRequest: GET '/admin/login/?next=/admin/'>, 'user': <SimpleLazyObject: <function AuthenticationMiddleware.process_request.<locals>.<lambda> at 0x7fb7b45ed580>>, 'perms': PermWrapper(<SimpleLazyObject: <function AuthenticationMiddleware.process_request.<locals>.<lambda> at 0x7fb7b45ed580>>), 'messages': <FallbackStorage: request=<WSGIRequest: GET '/admin/login/?next=/admin/'>>, 'DEFAULT_MESSAGE_LEVELS': {'DEBUG': 10, 'INFO': 20, 'SUCCESS': 25, 'WARNING': 30, 'ERROR': 40}}, {}, {'form': <HoneypotLoginForm bound=False, valid=Unknown, fields=(username;password)>, 'view': <admin_honeypot.views.AdminHoneypot object at 0x7fb7b4311410>, 'app_path': '/admin/login/?next=/admin/', 'next': '/admin/', 'title': 'Log in', 'LANGUAGE_CODE': 'en-us', 'LANGUAGE_BIDI': False}]
DEBUG 2024-01-30 10:04:21,025 base Exception while resolving variable 'subtitle' in template 'admin_honeypot/login.html'.
Traceback (most recent call last):
  File "/home/horeb/github/easygo/venv/lib/python3.11/site-packages/django/template/base.py", line 880, in _resolve_lookup
    current = current[bit]
              ~~~~~~~^^^^^
  File "/home/horeb/github/easygo/venv/lib/python3.11/site-packages/django/template/context.py", line 83, in __getitem__
    raise KeyError(key)
KeyError: 'subtitle'

During handling of the above exception, another exception occurred:

Traceback (most recent call last):
  File "/home/horeb/github/easygo/venv/lib/python3.11/site-packages/django/template/base.py", line 886, in _resolve_lookup
    if isinstance(current, BaseContext) and getattr(
                                            ^^^^^^^^
AttributeError: type object 'RequestContext' has no attribute 'subtitle'

During handling of the above exception, another exception occurred:

Traceback (most recent call last):
  File "/home/horeb/github/easygo/venv/lib/python3.11/site-packages/django/template/base.py", line 896, in _resolve_lookup
    current = current[int(bit)]
                      ^^^^^^^^
ValueError: invalid literal for int() with base 10: 'subtitle'

During handling of the above exception, another exception occurred:

Traceback (most recent call last):
  File "/home/horeb/github/easygo/venv/lib/python3.11/site-packages/django/template/base.py", line 903, in _resolve_lookup
    raise VariableDoesNotExist(
django.template.base.VariableDoesNotExist: Failed lookup for key [subtitle] in [{'True': True, 'False': False, 'None': None}, {'csrf_token': <SimpleLazyObject: <function csrf.<locals>._get_val at 0x7fb7b45ed8a0>>, 'request': <WSGIRequest: GET '/admin/login/?next=/admin/'>, 'user': <SimpleLazyObject: <function AuthenticationMiddleware.process_request.<locals>.<lambda> at 0x7fb7b45ed580>>, 'perms': PermWrapper(<SimpleLazyObject: <function AuthenticationMiddleware.process_request.<locals>.<lambda> at 0x7fb7b45ed580>>), 'messages': <FallbackStorage: request=<WSGIRequest: GET '/admin/login/?next=/admin/'>>, 'DEFAULT_MESSAGE_LEVELS': {'DEBUG': 10, 'INFO': 20, 'SUCCESS': 25, 'WARNING': 30, 'ERROR': 40}}, {}, {'form': <HoneypotLoginForm bound=False, valid=Unknown, fields=(username;password)>, 'view': <admin_honeypot.views.AdminHoneypot object at 0x7fb7b4311410>, 'app_path': '/admin/login/?next=/admin/', 'next': '/admin/', 'title': 'Log in', 'LANGUAGE_CODE': 'en-us', 'LANGUAGE_BIDI': False}, {'block': <Block Node: content_subtitle. Contents: [<IfNode>]>}]
ERROR 2024-01-30 10:05:04,951 exception Invalid HTTP_HOST header: 's3.ap-southeast-2.amazonaws.com'. You may need to add 's3.ap-southeast-2.amazonaws.com' to ALLOWED_HOSTS.
Traceback (most recent call last):
  File "/home/horeb/github/easygo/venv/lib/python3.11/site-packages/django/core/handlers/exception.py", line 55, in inner
    response = get_response(request)
               ^^^^^^^^^^^^^^^^^^^^^
  File "/home/horeb/github/easygo/venv/lib/python3.11/site-packages/django/utils/deprecation.py", line 133, in __call__
    response = self.process_request(request)
               ^^^^^^^^^^^^^^^^^^^^^^^^^^^^^
  File "/home/horeb/github/easygo/venv/lib/python3.11/site-packages/django/middleware/common.py", line 48, in process_request
    host = request.get_host()
           ^^^^^^^^^^^^^^^^^^
  File "/home/horeb/github/easygo/venv/lib/python3.11/site-packages/django/http/request.py", line 150, in get_host
    raise DisallowedHost(msg)
django.core.exceptions.DisallowedHost: Invalid HTTP_HOST header: 's3.ap-southeast-2.amazonaws.com'. You may need to add 's3.ap-southeast-2.amazonaws.com' to ALLOWED_HOSTS.
WARNING 2024-01-30 10:05:04,955 log Bad Request: /easygoshuttle.com.au/thumbsup_120241.webp
WARNING 2024-01-30 10:06:26,515 log Not Found: /.env
WARNING 2024-01-30 10:06:27,918 log Not Found: /.env.example
WARNING 2024-01-30 10:06:29,027 log Not Found: /blog/.env
WARNING 2024-01-30 10:06:30,132 log Not Found: /api/.env
WARNING 2024-01-30 10:06:31,237 log Not Found: /laravel/.env
WARNING 2024-01-30 10:06:32,361 log Not Found: /docs/.env
WARNING 2024-01-30 10:06:33,488 log Not Found: /_profiler/phpinfo
WARNING 2024-01-30 10:06:34,612 log Forbidden (Referer checking failed - no Referer.): /
WARNING 2024-01-30 10:08:53,633 log Not Found: /robots.txt
WARNING 2024-01-30 10:15:25,771 log Not Found: /shop/ko/product/moncler-여러-로고-여성-조끼-짧은-파란색/
DEBUG 2024-01-30 10:22:13,427 base Exception while resolving variable 'recaptcha_site_key' in template 'basecamp/inquiry1.html'.
Traceback (most recent call last):
  File "/home/horeb/github/easygo/venv/lib/python3.11/site-packages/django/template/base.py", line 880, in _resolve_lookup
    current = current[bit]
              ~~~~~~~^^^^^
  File "/home/horeb/github/easygo/venv/lib/python3.11/site-packages/django/template/context.py", line 83, in __getitem__
    raise KeyError(key)
KeyError: 'recaptcha_site_key'

During handling of the above exception, another exception occurred:

Traceback (most recent call last):
  File "/home/horeb/github/easygo/venv/lib/python3.11/site-packages/django/template/base.py", line 886, in _resolve_lookup
    if isinstance(current, BaseContext) and getattr(
                                            ^^^^^^^^
AttributeError: type object 'RequestContext' has no attribute 'recaptcha_site_key'

During handling of the above exception, another exception occurred:

Traceback (most recent call last):
  File "/home/horeb/github/easygo/venv/lib/python3.11/site-packages/django/template/base.py", line 896, in _resolve_lookup
    current = current[int(bit)]
                      ^^^^^^^^
ValueError: invalid literal for int() with base 10: 'recaptcha_site_key'

During handling of the above exception, another exception occurred:

Traceback (most recent call last):
  File "/home/horeb/github/easygo/venv/lib/python3.11/site-packages/django/template/base.py", line 903, in _resolve_lookup
    raise VariableDoesNotExist(
django.template.base.VariableDoesNotExist: Failed lookup for key [recaptcha_site_key] in [{'True': True, 'False': False, 'None': None}, {'csrf_token': <SimpleLazyObject: 'tvtVWkLcD7pD4HEnOkLF8217W1xN8qhRL5txXCFUr0zTT2DbKG20U6QCpXoU7whJ'>, 'request': <WSGIRequest: POST '/price_detail/'>, 'user': <SimpleLazyObject: <function AuthenticationMiddleware.process_request.<locals>.<lambda> at 0x7fb7b42bf380>>, 'perms': PermWrapper(<SimpleLazyObject: <function AuthenticationMiddleware.process_request.<locals>.<lambda> at 0x7fb7b42bf380>>), 'messages': <FallbackStorage: request=<WSGIRequest: POST '/price_detail/'>>, 'DEFAULT_MESSAGE_LEVELS': {'DEBUG': 10, 'INFO': 20, 'SUCCESS': 25, 'WARNING': 30, 'ERROR': 40}}, {}, {'flight_date': '2024-01-31', 'direction': 'Drop off to Domestic Airport', 'suburb': 'Sydney (city)', 'no_of_passenger': '2'}, {'block': <Block Node: content. Contents: [<TextNode: '\n      <!-- Page content-'>, <Variable Node: flight_date>, <TextNode: '</a><br>\n\t\t\t  <a style="f'>, <Variable Node: direction>, <TextNode: '</a><br>\n\t\t\t  <a style="f'>, <Variable Node: suburb>, <TextNode: '</a><br>\n\t\t\t  <a style="f'>, <Variable Node: no_of_passenger>, <TextNode: '</a> -->\n\t\t\t  <br><br>\n  '>, <django.template.defaulttags.CsrfTokenNode object at 0x7fb7b3fdca50>, <TextNode: '\n\t\t\t\t<div class="mb3 pb-1'>, <Variable Node: direction>, <TextNode: '">'>, <Variable Node: direction>, <TextNode: '</option>\t\t\t\t\t\t          '>, <Variable Node: flight_date>, <TextNode: '" type="text" >\t\t\t\t  \n   '>, <IfNode>, <TextNode: '\n\t\t\t\t  <div class="mb-3 p'>, <Variable Node: suburb>, <TextNode: '</label>\t\t\t\t\t\n\t\t\t\t</div>\n'>, <Variable Node: suburb>, <TextNode: '">'>, <Variable Node: suburb>, <TextNode: '</option>\t\t\t\t\t\n\t\t\t\t  </se'>, <Variable Node: no_of_passenger>, <TextNode: '">'>, <Variable Node: no_of_passenger>, <TextNode: '</option>\t\t\t\t  \n         '>, <Variable Node: recaptcha_site_key>, <TextNode: '"></div>\n\t\t\t\t<div id="err'>]>}]
DEBUG 2024-01-30 10:22:38,183 base Exception while resolving variable 'flight_date' in template 'basecamp/inquiry1.html'.
Traceback (most recent call last):
  File "/home/horeb/github/easygo/venv/lib/python3.11/site-packages/django/template/base.py", line 880, in _resolve_lookup
    current = current[bit]
              ~~~~~~~^^^^^
  File "/home/horeb/github/easygo/venv/lib/python3.11/site-packages/django/template/context.py", line 83, in __getitem__
    raise KeyError(key)
KeyError: 'flight_date'

During handling of the above exception, another exception occurred:

Traceback (most recent call last):
  File "/home/horeb/github/easygo/venv/lib/python3.11/site-packages/django/template/base.py", line 886, in _resolve_lookup
    if isinstance(current, BaseContext) and getattr(
                                            ^^^^^^^^
AttributeError: type object 'RequestContext' has no attribute 'flight_date'

During handling of the above exception, another exception occurred:

Traceback (most recent call last):
  File "/home/horeb/github/easygo/venv/lib/python3.11/site-packages/django/template/base.py", line 896, in _resolve_lookup
    current = current[int(bit)]
                      ^^^^^^^^
ValueError: invalid literal for int() with base 10: 'flight_date'

During handling of the above exception, another exception occurred:

Traceback (most recent call last):
  File "/home/horeb/github/easygo/venv/lib/python3.11/site-packages/django/template/base.py", line 903, in _resolve_lookup
    raise VariableDoesNotExist(
django.template.base.VariableDoesNotExist: Failed lookup for key [flight_date] in [{'True': True, 'False': False, 'None': None}, {'csrf_token': <SimpleLazyObject: <function csrf.<locals>._get_val at 0x7fb7b41f1580>>, 'request': <WSGIRequest: GET '/price_detail/'>, 'user': <SimpleLazyObject: <function AuthenticationMiddleware.process_request.<locals>.<lambda> at 0x7fb7b41f13a0>>, 'perms': PermWrapper(<SimpleLazyObject: <function AuthenticationMiddleware.process_request.<locals>.<lambda> at 0x7fb7b41f13a0>>), 'messages': <FallbackStorage: request=<WSGIRequest: GET '/price_detail/'>>, 'DEFAULT_MESSAGE_LEVELS': {'DEBUG': 10, 'INFO': 20, 'SUCCESS': 25, 'WARNING': 30, 'ERROR': 40}}, {}, {'block': <Block Node: content. Contents: [<TextNode: '\n      <!-- Page content-'>, <Variable Node: flight_date>, <TextNode: '</a><br>\n\t\t\t  <a style="f'>, <Variable Node: direction>, <TextNode: '</a><br>\n\t\t\t  <a style="f'>, <Variable Node: suburb>, <TextNode: '</a><br>\n\t\t\t  <a style="f'>, <Variable Node: no_of_passenger>, <TextNode: '</a> -->\n\t\t\t  <br><br>\n  '>, <django.template.defaulttags.CsrfTokenNode object at 0x7fb7b3fc2550>, <TextNode: '\n\t\t\t\t<div class="mb3 pb-1'>, <Variable Node: direction>, <TextNode: '">'>, <Variable Node: direction>, <TextNode: '</option>\t\t\t\t\t\t          '>, <Variable Node: flight_date>, <TextNode: '" type="text" >\t\t\t\t  \n   '>, <IfNode>, <TextNode: '\n\t\t\t\t  <div class="mb-3 p'>, <Variable Node: suburb>, <TextNode: '</label>\t\t\t\t\t\n\t\t\t\t</div>\n'>, <Variable Node: suburb>, <TextNode: '">'>, <Variable Node: suburb>, <TextNode: '</option>\t\t\t\t\t\n\t\t\t\t  </se'>, <Variable Node: no_of_passenger>, <TextNode: '">'>, <Variable Node: no_of_passenger>, <TextNode: '</option>\t\t\t\t  \n         '>, <Variable Node: recaptcha_site_key>, <TextNode: '"></div>\n\t\t\t\t<div id="err'>]>}]
DEBUG 2024-01-30 10:22:38,184 base Exception while resolving variable 'direction' in template 'basecamp/inquiry1.html'.
Traceback (most recent call last):
  File "/home/horeb/github/easygo/venv/lib/python3.11/site-packages/django/template/base.py", line 880, in _resolve_lookup
    current = current[bit]
              ~~~~~~~^^^^^
  File "/home/horeb/github/easygo/venv/lib/python3.11/site-packages/django/template/context.py", line 83, in __getitem__
    raise KeyError(key)
KeyError: 'direction'

During handling of the above exception, another exception occurred:

Traceback (most recent call last):
  File "/home/horeb/github/easygo/venv/lib/python3.11/site-packages/django/template/base.py", line 886, in _resolve_lookup
    if isinstance(current, BaseContext) and getattr(
                                            ^^^^^^^^
AttributeError: type object 'RequestContext' has no attribute 'direction'

During handling of the above exception, another exception occurred:

Traceback (most recent call last):
  File "/home/horeb/github/easygo/venv/lib/python3.11/site-packages/django/template/base.py", line 896, in _resolve_lookup
    current = current[int(bit)]
                      ^^^^^^^^
ValueError: invalid literal for int() with base 10: 'direction'

During handling of the above exception, another exception occurred:

Traceback (most recent call last):
  File "/home/horeb/github/easygo/venv/lib/python3.11/site-packages/django/template/base.py", line 903, in _resolve_lookup
    raise VariableDoesNotExist(
django.template.base.VariableDoesNotExist: Failed lookup for key [direction] in [{'True': True, 'False': False, 'None': None}, {'csrf_token': <SimpleLazyObject: <function csrf.<locals>._get_val at 0x7fb7b41f1580>>, 'request': <WSGIRequest: GET '/price_detail/'>, 'user': <SimpleLazyObject: <function AuthenticationMiddleware.process_request.<locals>.<lambda> at 0x7fb7b41f13a0>>, 'perms': PermWrapper(<SimpleLazyObject: <function AuthenticationMiddleware.process_request.<locals>.<lambda> at 0x7fb7b41f13a0>>), 'messages': <FallbackStorage: request=<WSGIRequest: GET '/price_detail/'>>, 'DEFAULT_MESSAGE_LEVELS': {'DEBUG': 10, 'INFO': 20, 'SUCCESS': 25, 'WARNING': 30, 'ERROR': 40}}, {}, {'block': <Block Node: content. Contents: [<TextNode: '\n      <!-- Page content-'>, <Variable Node: flight_date>, <TextNode: '</a><br>\n\t\t\t  <a style="f'>, <Variable Node: direction>, <TextNode: '</a><br>\n\t\t\t  <a style="f'>, <Variable Node: suburb>, <TextNode: '</a><br>\n\t\t\t  <a style="f'>, <Variable Node: no_of_passenger>, <TextNode: '</a> -->\n\t\t\t  <br><br>\n  '>, <django.template.defaulttags.CsrfTokenNode object at 0x7fb7b3fc2550>, <TextNode: '\n\t\t\t\t<div class="mb3 pb-1'>, <Variable Node: direction>, <TextNode: '">'>, <Variable Node: direction>, <TextNode: '</option>\t\t\t\t\t\t          '>, <Variable Node: flight_date>, <TextNode: '" type="text" >\t\t\t\t  \n   '>, <IfNode>, <TextNode: '\n\t\t\t\t  <div class="mb-3 p'>, <Variable Node: suburb>, <TextNode: '</label>\t\t\t\t\t\n\t\t\t\t</div>\n'>, <Variable Node: suburb>, <TextNode: '">'>, <Variable Node: suburb>, <TextNode: '</option>\t\t\t\t\t\n\t\t\t\t  </se'>, <Variable Node: no_of_passenger>, <TextNode: '">'>, <Variable Node: no_of_passenger>, <TextNode: '</option>\t\t\t\t  \n         '>, <Variable Node: recaptcha_site_key>, <TextNode: '"></div>\n\t\t\t\t<div id="err'>]>}]
DEBUG 2024-01-30 10:22:38,185 base Exception while resolving variable 'suburb' in template 'basecamp/inquiry1.html'.
Traceback (most recent call last):
  File "/home/horeb/github/easygo/venv/lib/python3.11/site-packages/django/template/base.py", line 880, in _resolve_lookup
    current = current[bit]
              ~~~~~~~^^^^^
  File "/home/horeb/github/easygo/venv/lib/python3.11/site-packages/django/template/context.py", line 83, in __getitem__
    raise KeyError(key)
KeyError: 'suburb'

During handling of the above exception, another exception occurred:

Traceback (most recent call last):
  File "/home/horeb/github/easygo/venv/lib/python3.11/site-packages/django/template/base.py", line 886, in _resolve_lookup
    if isinstance(current, BaseContext) and getattr(
                                            ^^^^^^^^
AttributeError: type object 'RequestContext' has no attribute 'suburb'

During handling of the above exception, another exception occurred:

Traceback (most recent call last):
  File "/home/horeb/github/easygo/venv/lib/python3.11/site-packages/django/template/base.py", line 896, in _resolve_lookup
    current = current[int(bit)]
                      ^^^^^^^^
ValueError: invalid literal for int() with base 10: 'suburb'

During handling of the above exception, another exception occurred:

Traceback (most recent call last):
  File "/home/horeb/github/easygo/venv/lib/python3.11/site-packages/django/template/base.py", line 903, in _resolve_lookup
    raise VariableDoesNotExist(
django.template.base.VariableDoesNotExist: Failed lookup for key [suburb] in [{'True': True, 'False': False, 'None': None}, {'csrf_token': <SimpleLazyObject: <function csrf.<locals>._get_val at 0x7fb7b41f1580>>, 'request': <WSGIRequest: GET '/price_detail/'>, 'user': <SimpleLazyObject: <function AuthenticationMiddleware.process_request.<locals>.<lambda> at 0x7fb7b41f13a0>>, 'perms': PermWrapper(<SimpleLazyObject: <function AuthenticationMiddleware.process_request.<locals>.<lambda> at 0x7fb7b41f13a0>>), 'messages': <FallbackStorage: request=<WSGIRequest: GET '/price_detail/'>>, 'DEFAULT_MESSAGE_LEVELS': {'DEBUG': 10, 'INFO': 20, 'SUCCESS': 25, 'WARNING': 30, 'ERROR': 40}}, {}, {'block': <Block Node: content. Contents: [<TextNode: '\n      <!-- Page content-'>, <Variable Node: flight_date>, <TextNode: '</a><br>\n\t\t\t  <a style="f'>, <Variable Node: direction>, <TextNode: '</a><br>\n\t\t\t  <a style="f'>, <Variable Node: suburb>, <TextNode: '</a><br>\n\t\t\t  <a style="f'>, <Variable Node: no_of_passenger>, <TextNode: '</a> -->\n\t\t\t  <br><br>\n  '>, <django.template.defaulttags.CsrfTokenNode object at 0x7fb7b3fc2550>, <TextNode: '\n\t\t\t\t<div class="mb3 pb-1'>, <Variable Node: direction>, <TextNode: '">'>, <Variable Node: direction>, <TextNode: '</option>\t\t\t\t\t\t          '>, <Variable Node: flight_date>, <TextNode: '" type="text" >\t\t\t\t  \n   '>, <IfNode>, <TextNode: '\n\t\t\t\t  <div class="mb-3 p'>, <Variable Node: suburb>, <TextNode: '</label>\t\t\t\t\t\n\t\t\t\t</div>\n'>, <Variable Node: suburb>, <TextNode: '">'>, <Variable Node: suburb>, <TextNode: '</option>\t\t\t\t\t\n\t\t\t\t  </se'>, <Variable Node: no_of_passenger>, <TextNode: '">'>, <Variable Node: no_of_passenger>, <TextNode: '</option>\t\t\t\t  \n         '>, <Variable Node: recaptcha_site_key>, <TextNode: '"></div>\n\t\t\t\t<div id="err'>]>}]
DEBUG 2024-01-30 10:22:38,185 base Exception while resolving variable 'no_of_passenger' in template 'basecamp/inquiry1.html'.
Traceback (most recent call last):
  File "/home/horeb/github/easygo/venv/lib/python3.11/site-packages/django/template/base.py", line 880, in _resolve_lookup
    current = current[bit]
              ~~~~~~~^^^^^
  File "/home/horeb/github/easygo/venv/lib/python3.11/site-packages/django/template/context.py", line 83, in __getitem__
    raise KeyError(key)
KeyError: 'no_of_passenger'

During handling of the above exception, another exception occurred:

Traceback (most recent call last):
  File "/home/horeb/github/easygo/venv/lib/python3.11/site-packages/django/template/base.py", line 886, in _resolve_lookup
    if isinstance(current, BaseContext) and getattr(
                                            ^^^^^^^^
AttributeError: type object 'RequestContext' has no attribute 'no_of_passenger'

During handling of the above exception, another exception occurred:

Traceback (most recent call last):
  File "/home/horeb/github/easygo/venv/lib/python3.11/site-packages/django/template/base.py", line 896, in _resolve_lookup
    current = current[int(bit)]
                      ^^^^^^^^
ValueError: invalid literal for int() with base 10: 'no_of_passenger'

During handling of the above exception, another exception occurred:

Traceback (most recent call last):
  File "/home/horeb/github/easygo/venv/lib/python3.11/site-packages/django/template/base.py", line 903, in _resolve_lookup
    raise VariableDoesNotExist(
django.template.base.VariableDoesNotExist: Failed lookup for key [no_of_passenger] in [{'True': True, 'False': False, 'None': None}, {'csrf_token': <SimpleLazyObject: <function csrf.<locals>._get_val at 0x7fb7b41f1580>>, 'request': <WSGIRequest: GET '/price_detail/'>, 'user': <SimpleLazyObject: <function AuthenticationMiddleware.process_request.<locals>.<lambda> at 0x7fb7b41f13a0>>, 'perms': PermWrapper(<SimpleLazyObject: <function AuthenticationMiddleware.process_request.<locals>.<lambda> at 0x7fb7b41f13a0>>), 'messages': <FallbackStorage: request=<WSGIRequest: GET '/price_detail/'>>, 'DEFAULT_MESSAGE_LEVELS': {'DEBUG': 10, 'INFO': 20, 'SUCCESS': 25, 'WARNING': 30, 'ERROR': 40}}, {}, {'block': <Block Node: content. Contents: [<TextNode: '\n      <!-- Page content-'>, <Variable Node: flight_date>, <TextNode: '</a><br>\n\t\t\t  <a style="f'>, <Variable Node: direction>, <TextNode: '</a><br>\n\t\t\t  <a style="f'>, <Variable Node: suburb>, <TextNode: '</a><br>\n\t\t\t  <a style="f'>, <Variable Node: no_of_passenger>, <TextNode: '</a> -->\n\t\t\t  <br><br>\n  '>, <django.template.defaulttags.CsrfTokenNode object at 0x7fb7b3fc2550>, <TextNode: '\n\t\t\t\t<div class="mb3 pb-1'>, <Variable Node: direction>, <TextNode: '">'>, <Variable Node: direction>, <TextNode: '</option>\t\t\t\t\t\t          '>, <Variable Node: flight_date>, <TextNode: '" type="text" >\t\t\t\t  \n   '>, <IfNode>, <TextNode: '\n\t\t\t\t  <div class="mb-3 p'>, <Variable Node: suburb>, <TextNode: '</label>\t\t\t\t\t\n\t\t\t\t</div>\n'>, <Variable Node: suburb>, <TextNode: '">'>, <Variable Node: suburb>, <TextNode: '</option>\t\t\t\t\t\n\t\t\t\t  </se'>, <Variable Node: no_of_passenger>, <TextNode: '">'>, <Variable Node: no_of_passenger>, <TextNode: '</option>\t\t\t\t  \n         '>, <Variable Node: recaptcha_site_key>, <TextNode: '"></div>\n\t\t\t\t<div id="err'>]>}]
DEBUG 2024-01-30 10:22:38,186 base Exception while resolving variable 'direction' in template 'basecamp/inquiry1.html'.
Traceback (most recent call last):
  File "/home/horeb/github/easygo/venv/lib/python3.11/site-packages/django/template/base.py", line 880, in _resolve_lookup
    current = current[bit]
              ~~~~~~~^^^^^
  File "/home/horeb/github/easygo/venv/lib/python3.11/site-packages/django/template/context.py", line 83, in __getitem__
    raise KeyError(key)
KeyError: 'direction'

During handling of the above exception, another exception occurred:

Traceback (most recent call last):
  File "/home/horeb/github/easygo/venv/lib/python3.11/site-packages/django/template/base.py", line 886, in _resolve_lookup
    if isinstance(current, BaseContext) and getattr(
                                            ^^^^^^^^
AttributeError: type object 'RequestContext' has no attribute 'direction'

During handling of the above exception, another exception occurred:

Traceback (most recent call last):
  File "/home/horeb/github/easygo/venv/lib/python3.11/site-packages/django/template/base.py", line 896, in _resolve_lookup
    current = current[int(bit)]
                      ^^^^^^^^
ValueError: invalid literal for int() with base 10: 'direction'

During handling of the above exception, another exception occurred:

Traceback (most recent call last):
  File "/home/horeb/github/easygo/venv/lib/python3.11/site-packages/django/template/base.py", line 903, in _resolve_lookup
    raise VariableDoesNotExist(
django.template.base.VariableDoesNotExist: Failed lookup for key [direction] in [{'True': True, 'False': False, 'None': None}, {'csrf_token': <SimpleLazyObject: '8lfBoZUxUvVbh0PCyePhFfbtS4mCb2TVvot0byzRxFRGGSrHU9klq0JFWgLpSIj0'>, 'request': <WSGIRequest: GET '/price_detail/'>, 'user': <SimpleLazyObject: <function AuthenticationMiddleware.process_request.<locals>.<lambda> at 0x7fb7b41f13a0>>, 'perms': PermWrapper(<SimpleLazyObject: <function AuthenticationMiddleware.process_request.<locals>.<lambda> at 0x7fb7b41f13a0>>), 'messages': <FallbackStorage: request=<WSGIRequest: GET '/price_detail/'>>, 'DEFAULT_MESSAGE_LEVELS': {'DEBUG': 10, 'INFO': 20, 'SUCCESS': 25, 'WARNING': 30, 'ERROR': 40}}, {}, {'block': <Block Node: content. Contents: [<TextNode: '\n      <!-- Page content-'>, <Variable Node: flight_date>, <TextNode: '</a><br>\n\t\t\t  <a style="f'>, <Variable Node: direction>, <TextNode: '</a><br>\n\t\t\t  <a style="f'>, <Variable Node: suburb>, <TextNode: '</a><br>\n\t\t\t  <a style="f'>, <Variable Node: no_of_passenger>, <TextNode: '</a> -->\n\t\t\t  <br><br>\n  '>, <django.template.defaulttags.CsrfTokenNode object at 0x7fb7b3fc2550>, <TextNode: '\n\t\t\t\t<div class="mb3 pb-1'>, <Variable Node: direction>, <TextNode: '">'>, <Variable Node: direction>, <TextNode: '</option>\t\t\t\t\t\t          '>, <Variable Node: flight_date>, <TextNode: '" type="text" >\t\t\t\t  \n   '>, <IfNode>, <TextNode: '\n\t\t\t\t  <div class="mb-3 p'>, <Variable Node: suburb>, <TextNode: '</label>\t\t\t\t\t\n\t\t\t\t</div>\n'>, <Variable Node: suburb>, <TextNode: '">'>, <Variable Node: suburb>, <TextNode: '</option>\t\t\t\t\t\n\t\t\t\t  </se'>, <Variable Node: no_of_passenger>, <TextNode: '">'>, <Variable Node: no_of_passenger>, <TextNode: '</option>\t\t\t\t  \n         '>, <Variable Node: recaptcha_site_key>, <TextNode: '"></div>\n\t\t\t\t<div id="err'>]>}]
DEBUG 2024-01-30 10:22:38,186 base Exception while resolving variable 'direction' in template 'basecamp/inquiry1.html'.
Traceback (most recent call last):
  File "/home/horeb/github/easygo/venv/lib/python3.11/site-packages/django/template/base.py", line 880, in _resolve_lookup
    current = current[bit]
              ~~~~~~~^^^^^
  File "/home/horeb/github/easygo/venv/lib/python3.11/site-packages/django/template/context.py", line 83, in __getitem__
    raise KeyError(key)
KeyError: 'direction'

During handling of the above exception, another exception occurred:

Traceback (most recent call last):
  File "/home/horeb/github/easygo/venv/lib/python3.11/site-packages/django/template/base.py", line 886, in _resolve_lookup
    if isinstance(current, BaseContext) and getattr(
                                            ^^^^^^^^
AttributeError: type object 'RequestContext' has no attribute 'direction'

During handling of the above exception, another exception occurred:

Traceback (most recent call last):
  File "/home/horeb/github/easygo/venv/lib/python3.11/site-packages/django/template/base.py", line 896, in _resolve_lookup
    current = current[int(bit)]
                      ^^^^^^^^
ValueError: invalid literal for int() with base 10: 'direction'

During handling of the above exception, another exception occurred:

Traceback (most recent call last):
  File "/home/horeb/github/easygo/venv/lib/python3.11/site-packages/django/template/base.py", line 903, in _resolve_lookup
    raise VariableDoesNotExist(
django.template.base.VariableDoesNotExist: Failed lookup for key [direction] in [{'True': True, 'False': False, 'None': None}, {'csrf_token': <SimpleLazyObject: '8lfBoZUxUvVbh0PCyePhFfbtS4mCb2TVvot0byzRxFRGGSrHU9klq0JFWgLpSIj0'>, 'request': <WSGIRequest: GET '/price_detail/'>, 'user': <SimpleLazyObject: <function AuthenticationMiddleware.process_request.<locals>.<lambda> at 0x7fb7b41f13a0>>, 'perms': PermWrapper(<SimpleLazyObject: <function AuthenticationMiddleware.process_request.<locals>.<lambda> at 0x7fb7b41f13a0>>), 'messages': <FallbackStorage: request=<WSGIRequest: GET '/price_detail/'>>, 'DEFAULT_MESSAGE_LEVELS': {'DEBUG': 10, 'INFO': 20, 'SUCCESS': 25, 'WARNING': 30, 'ERROR': 40}}, {}, {'block': <Block Node: content. Contents: [<TextNode: '\n      <!-- Page content-'>, <Variable Node: flight_date>, <TextNode: '</a><br>\n\t\t\t  <a style="f'>, <Variable Node: direction>, <TextNode: '</a><br>\n\t\t\t  <a style="f'>, <Variable Node: suburb>, <TextNode: '</a><br>\n\t\t\t  <a style="f'>, <Variable Node: no_of_passenger>, <TextNode: '</a> -->\n\t\t\t  <br><br>\n  '>, <django.template.defaulttags.CsrfTokenNode object at 0x7fb7b3fc2550>, <TextNode: '\n\t\t\t\t<div class="mb3 pb-1'>, <Variable Node: direction>, <TextNode: '">'>, <Variable Node: direction>, <TextNode: '</option>\t\t\t\t\t\t          '>, <Variable Node: flight_date>, <TextNode: '" type="text" >\t\t\t\t  \n   '>, <IfNode>, <TextNode: '\n\t\t\t\t  <div class="mb-3 p'>, <Variable Node: suburb>, <TextNode: '</label>\t\t\t\t\t\n\t\t\t\t</div>\n'>, <Variable Node: suburb>, <TextNode: '">'>, <Variable Node: suburb>, <TextNode: '</option>\t\t\t\t\t\n\t\t\t\t  </se'>, <Variable Node: no_of_passenger>, <TextNode: '">'>, <Variable Node: no_of_passenger>, <TextNode: '</option>\t\t\t\t  \n         '>, <Variable Node: recaptcha_site_key>, <TextNode: '"></div>\n\t\t\t\t<div id="err'>]>}]
DEBUG 2024-01-30 10:22:38,187 base Exception while resolving variable 'flight_date' in template 'basecamp/inquiry1.html'.
Traceback (most recent call last):
  File "/home/horeb/github/easygo/venv/lib/python3.11/site-packages/django/template/base.py", line 880, in _resolve_lookup
    current = current[bit]
              ~~~~~~~^^^^^
  File "/home/horeb/github/easygo/venv/lib/python3.11/site-packages/django/template/context.py", line 83, in __getitem__
    raise KeyError(key)
KeyError: 'flight_date'

During handling of the above exception, another exception occurred:

Traceback (most recent call last):
  File "/home/horeb/github/easygo/venv/lib/python3.11/site-packages/django/template/base.py", line 886, in _resolve_lookup
    if isinstance(current, BaseContext) and getattr(
                                            ^^^^^^^^
AttributeError: type object 'RequestContext' has no attribute 'flight_date'

During handling of the above exception, another exception occurred:

Traceback (most recent call last):
  File "/home/horeb/github/easygo/venv/lib/python3.11/site-packages/django/template/base.py", line 896, in _resolve_lookup
    current = current[int(bit)]
                      ^^^^^^^^
ValueError: invalid literal for int() with base 10: 'flight_date'

During handling of the above exception, another exception occurred:

Traceback (most recent call last):
  File "/home/horeb/github/easygo/venv/lib/python3.11/site-packages/django/template/base.py", line 903, in _resolve_lookup
    raise VariableDoesNotExist(
django.template.base.VariableDoesNotExist: Failed lookup for key [flight_date] in [{'True': True, 'False': False, 'None': None}, {'csrf_token': <SimpleLazyObject: '8lfBoZUxUvVbh0PCyePhFfbtS4mCb2TVvot0byzRxFRGGSrHU9klq0JFWgLpSIj0'>, 'request': <WSGIRequest: GET '/price_detail/'>, 'user': <SimpleLazyObject: <function AuthenticationMiddleware.process_request.<locals>.<lambda> at 0x7fb7b41f13a0>>, 'perms': PermWrapper(<SimpleLazyObject: <function AuthenticationMiddleware.process_request.<locals>.<lambda> at 0x7fb7b41f13a0>>), 'messages': <FallbackStorage: request=<WSGIRequest: GET '/price_detail/'>>, 'DEFAULT_MESSAGE_LEVELS': {'DEBUG': 10, 'INFO': 20, 'SUCCESS': 25, 'WARNING': 30, 'ERROR': 40}}, {}, {'block': <Block Node: content. Contents: [<TextNode: '\n      <!-- Page content-'>, <Variable Node: flight_date>, <TextNode: '</a><br>\n\t\t\t  <a style="f'>, <Variable Node: direction>, <TextNode: '</a><br>\n\t\t\t  <a style="f'>, <Variable Node: suburb>, <TextNode: '</a><br>\n\t\t\t  <a style="f'>, <Variable Node: no_of_passenger>, <TextNode: '</a> -->\n\t\t\t  <br><br>\n  '>, <django.template.defaulttags.CsrfTokenNode object at 0x7fb7b3fc2550>, <TextNode: '\n\t\t\t\t<div class="mb3 pb-1'>, <Variable Node: direction>, <TextNode: '">'>, <Variable Node: direction>, <TextNode: '</option>\t\t\t\t\t\t          '>, <Variable Node: flight_date>, <TextNode: '" type="text" >\t\t\t\t  \n   '>, <IfNode>, <TextNode: '\n\t\t\t\t  <div class="mb-3 p'>, <Variable Node: suburb>, <TextNode: '</label>\t\t\t\t\t\n\t\t\t\t</div>\n'>, <Variable Node: suburb>, <TextNode: '">'>, <Variable Node: suburb>, <TextNode: '</option>\t\t\t\t\t\n\t\t\t\t  </se'>, <Variable Node: no_of_passenger>, <TextNode: '">'>, <Variable Node: no_of_passenger>, <TextNode: '</option>\t\t\t\t  \n         '>, <Variable Node: recaptcha_site_key>, <TextNode: '"></div>\n\t\t\t\t<div id="err'>]>}]
DEBUG 2024-01-30 10:22:38,187 base Exception while resolving variable 'direction' in template 'basecamp/inquiry1.html'.
Traceback (most recent call last):
  File "/home/horeb/github/easygo/venv/lib/python3.11/site-packages/django/template/base.py", line 880, in _resolve_lookup
    current = current[bit]
              ~~~~~~~^^^^^
  File "/home/horeb/github/easygo/venv/lib/python3.11/site-packages/django/template/context.py", line 83, in __getitem__
    raise KeyError(key)
KeyError: 'direction'

During handling of the above exception, another exception occurred:

Traceback (most recent call last):
  File "/home/horeb/github/easygo/venv/lib/python3.11/site-packages/django/template/base.py", line 886, in _resolve_lookup
    if isinstance(current, BaseContext) and getattr(
                                            ^^^^^^^^
AttributeError: type object 'RequestContext' has no attribute 'direction'

During handling of the above exception, another exception occurred:

Traceback (most recent call last):
  File "/home/horeb/github/easygo/venv/lib/python3.11/site-packages/django/template/base.py", line 896, in _resolve_lookup
    current = current[int(bit)]
                      ^^^^^^^^
ValueError: invalid literal for int() with base 10: 'direction'

During handling of the above exception, another exception occurred:

Traceback (most recent call last):
  File "/home/horeb/github/easygo/venv/lib/python3.11/site-packages/django/template/base.py", line 903, in _resolve_lookup
    raise VariableDoesNotExist(
django.template.base.VariableDoesNotExist: Failed lookup for key [direction] in [{'True': True, 'False': False, 'None': None}, {'csrf_token': <SimpleLazyObject: '8lfBoZUxUvVbh0PCyePhFfbtS4mCb2TVvot0byzRxFRGGSrHU9klq0JFWgLpSIj0'>, 'request': <WSGIRequest: GET '/price_detail/'>, 'user': <SimpleLazyObject: <function AuthenticationMiddleware.process_request.<locals>.<lambda> at 0x7fb7b41f13a0>>, 'perms': PermWrapper(<SimpleLazyObject: <function AuthenticationMiddleware.process_request.<locals>.<lambda> at 0x7fb7b41f13a0>>), 'messages': <FallbackStorage: request=<WSGIRequest: GET '/price_detail/'>>, 'DEFAULT_MESSAGE_LEVELS': {'DEBUG': 10, 'INFO': 20, 'SUCCESS': 25, 'WARNING': 30, 'ERROR': 40}}, {}, {'block': <Block Node: content. Contents: [<TextNode: '\n      <!-- Page content-'>, <Variable Node: flight_date>, <TextNode: '</a><br>\n\t\t\t  <a style="f'>, <Variable Node: direction>, <TextNode: '</a><br>\n\t\t\t  <a style="f'>, <Variable Node: suburb>, <TextNode: '</a><br>\n\t\t\t  <a style="f'>, <Variable Node: no_of_passenger>, <TextNode: '</a> -->\n\t\t\t  <br><br>\n  '>, <django.template.defaulttags.CsrfTokenNode object at 0x7fb7b3fc2550>, <TextNode: '\n\t\t\t\t<div class="mb3 pb-1'>, <Variable Node: direction>, <TextNode: '">'>, <Variable Node: direction>, <TextNode: '</option>\t\t\t\t\t\t          '>, <Variable Node: flight_date>, <TextNode: '" type="text" >\t\t\t\t  \n   '>, <IfNode>, <TextNode: '\n\t\t\t\t  <div class="mb-3 p'>, <Variable Node: suburb>, <TextNode: '</label>\t\t\t\t\t\n\t\t\t\t</div>\n'>, <Variable Node: suburb>, <TextNode: '">'>, <Variable Node: suburb>, <TextNode: '</option>\t\t\t\t\t\n\t\t\t\t  </se'>, <Variable Node: no_of_passenger>, <TextNode: '">'>, <Variable Node: no_of_passenger>, <TextNode: '</option>\t\t\t\t  \n         '>, <Variable Node: recaptcha_site_key>, <TextNode: '"></div>\n\t\t\t\t<div id="err'>]>}]
DEBUG 2024-01-30 10:22:38,187 base Exception while resolving variable 'direction' in template 'basecamp/inquiry1.html'.
Traceback (most recent call last):
  File "/home/horeb/github/easygo/venv/lib/python3.11/site-packages/django/template/base.py", line 880, in _resolve_lookup
    current = current[bit]
              ~~~~~~~^^^^^
  File "/home/horeb/github/easygo/venv/lib/python3.11/site-packages/django/template/context.py", line 83, in __getitem__
    raise KeyError(key)
KeyError: 'direction'

During handling of the above exception, another exception occurred:

Traceback (most recent call last):
  File "/home/horeb/github/easygo/venv/lib/python3.11/site-packages/django/template/base.py", line 886, in _resolve_lookup
    if isinstance(current, BaseContext) and getattr(
                                            ^^^^^^^^
AttributeError: type object 'RequestContext' has no attribute 'direction'

During handling of the above exception, another exception occurred:

Traceback (most recent call last):
  File "/home/horeb/github/easygo/venv/lib/python3.11/site-packages/django/template/base.py", line 896, in _resolve_lookup
    current = current[int(bit)]
                      ^^^^^^^^
ValueError: invalid literal for int() with base 10: 'direction'

During handling of the above exception, another exception occurred:

Traceback (most recent call last):
  File "/home/horeb/github/easygo/venv/lib/python3.11/site-packages/django/template/base.py", line 903, in _resolve_lookup
    raise VariableDoesNotExist(
django.template.base.VariableDoesNotExist: Failed lookup for key [direction] in [{'True': True, 'False': False, 'None': None}, {'csrf_token': <SimpleLazyObject: '8lfBoZUxUvVbh0PCyePhFfbtS4mCb2TVvot0byzRxFRGGSrHU9klq0JFWgLpSIj0'>, 'request': <WSGIRequest: GET '/price_detail/'>, 'user': <SimpleLazyObject: <function AuthenticationMiddleware.process_request.<locals>.<lambda> at 0x7fb7b41f13a0>>, 'perms': PermWrapper(<SimpleLazyObject: <function AuthenticationMiddleware.process_request.<locals>.<lambda> at 0x7fb7b41f13a0>>), 'messages': <FallbackStorage: request=<WSGIRequest: GET '/price_detail/'>>, 'DEFAULT_MESSAGE_LEVELS': {'DEBUG': 10, 'INFO': 20, 'SUCCESS': 25, 'WARNING': 30, 'ERROR': 40}}, {}, {'block': <Block Node: content. Contents: [<TextNode: '\n      <!-- Page content-'>, <Variable Node: flight_date>, <TextNode: '</a><br>\n\t\t\t  <a style="f'>, <Variable Node: direction>, <TextNode: '</a><br>\n\t\t\t  <a style="f'>, <Variable Node: suburb>, <TextNode: '</a><br>\n\t\t\t  <a style="f'>, <Variable Node: no_of_passenger>, <TextNode: '</a> -->\n\t\t\t  <br><br>\n  '>, <django.template.defaulttags.CsrfTokenNode object at 0x7fb7b3fc2550>, <TextNode: '\n\t\t\t\t<div class="mb3 pb-1'>, <Variable Node: direction>, <TextNode: '">'>, <Variable Node: direction>, <TextNode: '</option>\t\t\t\t\t\t          '>, <Variable Node: flight_date>, <TextNode: '" type="text" >\t\t\t\t  \n   '>, <IfNode>, <TextNode: '\n\t\t\t\t  <div class="mb-3 p'>, <Variable Node: suburb>, <TextNode: '</label>\t\t\t\t\t\n\t\t\t\t</div>\n'>, <Variable Node: suburb>, <TextNode: '">'>, <Variable Node: suburb>, <TextNode: '</option>\t\t\t\t\t\n\t\t\t\t  </se'>, <Variable Node: no_of_passenger>, <TextNode: '">'>, <Variable Node: no_of_passenger>, <TextNode: '</option>\t\t\t\t  \n         '>, <Variable Node: recaptcha_site_key>, <TextNode: '"></div>\n\t\t\t\t<div id="err'>]>}]
DEBUG 2024-01-30 10:22:38,188 base Exception while resolving variable 'suburb' in template 'basecamp/inquiry1.html'.
Traceback (most recent call last):
  File "/home/horeb/github/easygo/venv/lib/python3.11/site-packages/django/template/base.py", line 880, in _resolve_lookup
    current = current[bit]
              ~~~~~~~^^^^^
  File "/home/horeb/github/easygo/venv/lib/python3.11/site-packages/django/template/context.py", line 83, in __getitem__
    raise KeyError(key)
KeyError: 'suburb'

During handling of the above exception, another exception occurred:

Traceback (most recent call last):
  File "/home/horeb/github/easygo/venv/lib/python3.11/site-packages/django/template/base.py", line 886, in _resolve_lookup
    if isinstance(current, BaseContext) and getattr(
                                            ^^^^^^^^
AttributeError: type object 'RequestContext' has no attribute 'suburb'

During handling of the above exception, another exception occurred:

Traceback (most recent call last):
  File "/home/horeb/github/easygo/venv/lib/python3.11/site-packages/django/template/base.py", line 896, in _resolve_lookup
    current = current[int(bit)]
                      ^^^^^^^^
ValueError: invalid literal for int() with base 10: 'suburb'

During handling of the above exception, another exception occurred:

Traceback (most recent call last):
  File "/home/horeb/github/easygo/venv/lib/python3.11/site-packages/django/template/base.py", line 903, in _resolve_lookup
    raise VariableDoesNotExist(
django.template.base.VariableDoesNotExist: Failed lookup for key [suburb] in [{'True': True, 'False': False, 'None': None}, {'csrf_token': <SimpleLazyObject: '8lfBoZUxUvVbh0PCyePhFfbtS4mCb2TVvot0byzRxFRGGSrHU9klq0JFWgLpSIj0'>, 'request': <WSGIRequest: GET '/price_detail/'>, 'user': <SimpleLazyObject: <function AuthenticationMiddleware.process_request.<locals>.<lambda> at 0x7fb7b41f13a0>>, 'perms': PermWrapper(<SimpleLazyObject: <function AuthenticationMiddleware.process_request.<locals>.<lambda> at 0x7fb7b41f13a0>>), 'messages': <FallbackStorage: request=<WSGIRequest: GET '/price_detail/'>>, 'DEFAULT_MESSAGE_LEVELS': {'DEBUG': 10, 'INFO': 20, 'SUCCESS': 25, 'WARNING': 30, 'ERROR': 40}}, {}, {'block': <Block Node: content. Contents: [<TextNode: '\n      <!-- Page content-'>, <Variable Node: flight_date>, <TextNode: '</a><br>\n\t\t\t  <a style="f'>, <Variable Node: direction>, <TextNode: '</a><br>\n\t\t\t  <a style="f'>, <Variable Node: suburb>, <TextNode: '</a><br>\n\t\t\t  <a style="f'>, <Variable Node: no_of_passenger>, <TextNode: '</a> -->\n\t\t\t  <br><br>\n  '>, <django.template.defaulttags.CsrfTokenNode object at 0x7fb7b3fc2550>, <TextNode: '\n\t\t\t\t<div class="mb3 pb-1'>, <Variable Node: direction>, <TextNode: '">'>, <Variable Node: direction>, <TextNode: '</option>\t\t\t\t\t\t          '>, <Variable Node: flight_date>, <TextNode: '" type="text" >\t\t\t\t  \n   '>, <IfNode>, <TextNode: '\n\t\t\t\t  <div class="mb-3 p'>, <Variable Node: suburb>, <TextNode: '</label>\t\t\t\t\t\n\t\t\t\t</div>\n'>, <Variable Node: suburb>, <TextNode: '">'>, <Variable Node: suburb>, <TextNode: '</option>\t\t\t\t\t\n\t\t\t\t  </se'>, <Variable Node: no_of_passenger>, <TextNode: '">'>, <Variable Node: no_of_passenger>, <TextNode: '</option>\t\t\t\t  \n         '>, <Variable Node: recaptcha_site_key>, <TextNode: '"></div>\n\t\t\t\t<div id="err'>]>}]
DEBUG 2024-01-30 10:22:38,188 base Exception while resolving variable 'suburb' in template 'basecamp/inquiry1.html'.
Traceback (most recent call last):
  File "/home/horeb/github/easygo/venv/lib/python3.11/site-packages/django/template/base.py", line 880, in _resolve_lookup
    current = current[bit]
              ~~~~~~~^^^^^
  File "/home/horeb/github/easygo/venv/lib/python3.11/site-packages/django/template/context.py", line 83, in __getitem__
    raise KeyError(key)
KeyError: 'suburb'

During handling of the above exception, another exception occurred:

Traceback (most recent call last):
  File "/home/horeb/github/easygo/venv/lib/python3.11/site-packages/django/template/base.py", line 886, in _resolve_lookup
    if isinstance(current, BaseContext) and getattr(
                                            ^^^^^^^^
AttributeError: type object 'RequestContext' has no attribute 'suburb'

During handling of the above exception, another exception occurred:

Traceback (most recent call last):
  File "/home/horeb/github/easygo/venv/lib/python3.11/site-packages/django/template/base.py", line 896, in _resolve_lookup
    current = current[int(bit)]
                      ^^^^^^^^
ValueError: invalid literal for int() with base 10: 'suburb'

During handling of the above exception, another exception occurred:

Traceback (most recent call last):
  File "/home/horeb/github/easygo/venv/lib/python3.11/site-packages/django/template/base.py", line 903, in _resolve_lookup
    raise VariableDoesNotExist(
django.template.base.VariableDoesNotExist: Failed lookup for key [suburb] in [{'True': True, 'False': False, 'None': None}, {'csrf_token': <SimpleLazyObject: '8lfBoZUxUvVbh0PCyePhFfbtS4mCb2TVvot0byzRxFRGGSrHU9klq0JFWgLpSIj0'>, 'request': <WSGIRequest: GET '/price_detail/'>, 'user': <SimpleLazyObject: <function AuthenticationMiddleware.process_request.<locals>.<lambda> at 0x7fb7b41f13a0>>, 'perms': PermWrapper(<SimpleLazyObject: <function AuthenticationMiddleware.process_request.<locals>.<lambda> at 0x7fb7b41f13a0>>), 'messages': <FallbackStorage: request=<WSGIRequest: GET '/price_detail/'>>, 'DEFAULT_MESSAGE_LEVELS': {'DEBUG': 10, 'INFO': 20, 'SUCCESS': 25, 'WARNING': 30, 'ERROR': 40}}, {}, {'block': <Block Node: content. Contents: [<TextNode: '\n      <!-- Page content-'>, <Variable Node: flight_date>, <TextNode: '</a><br>\n\t\t\t  <a style="f'>, <Variable Node: direction>, <TextNode: '</a><br>\n\t\t\t  <a style="f'>, <Variable Node: suburb>, <TextNode: '</a><br>\n\t\t\t  <a style="f'>, <Variable Node: no_of_passenger>, <TextNode: '</a> -->\n\t\t\t  <br><br>\n  '>, <django.template.defaulttags.CsrfTokenNode object at 0x7fb7b3fc2550>, <TextNode: '\n\t\t\t\t<div class="mb3 pb-1'>, <Variable Node: direction>, <TextNode: '">'>, <Variable Node: direction>, <TextNode: '</option>\t\t\t\t\t\t          '>, <Variable Node: flight_date>, <TextNode: '" type="text" >\t\t\t\t  \n   '>, <IfNode>, <TextNode: '\n\t\t\t\t  <div class="mb-3 p'>, <Variable Node: suburb>, <TextNode: '</label>\t\t\t\t\t\n\t\t\t\t</div>\n'>, <Variable Node: suburb>, <TextNode: '">'>, <Variable Node: suburb>, <TextNode: '</option>\t\t\t\t\t\n\t\t\t\t  </se'>, <Variable Node: no_of_passenger>, <TextNode: '">'>, <Variable Node: no_of_passenger>, <TextNode: '</option>\t\t\t\t  \n         '>, <Variable Node: recaptcha_site_key>, <TextNode: '"></div>\n\t\t\t\t<div id="err'>]>}]
DEBUG 2024-01-30 10:22:38,189 base Exception while resolving variable 'suburb' in template 'basecamp/inquiry1.html'.
Traceback (most recent call last):
  File "/home/horeb/github/easygo/venv/lib/python3.11/site-packages/django/template/base.py", line 880, in _resolve_lookup
    current = current[bit]
              ~~~~~~~^^^^^
  File "/home/horeb/github/easygo/venv/lib/python3.11/site-packages/django/template/context.py", line 83, in __getitem__
    raise KeyError(key)
KeyError: 'suburb'

During handling of the above exception, another exception occurred:

Traceback (most recent call last):
  File "/home/horeb/github/easygo/venv/lib/python3.11/site-packages/django/template/base.py", line 886, in _resolve_lookup
    if isinstance(current, BaseContext) and getattr(
                                            ^^^^^^^^
AttributeError: type object 'RequestContext' has no attribute 'suburb'

During handling of the above exception, another exception occurred:

Traceback (most recent call last):
  File "/home/horeb/github/easygo/venv/lib/python3.11/site-packages/django/template/base.py", line 896, in _resolve_lookup
    current = current[int(bit)]
                      ^^^^^^^^
ValueError: invalid literal for int() with base 10: 'suburb'

During handling of the above exception, another exception occurred:

Traceback (most recent call last):
  File "/home/horeb/github/easygo/venv/lib/python3.11/site-packages/django/template/base.py", line 903, in _resolve_lookup
    raise VariableDoesNotExist(
django.template.base.VariableDoesNotExist: Failed lookup for key [suburb] in [{'True': True, 'False': False, 'None': None}, {'csrf_token': <SimpleLazyObject: '8lfBoZUxUvVbh0PCyePhFfbtS4mCb2TVvot0byzRxFRGGSrHU9klq0JFWgLpSIj0'>, 'request': <WSGIRequest: GET '/price_detail/'>, 'user': <SimpleLazyObject: <function AuthenticationMiddleware.process_request.<locals>.<lambda> at 0x7fb7b41f13a0>>, 'perms': PermWrapper(<SimpleLazyObject: <function AuthenticationMiddleware.process_request.<locals>.<lambda> at 0x7fb7b41f13a0>>), 'messages': <FallbackStorage: request=<WSGIRequest: GET '/price_detail/'>>, 'DEFAULT_MESSAGE_LEVELS': {'DEBUG': 10, 'INFO': 20, 'SUCCESS': 25, 'WARNING': 30, 'ERROR': 40}}, {}, {'block': <Block Node: content. Contents: [<TextNode: '\n      <!-- Page content-'>, <Variable Node: flight_date>, <TextNode: '</a><br>\n\t\t\t  <a style="f'>, <Variable Node: direction>, <TextNode: '</a><br>\n\t\t\t  <a style="f'>, <Variable Node: suburb>, <TextNode: '</a><br>\n\t\t\t  <a style="f'>, <Variable Node: no_of_passenger>, <TextNode: '</a> -->\n\t\t\t  <br><br>\n  '>, <django.template.defaulttags.CsrfTokenNode object at 0x7fb7b3fc2550>, <TextNode: '\n\t\t\t\t<div class="mb3 pb-1'>, <Variable Node: direction>, <TextNode: '">'>, <Variable Node: direction>, <TextNode: '</option>\t\t\t\t\t\t          '>, <Variable Node: flight_date>, <TextNode: '" type="text" >\t\t\t\t  \n   '>, <IfNode>, <TextNode: '\n\t\t\t\t  <div class="mb-3 p'>, <Variable Node: suburb>, <TextNode: '</label>\t\t\t\t\t\n\t\t\t\t</div>\n'>, <Variable Node: suburb>, <TextNode: '">'>, <Variable Node: suburb>, <TextNode: '</option>\t\t\t\t\t\n\t\t\t\t  </se'>, <Variable Node: no_of_passenger>, <TextNode: '">'>, <Variable Node: no_of_passenger>, <TextNode: '</option>\t\t\t\t  \n         '>, <Variable Node: recaptcha_site_key>, <TextNode: '"></div>\n\t\t\t\t<div id="err'>]>}]
DEBUG 2024-01-30 10:22:38,189 base Exception while resolving variable 'no_of_passenger' in template 'basecamp/inquiry1.html'.
Traceback (most recent call last):
  File "/home/horeb/github/easygo/venv/lib/python3.11/site-packages/django/template/base.py", line 880, in _resolve_lookup
    current = current[bit]
              ~~~~~~~^^^^^
  File "/home/horeb/github/easygo/venv/lib/python3.11/site-packages/django/template/context.py", line 83, in __getitem__
    raise KeyError(key)
KeyError: 'no_of_passenger'

During handling of the above exception, another exception occurred:

Traceback (most recent call last):
  File "/home/horeb/github/easygo/venv/lib/python3.11/site-packages/django/template/base.py", line 886, in _resolve_lookup
    if isinstance(current, BaseContext) and getattr(
                                            ^^^^^^^^
AttributeError: type object 'RequestContext' has no attribute 'no_of_passenger'

During handling of the above exception, another exception occurred:

Traceback (most recent call last):
  File "/home/horeb/github/easygo/venv/lib/python3.11/site-packages/django/template/base.py", line 896, in _resolve_lookup
    current = current[int(bit)]
                      ^^^^^^^^
ValueError: invalid literal for int() with base 10: 'no_of_passenger'

During handling of the above exception, another exception occurred:

Traceback (most recent call last):
  File "/home/horeb/github/easygo/venv/lib/python3.11/site-packages/django/template/base.py", line 903, in _resolve_lookup
    raise VariableDoesNotExist(
django.template.base.VariableDoesNotExist: Failed lookup for key [no_of_passenger] in [{'True': True, 'False': False, 'None': None}, {'csrf_token': <SimpleLazyObject: '8lfBoZUxUvVbh0PCyePhFfbtS4mCb2TVvot0byzRxFRGGSrHU9klq0JFWgLpSIj0'>, 'request': <WSGIRequest: GET '/price_detail/'>, 'user': <SimpleLazyObject: <function AuthenticationMiddleware.process_request.<locals>.<lambda> at 0x7fb7b41f13a0>>, 'perms': PermWrapper(<SimpleLazyObject: <function AuthenticationMiddleware.process_request.<locals>.<lambda> at 0x7fb7b41f13a0>>), 'messages': <FallbackStorage: request=<WSGIRequest: GET '/price_detail/'>>, 'DEFAULT_MESSAGE_LEVELS': {'DEBUG': 10, 'INFO': 20, 'SUCCESS': 25, 'WARNING': 30, 'ERROR': 40}}, {}, {'block': <Block Node: content. Contents: [<TextNode: '\n      <!-- Page content-'>, <Variable Node: flight_date>, <TextNode: '</a><br>\n\t\t\t  <a style="f'>, <Variable Node: direction>, <TextNode: '</a><br>\n\t\t\t  <a style="f'>, <Variable Node: suburb>, <TextNode: '</a><br>\n\t\t\t  <a style="f'>, <Variable Node: no_of_passenger>, <TextNode: '</a> -->\n\t\t\t  <br><br>\n  '>, <django.template.defaulttags.CsrfTokenNode object at 0x7fb7b3fc2550>, <TextNode: '\n\t\t\t\t<div class="mb3 pb-1'>, <Variable Node: direction>, <TextNode: '">'>, <Variable Node: direction>, <TextNode: '</option>\t\t\t\t\t\t          '>, <Variable Node: flight_date>, <TextNode: '" type="text" >\t\t\t\t  \n   '>, <IfNode>, <TextNode: '\n\t\t\t\t  <div class="mb-3 p'>, <Variable Node: suburb>, <TextNode: '</label>\t\t\t\t\t\n\t\t\t\t</div>\n'>, <Variable Node: suburb>, <TextNode: '">'>, <Variable Node: suburb>, <TextNode: '</option>\t\t\t\t\t\n\t\t\t\t  </se'>, <Variable Node: no_of_passenger>, <TextNode: '">'>, <Variable Node: no_of_passenger>, <TextNode: '</option>\t\t\t\t  \n         '>, <Variable Node: recaptcha_site_key>, <TextNode: '"></div>\n\t\t\t\t<div id="err'>]>}]
DEBUG 2024-01-30 10:22:38,189 base Exception while resolving variable 'no_of_passenger' in template 'basecamp/inquiry1.html'.
Traceback (most recent call last):
  File "/home/horeb/github/easygo/venv/lib/python3.11/site-packages/django/template/base.py", line 880, in _resolve_lookup
    current = current[bit]
              ~~~~~~~^^^^^
  File "/home/horeb/github/easygo/venv/lib/python3.11/site-packages/django/template/context.py", line 83, in __getitem__
    raise KeyError(key)
KeyError: 'no_of_passenger'

During handling of the above exception, another exception occurred:

Traceback (most recent call last):
  File "/home/horeb/github/easygo/venv/lib/python3.11/site-packages/django/template/base.py", line 886, in _resolve_lookup
    if isinstance(current, BaseContext) and getattr(
                                            ^^^^^^^^
AttributeError: type object 'RequestContext' has no attribute 'no_of_passenger'

During handling of the above exception, another exception occurred:

Traceback (most recent call last):
  File "/home/horeb/github/easygo/venv/lib/python3.11/site-packages/django/template/base.py", line 896, in _resolve_lookup
    current = current[int(bit)]
                      ^^^^^^^^
ValueError: invalid literal for int() with base 10: 'no_of_passenger'

During handling of the above exception, another exception occurred:

Traceback (most recent call last):
  File "/home/horeb/github/easygo/venv/lib/python3.11/site-packages/django/template/base.py", line 903, in _resolve_lookup
    raise VariableDoesNotExist(
django.template.base.VariableDoesNotExist: Failed lookup for key [no_of_passenger] in [{'True': True, 'False': False, 'None': None}, {'csrf_token': <SimpleLazyObject: '8lfBoZUxUvVbh0PCyePhFfbtS4mCb2TVvot0byzRxFRGGSrHU9klq0JFWgLpSIj0'>, 'request': <WSGIRequest: GET '/price_detail/'>, 'user': <SimpleLazyObject: <function AuthenticationMiddleware.process_request.<locals>.<lambda> at 0x7fb7b41f13a0>>, 'perms': PermWrapper(<SimpleLazyObject: <function AuthenticationMiddleware.process_request.<locals>.<lambda> at 0x7fb7b41f13a0>>), 'messages': <FallbackStorage: request=<WSGIRequest: GET '/price_detail/'>>, 'DEFAULT_MESSAGE_LEVELS': {'DEBUG': 10, 'INFO': 20, 'SUCCESS': 25, 'WARNING': 30, 'ERROR': 40}}, {}, {'block': <Block Node: content. Contents: [<TextNode: '\n      <!-- Page content-'>, <Variable Node: flight_date>, <TextNode: '</a><br>\n\t\t\t  <a style="f'>, <Variable Node: direction>, <TextNode: '</a><br>\n\t\t\t  <a style="f'>, <Variable Node: suburb>, <TextNode: '</a><br>\n\t\t\t  <a style="f'>, <Variable Node: no_of_passenger>, <TextNode: '</a> -->\n\t\t\t  <br><br>\n  '>, <django.template.defaulttags.CsrfTokenNode object at 0x7fb7b3fc2550>, <TextNode: '\n\t\t\t\t<div class="mb3 pb-1'>, <Variable Node: direction>, <TextNode: '">'>, <Variable Node: direction>, <TextNode: '</option>\t\t\t\t\t\t          '>, <Variable Node: flight_date>, <TextNode: '" type="text" >\t\t\t\t  \n   '>, <IfNode>, <TextNode: '\n\t\t\t\t  <div class="mb-3 p'>, <Variable Node: suburb>, <TextNode: '</label>\t\t\t\t\t\n\t\t\t\t</div>\n'>, <Variable Node: suburb>, <TextNode: '">'>, <Variable Node: suburb>, <TextNode: '</option>\t\t\t\t\t\n\t\t\t\t  </se'>, <Variable Node: no_of_passenger>, <TextNode: '">'>, <Variable Node: no_of_passenger>, <TextNode: '</option>\t\t\t\t  \n         '>, <Variable Node: recaptcha_site_key>, <TextNode: '"></div>\n\t\t\t\t<div id="err'>]>}]
DEBUG 2024-01-30 10:22:38,190 base Exception while resolving variable 'recaptcha_site_key' in template 'basecamp/inquiry1.html'.
Traceback (most recent call last):
  File "/home/horeb/github/easygo/venv/lib/python3.11/site-packages/django/template/base.py", line 880, in _resolve_lookup
    current = current[bit]
              ~~~~~~~^^^^^
  File "/home/horeb/github/easygo/venv/lib/python3.11/site-packages/django/template/context.py", line 83, in __getitem__
    raise KeyError(key)
KeyError: 'recaptcha_site_key'

During handling of the above exception, another exception occurred:

Traceback (most recent call last):
  File "/home/horeb/github/easygo/venv/lib/python3.11/site-packages/django/template/base.py", line 886, in _resolve_lookup
    if isinstance(current, BaseContext) and getattr(
                                            ^^^^^^^^
AttributeError: type object 'RequestContext' has no attribute 'recaptcha_site_key'

During handling of the above exception, another exception occurred:

Traceback (most recent call last):
  File "/home/horeb/github/easygo/venv/lib/python3.11/site-packages/django/template/base.py", line 896, in _resolve_lookup
    current = current[int(bit)]
                      ^^^^^^^^
ValueError: invalid literal for int() with base 10: 'recaptcha_site_key'

During handling of the above exception, another exception occurred:

Traceback (most recent call last):
  File "/home/horeb/github/easygo/venv/lib/python3.11/site-packages/django/template/base.py", line 903, in _resolve_lookup
    raise VariableDoesNotExist(
django.template.base.VariableDoesNotExist: Failed lookup for key [recaptcha_site_key] in [{'True': True, 'False': False, 'None': None}, {'csrf_token': <SimpleLazyObject: '8lfBoZUxUvVbh0PCyePhFfbtS4mCb2TVvot0byzRxFRGGSrHU9klq0JFWgLpSIj0'>, 'request': <WSGIRequest: GET '/price_detail/'>, 'user': <SimpleLazyObject: <function AuthenticationMiddleware.process_request.<locals>.<lambda> at 0x7fb7b41f13a0>>, 'perms': PermWrapper(<SimpleLazyObject: <function AuthenticationMiddleware.process_request.<locals>.<lambda> at 0x7fb7b41f13a0>>), 'messages': <FallbackStorage: request=<WSGIRequest: GET '/price_detail/'>>, 'DEFAULT_MESSAGE_LEVELS': {'DEBUG': 10, 'INFO': 20, 'SUCCESS': 25, 'WARNING': 30, 'ERROR': 40}}, {}, {'block': <Block Node: content. Contents: [<TextNode: '\n      <!-- Page content-'>, <Variable Node: flight_date>, <TextNode: '</a><br>\n\t\t\t  <a style="f'>, <Variable Node: direction>, <TextNode: '</a><br>\n\t\t\t  <a style="f'>, <Variable Node: suburb>, <TextNode: '</a><br>\n\t\t\t  <a style="f'>, <Variable Node: no_of_passenger>, <TextNode: '</a> -->\n\t\t\t  <br><br>\n  '>, <django.template.defaulttags.CsrfTokenNode object at 0x7fb7b3fc2550>, <TextNode: '\n\t\t\t\t<div class="mb3 pb-1'>, <Variable Node: direction>, <TextNode: '">'>, <Variable Node: direction>, <TextNode: '</option>\t\t\t\t\t\t          '>, <Variable Node: flight_date>, <TextNode: '" type="text" >\t\t\t\t  \n   '>, <IfNode>, <TextNode: '\n\t\t\t\t  <div class="mb-3 p'>, <Variable Node: suburb>, <TextNode: '</label>\t\t\t\t\t\n\t\t\t\t</div>\n'>, <Variable Node: suburb>, <TextNode: '">'>, <Variable Node: suburb>, <TextNode: '</option>\t\t\t\t\t\n\t\t\t\t  </se'>, <Variable Node: no_of_passenger>, <TextNode: '">'>, <Variable Node: no_of_passenger>, <TextNode: '</option>\t\t\t\t  \n         '>, <Variable Node: recaptcha_site_key>, <TextNode: '"></div>\n\t\t\t\t<div id="err'>]>}]
WARNING 2024-01-30 10:22:38,389 log Not Found: /apple-touch-icon-120x120-precomposed.png
WARNING 2024-01-30 10:22:38,464 log Not Found: /apple-touch-icon-120x120.png
