ERROR 2023-10-29 03:30:03,386 log Internal Server Error: /p2p/
Traceback (most recent call last):
  File "/home/ubuntu/github/easygo/venv/lib/python3.10/site-packages/django/core/handlers/exception.py", line 56, in inner
    response = get_response(request)
  File "/home/ubuntu/github/easygo/venv/lib/python3.10/site-packages/django/core/handlers/base.py", line 197, in _get_response
    response = wrapped_callback(request, *callback_args, **callback_kwargs)
  File "/home/ubuntu/github/easygo/basecamp/views.py", line 1166, in p2p
    email.send()
  File "/home/ubuntu/github/easygo/venv/lib/python3.10/site-packages/django/core/mail/message.py", line 298, in send
    return self.get_connection(fail_silently).send_messages([self])
  File "/home/ubuntu/github/easygo/venv/lib/python3.10/site-packages/django/core/mail/backends/smtp.py", line 124, in send_messages
    new_conn_created = self.open()
  File "/home/ubuntu/github/easygo/venv/lib/python3.10/site-packages/django/core/mail/backends/smtp.py", line 91, in open
    self.connection.login(self.username, self.password)
  File "/usr/lib/python3.10/smtplib.py", line 739, in login
    (code, resp) = self.auth(
  File "/usr/lib/python3.10/smtplib.py", line 642, in auth
    (code, resp) = self.docmd("AUTH", mechanism + " " + response)
  File "/usr/lib/python3.10/smtplib.py", line 432, in docmd
    return self.getreply()
  File "/usr/lib/python3.10/smtplib.py", line 405, in getreply
    raise SMTPServerDisconnected("Connection unexpectedly closed")
smtplib.SMTPServerDisconnected: Connection unexpectedly closed
ERROR 2023-10-29 03:30:05,232 log Internal Server Error: /p2p/
Traceback (most recent call last):
  File "/home/ubuntu/github/easygo/venv/lib/python3.10/site-packages/django/core/handlers/exception.py", line 56, in inner
    response = get_response(request)
  File "/home/ubuntu/github/easygo/venv/lib/python3.10/site-packages/django/core/handlers/base.py", line 197, in _get_response
    response = wrapped_callback(request, *callback_args, **callback_kwargs)
  File "/home/ubuntu/github/easygo/basecamp/views.py", line 1166, in p2p
    email.send()
  File "/home/ubuntu/github/easygo/venv/lib/python3.10/site-packages/django/core/mail/message.py", line 298, in send
    return self.get_connection(fail_silently).send_messages([self])
  File "/home/ubuntu/github/easygo/venv/lib/python3.10/site-packages/django/core/mail/backends/smtp.py", line 124, in send_messages
    new_conn_created = self.open()
  File "/home/ubuntu/github/easygo/venv/lib/python3.10/site-packages/django/core/mail/backends/smtp.py", line 91, in open
    self.connection.login(self.username, self.password)
  File "/usr/lib/python3.10/smtplib.py", line 739, in login
    (code, resp) = self.auth(
  File "/usr/lib/python3.10/smtplib.py", line 642, in auth
    (code, resp) = self.docmd("AUTH", mechanism + " " + response)
  File "/usr/lib/python3.10/smtplib.py", line 432, in docmd
    return self.getreply()
  File "/usr/lib/python3.10/smtplib.py", line 405, in getreply
    raise SMTPServerDisconnected("Connection unexpectedly closed")
smtplib.SMTPServerDisconnected: Connection unexpectedly closed
ERROR 2023-10-29 03:30:07,130 log Internal Server Error: /p2p/
Traceback (most recent call last):
  File "/home/ubuntu/github/easygo/venv/lib/python3.10/site-packages/django/core/handlers/exception.py", line 56, in inner
    response = get_response(request)
  File "/home/ubuntu/github/easygo/venv/lib/python3.10/site-packages/django/core/handlers/base.py", line 197, in _get_response
    response = wrapped_callback(request, *callback_args, **callback_kwargs)
  File "/home/ubuntu/github/easygo/basecamp/views.py", line 1166, in p2p
    email.send()
  File "/home/ubuntu/github/easygo/venv/lib/python3.10/site-packages/django/core/mail/message.py", line 298, in send
    return self.get_connection(fail_silently).send_messages([self])
  File "/home/ubuntu/github/easygo/venv/lib/python3.10/site-packages/django/core/mail/backends/smtp.py", line 124, in send_messages
    new_conn_created = self.open()
  File "/home/ubuntu/github/easygo/venv/lib/python3.10/site-packages/django/core/mail/backends/smtp.py", line 91, in open
    self.connection.login(self.username, self.password)
  File "/usr/lib/python3.10/smtplib.py", line 739, in login
    (code, resp) = self.auth(
  File "/usr/lib/python3.10/smtplib.py", line 642, in auth
    (code, resp) = self.docmd("AUTH", mechanism + " " + response)
  File "/usr/lib/python3.10/smtplib.py", line 432, in docmd
    return self.getreply()
  File "/usr/lib/python3.10/smtplib.py", line 405, in getreply
    raise SMTPServerDisconnected("Connection unexpectedly closed")
smtplib.SMTPServerDisconnected: Connection unexpectedly closed
ERROR 2023-10-29 03:30:09,652 log Internal Server Error: /p2p/
Traceback (most recent call last):
  File "/home/ubuntu/github/easygo/venv/lib/python3.10/site-packages/django/core/handlers/exception.py", line 56, in inner
    response = get_response(request)
  File "/home/ubuntu/github/easygo/venv/lib/python3.10/site-packages/django/core/handlers/base.py", line 197, in _get_response
    response = wrapped_callback(request, *callback_args, **callback_kwargs)
  File "/home/ubuntu/github/easygo/basecamp/views.py", line 1166, in p2p
    email.send()
  File "/home/ubuntu/github/easygo/venv/lib/python3.10/site-packages/django/core/mail/message.py", line 298, in send
    return self.get_connection(fail_silently).send_messages([self])
  File "/home/ubuntu/github/easygo/venv/lib/python3.10/site-packages/django/core/mail/backends/smtp.py", line 124, in send_messages
    new_conn_created = self.open()
  File "/home/ubuntu/github/easygo/venv/lib/python3.10/site-packages/django/core/mail/backends/smtp.py", line 91, in open
    self.connection.login(self.username, self.password)
  File "/usr/lib/python3.10/smtplib.py", line 739, in login
    (code, resp) = self.auth(
  File "/usr/lib/python3.10/smtplib.py", line 642, in auth
    (code, resp) = self.docmd("AUTH", mechanism + " " + response)
  File "/usr/lib/python3.10/smtplib.py", line 432, in docmd
    return self.getreply()
  File "/usr/lib/python3.10/smtplib.py", line 405, in getreply
    raise SMTPServerDisconnected("Connection unexpectedly closed")
smtplib.SMTPServerDisconnected: Connection unexpectedly closed
ERROR 2023-10-29 03:30:12,173 log Internal Server Error: /p2p/
Traceback (most recent call last):
  File "/home/ubuntu/github/easygo/venv/lib/python3.10/site-packages/django/core/handlers/exception.py", line 56, in inner
    response = get_response(request)
  File "/home/ubuntu/github/easygo/venv/lib/python3.10/site-packages/django/core/handlers/base.py", line 197, in _get_response
    response = wrapped_callback(request, *callback_args, **callback_kwargs)
  File "/home/ubuntu/github/easygo/basecamp/views.py", line 1166, in p2p
    email.send()
  File "/home/ubuntu/github/easygo/venv/lib/python3.10/site-packages/django/core/mail/message.py", line 298, in send
    return self.get_connection(fail_silently).send_messages([self])
  File "/home/ubuntu/github/easygo/venv/lib/python3.10/site-packages/django/core/mail/backends/smtp.py", line 124, in send_messages
    new_conn_created = self.open()
  File "/home/ubuntu/github/easygo/venv/lib/python3.10/site-packages/django/core/mail/backends/smtp.py", line 91, in open
    self.connection.login(self.username, self.password)
  File "/usr/lib/python3.10/smtplib.py", line 739, in login
    (code, resp) = self.auth(
  File "/usr/lib/python3.10/smtplib.py", line 642, in auth
    (code, resp) = self.docmd("AUTH", mechanism + " " + response)
  File "/usr/lib/python3.10/smtplib.py", line 432, in docmd
    return self.getreply()
  File "/usr/lib/python3.10/smtplib.py", line 405, in getreply
    raise SMTPServerDisconnected("Connection unexpectedly closed")
smtplib.SMTPServerDisconnected: Connection unexpectedly closed
ERROR 2023-10-29 03:30:14,698 log Internal Server Error: /p2p/
Traceback (most recent call last):
  File "/home/ubuntu/github/easygo/venv/lib/python3.10/site-packages/django/core/handlers/exception.py", line 56, in inner
    response = get_response(request)
  File "/home/ubuntu/github/easygo/venv/lib/python3.10/site-packages/django/core/handlers/base.py", line 197, in _get_response
    response = wrapped_callback(request, *callback_args, **callback_kwargs)
  File "/home/ubuntu/github/easygo/basecamp/views.py", line 1166, in p2p
    email.send()
  File "/home/ubuntu/github/easygo/venv/lib/python3.10/site-packages/django/core/mail/message.py", line 298, in send
    return self.get_connection(fail_silently).send_messages([self])
  File "/home/ubuntu/github/easygo/venv/lib/python3.10/site-packages/django/core/mail/backends/smtp.py", line 124, in send_messages
    new_conn_created = self.open()
  File "/home/ubuntu/github/easygo/venv/lib/python3.10/site-packages/django/core/mail/backends/smtp.py", line 91, in open
    self.connection.login(self.username, self.password)
  File "/usr/lib/python3.10/smtplib.py", line 739, in login
    (code, resp) = self.auth(
  File "/usr/lib/python3.10/smtplib.py", line 642, in auth
    (code, resp) = self.docmd("AUTH", mechanism + " " + response)
  File "/usr/lib/python3.10/smtplib.py", line 432, in docmd
    return self.getreply()
  File "/usr/lib/python3.10/smtplib.py", line 405, in getreply
    raise SMTPServerDisconnected("Connection unexpectedly closed")
smtplib.SMTPServerDisconnected: Connection unexpectedly closed
ERROR 2023-10-29 03:30:17,255 log Internal Server Error: /p2p/
Traceback (most recent call last):
  File "/home/ubuntu/github/easygo/venv/lib/python3.10/site-packages/django/core/handlers/exception.py", line 56, in inner
    response = get_response(request)
  File "/home/ubuntu/github/easygo/venv/lib/python3.10/site-packages/django/core/handlers/base.py", line 197, in _get_response
    response = wrapped_callback(request, *callback_args, **callback_kwargs)
  File "/home/ubuntu/github/easygo/basecamp/views.py", line 1166, in p2p
    email.send()
  File "/home/ubuntu/github/easygo/venv/lib/python3.10/site-packages/django/core/mail/message.py", line 298, in send
    return self.get_connection(fail_silently).send_messages([self])
  File "/home/ubuntu/github/easygo/venv/lib/python3.10/site-packages/django/core/mail/backends/smtp.py", line 124, in send_messages
    new_conn_created = self.open()
  File "/home/ubuntu/github/easygo/venv/lib/python3.10/site-packages/django/core/mail/backends/smtp.py", line 91, in open
    self.connection.login(self.username, self.password)
  File "/usr/lib/python3.10/smtplib.py", line 739, in login
    (code, resp) = self.auth(
  File "/usr/lib/python3.10/smtplib.py", line 642, in auth
    (code, resp) = self.docmd("AUTH", mechanism + " " + response)
  File "/usr/lib/python3.10/smtplib.py", line 432, in docmd
    return self.getreply()
  File "/usr/lib/python3.10/smtplib.py", line 405, in getreply
    raise SMTPServerDisconnected("Connection unexpectedly closed")
smtplib.SMTPServerDisconnected: Connection unexpectedly closed
ERROR 2023-10-29 03:30:19,831 log Internal Server Error: /p2p/
Traceback (most recent call last):
  File "/home/ubuntu/github/easygo/venv/lib/python3.10/site-packages/django/core/handlers/exception.py", line 56, in inner
    response = get_response(request)
  File "/home/ubuntu/github/easygo/venv/lib/python3.10/site-packages/django/core/handlers/base.py", line 197, in _get_response
    response = wrapped_callback(request, *callback_args, **callback_kwargs)
  File "/home/ubuntu/github/easygo/basecamp/views.py", line 1166, in p2p
    email.send()
  File "/home/ubuntu/github/easygo/venv/lib/python3.10/site-packages/django/core/mail/message.py", line 298, in send
    return self.get_connection(fail_silently).send_messages([self])
  File "/home/ubuntu/github/easygo/venv/lib/python3.10/site-packages/django/core/mail/backends/smtp.py", line 124, in send_messages
    new_conn_created = self.open()
  File "/home/ubuntu/github/easygo/venv/lib/python3.10/site-packages/django/core/mail/backends/smtp.py", line 91, in open
    self.connection.login(self.username, self.password)
  File "/usr/lib/python3.10/smtplib.py", line 739, in login
    (code, resp) = self.auth(
  File "/usr/lib/python3.10/smtplib.py", line 642, in auth
    (code, resp) = self.docmd("AUTH", mechanism + " " + response)
  File "/usr/lib/python3.10/smtplib.py", line 432, in docmd
    return self.getreply()
  File "/usr/lib/python3.10/smtplib.py", line 405, in getreply
    raise SMTPServerDisconnected("Connection unexpectedly closed")
smtplib.SMTPServerDisconnected: Connection unexpectedly closed
ERROR 2023-10-29 03:30:22,352 log Internal Server Error: /p2p/
Traceback (most recent call last):
  File "/home/ubuntu/github/easygo/venv/lib/python3.10/site-packages/django/core/handlers/exception.py", line 56, in inner
    response = get_response(request)
  File "/home/ubuntu/github/easygo/venv/lib/python3.10/site-packages/django/core/handlers/base.py", line 197, in _get_response
    response = wrapped_callback(request, *callback_args, **callback_kwargs)
  File "/home/ubuntu/github/easygo/basecamp/views.py", line 1166, in p2p
    email.send()
  File "/home/ubuntu/github/easygo/venv/lib/python3.10/site-packages/django/core/mail/message.py", line 298, in send
    return self.get_connection(fail_silently).send_messages([self])
  File "/home/ubuntu/github/easygo/venv/lib/python3.10/site-packages/django/core/mail/backends/smtp.py", line 124, in send_messages
    new_conn_created = self.open()
  File "/home/ubuntu/github/easygo/venv/lib/python3.10/site-packages/django/core/mail/backends/smtp.py", line 91, in open
    self.connection.login(self.username, self.password)
  File "/usr/lib/python3.10/smtplib.py", line 739, in login
    (code, resp) = self.auth(
  File "/usr/lib/python3.10/smtplib.py", line 642, in auth
    (code, resp) = self.docmd("AUTH", mechanism + " " + response)
  File "/usr/lib/python3.10/smtplib.py", line 432, in docmd
    return self.getreply()
  File "/usr/lib/python3.10/smtplib.py", line 405, in getreply
    raise SMTPServerDisconnected("Connection unexpectedly closed")
smtplib.SMTPServerDisconnected: Connection unexpectedly closed
ERROR 2023-10-29 03:30:24,871 log Internal Server Error: /p2p/
Traceback (most recent call last):
  File "/home/ubuntu/github/easygo/venv/lib/python3.10/site-packages/django/core/handlers/exception.py", line 56, in inner
    response = get_response(request)
  File "/home/ubuntu/github/easygo/venv/lib/python3.10/site-packages/django/core/handlers/base.py", line 197, in _get_response
    response = wrapped_callback(request, *callback_args, **callback_kwargs)
  File "/home/ubuntu/github/easygo/basecamp/views.py", line 1166, in p2p
    email.send()
  File "/home/ubuntu/github/easygo/venv/lib/python3.10/site-packages/django/core/mail/message.py", line 298, in send
    return self.get_connection(fail_silently).send_messages([self])
  File "/home/ubuntu/github/easygo/venv/lib/python3.10/site-packages/django/core/mail/backends/smtp.py", line 124, in send_messages
    new_conn_created = self.open()
  File "/home/ubuntu/github/easygo/venv/lib/python3.10/site-packages/django/core/mail/backends/smtp.py", line 91, in open
    self.connection.login(self.username, self.password)
  File "/usr/lib/python3.10/smtplib.py", line 739, in login
    (code, resp) = self.auth(
  File "/usr/lib/python3.10/smtplib.py", line 642, in auth
    (code, resp) = self.docmd("AUTH", mechanism + " " + response)
  File "/usr/lib/python3.10/smtplib.py", line 432, in docmd
    return self.getreply()
  File "/usr/lib/python3.10/smtplib.py", line 405, in getreply
    raise SMTPServerDisconnected("Connection unexpectedly closed")
smtplib.SMTPServerDisconnected: Connection unexpectedly closed
ERROR 2023-10-29 03:30:27,442 log Internal Server Error: /p2p/
Traceback (most recent call last):
  File "/home/ubuntu/github/easygo/venv/lib/python3.10/site-packages/django/core/handlers/exception.py", line 56, in inner
    response = get_response(request)
  File "/home/ubuntu/github/easygo/venv/lib/python3.10/site-packages/django/core/handlers/base.py", line 197, in _get_response
    response = wrapped_callback(request, *callback_args, **callback_kwargs)
  File "/home/ubuntu/github/easygo/basecamp/views.py", line 1166, in p2p
    email.send()
  File "/home/ubuntu/github/easygo/venv/lib/python3.10/site-packages/django/core/mail/message.py", line 298, in send
    return self.get_connection(fail_silently).send_messages([self])
  File "/home/ubuntu/github/easygo/venv/lib/python3.10/site-packages/django/core/mail/backends/smtp.py", line 124, in send_messages
    new_conn_created = self.open()
  File "/home/ubuntu/github/easygo/venv/lib/python3.10/site-packages/django/core/mail/backends/smtp.py", line 91, in open
    self.connection.login(self.username, self.password)
  File "/usr/lib/python3.10/smtplib.py", line 739, in login
    (code, resp) = self.auth(
  File "/usr/lib/python3.10/smtplib.py", line 642, in auth
    (code, resp) = self.docmd("AUTH", mechanism + " " + response)
  File "/usr/lib/python3.10/smtplib.py", line 432, in docmd
    return self.getreply()
  File "/usr/lib/python3.10/smtplib.py", line 405, in getreply
    raise SMTPServerDisconnected("Connection unexpectedly closed")
smtplib.SMTPServerDisconnected: Connection unexpectedly closed
ERROR 2023-10-29 03:30:29,956 log Internal Server Error: /p2p/
Traceback (most recent call last):
  File "/home/ubuntu/github/easygo/venv/lib/python3.10/site-packages/django/core/handlers/exception.py", line 56, in inner
    response = get_response(request)
  File "/home/ubuntu/github/easygo/venv/lib/python3.10/site-packages/django/core/handlers/base.py", line 197, in _get_response
    response = wrapped_callback(request, *callback_args, **callback_kwargs)
  File "/home/ubuntu/github/easygo/basecamp/views.py", line 1166, in p2p
    email.send()
  File "/home/ubuntu/github/easygo/venv/lib/python3.10/site-packages/django/core/mail/message.py", line 298, in send
    return self.get_connection(fail_silently).send_messages([self])
  File "/home/ubuntu/github/easygo/venv/lib/python3.10/site-packages/django/core/mail/backends/smtp.py", line 124, in send_messages
    new_conn_created = self.open()
  File "/home/ubuntu/github/easygo/venv/lib/python3.10/site-packages/django/core/mail/backends/smtp.py", line 91, in open
    self.connection.login(self.username, self.password)
  File "/usr/lib/python3.10/smtplib.py", line 739, in login
    (code, resp) = self.auth(
  File "/usr/lib/python3.10/smtplib.py", line 642, in auth
    (code, resp) = self.docmd("AUTH", mechanism + " " + response)
  File "/usr/lib/python3.10/smtplib.py", line 432, in docmd
    return self.getreply()
  File "/usr/lib/python3.10/smtplib.py", line 405, in getreply
    raise SMTPServerDisconnected("Connection unexpectedly closed")
smtplib.SMTPServerDisconnected: Connection unexpectedly closed
ERROR 2023-10-29 03:30:32,484 log Internal Server Error: /p2p/
Traceback (most recent call last):
  File "/home/ubuntu/github/easygo/venv/lib/python3.10/site-packages/django/core/handlers/exception.py", line 56, in inner
    response = get_response(request)
  File "/home/ubuntu/github/easygo/venv/lib/python3.10/site-packages/django/core/handlers/base.py", line 197, in _get_response
    response = wrapped_callback(request, *callback_args, **callback_kwargs)
  File "/home/ubuntu/github/easygo/basecamp/views.py", line 1166, in p2p
    email.send()
  File "/home/ubuntu/github/easygo/venv/lib/python3.10/site-packages/django/core/mail/message.py", line 298, in send
    return self.get_connection(fail_silently).send_messages([self])
  File "/home/ubuntu/github/easygo/venv/lib/python3.10/site-packages/django/core/mail/backends/smtp.py", line 124, in send_messages
    new_conn_created = self.open()
  File "/home/ubuntu/github/easygo/venv/lib/python3.10/site-packages/django/core/mail/backends/smtp.py", line 91, in open
    self.connection.login(self.username, self.password)
  File "/usr/lib/python3.10/smtplib.py", line 739, in login
    (code, resp) = self.auth(
  File "/usr/lib/python3.10/smtplib.py", line 642, in auth
    (code, resp) = self.docmd("AUTH", mechanism + " " + response)
  File "/usr/lib/python3.10/smtplib.py", line 432, in docmd
    return self.getreply()
  File "/usr/lib/python3.10/smtplib.py", line 405, in getreply
    raise SMTPServerDisconnected("Connection unexpectedly closed")
smtplib.SMTPServerDisconnected: Connection unexpectedly closed
ERROR 2023-10-29 03:30:35,770 log Internal Server Error: /p2p/
Traceback (most recent call last):
  File "/home/ubuntu/github/easygo/venv/lib/python3.10/site-packages/django/core/handlers/exception.py", line 56, in inner
    response = get_response(request)
  File "/home/ubuntu/github/easygo/venv/lib/python3.10/site-packages/django/core/handlers/base.py", line 197, in _get_response
    response = wrapped_callback(request, *callback_args, **callback_kwargs)
  File "/home/ubuntu/github/easygo/basecamp/views.py", line 1166, in p2p
    email.send()
  File "/home/ubuntu/github/easygo/venv/lib/python3.10/site-packages/django/core/mail/message.py", line 298, in send
    return self.get_connection(fail_silently).send_messages([self])
  File "/home/ubuntu/github/easygo/venv/lib/python3.10/site-packages/django/core/mail/backends/smtp.py", line 124, in send_messages
    new_conn_created = self.open()
  File "/home/ubuntu/github/easygo/venv/lib/python3.10/site-packages/django/core/mail/backends/smtp.py", line 91, in open
    self.connection.login(self.username, self.password)
  File "/usr/lib/python3.10/smtplib.py", line 739, in login
    (code, resp) = self.auth(
  File "/usr/lib/python3.10/smtplib.py", line 642, in auth
    (code, resp) = self.docmd("AUTH", mechanism + " " + response)
  File "/usr/lib/python3.10/smtplib.py", line 432, in docmd
    return self.getreply()
  File "/usr/lib/python3.10/smtplib.py", line 405, in getreply
    raise SMTPServerDisconnected("Connection unexpectedly closed")
smtplib.SMTPServerDisconnected: Connection unexpectedly closed
ERROR 2023-10-29 03:30:38,276 log Internal Server Error: /p2p/
Traceback (most recent call last):
  File "/home/ubuntu/github/easygo/venv/lib/python3.10/site-packages/django/core/handlers/exception.py", line 56, in inner
    response = get_response(request)
  File "/home/ubuntu/github/easygo/venv/lib/python3.10/site-packages/django/core/handlers/base.py", line 197, in _get_response
    response = wrapped_callback(request, *callback_args, **callback_kwargs)
  File "/home/ubuntu/github/easygo/basecamp/views.py", line 1166, in p2p
    email.send()
  File "/home/ubuntu/github/easygo/venv/lib/python3.10/site-packages/django/core/mail/message.py", line 298, in send
    return self.get_connection(fail_silently).send_messages([self])
  File "/home/ubuntu/github/easygo/venv/lib/python3.10/site-packages/django/core/mail/backends/smtp.py", line 124, in send_messages
    new_conn_created = self.open()
  File "/home/ubuntu/github/easygo/venv/lib/python3.10/site-packages/django/core/mail/backends/smtp.py", line 91, in open
    self.connection.login(self.username, self.password)
  File "/usr/lib/python3.10/smtplib.py", line 739, in login
    (code, resp) = self.auth(
  File "/usr/lib/python3.10/smtplib.py", line 642, in auth
    (code, resp) = self.docmd("AUTH", mechanism + " " + response)
  File "/usr/lib/python3.10/smtplib.py", line 432, in docmd
    return self.getreply()
  File "/usr/lib/python3.10/smtplib.py", line 405, in getreply
    raise SMTPServerDisconnected("Connection unexpectedly closed")
smtplib.SMTPServerDisconnected: Connection unexpectedly closed
ERROR 2023-10-29 03:30:40,787 log Internal Server Error: /p2p/
Traceback (most recent call last):
  File "/home/ubuntu/github/easygo/venv/lib/python3.10/site-packages/django/core/handlers/exception.py", line 56, in inner
    response = get_response(request)
  File "/home/ubuntu/github/easygo/venv/lib/python3.10/site-packages/django/core/handlers/base.py", line 197, in _get_response
    response = wrapped_callback(request, *callback_args, **callback_kwargs)
  File "/home/ubuntu/github/easygo/basecamp/views.py", line 1166, in p2p
    email.send()
  File "/home/ubuntu/github/easygo/venv/lib/python3.10/site-packages/django/core/mail/message.py", line 298, in send
    return self.get_connection(fail_silently).send_messages([self])
  File "/home/ubuntu/github/easygo/venv/lib/python3.10/site-packages/django/core/mail/backends/smtp.py", line 124, in send_messages
    new_conn_created = self.open()
  File "/home/ubuntu/github/easygo/venv/lib/python3.10/site-packages/django/core/mail/backends/smtp.py", line 91, in open
    self.connection.login(self.username, self.password)
  File "/usr/lib/python3.10/smtplib.py", line 739, in login
    (code, resp) = self.auth(
  File "/usr/lib/python3.10/smtplib.py", line 642, in auth
    (code, resp) = self.docmd("AUTH", mechanism + " " + response)
  File "/usr/lib/python3.10/smtplib.py", line 432, in docmd
    return self.getreply()
  File "/usr/lib/python3.10/smtplib.py", line 405, in getreply
    raise SMTPServerDisconnected("Connection unexpectedly closed")
smtplib.SMTPServerDisconnected: Connection unexpectedly closed
ERROR 2023-10-29 03:30:43,309 log Internal Server Error: /p2p/
Traceback (most recent call last):
  File "/home/ubuntu/github/easygo/venv/lib/python3.10/site-packages/django/core/handlers/exception.py", line 56, in inner
    response = get_response(request)
  File "/home/ubuntu/github/easygo/venv/lib/python3.10/site-packages/django/core/handlers/base.py", line 197, in _get_response
    response = wrapped_callback(request, *callback_args, **callback_kwargs)
  File "/home/ubuntu/github/easygo/basecamp/views.py", line 1166, in p2p
    email.send()
  File "/home/ubuntu/github/easygo/venv/lib/python3.10/site-packages/django/core/mail/message.py", line 298, in send
    return self.get_connection(fail_silently).send_messages([self])
  File "/home/ubuntu/github/easygo/venv/lib/python3.10/site-packages/django/core/mail/backends/smtp.py", line 124, in send_messages
    new_conn_created = self.open()
  File "/home/ubuntu/github/easygo/venv/lib/python3.10/site-packages/django/core/mail/backends/smtp.py", line 91, in open
    self.connection.login(self.username, self.password)
  File "/usr/lib/python3.10/smtplib.py", line 739, in login
    (code, resp) = self.auth(
  File "/usr/lib/python3.10/smtplib.py", line 642, in auth
    (code, resp) = self.docmd("AUTH", mechanism + " " + response)
  File "/usr/lib/python3.10/smtplib.py", line 432, in docmd
    return self.getreply()
  File "/usr/lib/python3.10/smtplib.py", line 405, in getreply
    raise SMTPServerDisconnected("Connection unexpectedly closed")
smtplib.SMTPServerDisconnected: Connection unexpectedly closed
ERROR 2023-10-29 03:30:45,836 log Internal Server Error: /p2p/
Traceback (most recent call last):
  File "/home/ubuntu/github/easygo/venv/lib/python3.10/site-packages/django/core/handlers/exception.py", line 56, in inner
    response = get_response(request)
  File "/home/ubuntu/github/easygo/venv/lib/python3.10/site-packages/django/core/handlers/base.py", line 197, in _get_response
    response = wrapped_callback(request, *callback_args, **callback_kwargs)
  File "/home/ubuntu/github/easygo/basecamp/views.py", line 1166, in p2p
    email.send()
  File "/home/ubuntu/github/easygo/venv/lib/python3.10/site-packages/django/core/mail/message.py", line 298, in send
    return self.get_connection(fail_silently).send_messages([self])
  File "/home/ubuntu/github/easygo/venv/lib/python3.10/site-packages/django/core/mail/backends/smtp.py", line 124, in send_messages
    new_conn_created = self.open()
  File "/home/ubuntu/github/easygo/venv/lib/python3.10/site-packages/django/core/mail/backends/smtp.py", line 91, in open
    self.connection.login(self.username, self.password)
  File "/usr/lib/python3.10/smtplib.py", line 739, in login
    (code, resp) = self.auth(
  File "/usr/lib/python3.10/smtplib.py", line 642, in auth
    (code, resp) = self.docmd("AUTH", mechanism + " " + response)
  File "/usr/lib/python3.10/smtplib.py", line 432, in docmd
    return self.getreply()
  File "/usr/lib/python3.10/smtplib.py", line 405, in getreply
    raise SMTPServerDisconnected("Connection unexpectedly closed")
smtplib.SMTPServerDisconnected: Connection unexpectedly closed
ERROR 2023-10-29 03:30:48,948 log Internal Server Error: /p2p/
Traceback (most recent call last):
  File "/home/ubuntu/github/easygo/venv/lib/python3.10/site-packages/django/core/handlers/exception.py", line 56, in inner
    response = get_response(request)
  File "/home/ubuntu/github/easygo/venv/lib/python3.10/site-packages/django/core/handlers/base.py", line 197, in _get_response
    response = wrapped_callback(request, *callback_args, **callback_kwargs)
  File "/home/ubuntu/github/easygo/basecamp/views.py", line 1166, in p2p
    email.send()
  File "/home/ubuntu/github/easygo/venv/lib/python3.10/site-packages/django/core/mail/message.py", line 298, in send
    return self.get_connection(fail_silently).send_messages([self])
  File "/home/ubuntu/github/easygo/venv/lib/python3.10/site-packages/django/core/mail/backends/smtp.py", line 124, in send_messages
    new_conn_created = self.open()
  File "/home/ubuntu/github/easygo/venv/lib/python3.10/site-packages/django/core/mail/backends/smtp.py", line 91, in open
    self.connection.login(self.username, self.password)
  File "/usr/lib/python3.10/smtplib.py", line 739, in login
    (code, resp) = self.auth(
  File "/usr/lib/python3.10/smtplib.py", line 642, in auth
    (code, resp) = self.docmd("AUTH", mechanism + " " + response)
  File "/usr/lib/python3.10/smtplib.py", line 432, in docmd
    return self.getreply()
  File "/usr/lib/python3.10/smtplib.py", line 405, in getreply
    raise SMTPServerDisconnected("Connection unexpectedly closed")
smtplib.SMTPServerDisconnected: Connection unexpectedly closed
ERROR 2023-10-29 03:30:51,515 log Internal Server Error: /p2p/
Traceback (most recent call last):
  File "/home/ubuntu/github/easygo/venv/lib/python3.10/site-packages/django/core/handlers/exception.py", line 56, in inner
    response = get_response(request)
  File "/home/ubuntu/github/easygo/venv/lib/python3.10/site-packages/django/core/handlers/base.py", line 197, in _get_response
    response = wrapped_callback(request, *callback_args, **callback_kwargs)
  File "/home/ubuntu/github/easygo/basecamp/views.py", line 1166, in p2p
    email.send()
  File "/home/ubuntu/github/easygo/venv/lib/python3.10/site-packages/django/core/mail/message.py", line 298, in send
    return self.get_connection(fail_silently).send_messages([self])
  File "/home/ubuntu/github/easygo/venv/lib/python3.10/site-packages/django/core/mail/backends/smtp.py", line 124, in send_messages
    new_conn_created = self.open()
  File "/home/ubuntu/github/easygo/venv/lib/python3.10/site-packages/django/core/mail/backends/smtp.py", line 91, in open
    self.connection.login(self.username, self.password)
  File "/usr/lib/python3.10/smtplib.py", line 739, in login
    (code, resp) = self.auth(
  File "/usr/lib/python3.10/smtplib.py", line 642, in auth
    (code, resp) = self.docmd("AUTH", mechanism + " " + response)
  File "/usr/lib/python3.10/smtplib.py", line 432, in docmd
    return self.getreply()
  File "/usr/lib/python3.10/smtplib.py", line 405, in getreply
    raise SMTPServerDisconnected("Connection unexpectedly closed")
smtplib.SMTPServerDisconnected: Connection unexpectedly closed
ERROR 2023-10-29 03:30:54,046 log Internal Server Error: /p2p/
Traceback (most recent call last):
  File "/home/ubuntu/github/easygo/venv/lib/python3.10/site-packages/django/core/handlers/exception.py", line 56, in inner
    response = get_response(request)
  File "/home/ubuntu/github/easygo/venv/lib/python3.10/site-packages/django/core/handlers/base.py", line 197, in _get_response
    response = wrapped_callback(request, *callback_args, **callback_kwargs)
  File "/home/ubuntu/github/easygo/basecamp/views.py", line 1166, in p2p
    email.send()
  File "/home/ubuntu/github/easygo/venv/lib/python3.10/site-packages/django/core/mail/message.py", line 298, in send
    return self.get_connection(fail_silently).send_messages([self])
  File "/home/ubuntu/github/easygo/venv/lib/python3.10/site-packages/django/core/mail/backends/smtp.py", line 124, in send_messages
    new_conn_created = self.open()
  File "/home/ubuntu/github/easygo/venv/lib/python3.10/site-packages/django/core/mail/backends/smtp.py", line 91, in open
    self.connection.login(self.username, self.password)
  File "/usr/lib/python3.10/smtplib.py", line 739, in login
    (code, resp) = self.auth(
  File "/usr/lib/python3.10/smtplib.py", line 642, in auth
    (code, resp) = self.docmd("AUTH", mechanism + " " + response)
  File "/usr/lib/python3.10/smtplib.py", line 432, in docmd
    return self.getreply()
  File "/usr/lib/python3.10/smtplib.py", line 405, in getreply
    raise SMTPServerDisconnected("Connection unexpectedly closed")
smtplib.SMTPServerDisconnected: Connection unexpectedly closed
ERROR 2023-10-29 03:30:55,891 log Internal Server Error: /p2p/
Traceback (most recent call last):
  File "/home/ubuntu/github/easygo/venv/lib/python3.10/site-packages/django/core/handlers/exception.py", line 56, in inner
    response = get_response(request)
  File "/home/ubuntu/github/easygo/venv/lib/python3.10/site-packages/django/core/handlers/base.py", line 197, in _get_response
    response = wrapped_callback(request, *callback_args, **callback_kwargs)
  File "/home/ubuntu/github/easygo/basecamp/views.py", line 1166, in p2p
    email.send()
  File "/home/ubuntu/github/easygo/venv/lib/python3.10/site-packages/django/core/mail/message.py", line 298, in send
    return self.get_connection(fail_silently).send_messages([self])
  File "/home/ubuntu/github/easygo/venv/lib/python3.10/site-packages/django/core/mail/backends/smtp.py", line 124, in send_messages
    new_conn_created = self.open()
  File "/home/ubuntu/github/easygo/venv/lib/python3.10/site-packages/django/core/mail/backends/smtp.py", line 91, in open
    self.connection.login(self.username, self.password)
  File "/usr/lib/python3.10/smtplib.py", line 739, in login
    (code, resp) = self.auth(
  File "/usr/lib/python3.10/smtplib.py", line 642, in auth
    (code, resp) = self.docmd("AUTH", mechanism + " " + response)
  File "/usr/lib/python3.10/smtplib.py", line 432, in docmd
    return self.getreply()
  File "/usr/lib/python3.10/smtplib.py", line 405, in getreply
    raise SMTPServerDisconnected("Connection unexpectedly closed")
smtplib.SMTPServerDisconnected: Connection unexpectedly closed
ERROR 2023-10-29 03:30:57,751 log Internal Server Error: /p2p/
Traceback (most recent call last):
  File "/home/ubuntu/github/easygo/venv/lib/python3.10/site-packages/django/core/handlers/exception.py", line 56, in inner
    response = get_response(request)
  File "/home/ubuntu/github/easygo/venv/lib/python3.10/site-packages/django/core/handlers/base.py", line 197, in _get_response
    response = wrapped_callback(request, *callback_args, **callback_kwargs)
  File "/home/ubuntu/github/easygo/basecamp/views.py", line 1166, in p2p
    email.send()
  File "/home/ubuntu/github/easygo/venv/lib/python3.10/site-packages/django/core/mail/message.py", line 298, in send
    return self.get_connection(fail_silently).send_messages([self])
  File "/home/ubuntu/github/easygo/venv/lib/python3.10/site-packages/django/core/mail/backends/smtp.py", line 124, in send_messages
    new_conn_created = self.open()
  File "/home/ubuntu/github/easygo/venv/lib/python3.10/site-packages/django/core/mail/backends/smtp.py", line 91, in open
    self.connection.login(self.username, self.password)
  File "/usr/lib/python3.10/smtplib.py", line 739, in login
    (code, resp) = self.auth(
  File "/usr/lib/python3.10/smtplib.py", line 642, in auth
    (code, resp) = self.docmd("AUTH", mechanism + " " + response)
  File "/usr/lib/python3.10/smtplib.py", line 432, in docmd
    return self.getreply()
  File "/usr/lib/python3.10/smtplib.py", line 405, in getreply
    raise SMTPServerDisconnected("Connection unexpectedly closed")
smtplib.SMTPServerDisconnected: Connection unexpectedly closed
ERROR 2023-10-29 03:31:00,262 log Internal Server Error: /p2p/
Traceback (most recent call last):
  File "/home/ubuntu/github/easygo/venv/lib/python3.10/site-packages/django/core/handlers/exception.py", line 56, in inner
    response = get_response(request)
  File "/home/ubuntu/github/easygo/venv/lib/python3.10/site-packages/django/core/handlers/base.py", line 197, in _get_response
    response = wrapped_callback(request, *callback_args, **callback_kwargs)
  File "/home/ubuntu/github/easygo/basecamp/views.py", line 1166, in p2p
    email.send()
  File "/home/ubuntu/github/easygo/venv/lib/python3.10/site-packages/django/core/mail/message.py", line 298, in send
    return self.get_connection(fail_silently).send_messages([self])
  File "/home/ubuntu/github/easygo/venv/lib/python3.10/site-packages/django/core/mail/backends/smtp.py", line 124, in send_messages
    new_conn_created = self.open()
  File "/home/ubuntu/github/easygo/venv/lib/python3.10/site-packages/django/core/mail/backends/smtp.py", line 91, in open
    self.connection.login(self.username, self.password)
  File "/usr/lib/python3.10/smtplib.py", line 739, in login
    (code, resp) = self.auth(
  File "/usr/lib/python3.10/smtplib.py", line 642, in auth
    (code, resp) = self.docmd("AUTH", mechanism + " " + response)
  File "/usr/lib/python3.10/smtplib.py", line 432, in docmd
    return self.getreply()
  File "/usr/lib/python3.10/smtplib.py", line 405, in getreply
    raise SMTPServerDisconnected("Connection unexpectedly closed")
smtplib.SMTPServerDisconnected: Connection unexpectedly closed
ERROR 2023-10-29 03:31:02,879 log Internal Server Error: /p2p/
Traceback (most recent call last):
  File "/home/ubuntu/github/easygo/venv/lib/python3.10/site-packages/django/core/handlers/exception.py", line 56, in inner
    response = get_response(request)
  File "/home/ubuntu/github/easygo/venv/lib/python3.10/site-packages/django/core/handlers/base.py", line 197, in _get_response
    response = wrapped_callback(request, *callback_args, **callback_kwargs)
  File "/home/ubuntu/github/easygo/basecamp/views.py", line 1166, in p2p
    email.send()
  File "/home/ubuntu/github/easygo/venv/lib/python3.10/site-packages/django/core/mail/message.py", line 298, in send
    return self.get_connection(fail_silently).send_messages([self])
  File "/home/ubuntu/github/easygo/venv/lib/python3.10/site-packages/django/core/mail/backends/smtp.py", line 124, in send_messages
    new_conn_created = self.open()
  File "/home/ubuntu/github/easygo/venv/lib/python3.10/site-packages/django/core/mail/backends/smtp.py", line 91, in open
    self.connection.login(self.username, self.password)
  File "/usr/lib/python3.10/smtplib.py", line 739, in login
    (code, resp) = self.auth(
  File "/usr/lib/python3.10/smtplib.py", line 642, in auth
    (code, resp) = self.docmd("AUTH", mechanism + " " + response)
  File "/usr/lib/python3.10/smtplib.py", line 432, in docmd
    return self.getreply()
  File "/usr/lib/python3.10/smtplib.py", line 405, in getreply
    raise SMTPServerDisconnected("Connection unexpectedly closed")
smtplib.SMTPServerDisconnected: Connection unexpectedly closed
ERROR 2023-10-29 03:31:05,382 log Internal Server Error: /p2p/
Traceback (most recent call last):
  File "/home/ubuntu/github/easygo/venv/lib/python3.10/site-packages/django/core/handlers/exception.py", line 56, in inner
    response = get_response(request)
  File "/home/ubuntu/github/easygo/venv/lib/python3.10/site-packages/django/core/handlers/base.py", line 197, in _get_response
    response = wrapped_callback(request, *callback_args, **callback_kwargs)
  File "/home/ubuntu/github/easygo/basecamp/views.py", line 1166, in p2p
    email.send()
  File "/home/ubuntu/github/easygo/venv/lib/python3.10/site-packages/django/core/mail/message.py", line 298, in send
    return self.get_connection(fail_silently).send_messages([self])
  File "/home/ubuntu/github/easygo/venv/lib/python3.10/site-packages/django/core/mail/backends/smtp.py", line 124, in send_messages
    new_conn_created = self.open()
  File "/home/ubuntu/github/easygo/venv/lib/python3.10/site-packages/django/core/mail/backends/smtp.py", line 91, in open
    self.connection.login(self.username, self.password)
  File "/usr/lib/python3.10/smtplib.py", line 739, in login
    (code, resp) = self.auth(
  File "/usr/lib/python3.10/smtplib.py", line 642, in auth
    (code, resp) = self.docmd("AUTH", mechanism + " " + response)
  File "/usr/lib/python3.10/smtplib.py", line 432, in docmd
    return self.getreply()
  File "/usr/lib/python3.10/smtplib.py", line 405, in getreply
    raise SMTPServerDisconnected("Connection unexpectedly closed")
smtplib.SMTPServerDisconnected: Connection unexpectedly closed
ERROR 2023-10-29 03:31:07,900 log Internal Server Error: /p2p/
Traceback (most recent call last):
  File "/home/ubuntu/github/easygo/venv/lib/python3.10/site-packages/django/core/handlers/exception.py", line 56, in inner
    response = get_response(request)
  File "/home/ubuntu/github/easygo/venv/lib/python3.10/site-packages/django/core/handlers/base.py", line 197, in _get_response
    response = wrapped_callback(request, *callback_args, **callback_kwargs)
  File "/home/ubuntu/github/easygo/basecamp/views.py", line 1166, in p2p
    email.send()
  File "/home/ubuntu/github/easygo/venv/lib/python3.10/site-packages/django/core/mail/message.py", line 298, in send
    return self.get_connection(fail_silently).send_messages([self])
  File "/home/ubuntu/github/easygo/venv/lib/python3.10/site-packages/django/core/mail/backends/smtp.py", line 124, in send_messages
    new_conn_created = self.open()
  File "/home/ubuntu/github/easygo/venv/lib/python3.10/site-packages/django/core/mail/backends/smtp.py", line 91, in open
    self.connection.login(self.username, self.password)
  File "/usr/lib/python3.10/smtplib.py", line 739, in login
    (code, resp) = self.auth(
  File "/usr/lib/python3.10/smtplib.py", line 642, in auth
    (code, resp) = self.docmd("AUTH", mechanism + " " + response)
  File "/usr/lib/python3.10/smtplib.py", line 432, in docmd
    return self.getreply()
  File "/usr/lib/python3.10/smtplib.py", line 405, in getreply
    raise SMTPServerDisconnected("Connection unexpectedly closed")
smtplib.SMTPServerDisconnected: Connection unexpectedly closed
ERROR 2023-10-29 03:31:10,424 log Internal Server Error: /p2p/
Traceback (most recent call last):
  File "/home/ubuntu/github/easygo/venv/lib/python3.10/site-packages/django/core/handlers/exception.py", line 56, in inner
    response = get_response(request)
  File "/home/ubuntu/github/easygo/venv/lib/python3.10/site-packages/django/core/handlers/base.py", line 197, in _get_response
    response = wrapped_callback(request, *callback_args, **callback_kwargs)
  File "/home/ubuntu/github/easygo/basecamp/views.py", line 1166, in p2p
    email.send()
  File "/home/ubuntu/github/easygo/venv/lib/python3.10/site-packages/django/core/mail/message.py", line 298, in send
    return self.get_connection(fail_silently).send_messages([self])
  File "/home/ubuntu/github/easygo/venv/lib/python3.10/site-packages/django/core/mail/backends/smtp.py", line 124, in send_messages
    new_conn_created = self.open()
  File "/home/ubuntu/github/easygo/venv/lib/python3.10/site-packages/django/core/mail/backends/smtp.py", line 91, in open
    self.connection.login(self.username, self.password)
  File "/usr/lib/python3.10/smtplib.py", line 739, in login
    (code, resp) = self.auth(
  File "/usr/lib/python3.10/smtplib.py", line 642, in auth
    (code, resp) = self.docmd("AUTH", mechanism + " " + response)
  File "/usr/lib/python3.10/smtplib.py", line 432, in docmd
    return self.getreply()
  File "/usr/lib/python3.10/smtplib.py", line 405, in getreply
    raise SMTPServerDisconnected("Connection unexpectedly closed")
smtplib.SMTPServerDisconnected: Connection unexpectedly closed
ERROR 2023-10-29 03:31:13,556 log Internal Server Error: /p2p/
Traceback (most recent call last):
  File "/home/ubuntu/github/easygo/venv/lib/python3.10/site-packages/django/core/handlers/exception.py", line 56, in inner
    response = get_response(request)
  File "/home/ubuntu/github/easygo/venv/lib/python3.10/site-packages/django/core/handlers/base.py", line 197, in _get_response
    response = wrapped_callback(request, *callback_args, **callback_kwargs)
  File "/home/ubuntu/github/easygo/basecamp/views.py", line 1166, in p2p
    email.send()
  File "/home/ubuntu/github/easygo/venv/lib/python3.10/site-packages/django/core/mail/message.py", line 298, in send
    return self.get_connection(fail_silently).send_messages([self])
  File "/home/ubuntu/github/easygo/venv/lib/python3.10/site-packages/django/core/mail/backends/smtp.py", line 124, in send_messages
    new_conn_created = self.open()
  File "/home/ubuntu/github/easygo/venv/lib/python3.10/site-packages/django/core/mail/backends/smtp.py", line 91, in open
    self.connection.login(self.username, self.password)
  File "/usr/lib/python3.10/smtplib.py", line 739, in login
    (code, resp) = self.auth(
  File "/usr/lib/python3.10/smtplib.py", line 642, in auth
    (code, resp) = self.docmd("AUTH", mechanism + " " + response)
  File "/usr/lib/python3.10/smtplib.py", line 432, in docmd
    return self.getreply()
  File "/usr/lib/python3.10/smtplib.py", line 405, in getreply
    raise SMTPServerDisconnected("Connection unexpectedly closed")
smtplib.SMTPServerDisconnected: Connection unexpectedly closed
ERROR 2023-10-29 03:31:16,066 log Internal Server Error: /p2p/
Traceback (most recent call last):
  File "/home/ubuntu/github/easygo/venv/lib/python3.10/site-packages/django/core/handlers/exception.py", line 56, in inner
    response = get_response(request)
  File "/home/ubuntu/github/easygo/venv/lib/python3.10/site-packages/django/core/handlers/base.py", line 197, in _get_response
    response = wrapped_callback(request, *callback_args, **callback_kwargs)
  File "/home/ubuntu/github/easygo/basecamp/views.py", line 1166, in p2p
    email.send()
  File "/home/ubuntu/github/easygo/venv/lib/python3.10/site-packages/django/core/mail/message.py", line 298, in send
    return self.get_connection(fail_silently).send_messages([self])
  File "/home/ubuntu/github/easygo/venv/lib/python3.10/site-packages/django/core/mail/backends/smtp.py", line 124, in send_messages
    new_conn_created = self.open()
  File "/home/ubuntu/github/easygo/venv/lib/python3.10/site-packages/django/core/mail/backends/smtp.py", line 91, in open
    self.connection.login(self.username, self.password)
  File "/usr/lib/python3.10/smtplib.py", line 739, in login
    (code, resp) = self.auth(
  File "/usr/lib/python3.10/smtplib.py", line 642, in auth
    (code, resp) = self.docmd("AUTH", mechanism + " " + response)
  File "/usr/lib/python3.10/smtplib.py", line 432, in docmd
    return self.getreply()
  File "/usr/lib/python3.10/smtplib.py", line 405, in getreply
    raise SMTPServerDisconnected("Connection unexpectedly closed")
smtplib.SMTPServerDisconnected: Connection unexpectedly closed
ERROR 2023-10-29 03:31:18,616 log Internal Server Error: /p2p/
Traceback (most recent call last):
  File "/home/ubuntu/github/easygo/venv/lib/python3.10/site-packages/django/core/handlers/exception.py", line 56, in inner
    response = get_response(request)
  File "/home/ubuntu/github/easygo/venv/lib/python3.10/site-packages/django/core/handlers/base.py", line 197, in _get_response
    response = wrapped_callback(request, *callback_args, **callback_kwargs)
  File "/home/ubuntu/github/easygo/basecamp/views.py", line 1166, in p2p
    email.send()
  File "/home/ubuntu/github/easygo/venv/lib/python3.10/site-packages/django/core/mail/message.py", line 298, in send
    return self.get_connection(fail_silently).send_messages([self])
  File "/home/ubuntu/github/easygo/venv/lib/python3.10/site-packages/django/core/mail/backends/smtp.py", line 124, in send_messages
    new_conn_created = self.open()
  File "/home/ubuntu/github/easygo/venv/lib/python3.10/site-packages/django/core/mail/backends/smtp.py", line 91, in open
    self.connection.login(self.username, self.password)
  File "/usr/lib/python3.10/smtplib.py", line 739, in login
    (code, resp) = self.auth(
  File "/usr/lib/python3.10/smtplib.py", line 642, in auth
    (code, resp) = self.docmd("AUTH", mechanism + " " + response)
  File "/usr/lib/python3.10/smtplib.py", line 432, in docmd
    return self.getreply()
  File "/usr/lib/python3.10/smtplib.py", line 405, in getreply
    raise SMTPServerDisconnected("Connection unexpectedly closed")
smtplib.SMTPServerDisconnected: Connection unexpectedly closed
ERROR 2023-10-29 03:31:21,149 log Internal Server Error: /p2p/
Traceback (most recent call last):
  File "/home/ubuntu/github/easygo/venv/lib/python3.10/site-packages/django/core/handlers/exception.py", line 56, in inner
    response = get_response(request)
  File "/home/ubuntu/github/easygo/venv/lib/python3.10/site-packages/django/core/handlers/base.py", line 197, in _get_response
    response = wrapped_callback(request, *callback_args, **callback_kwargs)
  File "/home/ubuntu/github/easygo/basecamp/views.py", line 1166, in p2p
    email.send()
  File "/home/ubuntu/github/easygo/venv/lib/python3.10/site-packages/django/core/mail/message.py", line 298, in send
    return self.get_connection(fail_silently).send_messages([self])
  File "/home/ubuntu/github/easygo/venv/lib/python3.10/site-packages/django/core/mail/backends/smtp.py", line 124, in send_messages
    new_conn_created = self.open()
  File "/home/ubuntu/github/easygo/venv/lib/python3.10/site-packages/django/core/mail/backends/smtp.py", line 91, in open
    self.connection.login(self.username, self.password)
  File "/usr/lib/python3.10/smtplib.py", line 739, in login
    (code, resp) = self.auth(
  File "/usr/lib/python3.10/smtplib.py", line 642, in auth
    (code, resp) = self.docmd("AUTH", mechanism + " " + response)
  File "/usr/lib/python3.10/smtplib.py", line 432, in docmd
    return self.getreply()
  File "/usr/lib/python3.10/smtplib.py", line 405, in getreply
    raise SMTPServerDisconnected("Connection unexpectedly closed")
smtplib.SMTPServerDisconnected: Connection unexpectedly closed
ERROR 2023-10-29 03:31:24,311 log Internal Server Error: /p2p/
Traceback (most recent call last):
  File "/home/ubuntu/github/easygo/venv/lib/python3.10/site-packages/django/core/handlers/exception.py", line 56, in inner
    response = get_response(request)
  File "/home/ubuntu/github/easygo/venv/lib/python3.10/site-packages/django/core/handlers/base.py", line 197, in _get_response
    response = wrapped_callback(request, *callback_args, **callback_kwargs)
  File "/home/ubuntu/github/easygo/basecamp/views.py", line 1166, in p2p
    email.send()
  File "/home/ubuntu/github/easygo/venv/lib/python3.10/site-packages/django/core/mail/message.py", line 298, in send
    return self.get_connection(fail_silently).send_messages([self])
  File "/home/ubuntu/github/easygo/venv/lib/python3.10/site-packages/django/core/mail/backends/smtp.py", line 124, in send_messages
    new_conn_created = self.open()
  File "/home/ubuntu/github/easygo/venv/lib/python3.10/site-packages/django/core/mail/backends/smtp.py", line 91, in open
    self.connection.login(self.username, self.password)
  File "/usr/lib/python3.10/smtplib.py", line 739, in login
    (code, resp) = self.auth(
  File "/usr/lib/python3.10/smtplib.py", line 642, in auth
    (code, resp) = self.docmd("AUTH", mechanism + " " + response)
  File "/usr/lib/python3.10/smtplib.py", line 432, in docmd
    return self.getreply()
  File "/usr/lib/python3.10/smtplib.py", line 405, in getreply
    raise SMTPServerDisconnected("Connection unexpectedly closed")
smtplib.SMTPServerDisconnected: Connection unexpectedly closed
ERROR 2023-10-29 03:31:26,166 log Internal Server Error: /p2p/
Traceback (most recent call last):
  File "/home/ubuntu/github/easygo/venv/lib/python3.10/site-packages/django/core/handlers/exception.py", line 56, in inner
    response = get_response(request)
  File "/home/ubuntu/github/easygo/venv/lib/python3.10/site-packages/django/core/handlers/base.py", line 197, in _get_response
    response = wrapped_callback(request, *callback_args, **callback_kwargs)
  File "/home/ubuntu/github/easygo/basecamp/views.py", line 1166, in p2p
    email.send()
  File "/home/ubuntu/github/easygo/venv/lib/python3.10/site-packages/django/core/mail/message.py", line 298, in send
    return self.get_connection(fail_silently).send_messages([self])
  File "/home/ubuntu/github/easygo/venv/lib/python3.10/site-packages/django/core/mail/backends/smtp.py", line 124, in send_messages
    new_conn_created = self.open()
  File "/home/ubuntu/github/easygo/venv/lib/python3.10/site-packages/django/core/mail/backends/smtp.py", line 91, in open
    self.connection.login(self.username, self.password)
  File "/usr/lib/python3.10/smtplib.py", line 739, in login
    (code, resp) = self.auth(
  File "/usr/lib/python3.10/smtplib.py", line 642, in auth
    (code, resp) = self.docmd("AUTH", mechanism + " " + response)
  File "/usr/lib/python3.10/smtplib.py", line 432, in docmd
    return self.getreply()
  File "/usr/lib/python3.10/smtplib.py", line 405, in getreply
    raise SMTPServerDisconnected("Connection unexpectedly closed")
smtplib.SMTPServerDisconnected: Connection unexpectedly closed
ERROR 2023-10-29 03:31:28,033 log Internal Server Error: /p2p/
Traceback (most recent call last):
  File "/home/ubuntu/github/easygo/venv/lib/python3.10/site-packages/django/core/handlers/exception.py", line 56, in inner
    response = get_response(request)
  File "/home/ubuntu/github/easygo/venv/lib/python3.10/site-packages/django/core/handlers/base.py", line 197, in _get_response
    response = wrapped_callback(request, *callback_args, **callback_kwargs)
  File "/home/ubuntu/github/easygo/basecamp/views.py", line 1166, in p2p
    email.send()
  File "/home/ubuntu/github/easygo/venv/lib/python3.10/site-packages/django/core/mail/message.py", line 298, in send
    return self.get_connection(fail_silently).send_messages([self])
  File "/home/ubuntu/github/easygo/venv/lib/python3.10/site-packages/django/core/mail/backends/smtp.py", line 124, in send_messages
    new_conn_created = self.open()
  File "/home/ubuntu/github/easygo/venv/lib/python3.10/site-packages/django/core/mail/backends/smtp.py", line 91, in open
    self.connection.login(self.username, self.password)
  File "/usr/lib/python3.10/smtplib.py", line 739, in login
    (code, resp) = self.auth(
  File "/usr/lib/python3.10/smtplib.py", line 642, in auth
    (code, resp) = self.docmd("AUTH", mechanism + " " + response)
  File "/usr/lib/python3.10/smtplib.py", line 432, in docmd
    return self.getreply()
  File "/usr/lib/python3.10/smtplib.py", line 405, in getreply
    raise SMTPServerDisconnected("Connection unexpectedly closed")
smtplib.SMTPServerDisconnected: Connection unexpectedly closed
ERROR 2023-10-29 03:31:30,588 log Internal Server Error: /p2p/
Traceback (most recent call last):
  File "/home/ubuntu/github/easygo/venv/lib/python3.10/site-packages/django/core/handlers/exception.py", line 56, in inner
    response = get_response(request)
  File "/home/ubuntu/github/easygo/venv/lib/python3.10/site-packages/django/core/handlers/base.py", line 197, in _get_response
    response = wrapped_callback(request, *callback_args, **callback_kwargs)
  File "/home/ubuntu/github/easygo/basecamp/views.py", line 1166, in p2p
    email.send()
  File "/home/ubuntu/github/easygo/venv/lib/python3.10/site-packages/django/core/mail/message.py", line 298, in send
    return self.get_connection(fail_silently).send_messages([self])
  File "/home/ubuntu/github/easygo/venv/lib/python3.10/site-packages/django/core/mail/backends/smtp.py", line 124, in send_messages
    new_conn_created = self.open()
  File "/home/ubuntu/github/easygo/venv/lib/python3.10/site-packages/django/core/mail/backends/smtp.py", line 91, in open
    self.connection.login(self.username, self.password)
  File "/usr/lib/python3.10/smtplib.py", line 739, in login
    (code, resp) = self.auth(
  File "/usr/lib/python3.10/smtplib.py", line 642, in auth
    (code, resp) = self.docmd("AUTH", mechanism + " " + response)
  File "/usr/lib/python3.10/smtplib.py", line 432, in docmd
    return self.getreply()
  File "/usr/lib/python3.10/smtplib.py", line 405, in getreply
    raise SMTPServerDisconnected("Connection unexpectedly closed")
smtplib.SMTPServerDisconnected: Connection unexpectedly closed
ERROR 2023-10-29 03:31:33,113 log Internal Server Error: /p2p/
Traceback (most recent call last):
  File "/home/ubuntu/github/easygo/venv/lib/python3.10/site-packages/django/core/handlers/exception.py", line 56, in inner
    response = get_response(request)
  File "/home/ubuntu/github/easygo/venv/lib/python3.10/site-packages/django/core/handlers/base.py", line 197, in _get_response
    response = wrapped_callback(request, *callback_args, **callback_kwargs)
  File "/home/ubuntu/github/easygo/basecamp/views.py", line 1166, in p2p
    email.send()
  File "/home/ubuntu/github/easygo/venv/lib/python3.10/site-packages/django/core/mail/message.py", line 298, in send
    return self.get_connection(fail_silently).send_messages([self])
  File "/home/ubuntu/github/easygo/venv/lib/python3.10/site-packages/django/core/mail/backends/smtp.py", line 124, in send_messages
    new_conn_created = self.open()
  File "/home/ubuntu/github/easygo/venv/lib/python3.10/site-packages/django/core/mail/backends/smtp.py", line 91, in open
    self.connection.login(self.username, self.password)
  File "/usr/lib/python3.10/smtplib.py", line 739, in login
    (code, resp) = self.auth(
  File "/usr/lib/python3.10/smtplib.py", line 642, in auth
    (code, resp) = self.docmd("AUTH", mechanism + " " + response)
  File "/usr/lib/python3.10/smtplib.py", line 432, in docmd
    return self.getreply()
  File "/usr/lib/python3.10/smtplib.py", line 405, in getreply
    raise SMTPServerDisconnected("Connection unexpectedly closed")
smtplib.SMTPServerDisconnected: Connection unexpectedly closed
ERROR 2023-10-29 03:31:36,256 log Internal Server Error: /p2p/
Traceback (most recent call last):
  File "/home/ubuntu/github/easygo/venv/lib/python3.10/site-packages/django/core/handlers/exception.py", line 56, in inner
    response = get_response(request)
  File "/home/ubuntu/github/easygo/venv/lib/python3.10/site-packages/django/core/handlers/base.py", line 197, in _get_response
    response = wrapped_callback(request, *callback_args, **callback_kwargs)
  File "/home/ubuntu/github/easygo/basecamp/views.py", line 1166, in p2p
    email.send()
  File "/home/ubuntu/github/easygo/venv/lib/python3.10/site-packages/django/core/mail/message.py", line 298, in send
    return self.get_connection(fail_silently).send_messages([self])
  File "/home/ubuntu/github/easygo/venv/lib/python3.10/site-packages/django/core/mail/backends/smtp.py", line 124, in send_messages
    new_conn_created = self.open()
  File "/home/ubuntu/github/easygo/venv/lib/python3.10/site-packages/django/core/mail/backends/smtp.py", line 91, in open
    self.connection.login(self.username, self.password)
  File "/usr/lib/python3.10/smtplib.py", line 739, in login
    (code, resp) = self.auth(
  File "/usr/lib/python3.10/smtplib.py", line 642, in auth
    (code, resp) = self.docmd("AUTH", mechanism + " " + response)
  File "/usr/lib/python3.10/smtplib.py", line 432, in docmd
    return self.getreply()
  File "/usr/lib/python3.10/smtplib.py", line 405, in getreply
    raise SMTPServerDisconnected("Connection unexpectedly closed")
smtplib.SMTPServerDisconnected: Connection unexpectedly closed
ERROR 2023-10-29 03:31:38,833 log Internal Server Error: /p2p/
Traceback (most recent call last):
  File "/home/ubuntu/github/easygo/venv/lib/python3.10/site-packages/django/core/handlers/exception.py", line 56, in inner
    response = get_response(request)
  File "/home/ubuntu/github/easygo/venv/lib/python3.10/site-packages/django/core/handlers/base.py", line 197, in _get_response
    response = wrapped_callback(request, *callback_args, **callback_kwargs)
  File "/home/ubuntu/github/easygo/basecamp/views.py", line 1166, in p2p
    email.send()
  File "/home/ubuntu/github/easygo/venv/lib/python3.10/site-packages/django/core/mail/message.py", line 298, in send
    return self.get_connection(fail_silently).send_messages([self])
  File "/home/ubuntu/github/easygo/venv/lib/python3.10/site-packages/django/core/mail/backends/smtp.py", line 124, in send_messages
    new_conn_created = self.open()
  File "/home/ubuntu/github/easygo/venv/lib/python3.10/site-packages/django/core/mail/backends/smtp.py", line 91, in open
    self.connection.login(self.username, self.password)
  File "/usr/lib/python3.10/smtplib.py", line 739, in login
    (code, resp) = self.auth(
  File "/usr/lib/python3.10/smtplib.py", line 642, in auth
    (code, resp) = self.docmd("AUTH", mechanism + " " + response)
  File "/usr/lib/python3.10/smtplib.py", line 432, in docmd
    return self.getreply()
  File "/usr/lib/python3.10/smtplib.py", line 405, in getreply
    raise SMTPServerDisconnected("Connection unexpectedly closed")
smtplib.SMTPServerDisconnected: Connection unexpectedly closed
ERROR 2023-10-29 03:31:42,115 log Internal Server Error: /p2p/
Traceback (most recent call last):
  File "/home/ubuntu/github/easygo/venv/lib/python3.10/site-packages/django/core/handlers/exception.py", line 56, in inner
    response = get_response(request)
  File "/home/ubuntu/github/easygo/venv/lib/python3.10/site-packages/django/core/handlers/base.py", line 197, in _get_response
    response = wrapped_callback(request, *callback_args, **callback_kwargs)
  File "/home/ubuntu/github/easygo/basecamp/views.py", line 1166, in p2p
    email.send()
  File "/home/ubuntu/github/easygo/venv/lib/python3.10/site-packages/django/core/mail/message.py", line 298, in send
    return self.get_connection(fail_silently).send_messages([self])
  File "/home/ubuntu/github/easygo/venv/lib/python3.10/site-packages/django/core/mail/backends/smtp.py", line 124, in send_messages
    new_conn_created = self.open()
  File "/home/ubuntu/github/easygo/venv/lib/python3.10/site-packages/django/core/mail/backends/smtp.py", line 91, in open
    self.connection.login(self.username, self.password)
  File "/usr/lib/python3.10/smtplib.py", line 739, in login
    (code, resp) = self.auth(
  File "/usr/lib/python3.10/smtplib.py", line 642, in auth
    (code, resp) = self.docmd("AUTH", mechanism + " " + response)
  File "/usr/lib/python3.10/smtplib.py", line 432, in docmd
    return self.getreply()
  File "/usr/lib/python3.10/smtplib.py", line 405, in getreply
    raise SMTPServerDisconnected("Connection unexpectedly closed")
smtplib.SMTPServerDisconnected: Connection unexpectedly closed
ERROR 2023-10-29 03:31:44,639 log Internal Server Error: /p2p/
Traceback (most recent call last):
  File "/home/ubuntu/github/easygo/venv/lib/python3.10/site-packages/django/core/handlers/exception.py", line 56, in inner
    response = get_response(request)
  File "/home/ubuntu/github/easygo/venv/lib/python3.10/site-packages/django/core/handlers/base.py", line 197, in _get_response
    response = wrapped_callback(request, *callback_args, **callback_kwargs)
  File "/home/ubuntu/github/easygo/basecamp/views.py", line 1166, in p2p
    email.send()
  File "/home/ubuntu/github/easygo/venv/lib/python3.10/site-packages/django/core/mail/message.py", line 298, in send
    return self.get_connection(fail_silently).send_messages([self])
  File "/home/ubuntu/github/easygo/venv/lib/python3.10/site-packages/django/core/mail/backends/smtp.py", line 124, in send_messages
    new_conn_created = self.open()
  File "/home/ubuntu/github/easygo/venv/lib/python3.10/site-packages/django/core/mail/backends/smtp.py", line 91, in open
    self.connection.login(self.username, self.password)
  File "/usr/lib/python3.10/smtplib.py", line 739, in login
    (code, resp) = self.auth(
  File "/usr/lib/python3.10/smtplib.py", line 642, in auth
    (code, resp) = self.docmd("AUTH", mechanism + " " + response)
  File "/usr/lib/python3.10/smtplib.py", line 432, in docmd
    return self.getreply()
  File "/usr/lib/python3.10/smtplib.py", line 405, in getreply
    raise SMTPServerDisconnected("Connection unexpectedly closed")
smtplib.SMTPServerDisconnected: Connection unexpectedly closed
ERROR 2023-10-29 03:31:47,158 log Internal Server Error: /p2p/
Traceback (most recent call last):
  File "/home/ubuntu/github/easygo/venv/lib/python3.10/site-packages/django/core/handlers/exception.py", line 56, in inner
    response = get_response(request)
  File "/home/ubuntu/github/easygo/venv/lib/python3.10/site-packages/django/core/handlers/base.py", line 197, in _get_response
    response = wrapped_callback(request, *callback_args, **callback_kwargs)
  File "/home/ubuntu/github/easygo/basecamp/views.py", line 1166, in p2p
    email.send()
  File "/home/ubuntu/github/easygo/venv/lib/python3.10/site-packages/django/core/mail/message.py", line 298, in send
    return self.get_connection(fail_silently).send_messages([self])
  File "/home/ubuntu/github/easygo/venv/lib/python3.10/site-packages/django/core/mail/backends/smtp.py", line 124, in send_messages
    new_conn_created = self.open()
  File "/home/ubuntu/github/easygo/venv/lib/python3.10/site-packages/django/core/mail/backends/smtp.py", line 91, in open
    self.connection.login(self.username, self.password)
  File "/usr/lib/python3.10/smtplib.py", line 739, in login
    (code, resp) = self.auth(
  File "/usr/lib/python3.10/smtplib.py", line 642, in auth
    (code, resp) = self.docmd("AUTH", mechanism + " " + response)
  File "/usr/lib/python3.10/smtplib.py", line 432, in docmd
    return self.getreply()
  File "/usr/lib/python3.10/smtplib.py", line 405, in getreply
    raise SMTPServerDisconnected("Connection unexpectedly closed")
smtplib.SMTPServerDisconnected: Connection unexpectedly closed
ERROR 2023-10-29 03:31:49,686 log Internal Server Error: /p2p/
Traceback (most recent call last):
  File "/home/ubuntu/github/easygo/venv/lib/python3.10/site-packages/django/core/handlers/exception.py", line 56, in inner
    response = get_response(request)
  File "/home/ubuntu/github/easygo/venv/lib/python3.10/site-packages/django/core/handlers/base.py", line 197, in _get_response
    response = wrapped_callback(request, *callback_args, **callback_kwargs)
  File "/home/ubuntu/github/easygo/basecamp/views.py", line 1166, in p2p
    email.send()
  File "/home/ubuntu/github/easygo/venv/lib/python3.10/site-packages/django/core/mail/message.py", line 298, in send
    return self.get_connection(fail_silently).send_messages([self])
  File "/home/ubuntu/github/easygo/venv/lib/python3.10/site-packages/django/core/mail/backends/smtp.py", line 124, in send_messages
    new_conn_created = self.open()
  File "/home/ubuntu/github/easygo/venv/lib/python3.10/site-packages/django/core/mail/backends/smtp.py", line 91, in open
    self.connection.login(self.username, self.password)
  File "/usr/lib/python3.10/smtplib.py", line 739, in login
    (code, resp) = self.auth(
  File "/usr/lib/python3.10/smtplib.py", line 642, in auth
    (code, resp) = self.docmd("AUTH", mechanism + " " + response)
  File "/usr/lib/python3.10/smtplib.py", line 432, in docmd
    return self.getreply()
  File "/usr/lib/python3.10/smtplib.py", line 405, in getreply
    raise SMTPServerDisconnected("Connection unexpectedly closed")
smtplib.SMTPServerDisconnected: Connection unexpectedly closed
ERROR 2023-10-29 03:31:52,198 log Internal Server Error: /p2p/
Traceback (most recent call last):
  File "/home/ubuntu/github/easygo/venv/lib/python3.10/site-packages/django/core/handlers/exception.py", line 56, in inner
    response = get_response(request)
  File "/home/ubuntu/github/easygo/venv/lib/python3.10/site-packages/django/core/handlers/base.py", line 197, in _get_response
    response = wrapped_callback(request, *callback_args, **callback_kwargs)
  File "/home/ubuntu/github/easygo/basecamp/views.py", line 1166, in p2p
    email.send()
  File "/home/ubuntu/github/easygo/venv/lib/python3.10/site-packages/django/core/mail/message.py", line 298, in send
    return self.get_connection(fail_silently).send_messages([self])
  File "/home/ubuntu/github/easygo/venv/lib/python3.10/site-packages/django/core/mail/backends/smtp.py", line 124, in send_messages
    new_conn_created = self.open()
  File "/home/ubuntu/github/easygo/venv/lib/python3.10/site-packages/django/core/mail/backends/smtp.py", line 91, in open
    self.connection.login(self.username, self.password)
  File "/usr/lib/python3.10/smtplib.py", line 739, in login
    (code, resp) = self.auth(
  File "/usr/lib/python3.10/smtplib.py", line 642, in auth
    (code, resp) = self.docmd("AUTH", mechanism + " " + response)
  File "/usr/lib/python3.10/smtplib.py", line 432, in docmd
    return self.getreply()
  File "/usr/lib/python3.10/smtplib.py", line 405, in getreply
    raise SMTPServerDisconnected("Connection unexpectedly closed")
smtplib.SMTPServerDisconnected: Connection unexpectedly closed
ERROR 2023-10-29 03:31:54,766 log Internal Server Error: /p2p/
Traceback (most recent call last):
  File "/home/ubuntu/github/easygo/venv/lib/python3.10/site-packages/django/core/handlers/exception.py", line 56, in inner
    response = get_response(request)
  File "/home/ubuntu/github/easygo/venv/lib/python3.10/site-packages/django/core/handlers/base.py", line 197, in _get_response
    response = wrapped_callback(request, *callback_args, **callback_kwargs)
  File "/home/ubuntu/github/easygo/basecamp/views.py", line 1166, in p2p
    email.send()
  File "/home/ubuntu/github/easygo/venv/lib/python3.10/site-packages/django/core/mail/message.py", line 298, in send
    return self.get_connection(fail_silently).send_messages([self])
  File "/home/ubuntu/github/easygo/venv/lib/python3.10/site-packages/django/core/mail/backends/smtp.py", line 124, in send_messages
    new_conn_created = self.open()
  File "/home/ubuntu/github/easygo/venv/lib/python3.10/site-packages/django/core/mail/backends/smtp.py", line 91, in open
    self.connection.login(self.username, self.password)
  File "/usr/lib/python3.10/smtplib.py", line 739, in login
    (code, resp) = self.auth(
  File "/usr/lib/python3.10/smtplib.py", line 642, in auth
    (code, resp) = self.docmd("AUTH", mechanism + " " + response)
  File "/usr/lib/python3.10/smtplib.py", line 432, in docmd
    return self.getreply()
  File "/usr/lib/python3.10/smtplib.py", line 405, in getreply
    raise SMTPServerDisconnected("Connection unexpectedly closed")
smtplib.SMTPServerDisconnected: Connection unexpectedly closed
ERROR 2023-10-29 03:31:57,286 log Internal Server Error: /p2p/
Traceback (most recent call last):
  File "/home/ubuntu/github/easygo/venv/lib/python3.10/site-packages/django/core/handlers/exception.py", line 56, in inner
    response = get_response(request)
  File "/home/ubuntu/github/easygo/venv/lib/python3.10/site-packages/django/core/handlers/base.py", line 197, in _get_response
    response = wrapped_callback(request, *callback_args, **callback_kwargs)
  File "/home/ubuntu/github/easygo/basecamp/views.py", line 1166, in p2p
    email.send()
  File "/home/ubuntu/github/easygo/venv/lib/python3.10/site-packages/django/core/mail/message.py", line 298, in send
    return self.get_connection(fail_silently).send_messages([self])
  File "/home/ubuntu/github/easygo/venv/lib/python3.10/site-packages/django/core/mail/backends/smtp.py", line 124, in send_messages
    new_conn_created = self.open()
  File "/home/ubuntu/github/easygo/venv/lib/python3.10/site-packages/django/core/mail/backends/smtp.py", line 91, in open
    self.connection.login(self.username, self.password)
  File "/usr/lib/python3.10/smtplib.py", line 739, in login
    (code, resp) = self.auth(
  File "/usr/lib/python3.10/smtplib.py", line 642, in auth
    (code, resp) = self.docmd("AUTH", mechanism + " " + response)
  File "/usr/lib/python3.10/smtplib.py", line 432, in docmd
    return self.getreply()
  File "/usr/lib/python3.10/smtplib.py", line 405, in getreply
    raise SMTPServerDisconnected("Connection unexpectedly closed")
smtplib.SMTPServerDisconnected: Connection unexpectedly closed
ERROR 2023-10-29 03:31:59,804 log Internal Server Error: /p2p/
Traceback (most recent call last):
  File "/home/ubuntu/github/easygo/venv/lib/python3.10/site-packages/django/core/handlers/exception.py", line 56, in inner
    response = get_response(request)
  File "/home/ubuntu/github/easygo/venv/lib/python3.10/site-packages/django/core/handlers/base.py", line 197, in _get_response
    response = wrapped_callback(request, *callback_args, **callback_kwargs)
  File "/home/ubuntu/github/easygo/basecamp/views.py", line 1166, in p2p
    email.send()
  File "/home/ubuntu/github/easygo/venv/lib/python3.10/site-packages/django/core/mail/message.py", line 298, in send
    return self.get_connection(fail_silently).send_messages([self])
  File "/home/ubuntu/github/easygo/venv/lib/python3.10/site-packages/django/core/mail/backends/smtp.py", line 124, in send_messages
    new_conn_created = self.open()
  File "/home/ubuntu/github/easygo/venv/lib/python3.10/site-packages/django/core/mail/backends/smtp.py", line 91, in open
    self.connection.login(self.username, self.password)
  File "/usr/lib/python3.10/smtplib.py", line 739, in login
    (code, resp) = self.auth(
  File "/usr/lib/python3.10/smtplib.py", line 642, in auth
    (code, resp) = self.docmd("AUTH", mechanism + " " + response)
  File "/usr/lib/python3.10/smtplib.py", line 432, in docmd
    return self.getreply()
  File "/usr/lib/python3.10/smtplib.py", line 405, in getreply
    raise SMTPServerDisconnected("Connection unexpectedly closed")
smtplib.SMTPServerDisconnected: Connection unexpectedly closed
ERROR 2023-10-29 03:32:02,321 log Internal Server Error: /p2p/
Traceback (most recent call last):
  File "/home/ubuntu/github/easygo/venv/lib/python3.10/site-packages/django/core/handlers/exception.py", line 56, in inner
    response = get_response(request)
  File "/home/ubuntu/github/easygo/venv/lib/python3.10/site-packages/django/core/handlers/base.py", line 197, in _get_response
    response = wrapped_callback(request, *callback_args, **callback_kwargs)
  File "/home/ubuntu/github/easygo/basecamp/views.py", line 1166, in p2p
    email.send()
  File "/home/ubuntu/github/easygo/venv/lib/python3.10/site-packages/django/core/mail/message.py", line 298, in send
    return self.get_connection(fail_silently).send_messages([self])
  File "/home/ubuntu/github/easygo/venv/lib/python3.10/site-packages/django/core/mail/backends/smtp.py", line 124, in send_messages
    new_conn_created = self.open()
  File "/home/ubuntu/github/easygo/venv/lib/python3.10/site-packages/django/core/mail/backends/smtp.py", line 91, in open
    self.connection.login(self.username, self.password)
  File "/usr/lib/python3.10/smtplib.py", line 739, in login
    (code, resp) = self.auth(
  File "/usr/lib/python3.10/smtplib.py", line 642, in auth
    (code, resp) = self.docmd("AUTH", mechanism + " " + response)
  File "/usr/lib/python3.10/smtplib.py", line 432, in docmd
    return self.getreply()
  File "/usr/lib/python3.10/smtplib.py", line 405, in getreply
    raise SMTPServerDisconnected("Connection unexpectedly closed")
smtplib.SMTPServerDisconnected: Connection unexpectedly closed
ERROR 2023-10-29 03:32:04,858 log Internal Server Error: /p2p/
Traceback (most recent call last):
  File "/home/ubuntu/github/easygo/venv/lib/python3.10/site-packages/django/core/handlers/exception.py", line 56, in inner
    response = get_response(request)
  File "/home/ubuntu/github/easygo/venv/lib/python3.10/site-packages/django/core/handlers/base.py", line 197, in _get_response
    response = wrapped_callback(request, *callback_args, **callback_kwargs)
  File "/home/ubuntu/github/easygo/basecamp/views.py", line 1166, in p2p
    email.send()
  File "/home/ubuntu/github/easygo/venv/lib/python3.10/site-packages/django/core/mail/message.py", line 298, in send
    return self.get_connection(fail_silently).send_messages([self])
  File "/home/ubuntu/github/easygo/venv/lib/python3.10/site-packages/django/core/mail/backends/smtp.py", line 124, in send_messages
    new_conn_created = self.open()
  File "/home/ubuntu/github/easygo/venv/lib/python3.10/site-packages/django/core/mail/backends/smtp.py", line 91, in open
    self.connection.login(self.username, self.password)
  File "/usr/lib/python3.10/smtplib.py", line 739, in login
    (code, resp) = self.auth(
  File "/usr/lib/python3.10/smtplib.py", line 642, in auth
    (code, resp) = self.docmd("AUTH", mechanism + " " + response)
  File "/usr/lib/python3.10/smtplib.py", line 432, in docmd
    return self.getreply()
  File "/usr/lib/python3.10/smtplib.py", line 405, in getreply
    raise SMTPServerDisconnected("Connection unexpectedly closed")
smtplib.SMTPServerDisconnected: Connection unexpectedly closed
ERROR 2023-10-29 03:32:07,383 log Internal Server Error: /p2p/
Traceback (most recent call last):
  File "/home/ubuntu/github/easygo/venv/lib/python3.10/site-packages/django/core/handlers/exception.py", line 56, in inner
    response = get_response(request)
  File "/home/ubuntu/github/easygo/venv/lib/python3.10/site-packages/django/core/handlers/base.py", line 197, in _get_response
    response = wrapped_callback(request, *callback_args, **callback_kwargs)
  File "/home/ubuntu/github/easygo/basecamp/views.py", line 1166, in p2p
    email.send()
  File "/home/ubuntu/github/easygo/venv/lib/python3.10/site-packages/django/core/mail/message.py", line 298, in send
    return self.get_connection(fail_silently).send_messages([self])
  File "/home/ubuntu/github/easygo/venv/lib/python3.10/site-packages/django/core/mail/backends/smtp.py", line 124, in send_messages
    new_conn_created = self.open()
  File "/home/ubuntu/github/easygo/venv/lib/python3.10/site-packages/django/core/mail/backends/smtp.py", line 91, in open
    self.connection.login(self.username, self.password)
  File "/usr/lib/python3.10/smtplib.py", line 739, in login
    (code, resp) = self.auth(
  File "/usr/lib/python3.10/smtplib.py", line 642, in auth
    (code, resp) = self.docmd("AUTH", mechanism + " " + response)
  File "/usr/lib/python3.10/smtplib.py", line 432, in docmd
    return self.getreply()
  File "/usr/lib/python3.10/smtplib.py", line 405, in getreply
    raise SMTPServerDisconnected("Connection unexpectedly closed")
smtplib.SMTPServerDisconnected: Connection unexpectedly closed
ERROR 2023-10-29 03:32:09,899 log Internal Server Error: /p2p/
Traceback (most recent call last):
  File "/home/ubuntu/github/easygo/venv/lib/python3.10/site-packages/django/core/handlers/exception.py", line 56, in inner
    response = get_response(request)
  File "/home/ubuntu/github/easygo/venv/lib/python3.10/site-packages/django/core/handlers/base.py", line 197, in _get_response
    response = wrapped_callback(request, *callback_args, **callback_kwargs)
  File "/home/ubuntu/github/easygo/basecamp/views.py", line 1166, in p2p
    email.send()
  File "/home/ubuntu/github/easygo/venv/lib/python3.10/site-packages/django/core/mail/message.py", line 298, in send
    return self.get_connection(fail_silently).send_messages([self])
  File "/home/ubuntu/github/easygo/venv/lib/python3.10/site-packages/django/core/mail/backends/smtp.py", line 124, in send_messages
    new_conn_created = self.open()
  File "/home/ubuntu/github/easygo/venv/lib/python3.10/site-packages/django/core/mail/backends/smtp.py", line 91, in open
    self.connection.login(self.username, self.password)
  File "/usr/lib/python3.10/smtplib.py", line 739, in login
    (code, resp) = self.auth(
  File "/usr/lib/python3.10/smtplib.py", line 642, in auth
    (code, resp) = self.docmd("AUTH", mechanism + " " + response)
  File "/usr/lib/python3.10/smtplib.py", line 432, in docmd
    return self.getreply()
  File "/usr/lib/python3.10/smtplib.py", line 405, in getreply
    raise SMTPServerDisconnected("Connection unexpectedly closed")
smtplib.SMTPServerDisconnected: Connection unexpectedly closed
ERROR 2023-10-29 03:32:12,411 log Internal Server Error: /p2p/
Traceback (most recent call last):
  File "/home/ubuntu/github/easygo/venv/lib/python3.10/site-packages/django/core/handlers/exception.py", line 56, in inner
    response = get_response(request)
  File "/home/ubuntu/github/easygo/venv/lib/python3.10/site-packages/django/core/handlers/base.py", line 197, in _get_response
    response = wrapped_callback(request, *callback_args, **callback_kwargs)
  File "/home/ubuntu/github/easygo/basecamp/views.py", line 1166, in p2p
    email.send()
  File "/home/ubuntu/github/easygo/venv/lib/python3.10/site-packages/django/core/mail/message.py", line 298, in send
    return self.get_connection(fail_silently).send_messages([self])
  File "/home/ubuntu/github/easygo/venv/lib/python3.10/site-packages/django/core/mail/backends/smtp.py", line 124, in send_messages
    new_conn_created = self.open()
  File "/home/ubuntu/github/easygo/venv/lib/python3.10/site-packages/django/core/mail/backends/smtp.py", line 91, in open
    self.connection.login(self.username, self.password)
  File "/usr/lib/python3.10/smtplib.py", line 739, in login
    (code, resp) = self.auth(
  File "/usr/lib/python3.10/smtplib.py", line 642, in auth
    (code, resp) = self.docmd("AUTH", mechanism + " " + response)
  File "/usr/lib/python3.10/smtplib.py", line 432, in docmd
    return self.getreply()
  File "/usr/lib/python3.10/smtplib.py", line 405, in getreply
    raise SMTPServerDisconnected("Connection unexpectedly closed")
smtplib.SMTPServerDisconnected: Connection unexpectedly closed
WARNING 2023-10-29 03:32:13,409 log Forbidden (CSRF token from POST has incorrect length.): /p2p/
WARNING 2023-10-29 03:32:13,727 log Forbidden (CSRF token from POST has incorrect length.): /p2p/
WARNING 2023-10-29 03:32:14,047 log Forbidden (CSRF token from POST has incorrect length.): /p2p/
WARNING 2023-10-29 03:32:15,033 log Forbidden (CSRF token from POST has incorrect length.): /p2p/
WARNING 2023-10-29 03:32:16,021 log Forbidden (CSRF token from POST has incorrect length.): /p2p/
WARNING 2023-10-29 03:32:17,006 log Forbidden (CSRF token from POST has incorrect length.): /p2p/
WARNING 2023-10-29 03:32:17,991 log Forbidden (CSRF token from POST has incorrect length.): /p2p/
WARNING 2023-10-29 03:32:18,983 log Forbidden (CSRF token from POST has incorrect length.): /p2p/
WARNING 2023-10-29 03:32:19,966 log Forbidden (CSRF token from POST has incorrect length.): /p2p/
WARNING 2023-10-29 03:32:20,958 log Forbidden (CSRF token from POST has incorrect length.): /p2p/
WARNING 2023-10-29 03:32:21,942 log Forbidden (CSRF token from POST has incorrect length.): /p2p/
WARNING 2023-10-29 03:32:22,927 log Forbidden (CSRF token from POST has incorrect length.): /p2p/
ERROR 2023-10-29 03:32:25,443 log Internal Server Error: /p2p/
Traceback (most recent call last):
  File "/home/ubuntu/github/easygo/venv/lib/python3.10/site-packages/django/core/handlers/exception.py", line 56, in inner
    response = get_response(request)
  File "/home/ubuntu/github/easygo/venv/lib/python3.10/site-packages/django/core/handlers/base.py", line 197, in _get_response
    response = wrapped_callback(request, *callback_args, **callback_kwargs)
  File "/home/ubuntu/github/easygo/basecamp/views.py", line 1166, in p2p
    email.send()
  File "/home/ubuntu/github/easygo/venv/lib/python3.10/site-packages/django/core/mail/message.py", line 298, in send
    return self.get_connection(fail_silently).send_messages([self])
  File "/home/ubuntu/github/easygo/venv/lib/python3.10/site-packages/django/core/mail/backends/smtp.py", line 124, in send_messages
    new_conn_created = self.open()
  File "/home/ubuntu/github/easygo/venv/lib/python3.10/site-packages/django/core/mail/backends/smtp.py", line 91, in open
    self.connection.login(self.username, self.password)
  File "/usr/lib/python3.10/smtplib.py", line 739, in login
    (code, resp) = self.auth(
  File "/usr/lib/python3.10/smtplib.py", line 642, in auth
    (code, resp) = self.docmd("AUTH", mechanism + " " + response)
  File "/usr/lib/python3.10/smtplib.py", line 432, in docmd
    return self.getreply()
  File "/usr/lib/python3.10/smtplib.py", line 405, in getreply
    raise SMTPServerDisconnected("Connection unexpectedly closed")
smtplib.SMTPServerDisconnected: Connection unexpectedly closed
ERROR 2023-10-29 03:32:27,343 log Internal Server Error: /p2p/
Traceback (most recent call last):
  File "/home/ubuntu/github/easygo/venv/lib/python3.10/site-packages/django/core/handlers/exception.py", line 56, in inner
    response = get_response(request)
  File "/home/ubuntu/github/easygo/venv/lib/python3.10/site-packages/django/core/handlers/base.py", line 197, in _get_response
    response = wrapped_callback(request, *callback_args, **callback_kwargs)
  File "/home/ubuntu/github/easygo/basecamp/views.py", line 1166, in p2p
    email.send()
  File "/home/ubuntu/github/easygo/venv/lib/python3.10/site-packages/django/core/mail/message.py", line 298, in send
    return self.get_connection(fail_silently).send_messages([self])
  File "/home/ubuntu/github/easygo/venv/lib/python3.10/site-packages/django/core/mail/backends/smtp.py", line 124, in send_messages
    new_conn_created = self.open()
  File "/home/ubuntu/github/easygo/venv/lib/python3.10/site-packages/django/core/mail/backends/smtp.py", line 91, in open
    self.connection.login(self.username, self.password)
  File "/usr/lib/python3.10/smtplib.py", line 739, in login
    (code, resp) = self.auth(
  File "/usr/lib/python3.10/smtplib.py", line 642, in auth
    (code, resp) = self.docmd("AUTH", mechanism + " " + response)
  File "/usr/lib/python3.10/smtplib.py", line 432, in docmd
    return self.getreply()
  File "/usr/lib/python3.10/smtplib.py", line 405, in getreply
    raise SMTPServerDisconnected("Connection unexpectedly closed")
smtplib.SMTPServerDisconnected: Connection unexpectedly closed
ERROR 2023-10-29 03:32:29,203 log Internal Server Error: /p2p/
Traceback (most recent call last):
  File "/home/ubuntu/github/easygo/venv/lib/python3.10/site-packages/django/core/handlers/exception.py", line 56, in inner
    response = get_response(request)
  File "/home/ubuntu/github/easygo/venv/lib/python3.10/site-packages/django/core/handlers/base.py", line 197, in _get_response
    response = wrapped_callback(request, *callback_args, **callback_kwargs)
  File "/home/ubuntu/github/easygo/basecamp/views.py", line 1166, in p2p
    email.send()
  File "/home/ubuntu/github/easygo/venv/lib/python3.10/site-packages/django/core/mail/message.py", line 298, in send
    return self.get_connection(fail_silently).send_messages([self])
  File "/home/ubuntu/github/easygo/venv/lib/python3.10/site-packages/django/core/mail/backends/smtp.py", line 124, in send_messages
    new_conn_created = self.open()
  File "/home/ubuntu/github/easygo/venv/lib/python3.10/site-packages/django/core/mail/backends/smtp.py", line 91, in open
    self.connection.login(self.username, self.password)
  File "/usr/lib/python3.10/smtplib.py", line 739, in login
    (code, resp) = self.auth(
  File "/usr/lib/python3.10/smtplib.py", line 642, in auth
    (code, resp) = self.docmd("AUTH", mechanism + " " + response)
  File "/usr/lib/python3.10/smtplib.py", line 432, in docmd
    return self.getreply()
  File "/usr/lib/python3.10/smtplib.py", line 405, in getreply
    raise SMTPServerDisconnected("Connection unexpectedly closed")
smtplib.SMTPServerDisconnected: Connection unexpectedly closed
ERROR 2023-10-29 03:32:31,719 log Internal Server Error: /p2p/
Traceback (most recent call last):
  File "/home/ubuntu/github/easygo/venv/lib/python3.10/site-packages/django/core/handlers/exception.py", line 56, in inner
    response = get_response(request)
  File "/home/ubuntu/github/easygo/venv/lib/python3.10/site-packages/django/core/handlers/base.py", line 197, in _get_response
    response = wrapped_callback(request, *callback_args, **callback_kwargs)
  File "/home/ubuntu/github/easygo/basecamp/views.py", line 1166, in p2p
    email.send()
  File "/home/ubuntu/github/easygo/venv/lib/python3.10/site-packages/django/core/mail/message.py", line 298, in send
    return self.get_connection(fail_silently).send_messages([self])
  File "/home/ubuntu/github/easygo/venv/lib/python3.10/site-packages/django/core/mail/backends/smtp.py", line 124, in send_messages
    new_conn_created = self.open()
  File "/home/ubuntu/github/easygo/venv/lib/python3.10/site-packages/django/core/mail/backends/smtp.py", line 91, in open
    self.connection.login(self.username, self.password)
  File "/usr/lib/python3.10/smtplib.py", line 739, in login
    (code, resp) = self.auth(
  File "/usr/lib/python3.10/smtplib.py", line 642, in auth
    (code, resp) = self.docmd("AUTH", mechanism + " " + response)
  File "/usr/lib/python3.10/smtplib.py", line 432, in docmd
    return self.getreply()
  File "/usr/lib/python3.10/smtplib.py", line 405, in getreply
    raise SMTPServerDisconnected("Connection unexpectedly closed")
smtplib.SMTPServerDisconnected: Connection unexpectedly closed
ERROR 2023-10-29 03:32:34,242 log Internal Server Error: /p2p/
Traceback (most recent call last):
  File "/home/ubuntu/github/easygo/venv/lib/python3.10/site-packages/django/core/handlers/exception.py", line 56, in inner
    response = get_response(request)
  File "/home/ubuntu/github/easygo/venv/lib/python3.10/site-packages/django/core/handlers/base.py", line 197, in _get_response
    response = wrapped_callback(request, *callback_args, **callback_kwargs)
  File "/home/ubuntu/github/easygo/basecamp/views.py", line 1166, in p2p
    email.send()
  File "/home/ubuntu/github/easygo/venv/lib/python3.10/site-packages/django/core/mail/message.py", line 298, in send
    return self.get_connection(fail_silently).send_messages([self])
  File "/home/ubuntu/github/easygo/venv/lib/python3.10/site-packages/django/core/mail/backends/smtp.py", line 124, in send_messages
    new_conn_created = self.open()
  File "/home/ubuntu/github/easygo/venv/lib/python3.10/site-packages/django/core/mail/backends/smtp.py", line 91, in open
    self.connection.login(self.username, self.password)
  File "/usr/lib/python3.10/smtplib.py", line 739, in login
    (code, resp) = self.auth(
  File "/usr/lib/python3.10/smtplib.py", line 642, in auth
    (code, resp) = self.docmd("AUTH", mechanism + " " + response)
  File "/usr/lib/python3.10/smtplib.py", line 432, in docmd
    return self.getreply()
  File "/usr/lib/python3.10/smtplib.py", line 405, in getreply
    raise SMTPServerDisconnected("Connection unexpectedly closed")
smtplib.SMTPServerDisconnected: Connection unexpectedly closed
ERROR 2023-10-29 03:32:37,395 log Internal Server Error: /p2p/
Traceback (most recent call last):
  File "/home/ubuntu/github/easygo/venv/lib/python3.10/site-packages/django/core/handlers/exception.py", line 56, in inner
    response = get_response(request)
  File "/home/ubuntu/github/easygo/venv/lib/python3.10/site-packages/django/core/handlers/base.py", line 197, in _get_response
    response = wrapped_callback(request, *callback_args, **callback_kwargs)
  File "/home/ubuntu/github/easygo/basecamp/views.py", line 1166, in p2p
    email.send()
  File "/home/ubuntu/github/easygo/venv/lib/python3.10/site-packages/django/core/mail/message.py", line 298, in send
    return self.get_connection(fail_silently).send_messages([self])
  File "/home/ubuntu/github/easygo/venv/lib/python3.10/site-packages/django/core/mail/backends/smtp.py", line 124, in send_messages
    new_conn_created = self.open()
  File "/home/ubuntu/github/easygo/venv/lib/python3.10/site-packages/django/core/mail/backends/smtp.py", line 91, in open
    self.connection.login(self.username, self.password)
  File "/usr/lib/python3.10/smtplib.py", line 739, in login
    (code, resp) = self.auth(
  File "/usr/lib/python3.10/smtplib.py", line 642, in auth
    (code, resp) = self.docmd("AUTH", mechanism + " " + response)
  File "/usr/lib/python3.10/smtplib.py", line 432, in docmd
    return self.getreply()
  File "/usr/lib/python3.10/smtplib.py", line 405, in getreply
    raise SMTPServerDisconnected("Connection unexpectedly closed")
smtplib.SMTPServerDisconnected: Connection unexpectedly closed
ERROR 2023-10-29 03:32:39,967 log Internal Server Error: /p2p/
Traceback (most recent call last):
  File "/home/ubuntu/github/easygo/venv/lib/python3.10/site-packages/django/core/handlers/exception.py", line 56, in inner
    response = get_response(request)
  File "/home/ubuntu/github/easygo/venv/lib/python3.10/site-packages/django/core/handlers/base.py", line 197, in _get_response
    response = wrapped_callback(request, *callback_args, **callback_kwargs)
  File "/home/ubuntu/github/easygo/basecamp/views.py", line 1166, in p2p
    email.send()
  File "/home/ubuntu/github/easygo/venv/lib/python3.10/site-packages/django/core/mail/message.py", line 298, in send
    return self.get_connection(fail_silently).send_messages([self])
  File "/home/ubuntu/github/easygo/venv/lib/python3.10/site-packages/django/core/mail/backends/smtp.py", line 124, in send_messages
    new_conn_created = self.open()
  File "/home/ubuntu/github/easygo/venv/lib/python3.10/site-packages/django/core/mail/backends/smtp.py", line 91, in open
    self.connection.login(self.username, self.password)
  File "/usr/lib/python3.10/smtplib.py", line 739, in login
    (code, resp) = self.auth(
  File "/usr/lib/python3.10/smtplib.py", line 642, in auth
    (code, resp) = self.docmd("AUTH", mechanism + " " + response)
  File "/usr/lib/python3.10/smtplib.py", line 432, in docmd
    return self.getreply()
  File "/usr/lib/python3.10/smtplib.py", line 405, in getreply
    raise SMTPServerDisconnected("Connection unexpectedly closed")
smtplib.SMTPServerDisconnected: Connection unexpectedly closed
ERROR 2023-10-29 03:32:42,487 log Internal Server Error: /p2p/
Traceback (most recent call last):
  File "/home/ubuntu/github/easygo/venv/lib/python3.10/site-packages/django/core/handlers/exception.py", line 56, in inner
    response = get_response(request)
  File "/home/ubuntu/github/easygo/venv/lib/python3.10/site-packages/django/core/handlers/base.py", line 197, in _get_response
    response = wrapped_callback(request, *callback_args, **callback_kwargs)
  File "/home/ubuntu/github/easygo/basecamp/views.py", line 1166, in p2p
    email.send()
  File "/home/ubuntu/github/easygo/venv/lib/python3.10/site-packages/django/core/mail/message.py", line 298, in send
    return self.get_connection(fail_silently).send_messages([self])
  File "/home/ubuntu/github/easygo/venv/lib/python3.10/site-packages/django/core/mail/backends/smtp.py", line 124, in send_messages
    new_conn_created = self.open()
  File "/home/ubuntu/github/easygo/venv/lib/python3.10/site-packages/django/core/mail/backends/smtp.py", line 91, in open
    self.connection.login(self.username, self.password)
  File "/usr/lib/python3.10/smtplib.py", line 739, in login
    (code, resp) = self.auth(
  File "/usr/lib/python3.10/smtplib.py", line 642, in auth
    (code, resp) = self.docmd("AUTH", mechanism + " " + response)
  File "/usr/lib/python3.10/smtplib.py", line 432, in docmd
    return self.getreply()
  File "/usr/lib/python3.10/smtplib.py", line 405, in getreply
    raise SMTPServerDisconnected("Connection unexpectedly closed")
smtplib.SMTPServerDisconnected: Connection unexpectedly closed
ERROR 2023-10-29 03:32:45,059 log Internal Server Error: /p2p/
Traceback (most recent call last):
  File "/home/ubuntu/github/easygo/venv/lib/python3.10/site-packages/django/core/handlers/exception.py", line 56, in inner
    response = get_response(request)
  File "/home/ubuntu/github/easygo/venv/lib/python3.10/site-packages/django/core/handlers/base.py", line 197, in _get_response
    response = wrapped_callback(request, *callback_args, **callback_kwargs)
  File "/home/ubuntu/github/easygo/basecamp/views.py", line 1166, in p2p
    email.send()
  File "/home/ubuntu/github/easygo/venv/lib/python3.10/site-packages/django/core/mail/message.py", line 298, in send
    return self.get_connection(fail_silently).send_messages([self])
  File "/home/ubuntu/github/easygo/venv/lib/python3.10/site-packages/django/core/mail/backends/smtp.py", line 124, in send_messages
    new_conn_created = self.open()
  File "/home/ubuntu/github/easygo/venv/lib/python3.10/site-packages/django/core/mail/backends/smtp.py", line 91, in open
    self.connection.login(self.username, self.password)
  File "/usr/lib/python3.10/smtplib.py", line 739, in login
    (code, resp) = self.auth(
  File "/usr/lib/python3.10/smtplib.py", line 642, in auth
    (code, resp) = self.docmd("AUTH", mechanism + " " + response)
  File "/usr/lib/python3.10/smtplib.py", line 432, in docmd
    return self.getreply()
  File "/usr/lib/python3.10/smtplib.py", line 405, in getreply
    raise SMTPServerDisconnected("Connection unexpectedly closed")
smtplib.SMTPServerDisconnected: Connection unexpectedly closed
ERROR 2023-10-29 03:32:47,632 log Internal Server Error: /p2p/
Traceback (most recent call last):
  File "/home/ubuntu/github/easygo/venv/lib/python3.10/site-packages/django/core/handlers/exception.py", line 56, in inner
    response = get_response(request)
  File "/home/ubuntu/github/easygo/venv/lib/python3.10/site-packages/django/core/handlers/base.py", line 197, in _get_response
    response = wrapped_callback(request, *callback_args, **callback_kwargs)
  File "/home/ubuntu/github/easygo/basecamp/views.py", line 1166, in p2p
    email.send()
  File "/home/ubuntu/github/easygo/venv/lib/python3.10/site-packages/django/core/mail/message.py", line 298, in send
    return self.get_connection(fail_silently).send_messages([self])
  File "/home/ubuntu/github/easygo/venv/lib/python3.10/site-packages/django/core/mail/backends/smtp.py", line 124, in send_messages
    new_conn_created = self.open()
  File "/home/ubuntu/github/easygo/venv/lib/python3.10/site-packages/django/core/mail/backends/smtp.py", line 91, in open
    self.connection.login(self.username, self.password)
  File "/usr/lib/python3.10/smtplib.py", line 739, in login
    (code, resp) = self.auth(
  File "/usr/lib/python3.10/smtplib.py", line 642, in auth
    (code, resp) = self.docmd("AUTH", mechanism + " " + response)
  File "/usr/lib/python3.10/smtplib.py", line 432, in docmd
    return self.getreply()
  File "/usr/lib/python3.10/smtplib.py", line 405, in getreply
    raise SMTPServerDisconnected("Connection unexpectedly closed")
smtplib.SMTPServerDisconnected: Connection unexpectedly closed
ERROR 2023-10-29 03:32:50,246 log Internal Server Error: /p2p/
Traceback (most recent call last):
  File "/home/ubuntu/github/easygo/venv/lib/python3.10/site-packages/django/core/handlers/exception.py", line 56, in inner
    response = get_response(request)
  File "/home/ubuntu/github/easygo/venv/lib/python3.10/site-packages/django/core/handlers/base.py", line 197, in _get_response
    response = wrapped_callback(request, *callback_args, **callback_kwargs)
  File "/home/ubuntu/github/easygo/basecamp/views.py", line 1166, in p2p
    email.send()
  File "/home/ubuntu/github/easygo/venv/lib/python3.10/site-packages/django/core/mail/message.py", line 298, in send
    return self.get_connection(fail_silently).send_messages([self])
  File "/home/ubuntu/github/easygo/venv/lib/python3.10/site-packages/django/core/mail/backends/smtp.py", line 124, in send_messages
    new_conn_created = self.open()
  File "/home/ubuntu/github/easygo/venv/lib/python3.10/site-packages/django/core/mail/backends/smtp.py", line 91, in open
    self.connection.login(self.username, self.password)
  File "/usr/lib/python3.10/smtplib.py", line 739, in login
    (code, resp) = self.auth(
  File "/usr/lib/python3.10/smtplib.py", line 642, in auth
    (code, resp) = self.docmd("AUTH", mechanism + " " + response)
  File "/usr/lib/python3.10/smtplib.py", line 432, in docmd
    return self.getreply()
  File "/usr/lib/python3.10/smtplib.py", line 405, in getreply
    raise SMTPServerDisconnected("Connection unexpectedly closed")
smtplib.SMTPServerDisconnected: Connection unexpectedly closed
ERROR 2023-10-29 03:32:53,446 log Internal Server Error: /p2p/
Traceback (most recent call last):
  File "/home/ubuntu/github/easygo/venv/lib/python3.10/site-packages/django/core/handlers/exception.py", line 56, in inner
    response = get_response(request)
  File "/home/ubuntu/github/easygo/venv/lib/python3.10/site-packages/django/core/handlers/base.py", line 197, in _get_response
    response = wrapped_callback(request, *callback_args, **callback_kwargs)
  File "/home/ubuntu/github/easygo/basecamp/views.py", line 1166, in p2p
    email.send()
  File "/home/ubuntu/github/easygo/venv/lib/python3.10/site-packages/django/core/mail/message.py", line 298, in send
    return self.get_connection(fail_silently).send_messages([self])
  File "/home/ubuntu/github/easygo/venv/lib/python3.10/site-packages/django/core/mail/backends/smtp.py", line 124, in send_messages
    new_conn_created = self.open()
  File "/home/ubuntu/github/easygo/venv/lib/python3.10/site-packages/django/core/mail/backends/smtp.py", line 91, in open
    self.connection.login(self.username, self.password)
  File "/usr/lib/python3.10/smtplib.py", line 739, in login
    (code, resp) = self.auth(
  File "/usr/lib/python3.10/smtplib.py", line 642, in auth
    (code, resp) = self.docmd("AUTH", mechanism + " " + response)
  File "/usr/lib/python3.10/smtplib.py", line 432, in docmd
    return self.getreply()
  File "/usr/lib/python3.10/smtplib.py", line 405, in getreply
    raise SMTPServerDisconnected("Connection unexpectedly closed")
smtplib.SMTPServerDisconnected: Connection unexpectedly closed
ERROR 2023-10-29 03:32:56,021 log Internal Server Error: /p2p/
Traceback (most recent call last):
  File "/home/ubuntu/github/easygo/venv/lib/python3.10/site-packages/django/core/handlers/exception.py", line 56, in inner
    response = get_response(request)
  File "/home/ubuntu/github/easygo/venv/lib/python3.10/site-packages/django/core/handlers/base.py", line 197, in _get_response
    response = wrapped_callback(request, *callback_args, **callback_kwargs)
  File "/home/ubuntu/github/easygo/basecamp/views.py", line 1166, in p2p
    email.send()
  File "/home/ubuntu/github/easygo/venv/lib/python3.10/site-packages/django/core/mail/message.py", line 298, in send
    return self.get_connection(fail_silently).send_messages([self])
  File "/home/ubuntu/github/easygo/venv/lib/python3.10/site-packages/django/core/mail/backends/smtp.py", line 124, in send_messages
    new_conn_created = self.open()
  File "/home/ubuntu/github/easygo/venv/lib/python3.10/site-packages/django/core/mail/backends/smtp.py", line 91, in open
    self.connection.login(self.username, self.password)
  File "/usr/lib/python3.10/smtplib.py", line 739, in login
    (code, resp) = self.auth(
  File "/usr/lib/python3.10/smtplib.py", line 642, in auth
    (code, resp) = self.docmd("AUTH", mechanism + " " + response)
  File "/usr/lib/python3.10/smtplib.py", line 432, in docmd
    return self.getreply()
  File "/usr/lib/python3.10/smtplib.py", line 405, in getreply
    raise SMTPServerDisconnected("Connection unexpectedly closed")
smtplib.SMTPServerDisconnected: Connection unexpectedly closed
ERROR 2023-10-29 03:32:58,543 log Internal Server Error: /p2p/
Traceback (most recent call last):
  File "/home/ubuntu/github/easygo/venv/lib/python3.10/site-packages/django/core/handlers/exception.py", line 56, in inner
    response = get_response(request)
  File "/home/ubuntu/github/easygo/venv/lib/python3.10/site-packages/django/core/handlers/base.py", line 197, in _get_response
    response = wrapped_callback(request, *callback_args, **callback_kwargs)
  File "/home/ubuntu/github/easygo/basecamp/views.py", line 1166, in p2p
    email.send()
  File "/home/ubuntu/github/easygo/venv/lib/python3.10/site-packages/django/core/mail/message.py", line 298, in send
    return self.get_connection(fail_silently).send_messages([self])
  File "/home/ubuntu/github/easygo/venv/lib/python3.10/site-packages/django/core/mail/backends/smtp.py", line 124, in send_messages
    new_conn_created = self.open()
  File "/home/ubuntu/github/easygo/venv/lib/python3.10/site-packages/django/core/mail/backends/smtp.py", line 91, in open
    self.connection.login(self.username, self.password)
  File "/usr/lib/python3.10/smtplib.py", line 739, in login
    (code, resp) = self.auth(
  File "/usr/lib/python3.10/smtplib.py", line 642, in auth
    (code, resp) = self.docmd("AUTH", mechanism + " " + response)
  File "/usr/lib/python3.10/smtplib.py", line 432, in docmd
    return self.getreply()
  File "/usr/lib/python3.10/smtplib.py", line 405, in getreply
    raise SMTPServerDisconnected("Connection unexpectedly closed")
smtplib.SMTPServerDisconnected: Connection unexpectedly closed
ERROR 2023-10-29 03:33:01,077 log Internal Server Error: /p2p/
Traceback (most recent call last):
  File "/home/ubuntu/github/easygo/venv/lib/python3.10/site-packages/django/core/handlers/exception.py", line 56, in inner
    response = get_response(request)
  File "/home/ubuntu/github/easygo/venv/lib/python3.10/site-packages/django/core/handlers/base.py", line 197, in _get_response
    response = wrapped_callback(request, *callback_args, **callback_kwargs)
  File "/home/ubuntu/github/easygo/basecamp/views.py", line 1166, in p2p
    email.send()
  File "/home/ubuntu/github/easygo/venv/lib/python3.10/site-packages/django/core/mail/message.py", line 298, in send
    return self.get_connection(fail_silently).send_messages([self])
  File "/home/ubuntu/github/easygo/venv/lib/python3.10/site-packages/django/core/mail/backends/smtp.py", line 124, in send_messages
    new_conn_created = self.open()
  File "/home/ubuntu/github/easygo/venv/lib/python3.10/site-packages/django/core/mail/backends/smtp.py", line 91, in open
    self.connection.login(self.username, self.password)
  File "/usr/lib/python3.10/smtplib.py", line 739, in login
    (code, resp) = self.auth(
  File "/usr/lib/python3.10/smtplib.py", line 642, in auth
    (code, resp) = self.docmd("AUTH", mechanism + " " + response)
  File "/usr/lib/python3.10/smtplib.py", line 432, in docmd
    return self.getreply()
  File "/usr/lib/python3.10/smtplib.py", line 405, in getreply
    raise SMTPServerDisconnected("Connection unexpectedly closed")
smtplib.SMTPServerDisconnected: Connection unexpectedly closed
ERROR 2023-10-29 03:33:03,637 log Internal Server Error: /p2p/
Traceback (most recent call last):
  File "/home/ubuntu/github/easygo/venv/lib/python3.10/site-packages/django/core/handlers/exception.py", line 56, in inner
    response = get_response(request)
  File "/home/ubuntu/github/easygo/venv/lib/python3.10/site-packages/django/core/handlers/base.py", line 197, in _get_response
    response = wrapped_callback(request, *callback_args, **callback_kwargs)
  File "/home/ubuntu/github/easygo/basecamp/views.py", line 1166, in p2p
    email.send()
  File "/home/ubuntu/github/easygo/venv/lib/python3.10/site-packages/django/core/mail/message.py", line 298, in send
    return self.get_connection(fail_silently).send_messages([self])
  File "/home/ubuntu/github/easygo/venv/lib/python3.10/site-packages/django/core/mail/backends/smtp.py", line 124, in send_messages
    new_conn_created = self.open()
  File "/home/ubuntu/github/easygo/venv/lib/python3.10/site-packages/django/core/mail/backends/smtp.py", line 91, in open
    self.connection.login(self.username, self.password)
  File "/usr/lib/python3.10/smtplib.py", line 739, in login
    (code, resp) = self.auth(
  File "/usr/lib/python3.10/smtplib.py", line 642, in auth
    (code, resp) = self.docmd("AUTH", mechanism + " " + response)
  File "/usr/lib/python3.10/smtplib.py", line 432, in docmd
    return self.getreply()
  File "/usr/lib/python3.10/smtplib.py", line 405, in getreply
    raise SMTPServerDisconnected("Connection unexpectedly closed")
smtplib.SMTPServerDisconnected: Connection unexpectedly closed
ERROR 2023-10-29 03:33:06,161 log Internal Server Error: /p2p/
Traceback (most recent call last):
  File "/home/ubuntu/github/easygo/venv/lib/python3.10/site-packages/django/core/handlers/exception.py", line 56, in inner
    response = get_response(request)
  File "/home/ubuntu/github/easygo/venv/lib/python3.10/site-packages/django/core/handlers/base.py", line 197, in _get_response
    response = wrapped_callback(request, *callback_args, **callback_kwargs)
  File "/home/ubuntu/github/easygo/basecamp/views.py", line 1166, in p2p
    email.send()
  File "/home/ubuntu/github/easygo/venv/lib/python3.10/site-packages/django/core/mail/message.py", line 298, in send
    return self.get_connection(fail_silently).send_messages([self])
  File "/home/ubuntu/github/easygo/venv/lib/python3.10/site-packages/django/core/mail/backends/smtp.py", line 124, in send_messages
    new_conn_created = self.open()
  File "/home/ubuntu/github/easygo/venv/lib/python3.10/site-packages/django/core/mail/backends/smtp.py", line 91, in open
    self.connection.login(self.username, self.password)
  File "/usr/lib/python3.10/smtplib.py", line 739, in login
    (code, resp) = self.auth(
  File "/usr/lib/python3.10/smtplib.py", line 642, in auth
    (code, resp) = self.docmd("AUTH", mechanism + " " + response)
  File "/usr/lib/python3.10/smtplib.py", line 432, in docmd
    return self.getreply()
  File "/usr/lib/python3.10/smtplib.py", line 405, in getreply
    raise SMTPServerDisconnected("Connection unexpectedly closed")
smtplib.SMTPServerDisconnected: Connection unexpectedly closed
ERROR 2023-10-29 03:33:08,685 log Internal Server Error: /p2p/
Traceback (most recent call last):
  File "/home/ubuntu/github/easygo/venv/lib/python3.10/site-packages/django/core/handlers/exception.py", line 56, in inner
    response = get_response(request)
  File "/home/ubuntu/github/easygo/venv/lib/python3.10/site-packages/django/core/handlers/base.py", line 197, in _get_response
    response = wrapped_callback(request, *callback_args, **callback_kwargs)
  File "/home/ubuntu/github/easygo/basecamp/views.py", line 1166, in p2p
    email.send()
  File "/home/ubuntu/github/easygo/venv/lib/python3.10/site-packages/django/core/mail/message.py", line 298, in send
    return self.get_connection(fail_silently).send_messages([self])
  File "/home/ubuntu/github/easygo/venv/lib/python3.10/site-packages/django/core/mail/backends/smtp.py", line 124, in send_messages
    new_conn_created = self.open()
  File "/home/ubuntu/github/easygo/venv/lib/python3.10/site-packages/django/core/mail/backends/smtp.py", line 91, in open
    self.connection.login(self.username, self.password)
  File "/usr/lib/python3.10/smtplib.py", line 739, in login
    (code, resp) = self.auth(
  File "/usr/lib/python3.10/smtplib.py", line 642, in auth
    (code, resp) = self.docmd("AUTH", mechanism + " " + response)
  File "/usr/lib/python3.10/smtplib.py", line 432, in docmd
    return self.getreply()
  File "/usr/lib/python3.10/smtplib.py", line 405, in getreply
    raise SMTPServerDisconnected("Connection unexpectedly closed")
smtplib.SMTPServerDisconnected: Connection unexpectedly closed
ERROR 2023-10-29 03:33:11,219 log Internal Server Error: /p2p/
Traceback (most recent call last):
  File "/home/ubuntu/github/easygo/venv/lib/python3.10/site-packages/django/core/handlers/exception.py", line 56, in inner
    response = get_response(request)
  File "/home/ubuntu/github/easygo/venv/lib/python3.10/site-packages/django/core/handlers/base.py", line 197, in _get_response
    response = wrapped_callback(request, *callback_args, **callback_kwargs)
  File "/home/ubuntu/github/easygo/basecamp/views.py", line 1166, in p2p
    email.send()
  File "/home/ubuntu/github/easygo/venv/lib/python3.10/site-packages/django/core/mail/message.py", line 298, in send
    return self.get_connection(fail_silently).send_messages([self])
  File "/home/ubuntu/github/easygo/venv/lib/python3.10/site-packages/django/core/mail/backends/smtp.py", line 124, in send_messages
    new_conn_created = self.open()
  File "/home/ubuntu/github/easygo/venv/lib/python3.10/site-packages/django/core/mail/backends/smtp.py", line 91, in open
    self.connection.login(self.username, self.password)
  File "/usr/lib/python3.10/smtplib.py", line 739, in login
    (code, resp) = self.auth(
  File "/usr/lib/python3.10/smtplib.py", line 642, in auth
    (code, resp) = self.docmd("AUTH", mechanism + " " + response)
  File "/usr/lib/python3.10/smtplib.py", line 432, in docmd
    return self.getreply()
  File "/usr/lib/python3.10/smtplib.py", line 405, in getreply
    raise SMTPServerDisconnected("Connection unexpectedly closed")
smtplib.SMTPServerDisconnected: Connection unexpectedly closed
ERROR 2023-10-29 03:33:13,744 log Internal Server Error: /p2p/
Traceback (most recent call last):
  File "/home/ubuntu/github/easygo/venv/lib/python3.10/site-packages/django/core/handlers/exception.py", line 56, in inner
    response = get_response(request)
  File "/home/ubuntu/github/easygo/venv/lib/python3.10/site-packages/django/core/handlers/base.py", line 197, in _get_response
    response = wrapped_callback(request, *callback_args, **callback_kwargs)
  File "/home/ubuntu/github/easygo/basecamp/views.py", line 1166, in p2p
    email.send()
  File "/home/ubuntu/github/easygo/venv/lib/python3.10/site-packages/django/core/mail/message.py", line 298, in send
    return self.get_connection(fail_silently).send_messages([self])
  File "/home/ubuntu/github/easygo/venv/lib/python3.10/site-packages/django/core/mail/backends/smtp.py", line 124, in send_messages
    new_conn_created = self.open()
  File "/home/ubuntu/github/easygo/venv/lib/python3.10/site-packages/django/core/mail/backends/smtp.py", line 91, in open
    self.connection.login(self.username, self.password)
  File "/usr/lib/python3.10/smtplib.py", line 739, in login
    (code, resp) = self.auth(
  File "/usr/lib/python3.10/smtplib.py", line 642, in auth
    (code, resp) = self.docmd("AUTH", mechanism + " " + response)
  File "/usr/lib/python3.10/smtplib.py", line 432, in docmd
    return self.getreply()
  File "/usr/lib/python3.10/smtplib.py", line 405, in getreply
    raise SMTPServerDisconnected("Connection unexpectedly closed")
smtplib.SMTPServerDisconnected: Connection unexpectedly closed
ERROR 2023-10-29 03:33:16,271 log Internal Server Error: /p2p/
Traceback (most recent call last):
  File "/home/ubuntu/github/easygo/venv/lib/python3.10/site-packages/django/core/handlers/exception.py", line 56, in inner
    response = get_response(request)
  File "/home/ubuntu/github/easygo/venv/lib/python3.10/site-packages/django/core/handlers/base.py", line 197, in _get_response
    response = wrapped_callback(request, *callback_args, **callback_kwargs)
  File "/home/ubuntu/github/easygo/basecamp/views.py", line 1166, in p2p
    email.send()
  File "/home/ubuntu/github/easygo/venv/lib/python3.10/site-packages/django/core/mail/message.py", line 298, in send
    return self.get_connection(fail_silently).send_messages([self])
  File "/home/ubuntu/github/easygo/venv/lib/python3.10/site-packages/django/core/mail/backends/smtp.py", line 124, in send_messages
    new_conn_created = self.open()
  File "/home/ubuntu/github/easygo/venv/lib/python3.10/site-packages/django/core/mail/backends/smtp.py", line 91, in open
    self.connection.login(self.username, self.password)
  File "/usr/lib/python3.10/smtplib.py", line 739, in login
    (code, resp) = self.auth(
  File "/usr/lib/python3.10/smtplib.py", line 642, in auth
    (code, resp) = self.docmd("AUTH", mechanism + " " + response)
  File "/usr/lib/python3.10/smtplib.py", line 432, in docmd
    return self.getreply()
  File "/usr/lib/python3.10/smtplib.py", line 405, in getreply
    raise SMTPServerDisconnected("Connection unexpectedly closed")
smtplib.SMTPServerDisconnected: Connection unexpectedly closed
ERROR 2023-10-29 03:33:18,123 log Internal Server Error: /p2p/
Traceback (most recent call last):
  File "/home/ubuntu/github/easygo/venv/lib/python3.10/site-packages/django/core/handlers/exception.py", line 56, in inner
    response = get_response(request)
  File "/home/ubuntu/github/easygo/venv/lib/python3.10/site-packages/django/core/handlers/base.py", line 197, in _get_response
    response = wrapped_callback(request, *callback_args, **callback_kwargs)
  File "/home/ubuntu/github/easygo/basecamp/views.py", line 1166, in p2p
    email.send()
  File "/home/ubuntu/github/easygo/venv/lib/python3.10/site-packages/django/core/mail/message.py", line 298, in send
    return self.get_connection(fail_silently).send_messages([self])
  File "/home/ubuntu/github/easygo/venv/lib/python3.10/site-packages/django/core/mail/backends/smtp.py", line 124, in send_messages
    new_conn_created = self.open()
  File "/home/ubuntu/github/easygo/venv/lib/python3.10/site-packages/django/core/mail/backends/smtp.py", line 91, in open
    self.connection.login(self.username, self.password)
  File "/usr/lib/python3.10/smtplib.py", line 739, in login
    (code, resp) = self.auth(
  File "/usr/lib/python3.10/smtplib.py", line 642, in auth
    (code, resp) = self.docmd("AUTH", mechanism + " " + response)
  File "/usr/lib/python3.10/smtplib.py", line 432, in docmd
    return self.getreply()
  File "/usr/lib/python3.10/smtplib.py", line 405, in getreply
    raise SMTPServerDisconnected("Connection unexpectedly closed")
smtplib.SMTPServerDisconnected: Connection unexpectedly closed
ERROR 2023-10-29 03:33:20,057 log Internal Server Error: /p2p/
Traceback (most recent call last):
  File "/home/ubuntu/github/easygo/venv/lib/python3.10/site-packages/django/core/handlers/exception.py", line 56, in inner
    response = get_response(request)
  File "/home/ubuntu/github/easygo/venv/lib/python3.10/site-packages/django/core/handlers/base.py", line 197, in _get_response
    response = wrapped_callback(request, *callback_args, **callback_kwargs)
  File "/home/ubuntu/github/easygo/basecamp/views.py", line 1166, in p2p
    email.send()
  File "/home/ubuntu/github/easygo/venv/lib/python3.10/site-packages/django/core/mail/message.py", line 298, in send
    return self.get_connection(fail_silently).send_messages([self])
  File "/home/ubuntu/github/easygo/venv/lib/python3.10/site-packages/django/core/mail/backends/smtp.py", line 124, in send_messages
    new_conn_created = self.open()
  File "/home/ubuntu/github/easygo/venv/lib/python3.10/site-packages/django/core/mail/backends/smtp.py", line 91, in open
    self.connection.login(self.username, self.password)
  File "/usr/lib/python3.10/smtplib.py", line 739, in login
    (code, resp) = self.auth(
  File "/usr/lib/python3.10/smtplib.py", line 642, in auth
    (code, resp) = self.docmd("AUTH", mechanism + " " + response)
  File "/usr/lib/python3.10/smtplib.py", line 432, in docmd
    return self.getreply()
  File "/usr/lib/python3.10/smtplib.py", line 405, in getreply
    raise SMTPServerDisconnected("Connection unexpectedly closed")
smtplib.SMTPServerDisconnected: Connection unexpectedly closed
ERROR 2023-10-29 03:33:22,622 log Internal Server Error: /p2p/
Traceback (most recent call last):
  File "/home/ubuntu/github/easygo/venv/lib/python3.10/site-packages/django/core/handlers/exception.py", line 56, in inner
    response = get_response(request)
  File "/home/ubuntu/github/easygo/venv/lib/python3.10/site-packages/django/core/handlers/base.py", line 197, in _get_response
    response = wrapped_callback(request, *callback_args, **callback_kwargs)
  File "/home/ubuntu/github/easygo/basecamp/views.py", line 1166, in p2p
    email.send()
  File "/home/ubuntu/github/easygo/venv/lib/python3.10/site-packages/django/core/mail/message.py", line 298, in send
    return self.get_connection(fail_silently).send_messages([self])
  File "/home/ubuntu/github/easygo/venv/lib/python3.10/site-packages/django/core/mail/backends/smtp.py", line 124, in send_messages
    new_conn_created = self.open()
  File "/home/ubuntu/github/easygo/venv/lib/python3.10/site-packages/django/core/mail/backends/smtp.py", line 91, in open
    self.connection.login(self.username, self.password)
  File "/usr/lib/python3.10/smtplib.py", line 739, in login
    (code, resp) = self.auth(
  File "/usr/lib/python3.10/smtplib.py", line 642, in auth
    (code, resp) = self.docmd("AUTH", mechanism + " " + response)
  File "/usr/lib/python3.10/smtplib.py", line 432, in docmd
    return self.getreply()
  File "/usr/lib/python3.10/smtplib.py", line 405, in getreply
    raise SMTPServerDisconnected("Connection unexpectedly closed")
smtplib.SMTPServerDisconnected: Connection unexpectedly closed
ERROR 2023-10-29 03:33:25,165 log Internal Server Error: /p2p/
Traceback (most recent call last):
  File "/home/ubuntu/github/easygo/venv/lib/python3.10/site-packages/django/core/handlers/exception.py", line 56, in inner
    response = get_response(request)
  File "/home/ubuntu/github/easygo/venv/lib/python3.10/site-packages/django/core/handlers/base.py", line 197, in _get_response
    response = wrapped_callback(request, *callback_args, **callback_kwargs)
  File "/home/ubuntu/github/easygo/basecamp/views.py", line 1166, in p2p
    email.send()
  File "/home/ubuntu/github/easygo/venv/lib/python3.10/site-packages/django/core/mail/message.py", line 298, in send
    return self.get_connection(fail_silently).send_messages([self])
  File "/home/ubuntu/github/easygo/venv/lib/python3.10/site-packages/django/core/mail/backends/smtp.py", line 124, in send_messages
    new_conn_created = self.open()
  File "/home/ubuntu/github/easygo/venv/lib/python3.10/site-packages/django/core/mail/backends/smtp.py", line 91, in open
    self.connection.login(self.username, self.password)
  File "/usr/lib/python3.10/smtplib.py", line 739, in login
    (code, resp) = self.auth(
  File "/usr/lib/python3.10/smtplib.py", line 642, in auth
    (code, resp) = self.docmd("AUTH", mechanism + " " + response)
  File "/usr/lib/python3.10/smtplib.py", line 432, in docmd
    return self.getreply()
  File "/usr/lib/python3.10/smtplib.py", line 405, in getreply
    raise SMTPServerDisconnected("Connection unexpectedly closed")
smtplib.SMTPServerDisconnected: Connection unexpectedly closed
ERROR 2023-10-29 03:33:27,681 log Internal Server Error: /p2p/
Traceback (most recent call last):
  File "/home/ubuntu/github/easygo/venv/lib/python3.10/site-packages/django/core/handlers/exception.py", line 56, in inner
    response = get_response(request)
  File "/home/ubuntu/github/easygo/venv/lib/python3.10/site-packages/django/core/handlers/base.py", line 197, in _get_response
    response = wrapped_callback(request, *callback_args, **callback_kwargs)
  File "/home/ubuntu/github/easygo/basecamp/views.py", line 1166, in p2p
    email.send()
  File "/home/ubuntu/github/easygo/venv/lib/python3.10/site-packages/django/core/mail/message.py", line 298, in send
    return self.get_connection(fail_silently).send_messages([self])
  File "/home/ubuntu/github/easygo/venv/lib/python3.10/site-packages/django/core/mail/backends/smtp.py", line 124, in send_messages
    new_conn_created = self.open()
  File "/home/ubuntu/github/easygo/venv/lib/python3.10/site-packages/django/core/mail/backends/smtp.py", line 91, in open
    self.connection.login(self.username, self.password)
  File "/usr/lib/python3.10/smtplib.py", line 739, in login
    (code, resp) = self.auth(
  File "/usr/lib/python3.10/smtplib.py", line 642, in auth
    (code, resp) = self.docmd("AUTH", mechanism + " " + response)
  File "/usr/lib/python3.10/smtplib.py", line 432, in docmd
    return self.getreply()
  File "/usr/lib/python3.10/smtplib.py", line 405, in getreply
    raise SMTPServerDisconnected("Connection unexpectedly closed")
smtplib.SMTPServerDisconnected: Connection unexpectedly closed
ERROR 2023-10-29 03:33:30,208 log Internal Server Error: /p2p/
Traceback (most recent call last):
  File "/home/ubuntu/github/easygo/venv/lib/python3.10/site-packages/django/core/handlers/exception.py", line 56, in inner
    response = get_response(request)
  File "/home/ubuntu/github/easygo/venv/lib/python3.10/site-packages/django/core/handlers/base.py", line 197, in _get_response
    response = wrapped_callback(request, *callback_args, **callback_kwargs)
  File "/home/ubuntu/github/easygo/basecamp/views.py", line 1166, in p2p
    email.send()
  File "/home/ubuntu/github/easygo/venv/lib/python3.10/site-packages/django/core/mail/message.py", line 298, in send
    return self.get_connection(fail_silently).send_messages([self])
  File "/home/ubuntu/github/easygo/venv/lib/python3.10/site-packages/django/core/mail/backends/smtp.py", line 124, in send_messages
    new_conn_created = self.open()
  File "/home/ubuntu/github/easygo/venv/lib/python3.10/site-packages/django/core/mail/backends/smtp.py", line 91, in open
    self.connection.login(self.username, self.password)
  File "/usr/lib/python3.10/smtplib.py", line 739, in login
    (code, resp) = self.auth(
  File "/usr/lib/python3.10/smtplib.py", line 642, in auth
    (code, resp) = self.docmd("AUTH", mechanism + " " + response)
  File "/usr/lib/python3.10/smtplib.py", line 432, in docmd
    return self.getreply()
  File "/usr/lib/python3.10/smtplib.py", line 405, in getreply
    raise SMTPServerDisconnected("Connection unexpectedly closed")
smtplib.SMTPServerDisconnected: Connection unexpectedly closed
ERROR 2023-10-29 03:33:32,732 log Internal Server Error: /p2p/
Traceback (most recent call last):
  File "/home/ubuntu/github/easygo/venv/lib/python3.10/site-packages/django/core/handlers/exception.py", line 56, in inner
    response = get_response(request)
  File "/home/ubuntu/github/easygo/venv/lib/python3.10/site-packages/django/core/handlers/base.py", line 197, in _get_response
    response = wrapped_callback(request, *callback_args, **callback_kwargs)
  File "/home/ubuntu/github/easygo/basecamp/views.py", line 1166, in p2p
    email.send()
  File "/home/ubuntu/github/easygo/venv/lib/python3.10/site-packages/django/core/mail/message.py", line 298, in send
    return self.get_connection(fail_silently).send_messages([self])
  File "/home/ubuntu/github/easygo/venv/lib/python3.10/site-packages/django/core/mail/backends/smtp.py", line 124, in send_messages
    new_conn_created = self.open()
  File "/home/ubuntu/github/easygo/venv/lib/python3.10/site-packages/django/core/mail/backends/smtp.py", line 91, in open
    self.connection.login(self.username, self.password)
  File "/usr/lib/python3.10/smtplib.py", line 739, in login
    (code, resp) = self.auth(
  File "/usr/lib/python3.10/smtplib.py", line 642, in auth
    (code, resp) = self.docmd("AUTH", mechanism + " " + response)
  File "/usr/lib/python3.10/smtplib.py", line 432, in docmd
    return self.getreply()
  File "/usr/lib/python3.10/smtplib.py", line 405, in getreply
    raise SMTPServerDisconnected("Connection unexpectedly closed")
smtplib.SMTPServerDisconnected: Connection unexpectedly closed
ERROR 2023-10-29 03:33:35,253 log Internal Server Error: /p2p/
Traceback (most recent call last):
  File "/home/ubuntu/github/easygo/venv/lib/python3.10/site-packages/django/core/handlers/exception.py", line 56, in inner
    response = get_response(request)
  File "/home/ubuntu/github/easygo/venv/lib/python3.10/site-packages/django/core/handlers/base.py", line 197, in _get_response
    response = wrapped_callback(request, *callback_args, **callback_kwargs)
  File "/home/ubuntu/github/easygo/basecamp/views.py", line 1166, in p2p
    email.send()
  File "/home/ubuntu/github/easygo/venv/lib/python3.10/site-packages/django/core/mail/message.py", line 298, in send
    return self.get_connection(fail_silently).send_messages([self])
  File "/home/ubuntu/github/easygo/venv/lib/python3.10/site-packages/django/core/mail/backends/smtp.py", line 124, in send_messages
    new_conn_created = self.open()
  File "/home/ubuntu/github/easygo/venv/lib/python3.10/site-packages/django/core/mail/backends/smtp.py", line 91, in open
    self.connection.login(self.username, self.password)
  File "/usr/lib/python3.10/smtplib.py", line 739, in login
    (code, resp) = self.auth(
  File "/usr/lib/python3.10/smtplib.py", line 642, in auth
    (code, resp) = self.docmd("AUTH", mechanism + " " + response)
  File "/usr/lib/python3.10/smtplib.py", line 432, in docmd
    return self.getreply()
  File "/usr/lib/python3.10/smtplib.py", line 405, in getreply
    raise SMTPServerDisconnected("Connection unexpectedly closed")
smtplib.SMTPServerDisconnected: Connection unexpectedly closed
ERROR 2023-10-29 03:33:37,783 log Internal Server Error: /p2p/
Traceback (most recent call last):
  File "/home/ubuntu/github/easygo/venv/lib/python3.10/site-packages/django/core/handlers/exception.py", line 56, in inner
    response = get_response(request)
  File "/home/ubuntu/github/easygo/venv/lib/python3.10/site-packages/django/core/handlers/base.py", line 197, in _get_response
    response = wrapped_callback(request, *callback_args, **callback_kwargs)
  File "/home/ubuntu/github/easygo/basecamp/views.py", line 1166, in p2p
    email.send()
  File "/home/ubuntu/github/easygo/venv/lib/python3.10/site-packages/django/core/mail/message.py", line 298, in send
    return self.get_connection(fail_silently).send_messages([self])
  File "/home/ubuntu/github/easygo/venv/lib/python3.10/site-packages/django/core/mail/backends/smtp.py", line 124, in send_messages
    new_conn_created = self.open()
  File "/home/ubuntu/github/easygo/venv/lib/python3.10/site-packages/django/core/mail/backends/smtp.py", line 91, in open
    self.connection.login(self.username, self.password)
  File "/usr/lib/python3.10/smtplib.py", line 739, in login
    (code, resp) = self.auth(
  File "/usr/lib/python3.10/smtplib.py", line 642, in auth
    (code, resp) = self.docmd("AUTH", mechanism + " " + response)
  File "/usr/lib/python3.10/smtplib.py", line 432, in docmd
    return self.getreply()
  File "/usr/lib/python3.10/smtplib.py", line 405, in getreply
    raise SMTPServerDisconnected("Connection unexpectedly closed")
smtplib.SMTPServerDisconnected: Connection unexpectedly closed
ERROR 2023-10-29 03:33:40,300 log Internal Server Error: /p2p/
Traceback (most recent call last):
  File "/home/ubuntu/github/easygo/venv/lib/python3.10/site-packages/django/core/handlers/exception.py", line 56, in inner
    response = get_response(request)
  File "/home/ubuntu/github/easygo/venv/lib/python3.10/site-packages/django/core/handlers/base.py", line 197, in _get_response
    response = wrapped_callback(request, *callback_args, **callback_kwargs)
  File "/home/ubuntu/github/easygo/basecamp/views.py", line 1166, in p2p
    email.send()
  File "/home/ubuntu/github/easygo/venv/lib/python3.10/site-packages/django/core/mail/message.py", line 298, in send
    return self.get_connection(fail_silently).send_messages([self])
  File "/home/ubuntu/github/easygo/venv/lib/python3.10/site-packages/django/core/mail/backends/smtp.py", line 124, in send_messages
    new_conn_created = self.open()
  File "/home/ubuntu/github/easygo/venv/lib/python3.10/site-packages/django/core/mail/backends/smtp.py", line 91, in open
    self.connection.login(self.username, self.password)
  File "/usr/lib/python3.10/smtplib.py", line 739, in login
    (code, resp) = self.auth(
  File "/usr/lib/python3.10/smtplib.py", line 642, in auth
    (code, resp) = self.docmd("AUTH", mechanism + " " + response)
  File "/usr/lib/python3.10/smtplib.py", line 432, in docmd
    return self.getreply()
  File "/usr/lib/python3.10/smtplib.py", line 405, in getreply
    raise SMTPServerDisconnected("Connection unexpectedly closed")
smtplib.SMTPServerDisconnected: Connection unexpectedly closed
ERROR 2023-10-29 03:33:42,833 log Internal Server Error: /p2p/
Traceback (most recent call last):
  File "/home/ubuntu/github/easygo/venv/lib/python3.10/site-packages/django/core/handlers/exception.py", line 56, in inner
    response = get_response(request)
  File "/home/ubuntu/github/easygo/venv/lib/python3.10/site-packages/django/core/handlers/base.py", line 197, in _get_response
    response = wrapped_callback(request, *callback_args, **callback_kwargs)
  File "/home/ubuntu/github/easygo/basecamp/views.py", line 1166, in p2p
    email.send()
  File "/home/ubuntu/github/easygo/venv/lib/python3.10/site-packages/django/core/mail/message.py", line 298, in send
    return self.get_connection(fail_silently).send_messages([self])
  File "/home/ubuntu/github/easygo/venv/lib/python3.10/site-packages/django/core/mail/backends/smtp.py", line 124, in send_messages
    new_conn_created = self.open()
  File "/home/ubuntu/github/easygo/venv/lib/python3.10/site-packages/django/core/mail/backends/smtp.py", line 91, in open
    self.connection.login(self.username, self.password)
  File "/usr/lib/python3.10/smtplib.py", line 739, in login
    (code, resp) = self.auth(
  File "/usr/lib/python3.10/smtplib.py", line 642, in auth
    (code, resp) = self.docmd("AUTH", mechanism + " " + response)
  File "/usr/lib/python3.10/smtplib.py", line 432, in docmd
    return self.getreply()
  File "/usr/lib/python3.10/smtplib.py", line 405, in getreply
    raise SMTPServerDisconnected("Connection unexpectedly closed")
smtplib.SMTPServerDisconnected: Connection unexpectedly closed
ERROR 2023-10-29 03:33:45,385 log Internal Server Error: /p2p/
Traceback (most recent call last):
  File "/home/ubuntu/github/easygo/venv/lib/python3.10/site-packages/django/core/handlers/exception.py", line 56, in inner
    response = get_response(request)
  File "/home/ubuntu/github/easygo/venv/lib/python3.10/site-packages/django/core/handlers/base.py", line 197, in _get_response
    response = wrapped_callback(request, *callback_args, **callback_kwargs)
  File "/home/ubuntu/github/easygo/basecamp/views.py", line 1166, in p2p
    email.send()
  File "/home/ubuntu/github/easygo/venv/lib/python3.10/site-packages/django/core/mail/message.py", line 298, in send
    return self.get_connection(fail_silently).send_messages([self])
  File "/home/ubuntu/github/easygo/venv/lib/python3.10/site-packages/django/core/mail/backends/smtp.py", line 124, in send_messages
    new_conn_created = self.open()
  File "/home/ubuntu/github/easygo/venv/lib/python3.10/site-packages/django/core/mail/backends/smtp.py", line 91, in open
    self.connection.login(self.username, self.password)
  File "/usr/lib/python3.10/smtplib.py", line 739, in login
    (code, resp) = self.auth(
  File "/usr/lib/python3.10/smtplib.py", line 642, in auth
    (code, resp) = self.docmd("AUTH", mechanism + " " + response)
  File "/usr/lib/python3.10/smtplib.py", line 432, in docmd
    return self.getreply()
  File "/usr/lib/python3.10/smtplib.py", line 405, in getreply
    raise SMTPServerDisconnected("Connection unexpectedly closed")
smtplib.SMTPServerDisconnected: Connection unexpectedly closed
ERROR 2023-10-29 03:33:47,930 log Internal Server Error: /p2p/
Traceback (most recent call last):
  File "/home/ubuntu/github/easygo/venv/lib/python3.10/site-packages/django/core/handlers/exception.py", line 56, in inner
    response = get_response(request)
  File "/home/ubuntu/github/easygo/venv/lib/python3.10/site-packages/django/core/handlers/base.py", line 197, in _get_response
    response = wrapped_callback(request, *callback_args, **callback_kwargs)
  File "/home/ubuntu/github/easygo/basecamp/views.py", line 1166, in p2p
    email.send()
  File "/home/ubuntu/github/easygo/venv/lib/python3.10/site-packages/django/core/mail/message.py", line 298, in send
    return self.get_connection(fail_silently).send_messages([self])
  File "/home/ubuntu/github/easygo/venv/lib/python3.10/site-packages/django/core/mail/backends/smtp.py", line 124, in send_messages
    new_conn_created = self.open()
  File "/home/ubuntu/github/easygo/venv/lib/python3.10/site-packages/django/core/mail/backends/smtp.py", line 91, in open
    self.connection.login(self.username, self.password)
  File "/usr/lib/python3.10/smtplib.py", line 739, in login
    (code, resp) = self.auth(
  File "/usr/lib/python3.10/smtplib.py", line 642, in auth
    (code, resp) = self.docmd("AUTH", mechanism + " " + response)
  File "/usr/lib/python3.10/smtplib.py", line 432, in docmd
    return self.getreply()
  File "/usr/lib/python3.10/smtplib.py", line 405, in getreply
    raise SMTPServerDisconnected("Connection unexpectedly closed")
smtplib.SMTPServerDisconnected: Connection unexpectedly closed
ERROR 2023-10-29 03:33:50,493 log Internal Server Error: /p2p/
Traceback (most recent call last):
  File "/home/ubuntu/github/easygo/venv/lib/python3.10/site-packages/django/core/handlers/exception.py", line 56, in inner
    response = get_response(request)
  File "/home/ubuntu/github/easygo/venv/lib/python3.10/site-packages/django/core/handlers/base.py", line 197, in _get_response
    response = wrapped_callback(request, *callback_args, **callback_kwargs)
  File "/home/ubuntu/github/easygo/basecamp/views.py", line 1166, in p2p
    email.send()
  File "/home/ubuntu/github/easygo/venv/lib/python3.10/site-packages/django/core/mail/message.py", line 298, in send
    return self.get_connection(fail_silently).send_messages([self])
  File "/home/ubuntu/github/easygo/venv/lib/python3.10/site-packages/django/core/mail/backends/smtp.py", line 124, in send_messages
    new_conn_created = self.open()
  File "/home/ubuntu/github/easygo/venv/lib/python3.10/site-packages/django/core/mail/backends/smtp.py", line 91, in open
    self.connection.login(self.username, self.password)
  File "/usr/lib/python3.10/smtplib.py", line 739, in login
    (code, resp) = self.auth(
  File "/usr/lib/python3.10/smtplib.py", line 642, in auth
    (code, resp) = self.docmd("AUTH", mechanism + " " + response)
  File "/usr/lib/python3.10/smtplib.py", line 432, in docmd
    return self.getreply()
  File "/usr/lib/python3.10/smtplib.py", line 405, in getreply
    raise SMTPServerDisconnected("Connection unexpectedly closed")
smtplib.SMTPServerDisconnected: Connection unexpectedly closed
ERROR 2023-10-29 03:33:53,024 log Internal Server Error: /p2p/
Traceback (most recent call last):
  File "/home/ubuntu/github/easygo/venv/lib/python3.10/site-packages/django/core/handlers/exception.py", line 56, in inner
    response = get_response(request)
  File "/home/ubuntu/github/easygo/venv/lib/python3.10/site-packages/django/core/handlers/base.py", line 197, in _get_response
    response = wrapped_callback(request, *callback_args, **callback_kwargs)
  File "/home/ubuntu/github/easygo/basecamp/views.py", line 1166, in p2p
    email.send()
  File "/home/ubuntu/github/easygo/venv/lib/python3.10/site-packages/django/core/mail/message.py", line 298, in send
    return self.get_connection(fail_silently).send_messages([self])
  File "/home/ubuntu/github/easygo/venv/lib/python3.10/site-packages/django/core/mail/backends/smtp.py", line 124, in send_messages
    new_conn_created = self.open()
  File "/home/ubuntu/github/easygo/venv/lib/python3.10/site-packages/django/core/mail/backends/smtp.py", line 91, in open
    self.connection.login(self.username, self.password)
  File "/usr/lib/python3.10/smtplib.py", line 739, in login
    (code, resp) = self.auth(
  File "/usr/lib/python3.10/smtplib.py", line 642, in auth
    (code, resp) = self.docmd("AUTH", mechanism + " " + response)
  File "/usr/lib/python3.10/smtplib.py", line 432, in docmd
    return self.getreply()
  File "/usr/lib/python3.10/smtplib.py", line 405, in getreply
    raise SMTPServerDisconnected("Connection unexpectedly closed")
smtplib.SMTPServerDisconnected: Connection unexpectedly closed
ERROR 2023-10-29 03:33:55,583 log Internal Server Error: /p2p/
Traceback (most recent call last):
  File "/home/ubuntu/github/easygo/venv/lib/python3.10/site-packages/django/core/handlers/exception.py", line 56, in inner
    response = get_response(request)
  File "/home/ubuntu/github/easygo/venv/lib/python3.10/site-packages/django/core/handlers/base.py", line 197, in _get_response
    response = wrapped_callback(request, *callback_args, **callback_kwargs)
  File "/home/ubuntu/github/easygo/basecamp/views.py", line 1166, in p2p
    email.send()
  File "/home/ubuntu/github/easygo/venv/lib/python3.10/site-packages/django/core/mail/message.py", line 298, in send
    return self.get_connection(fail_silently).send_messages([self])
  File "/home/ubuntu/github/easygo/venv/lib/python3.10/site-packages/django/core/mail/backends/smtp.py", line 124, in send_messages
    new_conn_created = self.open()
  File "/home/ubuntu/github/easygo/venv/lib/python3.10/site-packages/django/core/mail/backends/smtp.py", line 91, in open
    self.connection.login(self.username, self.password)
  File "/usr/lib/python3.10/smtplib.py", line 739, in login
    (code, resp) = self.auth(
  File "/usr/lib/python3.10/smtplib.py", line 642, in auth
    (code, resp) = self.docmd("AUTH", mechanism + " " + response)
  File "/usr/lib/python3.10/smtplib.py", line 432, in docmd
    return self.getreply()
  File "/usr/lib/python3.10/smtplib.py", line 405, in getreply
    raise SMTPServerDisconnected("Connection unexpectedly closed")
smtplib.SMTPServerDisconnected: Connection unexpectedly closed
ERROR 2023-10-29 03:33:58,114 log Internal Server Error: /p2p/
Traceback (most recent call last):
  File "/home/ubuntu/github/easygo/venv/lib/python3.10/site-packages/django/core/handlers/exception.py", line 56, in inner
    response = get_response(request)
  File "/home/ubuntu/github/easygo/venv/lib/python3.10/site-packages/django/core/handlers/base.py", line 197, in _get_response
    response = wrapped_callback(request, *callback_args, **callback_kwargs)
  File "/home/ubuntu/github/easygo/basecamp/views.py", line 1166, in p2p
    email.send()
  File "/home/ubuntu/github/easygo/venv/lib/python3.10/site-packages/django/core/mail/message.py", line 298, in send
    return self.get_connection(fail_silently).send_messages([self])
  File "/home/ubuntu/github/easygo/venv/lib/python3.10/site-packages/django/core/mail/backends/smtp.py", line 124, in send_messages
    new_conn_created = self.open()
  File "/home/ubuntu/github/easygo/venv/lib/python3.10/site-packages/django/core/mail/backends/smtp.py", line 91, in open
    self.connection.login(self.username, self.password)
  File "/usr/lib/python3.10/smtplib.py", line 739, in login
    (code, resp) = self.auth(
  File "/usr/lib/python3.10/smtplib.py", line 642, in auth
    (code, resp) = self.docmd("AUTH", mechanism + " " + response)
  File "/usr/lib/python3.10/smtplib.py", line 432, in docmd
    return self.getreply()
  File "/usr/lib/python3.10/smtplib.py", line 405, in getreply
    raise SMTPServerDisconnected("Connection unexpectedly closed")
smtplib.SMTPServerDisconnected: Connection unexpectedly closed
ERROR 2023-10-29 03:34:00,624 log Internal Server Error: /p2p/
Traceback (most recent call last):
  File "/home/ubuntu/github/easygo/venv/lib/python3.10/site-packages/django/core/handlers/exception.py", line 56, in inner
    response = get_response(request)
  File "/home/ubuntu/github/easygo/venv/lib/python3.10/site-packages/django/core/handlers/base.py", line 197, in _get_response
    response = wrapped_callback(request, *callback_args, **callback_kwargs)
  File "/home/ubuntu/github/easygo/basecamp/views.py", line 1166, in p2p
    email.send()
  File "/home/ubuntu/github/easygo/venv/lib/python3.10/site-packages/django/core/mail/message.py", line 298, in send
    return self.get_connection(fail_silently).send_messages([self])
  File "/home/ubuntu/github/easygo/venv/lib/python3.10/site-packages/django/core/mail/backends/smtp.py", line 124, in send_messages
    new_conn_created = self.open()
  File "/home/ubuntu/github/easygo/venv/lib/python3.10/site-packages/django/core/mail/backends/smtp.py", line 91, in open
    self.connection.login(self.username, self.password)
  File "/usr/lib/python3.10/smtplib.py", line 739, in login
    (code, resp) = self.auth(
  File "/usr/lib/python3.10/smtplib.py", line 642, in auth
    (code, resp) = self.docmd("AUTH", mechanism + " " + response)
  File "/usr/lib/python3.10/smtplib.py", line 432, in docmd
    return self.getreply()
  File "/usr/lib/python3.10/smtplib.py", line 405, in getreply
    raise SMTPServerDisconnected("Connection unexpectedly closed")
smtplib.SMTPServerDisconnected: Connection unexpectedly closed
ERROR 2023-10-29 03:34:03,514 log Internal Server Error: /p2p/
Traceback (most recent call last):
  File "/home/ubuntu/github/easygo/venv/lib/python3.10/site-packages/django/core/handlers/exception.py", line 56, in inner
    response = get_response(request)
  File "/home/ubuntu/github/easygo/venv/lib/python3.10/site-packages/django/core/handlers/base.py", line 197, in _get_response
    response = wrapped_callback(request, *callback_args, **callback_kwargs)
  File "/home/ubuntu/github/easygo/basecamp/views.py", line 1166, in p2p
    email.send()
  File "/home/ubuntu/github/easygo/venv/lib/python3.10/site-packages/django/core/mail/message.py", line 298, in send
    return self.get_connection(fail_silently).send_messages([self])
  File "/home/ubuntu/github/easygo/venv/lib/python3.10/site-packages/django/core/mail/backends/smtp.py", line 124, in send_messages
    new_conn_created = self.open()
  File "/home/ubuntu/github/easygo/venv/lib/python3.10/site-packages/django/core/mail/backends/smtp.py", line 91, in open
    self.connection.login(self.username, self.password)
  File "/usr/lib/python3.10/smtplib.py", line 739, in login
    (code, resp) = self.auth(
  File "/usr/lib/python3.10/smtplib.py", line 642, in auth
    (code, resp) = self.docmd("AUTH", mechanism + " " + response)
  File "/usr/lib/python3.10/smtplib.py", line 432, in docmd
    return self.getreply()
  File "/usr/lib/python3.10/smtplib.py", line 405, in getreply
    raise SMTPServerDisconnected("Connection unexpectedly closed")
smtplib.SMTPServerDisconnected: Connection unexpectedly closed
ERROR 2023-10-29 03:34:06,048 log Internal Server Error: /p2p/
Traceback (most recent call last):
  File "/home/ubuntu/github/easygo/venv/lib/python3.10/site-packages/django/core/handlers/exception.py", line 56, in inner
    response = get_response(request)
  File "/home/ubuntu/github/easygo/venv/lib/python3.10/site-packages/django/core/handlers/base.py", line 197, in _get_response
    response = wrapped_callback(request, *callback_args, **callback_kwargs)
  File "/home/ubuntu/github/easygo/basecamp/views.py", line 1166, in p2p
    email.send()
  File "/home/ubuntu/github/easygo/venv/lib/python3.10/site-packages/django/core/mail/message.py", line 298, in send
    return self.get_connection(fail_silently).send_messages([self])
  File "/home/ubuntu/github/easygo/venv/lib/python3.10/site-packages/django/core/mail/backends/smtp.py", line 124, in send_messages
    new_conn_created = self.open()
  File "/home/ubuntu/github/easygo/venv/lib/python3.10/site-packages/django/core/mail/backends/smtp.py", line 91, in open
    self.connection.login(self.username, self.password)
  File "/usr/lib/python3.10/smtplib.py", line 739, in login
    (code, resp) = self.auth(
  File "/usr/lib/python3.10/smtplib.py", line 642, in auth
    (code, resp) = self.docmd("AUTH", mechanism + " " + response)
  File "/usr/lib/python3.10/smtplib.py", line 432, in docmd
    return self.getreply()
  File "/usr/lib/python3.10/smtplib.py", line 405, in getreply
    raise SMTPServerDisconnected("Connection unexpectedly closed")
smtplib.SMTPServerDisconnected: Connection unexpectedly closed
ERROR 2023-10-29 03:34:07,951 log Internal Server Error: /p2p/
Traceback (most recent call last):
  File "/home/ubuntu/github/easygo/venv/lib/python3.10/site-packages/django/core/handlers/exception.py", line 56, in inner
    response = get_response(request)
  File "/home/ubuntu/github/easygo/venv/lib/python3.10/site-packages/django/core/handlers/base.py", line 197, in _get_response
    response = wrapped_callback(request, *callback_args, **callback_kwargs)
  File "/home/ubuntu/github/easygo/basecamp/views.py", line 1166, in p2p
    email.send()
  File "/home/ubuntu/github/easygo/venv/lib/python3.10/site-packages/django/core/mail/message.py", line 298, in send
    return self.get_connection(fail_silently).send_messages([self])
  File "/home/ubuntu/github/easygo/venv/lib/python3.10/site-packages/django/core/mail/backends/smtp.py", line 124, in send_messages
    new_conn_created = self.open()
  File "/home/ubuntu/github/easygo/venv/lib/python3.10/site-packages/django/core/mail/backends/smtp.py", line 91, in open
    self.connection.login(self.username, self.password)
  File "/usr/lib/python3.10/smtplib.py", line 739, in login
    (code, resp) = self.auth(
  File "/usr/lib/python3.10/smtplib.py", line 642, in auth
    (code, resp) = self.docmd("AUTH", mechanism + " " + response)
  File "/usr/lib/python3.10/smtplib.py", line 432, in docmd
    return self.getreply()
  File "/usr/lib/python3.10/smtplib.py", line 405, in getreply
    raise SMTPServerDisconnected("Connection unexpectedly closed")
smtplib.SMTPServerDisconnected: Connection unexpectedly closed
ERROR 2023-10-29 03:34:09,806 log Internal Server Error: /p2p/
Traceback (most recent call last):
  File "/home/ubuntu/github/easygo/venv/lib/python3.10/site-packages/django/core/handlers/exception.py", line 56, in inner
    response = get_response(request)
  File "/home/ubuntu/github/easygo/venv/lib/python3.10/site-packages/django/core/handlers/base.py", line 197, in _get_response
    response = wrapped_callback(request, *callback_args, **callback_kwargs)
  File "/home/ubuntu/github/easygo/basecamp/views.py", line 1166, in p2p
    email.send()
  File "/home/ubuntu/github/easygo/venv/lib/python3.10/site-packages/django/core/mail/message.py", line 298, in send
    return self.get_connection(fail_silently).send_messages([self])
  File "/home/ubuntu/github/easygo/venv/lib/python3.10/site-packages/django/core/mail/backends/smtp.py", line 124, in send_messages
    new_conn_created = self.open()
  File "/home/ubuntu/github/easygo/venv/lib/python3.10/site-packages/django/core/mail/backends/smtp.py", line 91, in open
    self.connection.login(self.username, self.password)
  File "/usr/lib/python3.10/smtplib.py", line 739, in login
    (code, resp) = self.auth(
  File "/usr/lib/python3.10/smtplib.py", line 642, in auth
    (code, resp) = self.docmd("AUTH", mechanism + " " + response)
  File "/usr/lib/python3.10/smtplib.py", line 432, in docmd
    return self.getreply()
  File "/usr/lib/python3.10/smtplib.py", line 405, in getreply
    raise SMTPServerDisconnected("Connection unexpectedly closed")
smtplib.SMTPServerDisconnected: Connection unexpectedly closed
ERROR 2023-10-29 03:34:12,328 log Internal Server Error: /p2p/
Traceback (most recent call last):
  File "/home/ubuntu/github/easygo/venv/lib/python3.10/site-packages/django/core/handlers/exception.py", line 56, in inner
    response = get_response(request)
  File "/home/ubuntu/github/easygo/venv/lib/python3.10/site-packages/django/core/handlers/base.py", line 197, in _get_response
    response = wrapped_callback(request, *callback_args, **callback_kwargs)
  File "/home/ubuntu/github/easygo/basecamp/views.py", line 1166, in p2p
    email.send()
  File "/home/ubuntu/github/easygo/venv/lib/python3.10/site-packages/django/core/mail/message.py", line 298, in send
    return self.get_connection(fail_silently).send_messages([self])
  File "/home/ubuntu/github/easygo/venv/lib/python3.10/site-packages/django/core/mail/backends/smtp.py", line 124, in send_messages
    new_conn_created = self.open()
  File "/home/ubuntu/github/easygo/venv/lib/python3.10/site-packages/django/core/mail/backends/smtp.py", line 91, in open
    self.connection.login(self.username, self.password)
  File "/usr/lib/python3.10/smtplib.py", line 739, in login
    (code, resp) = self.auth(
  File "/usr/lib/python3.10/smtplib.py", line 642, in auth
    (code, resp) = self.docmd("AUTH", mechanism + " " + response)
  File "/usr/lib/python3.10/smtplib.py", line 432, in docmd
    return self.getreply()
  File "/usr/lib/python3.10/smtplib.py", line 405, in getreply
    raise SMTPServerDisconnected("Connection unexpectedly closed")
smtplib.SMTPServerDisconnected: Connection unexpectedly closed
ERROR 2023-10-29 03:34:14,852 log Internal Server Error: /p2p/
Traceback (most recent call last):
  File "/home/ubuntu/github/easygo/venv/lib/python3.10/site-packages/django/core/handlers/exception.py", line 56, in inner
    response = get_response(request)
  File "/home/ubuntu/github/easygo/venv/lib/python3.10/site-packages/django/core/handlers/base.py", line 197, in _get_response
    response = wrapped_callback(request, *callback_args, **callback_kwargs)
  File "/home/ubuntu/github/easygo/basecamp/views.py", line 1166, in p2p
    email.send()
  File "/home/ubuntu/github/easygo/venv/lib/python3.10/site-packages/django/core/mail/message.py", line 298, in send
    return self.get_connection(fail_silently).send_messages([self])
  File "/home/ubuntu/github/easygo/venv/lib/python3.10/site-packages/django/core/mail/backends/smtp.py", line 124, in send_messages
    new_conn_created = self.open()
  File "/home/ubuntu/github/easygo/venv/lib/python3.10/site-packages/django/core/mail/backends/smtp.py", line 91, in open
    self.connection.login(self.username, self.password)
  File "/usr/lib/python3.10/smtplib.py", line 739, in login
    (code, resp) = self.auth(
  File "/usr/lib/python3.10/smtplib.py", line 642, in auth
    (code, resp) = self.docmd("AUTH", mechanism + " " + response)
  File "/usr/lib/python3.10/smtplib.py", line 432, in docmd
    return self.getreply()
  File "/usr/lib/python3.10/smtplib.py", line 405, in getreply
    raise SMTPServerDisconnected("Connection unexpectedly closed")
smtplib.SMTPServerDisconnected: Connection unexpectedly closed
ERROR 2023-10-29 03:34:17,385 log Internal Server Error: /p2p/
Traceback (most recent call last):
  File "/home/ubuntu/github/easygo/venv/lib/python3.10/site-packages/django/core/handlers/exception.py", line 56, in inner
    response = get_response(request)
  File "/home/ubuntu/github/easygo/venv/lib/python3.10/site-packages/django/core/handlers/base.py", line 197, in _get_response
    response = wrapped_callback(request, *callback_args, **callback_kwargs)
  File "/home/ubuntu/github/easygo/basecamp/views.py", line 1166, in p2p
    email.send()
  File "/home/ubuntu/github/easygo/venv/lib/python3.10/site-packages/django/core/mail/message.py", line 298, in send
    return self.get_connection(fail_silently).send_messages([self])
  File "/home/ubuntu/github/easygo/venv/lib/python3.10/site-packages/django/core/mail/backends/smtp.py", line 124, in send_messages
    new_conn_created = self.open()
  File "/home/ubuntu/github/easygo/venv/lib/python3.10/site-packages/django/core/mail/backends/smtp.py", line 91, in open
    self.connection.login(self.username, self.password)
  File "/usr/lib/python3.10/smtplib.py", line 739, in login
    (code, resp) = self.auth(
  File "/usr/lib/python3.10/smtplib.py", line 642, in auth
    (code, resp) = self.docmd("AUTH", mechanism + " " + response)
  File "/usr/lib/python3.10/smtplib.py", line 432, in docmd
    return self.getreply()
  File "/usr/lib/python3.10/smtplib.py", line 405, in getreply
    raise SMTPServerDisconnected("Connection unexpectedly closed")
smtplib.SMTPServerDisconnected: Connection unexpectedly closed
ERROR 2023-10-29 03:34:19,891 log Internal Server Error: /p2p/
Traceback (most recent call last):
  File "/home/ubuntu/github/easygo/venv/lib/python3.10/site-packages/django/core/handlers/exception.py", line 56, in inner
    response = get_response(request)
  File "/home/ubuntu/github/easygo/venv/lib/python3.10/site-packages/django/core/handlers/base.py", line 197, in _get_response
    response = wrapped_callback(request, *callback_args, **callback_kwargs)
  File "/home/ubuntu/github/easygo/basecamp/views.py", line 1166, in p2p
    email.send()
  File "/home/ubuntu/github/easygo/venv/lib/python3.10/site-packages/django/core/mail/message.py", line 298, in send
    return self.get_connection(fail_silently).send_messages([self])
  File "/home/ubuntu/github/easygo/venv/lib/python3.10/site-packages/django/core/mail/backends/smtp.py", line 124, in send_messages
    new_conn_created = self.open()
  File "/home/ubuntu/github/easygo/venv/lib/python3.10/site-packages/django/core/mail/backends/smtp.py", line 91, in open
    self.connection.login(self.username, self.password)
  File "/usr/lib/python3.10/smtplib.py", line 739, in login
    (code, resp) = self.auth(
  File "/usr/lib/python3.10/smtplib.py", line 642, in auth
    (code, resp) = self.docmd("AUTH", mechanism + " " + response)
  File "/usr/lib/python3.10/smtplib.py", line 432, in docmd
    return self.getreply()
  File "/usr/lib/python3.10/smtplib.py", line 405, in getreply
    raise SMTPServerDisconnected("Connection unexpectedly closed")
smtplib.SMTPServerDisconnected: Connection unexpectedly closed
ERROR 2023-10-29 03:34:22,411 log Internal Server Error: /p2p/
Traceback (most recent call last):
  File "/home/ubuntu/github/easygo/venv/lib/python3.10/site-packages/django/core/handlers/exception.py", line 56, in inner
    response = get_response(request)
  File "/home/ubuntu/github/easygo/venv/lib/python3.10/site-packages/django/core/handlers/base.py", line 197, in _get_response
    response = wrapped_callback(request, *callback_args, **callback_kwargs)
  File "/home/ubuntu/github/easygo/basecamp/views.py", line 1166, in p2p
    email.send()
  File "/home/ubuntu/github/easygo/venv/lib/python3.10/site-packages/django/core/mail/message.py", line 298, in send
    return self.get_connection(fail_silently).send_messages([self])
  File "/home/ubuntu/github/easygo/venv/lib/python3.10/site-packages/django/core/mail/backends/smtp.py", line 124, in send_messages
    new_conn_created = self.open()
  File "/home/ubuntu/github/easygo/venv/lib/python3.10/site-packages/django/core/mail/backends/smtp.py", line 91, in open
    self.connection.login(self.username, self.password)
  File "/usr/lib/python3.10/smtplib.py", line 739, in login
    (code, resp) = self.auth(
  File "/usr/lib/python3.10/smtplib.py", line 642, in auth
    (code, resp) = self.docmd("AUTH", mechanism + " " + response)
  File "/usr/lib/python3.10/smtplib.py", line 432, in docmd
    return self.getreply()
  File "/usr/lib/python3.10/smtplib.py", line 405, in getreply
    raise SMTPServerDisconnected("Connection unexpectedly closed")
smtplib.SMTPServerDisconnected: Connection unexpectedly closed
ERROR 2023-10-29 03:34:25,469 log Internal Server Error: /p2p/
Traceback (most recent call last):
  File "/home/ubuntu/github/easygo/venv/lib/python3.10/site-packages/django/core/handlers/exception.py", line 56, in inner
    response = get_response(request)
  File "/home/ubuntu/github/easygo/venv/lib/python3.10/site-packages/django/core/handlers/base.py", line 197, in _get_response
    response = wrapped_callback(request, *callback_args, **callback_kwargs)
  File "/home/ubuntu/github/easygo/basecamp/views.py", line 1166, in p2p
    email.send()
  File "/home/ubuntu/github/easygo/venv/lib/python3.10/site-packages/django/core/mail/message.py", line 298, in send
    return self.get_connection(fail_silently).send_messages([self])
  File "/home/ubuntu/github/easygo/venv/lib/python3.10/site-packages/django/core/mail/backends/smtp.py", line 124, in send_messages
    new_conn_created = self.open()
  File "/home/ubuntu/github/easygo/venv/lib/python3.10/site-packages/django/core/mail/backends/smtp.py", line 91, in open
    self.connection.login(self.username, self.password)
  File "/usr/lib/python3.10/smtplib.py", line 739, in login
    (code, resp) = self.auth(
  File "/usr/lib/python3.10/smtplib.py", line 642, in auth
    (code, resp) = self.docmd("AUTH", mechanism + " " + response)
  File "/usr/lib/python3.10/smtplib.py", line 432, in docmd
    return self.getreply()
  File "/usr/lib/python3.10/smtplib.py", line 405, in getreply
    raise SMTPServerDisconnected("Connection unexpectedly closed")
smtplib.SMTPServerDisconnected: Connection unexpectedly closed
ERROR 2023-10-29 03:34:28,071 log Internal Server Error: /p2p/
Traceback (most recent call last):
  File "/home/ubuntu/github/easygo/venv/lib/python3.10/site-packages/django/core/handlers/exception.py", line 56, in inner
    response = get_response(request)
  File "/home/ubuntu/github/easygo/venv/lib/python3.10/site-packages/django/core/handlers/base.py", line 197, in _get_response
    response = wrapped_callback(request, *callback_args, **callback_kwargs)
  File "/home/ubuntu/github/easygo/basecamp/views.py", line 1166, in p2p
    email.send()
  File "/home/ubuntu/github/easygo/venv/lib/python3.10/site-packages/django/core/mail/message.py", line 298, in send
    return self.get_connection(fail_silently).send_messages([self])
  File "/home/ubuntu/github/easygo/venv/lib/python3.10/site-packages/django/core/mail/backends/smtp.py", line 124, in send_messages
    new_conn_created = self.open()
  File "/home/ubuntu/github/easygo/venv/lib/python3.10/site-packages/django/core/mail/backends/smtp.py", line 91, in open
    self.connection.login(self.username, self.password)
  File "/usr/lib/python3.10/smtplib.py", line 739, in login
    (code, resp) = self.auth(
  File "/usr/lib/python3.10/smtplib.py", line 642, in auth
    (code, resp) = self.docmd("AUTH", mechanism + " " + response)
  File "/usr/lib/python3.10/smtplib.py", line 432, in docmd
    return self.getreply()
  File "/usr/lib/python3.10/smtplib.py", line 405, in getreply
    raise SMTPServerDisconnected("Connection unexpectedly closed")
smtplib.SMTPServerDisconnected: Connection unexpectedly closed
ERROR 2023-10-29 03:34:30,598 log Internal Server Error: /p2p/
Traceback (most recent call last):
  File "/home/ubuntu/github/easygo/venv/lib/python3.10/site-packages/django/core/handlers/exception.py", line 56, in inner
    response = get_response(request)
  File "/home/ubuntu/github/easygo/venv/lib/python3.10/site-packages/django/core/handlers/base.py", line 197, in _get_response
    response = wrapped_callback(request, *callback_args, **callback_kwargs)
  File "/home/ubuntu/github/easygo/basecamp/views.py", line 1166, in p2p
    email.send()
  File "/home/ubuntu/github/easygo/venv/lib/python3.10/site-packages/django/core/mail/message.py", line 298, in send
    return self.get_connection(fail_silently).send_messages([self])
  File "/home/ubuntu/github/easygo/venv/lib/python3.10/site-packages/django/core/mail/backends/smtp.py", line 124, in send_messages
    new_conn_created = self.open()
  File "/home/ubuntu/github/easygo/venv/lib/python3.10/site-packages/django/core/mail/backends/smtp.py", line 91, in open
    self.connection.login(self.username, self.password)
  File "/usr/lib/python3.10/smtplib.py", line 739, in login
    (code, resp) = self.auth(
  File "/usr/lib/python3.10/smtplib.py", line 642, in auth
    (code, resp) = self.docmd("AUTH", mechanism + " " + response)
  File "/usr/lib/python3.10/smtplib.py", line 432, in docmd
    return self.getreply()
  File "/usr/lib/python3.10/smtplib.py", line 405, in getreply
    raise SMTPServerDisconnected("Connection unexpectedly closed")
smtplib.SMTPServerDisconnected: Connection unexpectedly closed
ERROR 2023-10-29 03:34:33,123 log Internal Server Error: /p2p/
Traceback (most recent call last):
  File "/home/ubuntu/github/easygo/venv/lib/python3.10/site-packages/django/core/handlers/exception.py", line 56, in inner
    response = get_response(request)
  File "/home/ubuntu/github/easygo/venv/lib/python3.10/site-packages/django/core/handlers/base.py", line 197, in _get_response
    response = wrapped_callback(request, *callback_args, **callback_kwargs)
  File "/home/ubuntu/github/easygo/basecamp/views.py", line 1166, in p2p
    email.send()
  File "/home/ubuntu/github/easygo/venv/lib/python3.10/site-packages/django/core/mail/message.py", line 298, in send
    return self.get_connection(fail_silently).send_messages([self])
  File "/home/ubuntu/github/easygo/venv/lib/python3.10/site-packages/django/core/mail/backends/smtp.py", line 124, in send_messages
    new_conn_created = self.open()
  File "/home/ubuntu/github/easygo/venv/lib/python3.10/site-packages/django/core/mail/backends/smtp.py", line 91, in open
    self.connection.login(self.username, self.password)
  File "/usr/lib/python3.10/smtplib.py", line 739, in login
    (code, resp) = self.auth(
  File "/usr/lib/python3.10/smtplib.py", line 642, in auth
    (code, resp) = self.docmd("AUTH", mechanism + " " + response)
  File "/usr/lib/python3.10/smtplib.py", line 432, in docmd
    return self.getreply()
  File "/usr/lib/python3.10/smtplib.py", line 405, in getreply
    raise SMTPServerDisconnected("Connection unexpectedly closed")
smtplib.SMTPServerDisconnected: Connection unexpectedly closed
ERROR 2023-10-29 03:34:35,696 log Internal Server Error: /p2p/
Traceback (most recent call last):
  File "/home/ubuntu/github/easygo/venv/lib/python3.10/site-packages/django/core/handlers/exception.py", line 56, in inner
    response = get_response(request)
  File "/home/ubuntu/github/easygo/venv/lib/python3.10/site-packages/django/core/handlers/base.py", line 197, in _get_response
    response = wrapped_callback(request, *callback_args, **callback_kwargs)
  File "/home/ubuntu/github/easygo/basecamp/views.py", line 1166, in p2p
    email.send()
  File "/home/ubuntu/github/easygo/venv/lib/python3.10/site-packages/django/core/mail/message.py", line 298, in send
    return self.get_connection(fail_silently).send_messages([self])
  File "/home/ubuntu/github/easygo/venv/lib/python3.10/site-packages/django/core/mail/backends/smtp.py", line 124, in send_messages
    new_conn_created = self.open()
  File "/home/ubuntu/github/easygo/venv/lib/python3.10/site-packages/django/core/mail/backends/smtp.py", line 91, in open
    self.connection.login(self.username, self.password)
  File "/usr/lib/python3.10/smtplib.py", line 739, in login
    (code, resp) = self.auth(
  File "/usr/lib/python3.10/smtplib.py", line 642, in auth
    (code, resp) = self.docmd("AUTH", mechanism + " " + response)
  File "/usr/lib/python3.10/smtplib.py", line 432, in docmd
    return self.getreply()
  File "/usr/lib/python3.10/smtplib.py", line 405, in getreply
    raise SMTPServerDisconnected("Connection unexpectedly closed")
smtplib.SMTPServerDisconnected: Connection unexpectedly closed
ERROR 2023-10-29 03:34:38,201 log Internal Server Error: /p2p/
Traceback (most recent call last):
  File "/home/ubuntu/github/easygo/venv/lib/python3.10/site-packages/django/core/handlers/exception.py", line 56, in inner
    response = get_response(request)
  File "/home/ubuntu/github/easygo/venv/lib/python3.10/site-packages/django/core/handlers/base.py", line 197, in _get_response
    response = wrapped_callback(request, *callback_args, **callback_kwargs)
  File "/home/ubuntu/github/easygo/basecamp/views.py", line 1166, in p2p
    email.send()
  File "/home/ubuntu/github/easygo/venv/lib/python3.10/site-packages/django/core/mail/message.py", line 298, in send
    return self.get_connection(fail_silently).send_messages([self])
  File "/home/ubuntu/github/easygo/venv/lib/python3.10/site-packages/django/core/mail/backends/smtp.py", line 124, in send_messages
    new_conn_created = self.open()
  File "/home/ubuntu/github/easygo/venv/lib/python3.10/site-packages/django/core/mail/backends/smtp.py", line 91, in open
    self.connection.login(self.username, self.password)
  File "/usr/lib/python3.10/smtplib.py", line 739, in login
    (code, resp) = self.auth(
  File "/usr/lib/python3.10/smtplib.py", line 642, in auth
    (code, resp) = self.docmd("AUTH", mechanism + " " + response)
  File "/usr/lib/python3.10/smtplib.py", line 432, in docmd
    return self.getreply()
  File "/usr/lib/python3.10/smtplib.py", line 405, in getreply
    raise SMTPServerDisconnected("Connection unexpectedly closed")
smtplib.SMTPServerDisconnected: Connection unexpectedly closed
ERROR 2023-10-29 03:34:40,731 log Internal Server Error: /p2p/
Traceback (most recent call last):
  File "/home/ubuntu/github/easygo/venv/lib/python3.10/site-packages/django/core/handlers/exception.py", line 56, in inner
    response = get_response(request)
  File "/home/ubuntu/github/easygo/venv/lib/python3.10/site-packages/django/core/handlers/base.py", line 197, in _get_response
    response = wrapped_callback(request, *callback_args, **callback_kwargs)
  File "/home/ubuntu/github/easygo/basecamp/views.py", line 1166, in p2p
    email.send()
  File "/home/ubuntu/github/easygo/venv/lib/python3.10/site-packages/django/core/mail/message.py", line 298, in send
    return self.get_connection(fail_silently).send_messages([self])
  File "/home/ubuntu/github/easygo/venv/lib/python3.10/site-packages/django/core/mail/backends/smtp.py", line 124, in send_messages
    new_conn_created = self.open()
  File "/home/ubuntu/github/easygo/venv/lib/python3.10/site-packages/django/core/mail/backends/smtp.py", line 91, in open
    self.connection.login(self.username, self.password)
  File "/usr/lib/python3.10/smtplib.py", line 739, in login
    (code, resp) = self.auth(
  File "/usr/lib/python3.10/smtplib.py", line 642, in auth
    (code, resp) = self.docmd("AUTH", mechanism + " " + response)
  File "/usr/lib/python3.10/smtplib.py", line 432, in docmd
    return self.getreply()
  File "/usr/lib/python3.10/smtplib.py", line 405, in getreply
    raise SMTPServerDisconnected("Connection unexpectedly closed")
smtplib.SMTPServerDisconnected: Connection unexpectedly closed
ERROR 2023-10-29 03:34:43,250 log Internal Server Error: /p2p/
Traceback (most recent call last):
  File "/home/ubuntu/github/easygo/venv/lib/python3.10/site-packages/django/core/handlers/exception.py", line 56, in inner
    response = get_response(request)
  File "/home/ubuntu/github/easygo/venv/lib/python3.10/site-packages/django/core/handlers/base.py", line 197, in _get_response
    response = wrapped_callback(request, *callback_args, **callback_kwargs)
  File "/home/ubuntu/github/easygo/basecamp/views.py", line 1166, in p2p
    email.send()
  File "/home/ubuntu/github/easygo/venv/lib/python3.10/site-packages/django/core/mail/message.py", line 298, in send
    return self.get_connection(fail_silently).send_messages([self])
  File "/home/ubuntu/github/easygo/venv/lib/python3.10/site-packages/django/core/mail/backends/smtp.py", line 124, in send_messages
    new_conn_created = self.open()
  File "/home/ubuntu/github/easygo/venv/lib/python3.10/site-packages/django/core/mail/backends/smtp.py", line 91, in open
    self.connection.login(self.username, self.password)
  File "/usr/lib/python3.10/smtplib.py", line 739, in login
    (code, resp) = self.auth(
  File "/usr/lib/python3.10/smtplib.py", line 642, in auth
    (code, resp) = self.docmd("AUTH", mechanism + " " + response)
  File "/usr/lib/python3.10/smtplib.py", line 432, in docmd
    return self.getreply()
  File "/usr/lib/python3.10/smtplib.py", line 405, in getreply
    raise SMTPServerDisconnected("Connection unexpectedly closed")
smtplib.SMTPServerDisconnected: Connection unexpectedly closed
ERROR 2023-10-29 03:34:45,758 log Internal Server Error: /p2p/
Traceback (most recent call last):
  File "/home/ubuntu/github/easygo/venv/lib/python3.10/site-packages/django/core/handlers/exception.py", line 56, in inner
    response = get_response(request)
  File "/home/ubuntu/github/easygo/venv/lib/python3.10/site-packages/django/core/handlers/base.py", line 197, in _get_response
    response = wrapped_callback(request, *callback_args, **callback_kwargs)
  File "/home/ubuntu/github/easygo/basecamp/views.py", line 1166, in p2p
    email.send()
  File "/home/ubuntu/github/easygo/venv/lib/python3.10/site-packages/django/core/mail/message.py", line 298, in send
    return self.get_connection(fail_silently).send_messages([self])
  File "/home/ubuntu/github/easygo/venv/lib/python3.10/site-packages/django/core/mail/backends/smtp.py", line 124, in send_messages
    new_conn_created = self.open()
  File "/home/ubuntu/github/easygo/venv/lib/python3.10/site-packages/django/core/mail/backends/smtp.py", line 91, in open
    self.connection.login(self.username, self.password)
  File "/usr/lib/python3.10/smtplib.py", line 739, in login
    (code, resp) = self.auth(
  File "/usr/lib/python3.10/smtplib.py", line 642, in auth
    (code, resp) = self.docmd("AUTH", mechanism + " " + response)
  File "/usr/lib/python3.10/smtplib.py", line 432, in docmd
    return self.getreply()
  File "/usr/lib/python3.10/smtplib.py", line 405, in getreply
    raise SMTPServerDisconnected("Connection unexpectedly closed")
smtplib.SMTPServerDisconnected: Connection unexpectedly closed
ERROR 2023-10-29 03:34:48,264 log Internal Server Error: /p2p/
Traceback (most recent call last):
  File "/home/ubuntu/github/easygo/venv/lib/python3.10/site-packages/django/core/handlers/exception.py", line 56, in inner
    response = get_response(request)
  File "/home/ubuntu/github/easygo/venv/lib/python3.10/site-packages/django/core/handlers/base.py", line 197, in _get_response
    response = wrapped_callback(request, *callback_args, **callback_kwargs)
  File "/home/ubuntu/github/easygo/basecamp/views.py", line 1166, in p2p
    email.send()
  File "/home/ubuntu/github/easygo/venv/lib/python3.10/site-packages/django/core/mail/message.py", line 298, in send
    return self.get_connection(fail_silently).send_messages([self])
  File "/home/ubuntu/github/easygo/venv/lib/python3.10/site-packages/django/core/mail/backends/smtp.py", line 124, in send_messages
    new_conn_created = self.open()
  File "/home/ubuntu/github/easygo/venv/lib/python3.10/site-packages/django/core/mail/backends/smtp.py", line 91, in open
    self.connection.login(self.username, self.password)
  File "/usr/lib/python3.10/smtplib.py", line 739, in login
    (code, resp) = self.auth(
  File "/usr/lib/python3.10/smtplib.py", line 642, in auth
    (code, resp) = self.docmd("AUTH", mechanism + " " + response)
  File "/usr/lib/python3.10/smtplib.py", line 432, in docmd
    return self.getreply()
  File "/usr/lib/python3.10/smtplib.py", line 405, in getreply
    raise SMTPServerDisconnected("Connection unexpectedly closed")
smtplib.SMTPServerDisconnected: Connection unexpectedly closed
ERROR 2023-10-29 03:34:50,794 log Internal Server Error: /p2p/
Traceback (most recent call last):
  File "/home/ubuntu/github/easygo/venv/lib/python3.10/site-packages/django/core/handlers/exception.py", line 56, in inner
    response = get_response(request)
  File "/home/ubuntu/github/easygo/venv/lib/python3.10/site-packages/django/core/handlers/base.py", line 197, in _get_response
    response = wrapped_callback(request, *callback_args, **callback_kwargs)
  File "/home/ubuntu/github/easygo/basecamp/views.py", line 1166, in p2p
    email.send()
  File "/home/ubuntu/github/easygo/venv/lib/python3.10/site-packages/django/core/mail/message.py", line 298, in send
    return self.get_connection(fail_silently).send_messages([self])
  File "/home/ubuntu/github/easygo/venv/lib/python3.10/site-packages/django/core/mail/backends/smtp.py", line 124, in send_messages
    new_conn_created = self.open()
  File "/home/ubuntu/github/easygo/venv/lib/python3.10/site-packages/django/core/mail/backends/smtp.py", line 91, in open
    self.connection.login(self.username, self.password)
  File "/usr/lib/python3.10/smtplib.py", line 739, in login
    (code, resp) = self.auth(
  File "/usr/lib/python3.10/smtplib.py", line 642, in auth
    (code, resp) = self.docmd("AUTH", mechanism + " " + response)
  File "/usr/lib/python3.10/smtplib.py", line 432, in docmd
    return self.getreply()
  File "/usr/lib/python3.10/smtplib.py", line 405, in getreply
    raise SMTPServerDisconnected("Connection unexpectedly closed")
smtplib.SMTPServerDisconnected: Connection unexpectedly closed
ERROR 2023-10-29 03:34:53,308 log Internal Server Error: /p2p/
Traceback (most recent call last):
  File "/home/ubuntu/github/easygo/venv/lib/python3.10/site-packages/django/core/handlers/exception.py", line 56, in inner
    response = get_response(request)
  File "/home/ubuntu/github/easygo/venv/lib/python3.10/site-packages/django/core/handlers/base.py", line 197, in _get_response
    response = wrapped_callback(request, *callback_args, **callback_kwargs)
  File "/home/ubuntu/github/easygo/basecamp/views.py", line 1166, in p2p
    email.send()
  File "/home/ubuntu/github/easygo/venv/lib/python3.10/site-packages/django/core/mail/message.py", line 298, in send
    return self.get_connection(fail_silently).send_messages([self])
  File "/home/ubuntu/github/easygo/venv/lib/python3.10/site-packages/django/core/mail/backends/smtp.py", line 124, in send_messages
    new_conn_created = self.open()
  File "/home/ubuntu/github/easygo/venv/lib/python3.10/site-packages/django/core/mail/backends/smtp.py", line 91, in open
    self.connection.login(self.username, self.password)
  File "/usr/lib/python3.10/smtplib.py", line 739, in login
    (code, resp) = self.auth(
  File "/usr/lib/python3.10/smtplib.py", line 642, in auth
    (code, resp) = self.docmd("AUTH", mechanism + " " + response)
  File "/usr/lib/python3.10/smtplib.py", line 432, in docmd
    return self.getreply()
  File "/usr/lib/python3.10/smtplib.py", line 405, in getreply
    raise SMTPServerDisconnected("Connection unexpectedly closed")
smtplib.SMTPServerDisconnected: Connection unexpectedly closed
WARNING 2023-10-29 03:44:35,167 log Not Found: /robots.txt
WARNING 2023-10-29 03:57:07,746 log Not Found: /airport-transfers-dural/
WARNING 2023-10-29 03:57:16,639 log Not Found: /robots.txt
WARNING 2023-10-29 04:23:09,438 log Forbidden (Referer checking failed - no Referer.): /inquiry_details/
WARNING 2023-10-29 04:23:10,309 log Forbidden (Referer checking failed - no Referer.): /inquiry_details/
WARNING 2023-10-29 04:23:11,073 log Forbidden (Referer checking failed - no Referer.): /inquiry_details/
WARNING 2023-10-29 04:23:12,678 log Forbidden (Referer checking failed - no Referer.): /inquiry_details1/
WARNING 2023-10-29 04:23:13,345 log Forbidden (Referer checking failed - no Referer.): /inquiry_details1/
WARNING 2023-10-29 04:23:14,014 log Forbidden (Referer checking failed - no Referer.): /inquiry_details1/
WARNING 2023-10-29 04:23:32,544 log Not Found: /products/registry/
WARNING 2023-10-29 04:23:37,574 log Not Found: /technology/
WARNING 2023-10-29 04:23:38,241 log Not Found: /products/news/
WARNING 2023-10-29 04:23:38,907 log Not Found: /technology/developers/
WARNING 2023-10-29 04:23:42,512 log Forbidden (Referer checking failed - no Referer.): /inquiry_details2/
WARNING 2023-10-29 04:23:43,498 log Forbidden (Referer checking failed - no Referer.): /inquiry_details2/
WARNING 2023-10-29 04:23:44,167 log Forbidden (Referer checking failed - no Referer.): /inquiry_details2/
WARNING 2023-10-29 04:28:30,236 log Not Found: /robots.txt
WARNING 2023-10-29 04:29:16,504 log Not Found: /.env
WARNING 2023-10-29 04:29:17,919 log Forbidden (Referer checking failed - no Referer.): /
WARNING 2023-10-29 04:29:22,381 log Not Found: /vendor/phpunit/phpunit/src/Util/PHP/eval-stdin.php
WARNING 2023-10-29 04:40:03,396 log Not Found: /.git/config
WARNING 2023-10-29 04:50:24,645 log Not Found: /robots.txt
WARNING 2023-10-29 04:51:52,089 log Not Found: /robots.txt
WARNING 2023-10-29 05:00:23,574 log Not Found: /Core/Skin/Login.aspx
WARNING 2023-10-29 06:04:21,771 log Not Found: /robots.txt
WARNING 2023-10-29 06:16:43,906 log Not Found: /apple-touch-icon-precomposed.png
WARNING 2023-10-29 06:16:43,914 log Not Found: /apple-touch-icon.png
WARNING 2023-10-29 06:21:07,296 log Not Found: /shop/sv/product-category/moncler-stovlar/
WARNING 2023-10-29 06:37:20,650 log Not Found: /Core/Skin/Login.aspx
WARNING 2023-10-29 06:39:38,789 log Not Found: /shop/nn/product/moncler-auburn-10/
WARNING 2023-10-29 06:50:54,430 log Not Found: /robots.txt
WARNING 2023-10-29 07:42:25,329 log Not Found: /airport-transfers-drummoyne/
