WARNING 2024-01-28 12:15:15,005 log Not Found: /robots.txt
WARNING 2024-01-28 12:32:16,985 log Not Found: /admin.php
WARNING 2024-01-28 12:33:31,855 log Not Found: /about.php
WARNING 2024-01-28 12:43:09,174 log Not Found: /robots.txt
WARNING 2024-01-28 12:43:18,302 log Not Found: /shop/de/product/moncler-jacken-kinder-maka-moka/
WARNING 2024-01-28 12:55:31,928 log Not Found: /robots.txt
WARNING 2024-01-28 12:58:09,787 log Not Found: /robots.txt
WARNING 2024-01-28 13:01:10,791 log Not Found: /shop/de/product/kinder-moncler-jacken-junge-schwarz/
WARNING 2024-01-28 13:08:16,222 log Not Found: /.well-known/traffic-advice
WARNING 2024-01-28 13:10:22,643 log Not Found: /.env
WARNING 2024-01-28 13:10:44,884 log Not Found: /public/.env
WARNING 2024-01-28 13:11:03,503 log Not Found: /staging/.env
DEBUG 2024-01-28 13:12:08,219 base Exception while resolving variable 'subtitle' in template 'admin_honeypot/login.html'.
Traceback (most recent call last):
  File "/home/horeb/github/easygo/venv/lib/python3.11/site-packages/django/template/base.py", line 880, in _resolve_lookup
    current = current[bit]
              ~~~~~~~^^^^^
  File "/home/horeb/github/easygo/venv/lib/python3.11/site-packages/django/template/context.py", line 83, in __getitem__
    raise KeyError(key)
KeyError: 'subtitle'

During handling of the above exception, another exception occurred:

Traceback (most recent call last):
  File "/home/horeb/github/easygo/venv/lib/python3.11/site-packages/django/template/base.py", line 886, in _resolve_lookup
    if isinstance(current, BaseContext) and getattr(
                                            ^^^^^^^^
AttributeError: type object 'RequestContext' has no attribute 'subtitle'

During handling of the above exception, another exception occurred:

Traceback (most recent call last):
  File "/home/horeb/github/easygo/venv/lib/python3.11/site-packages/django/template/base.py", line 896, in _resolve_lookup
    current = current[int(bit)]
                      ^^^^^^^^
ValueError: invalid literal for int() with base 10: 'subtitle'

During handling of the above exception, another exception occurred:

Traceback (most recent call last):
  File "/home/horeb/github/easygo/venv/lib/python3.11/site-packages/django/template/base.py", line 903, in _resolve_lookup
    raise VariableDoesNotExist(
django.template.base.VariableDoesNotExist: Failed lookup for key [subtitle] in [{'True': True, 'False': False, 'None': None}, {'csrf_token': <SimpleLazyObject: <function csrf.<locals>._get_val at 0x7f33a2b3bec0>>, 'request': <WSGIRequest: GET '/admin/login/?next=/admin/.env/'>, 'user': <SimpleLazyObject: <function AuthenticationMiddleware.process_request.<locals>.<lambda> at 0x7f33a2d53a60>>, 'perms': PermWrapper(<SimpleLazyObject: <function AuthenticationMiddleware.process_request.<locals>.<lambda> at 0x7f33a2d53a60>>), 'messages': <FallbackStorage: request=<WSGIRequest: GET '/admin/login/?next=/admin/.env/'>>, 'DEFAULT_MESSAGE_LEVELS': {'DEBUG': 10, 'INFO': 20, 'SUCCESS': 25, 'WARNING': 30, 'ERROR': 40}}, {}, {'form': <HoneypotLoginForm bound=False, valid=Unknown, fields=(username;password)>, 'view': <admin_honeypot.views.AdminHoneypot object at 0x7f33a1db68d0>, 'app_path': '/admin/login/?next=/admin/.env/', 'next': '/admin/', 'title': 'Log in', 'LANGUAGE_CODE': 'en-us', 'LANGUAGE_BIDI': False}, {'block': <Block Node: title. Contents: [<IfNode>, <Variable Node: title>, <TextNode: ' | '>, <Variable Node: site_title|default:_('Django site admin')>]>}]
DEBUG 2024-01-28 13:12:08,221 base Exception while resolving variable 'site_title' in template 'admin_honeypot/login.html'.
Traceback (most recent call last):
  File "/home/horeb/github/easygo/venv/lib/python3.11/site-packages/django/template/base.py", line 880, in _resolve_lookup
    current = current[bit]
              ~~~~~~~^^^^^
  File "/home/horeb/github/easygo/venv/lib/python3.11/site-packages/django/template/context.py", line 83, in __getitem__
    raise KeyError(key)
KeyError: 'site_title'

During handling of the above exception, another exception occurred:

Traceback (most recent call last):
  File "/home/horeb/github/easygo/venv/lib/python3.11/site-packages/django/template/base.py", line 886, in _resolve_lookup
    if isinstance(current, BaseContext) and getattr(
                                            ^^^^^^^^
AttributeError: type object 'RequestContext' has no attribute 'site_title'

During handling of the above exception, another exception occurred:

Traceback (most recent call last):
  File "/home/horeb/github/easygo/venv/lib/python3.11/site-packages/django/template/base.py", line 896, in _resolve_lookup
    current = current[int(bit)]
                      ^^^^^^^^
ValueError: invalid literal for int() with base 10: 'site_title'

During handling of the above exception, another exception occurred:

Traceback (most recent call last):
  File "/home/horeb/github/easygo/venv/lib/python3.11/site-packages/django/template/base.py", line 903, in _resolve_lookup
    raise VariableDoesNotExist(
django.template.base.VariableDoesNotExist: Failed lookup for key [site_title] in [{'True': True, 'False': False, 'None': None}, {'csrf_token': <SimpleLazyObject: <function csrf.<locals>._get_val at 0x7f33a2b3bec0>>, 'request': <WSGIRequest: GET '/admin/login/?next=/admin/.env/'>, 'user': <SimpleLazyObject: <function AuthenticationMiddleware.process_request.<locals>.<lambda> at 0x7f33a2d53a60>>, 'perms': PermWrapper(<SimpleLazyObject: <function AuthenticationMiddleware.process_request.<locals>.<lambda> at 0x7f33a2d53a60>>), 'messages': <FallbackStorage: request=<WSGIRequest: GET '/admin/login/?next=/admin/.env/'>>, 'DEFAULT_MESSAGE_LEVELS': {'DEBUG': 10, 'INFO': 20, 'SUCCESS': 25, 'WARNING': 30, 'ERROR': 40}}, {}, {'form': <HoneypotLoginForm bound=False, valid=Unknown, fields=(username;password)>, 'view': <admin_honeypot.views.AdminHoneypot object at 0x7f33a1db68d0>, 'app_path': '/admin/login/?next=/admin/.env/', 'next': '/admin/', 'title': 'Log in', 'LANGUAGE_CODE': 'en-us', 'LANGUAGE_BIDI': False}, {'block': <Block Node: title. Contents: [<IfNode>, <Variable Node: title>, <TextNode: ' | '>, <Variable Node: site_title|default:_('Django site admin')>]>}]
DEBUG 2024-01-28 13:12:08,221 base Exception while resolving variable 'is_popup' in template 'admin_honeypot/login.html'.
Traceback (most recent call last):
  File "/home/horeb/github/easygo/venv/lib/python3.11/site-packages/django/template/base.py", line 880, in _resolve_lookup
    current = current[bit]
              ~~~~~~~^^^^^
  File "/home/horeb/github/easygo/venv/lib/python3.11/site-packages/django/template/context.py", line 83, in __getitem__
    raise KeyError(key)
KeyError: 'is_popup'

During handling of the above exception, another exception occurred:

Traceback (most recent call last):
  File "/home/horeb/github/easygo/venv/lib/python3.11/site-packages/django/template/base.py", line 886, in _resolve_lookup
    if isinstance(current, BaseContext) and getattr(
                                            ^^^^^^^^
AttributeError: type object 'RequestContext' has no attribute 'is_popup'

During handling of the above exception, another exception occurred:

Traceback (most recent call last):
  File "/home/horeb/github/easygo/venv/lib/python3.11/site-packages/django/template/base.py", line 896, in _resolve_lookup
    current = current[int(bit)]
                      ^^^^^^^^
ValueError: invalid literal for int() with base 10: 'is_popup'

During handling of the above exception, another exception occurred:

Traceback (most recent call last):
  File "/home/horeb/github/easygo/venv/lib/python3.11/site-packages/django/template/base.py", line 903, in _resolve_lookup
    raise VariableDoesNotExist(
django.template.base.VariableDoesNotExist: Failed lookup for key [is_popup] in [{'True': True, 'False': False, 'None': None}, {'csrf_token': <SimpleLazyObject: <function csrf.<locals>._get_val at 0x7f33a2b3bec0>>, 'request': <WSGIRequest: GET '/admin/login/?next=/admin/.env/'>, 'user': <SimpleLazyObject: <function AuthenticationMiddleware.process_request.<locals>.<lambda> at 0x7f33a2d53a60>>, 'perms': PermWrapper(<SimpleLazyObject: <function AuthenticationMiddleware.process_request.<locals>.<lambda> at 0x7f33a2d53a60>>), 'messages': <FallbackStorage: request=<WSGIRequest: GET '/admin/login/?next=/admin/.env/'>>, 'DEFAULT_MESSAGE_LEVELS': {'DEBUG': 10, 'INFO': 20, 'SUCCESS': 25, 'WARNING': 30, 'ERROR': 40}}, {}, {'form': <HoneypotLoginForm bound=False, valid=Unknown, fields=(username;password)>, 'view': <admin_honeypot.views.AdminHoneypot object at 0x7f33a1db68d0>, 'app_path': '/admin/login/?next=/admin/.env/', 'next': '/admin/', 'title': 'Log in', 'LANGUAGE_CODE': 'en-us', 'LANGUAGE_BIDI': False}]
DEBUG 2024-01-28 13:12:08,222 base Exception while resolving variable 'is_nav_sidebar_enabled' in template 'admin_honeypot/login.html'.
Traceback (most recent call last):
  File "/home/horeb/github/easygo/venv/lib/python3.11/site-packages/django/template/base.py", line 880, in _resolve_lookup
    current = current[bit]
              ~~~~~~~^^^^^
  File "/home/horeb/github/easygo/venv/lib/python3.11/site-packages/django/template/context.py", line 83, in __getitem__
    raise KeyError(key)
KeyError: 'is_nav_sidebar_enabled'

During handling of the above exception, another exception occurred:

Traceback (most recent call last):
  File "/home/horeb/github/easygo/venv/lib/python3.11/site-packages/django/template/base.py", line 886, in _resolve_lookup
    if isinstance(current, BaseContext) and getattr(
                                            ^^^^^^^^
AttributeError: type object 'RequestContext' has no attribute 'is_nav_sidebar_enabled'

During handling of the above exception, another exception occurred:

Traceback (most recent call last):
  File "/home/horeb/github/easygo/venv/lib/python3.11/site-packages/django/template/base.py", line 896, in _resolve_lookup
    current = current[int(bit)]
                      ^^^^^^^^
ValueError: invalid literal for int() with base 10: 'is_nav_sidebar_enabled'

During handling of the above exception, another exception occurred:

Traceback (most recent call last):
  File "/home/horeb/github/easygo/venv/lib/python3.11/site-packages/django/template/base.py", line 903, in _resolve_lookup
    raise VariableDoesNotExist(
django.template.base.VariableDoesNotExist: Failed lookup for key [is_nav_sidebar_enabled] in [{'True': True, 'False': False, 'None': None}, {'csrf_token': <SimpleLazyObject: <function csrf.<locals>._get_val at 0x7f33a2b3bec0>>, 'request': <WSGIRequest: GET '/admin/login/?next=/admin/.env/'>, 'user': <SimpleLazyObject: <function AuthenticationMiddleware.process_request.<locals>.<lambda> at 0x7f33a2d53a60>>, 'perms': PermWrapper(<SimpleLazyObject: <function AuthenticationMiddleware.process_request.<locals>.<lambda> at 0x7f33a2d53a60>>), 'messages': <FallbackStorage: request=<WSGIRequest: GET '/admin/login/?next=/admin/.env/'>>, 'DEFAULT_MESSAGE_LEVELS': {'DEBUG': 10, 'INFO': 20, 'SUCCESS': 25, 'WARNING': 30, 'ERROR': 40}}, {}, {'form': <HoneypotLoginForm bound=False, valid=Unknown, fields=(username;password)>, 'view': <admin_honeypot.views.AdminHoneypot object at 0x7f33a1db68d0>, 'app_path': '/admin/login/?next=/admin/.env/', 'next': '/admin/', 'title': 'Log in', 'LANGUAGE_CODE': 'en-us', 'LANGUAGE_BIDI': False}]
DEBUG 2024-01-28 13:12:08,222 base Exception while resolving variable 'is_popup' in template 'admin_honeypot/login.html'.
Traceback (most recent call last):
  File "/home/horeb/github/easygo/venv/lib/python3.11/site-packages/django/template/base.py", line 880, in _resolve_lookup
    current = current[bit]
              ~~~~~~~^^^^^
  File "/home/horeb/github/easygo/venv/lib/python3.11/site-packages/django/template/context.py", line 83, in __getitem__
    raise KeyError(key)
KeyError: 'is_popup'

During handling of the above exception, another exception occurred:

Traceback (most recent call last):
  File "/home/horeb/github/easygo/venv/lib/python3.11/site-packages/django/template/base.py", line 886, in _resolve_lookup
    if isinstance(current, BaseContext) and getattr(
                                            ^^^^^^^^
AttributeError: type object 'RequestContext' has no attribute 'is_popup'

During handling of the above exception, another exception occurred:

Traceback (most recent call last):
  File "/home/horeb/github/easygo/venv/lib/python3.11/site-packages/django/template/base.py", line 896, in _resolve_lookup
    current = current[int(bit)]
                      ^^^^^^^^
ValueError: invalid literal for int() with base 10: 'is_popup'

During handling of the above exception, another exception occurred:

Traceback (most recent call last):
  File "/home/horeb/github/easygo/venv/lib/python3.11/site-packages/django/template/base.py", line 903, in _resolve_lookup
    raise VariableDoesNotExist(
django.template.base.VariableDoesNotExist: Failed lookup for key [is_popup] in [{'True': True, 'False': False, 'None': None}, {'csrf_token': <SimpleLazyObject: <function csrf.<locals>._get_val at 0x7f33a2b3bec0>>, 'request': <WSGIRequest: GET '/admin/login/?next=/admin/.env/'>, 'user': <SimpleLazyObject: <function AuthenticationMiddleware.process_request.<locals>.<lambda> at 0x7f33a2d53a60>>, 'perms': PermWrapper(<SimpleLazyObject: <function AuthenticationMiddleware.process_request.<locals>.<lambda> at 0x7f33a2d53a60>>), 'messages': <FallbackStorage: request=<WSGIRequest: GET '/admin/login/?next=/admin/.env/'>>, 'DEFAULT_MESSAGE_LEVELS': {'DEBUG': 10, 'INFO': 20, 'SUCCESS': 25, 'WARNING': 30, 'ERROR': 40}}, {}, {'form': <HoneypotLoginForm bound=False, valid=Unknown, fields=(username;password)>, 'view': <admin_honeypot.views.AdminHoneypot object at 0x7f33a1db68d0>, 'app_path': '/admin/login/?next=/admin/.env/', 'next': '/admin/', 'title': 'Log in', 'LANGUAGE_CODE': 'en-us', 'LANGUAGE_BIDI': False}]
DEBUG 2024-01-28 13:12:08,223 base Exception while resolving variable 'is_popup' in template 'admin_honeypot/login.html'.
Traceback (most recent call last):
  File "/home/horeb/github/easygo/venv/lib/python3.11/site-packages/django/template/base.py", line 880, in _resolve_lookup
    current = current[bit]
              ~~~~~~~^^^^^
  File "/home/horeb/github/easygo/venv/lib/python3.11/site-packages/django/template/context.py", line 83, in __getitem__
    raise KeyError(key)
KeyError: 'is_popup'

During handling of the above exception, another exception occurred:

Traceback (most recent call last):
  File "/home/horeb/github/easygo/venv/lib/python3.11/site-packages/django/template/base.py", line 886, in _resolve_lookup
    if isinstance(current, BaseContext) and getattr(
                                            ^^^^^^^^
AttributeError: type object 'RequestContext' has no attribute 'is_popup'

During handling of the above exception, another exception occurred:

Traceback (most recent call last):
  File "/home/horeb/github/easygo/venv/lib/python3.11/site-packages/django/template/base.py", line 896, in _resolve_lookup
    current = current[int(bit)]
                      ^^^^^^^^
ValueError: invalid literal for int() with base 10: 'is_popup'

During handling of the above exception, another exception occurred:

Traceback (most recent call last):
  File "/home/horeb/github/easygo/venv/lib/python3.11/site-packages/django/template/base.py", line 903, in _resolve_lookup
    raise VariableDoesNotExist(
django.template.base.VariableDoesNotExist: Failed lookup for key [is_popup] in [{'True': True, 'False': False, 'None': None}, {'csrf_token': <SimpleLazyObject: <function csrf.<locals>._get_val at 0x7f33a2b3bec0>>, 'request': <WSGIRequest: GET '/admin/login/?next=/admin/.env/'>, 'user': <SimpleLazyObject: <function AuthenticationMiddleware.process_request.<locals>.<lambda> at 0x7f33a2d53a60>>, 'perms': PermWrapper(<SimpleLazyObject: <function AuthenticationMiddleware.process_request.<locals>.<lambda> at 0x7f33a2d53a60>>), 'messages': <FallbackStorage: request=<WSGIRequest: GET '/admin/login/?next=/admin/.env/'>>, 'DEFAULT_MESSAGE_LEVELS': {'DEBUG': 10, 'INFO': 20, 'SUCCESS': 25, 'WARNING': 30, 'ERROR': 40}}, {}, {'form': <HoneypotLoginForm bound=False, valid=Unknown, fields=(username;password)>, 'view': <admin_honeypot.views.AdminHoneypot object at 0x7f33a1db68d0>, 'app_path': '/admin/login/?next=/admin/.env/', 'next': '/admin/', 'title': 'Log in', 'LANGUAGE_CODE': 'en-us', 'LANGUAGE_BIDI': False}]
DEBUG 2024-01-28 13:12:08,223 base Exception while resolving variable 'site_header' in template 'admin_honeypot/login.html'.
Traceback (most recent call last):
  File "/home/horeb/github/easygo/venv/lib/python3.11/site-packages/django/template/base.py", line 880, in _resolve_lookup
    current = current[bit]
              ~~~~~~~^^^^^
  File "/home/horeb/github/easygo/venv/lib/python3.11/site-packages/django/template/context.py", line 83, in __getitem__
    raise KeyError(key)
KeyError: 'site_header'

During handling of the above exception, another exception occurred:

Traceback (most recent call last):
  File "/home/horeb/github/easygo/venv/lib/python3.11/site-packages/django/template/base.py", line 886, in _resolve_lookup
    if isinstance(current, BaseContext) and getattr(
                                            ^^^^^^^^
AttributeError: type object 'RequestContext' has no attribute 'site_header'

During handling of the above exception, another exception occurred:

Traceback (most recent call last):
  File "/home/horeb/github/easygo/venv/lib/python3.11/site-packages/django/template/base.py", line 896, in _resolve_lookup
    current = current[int(bit)]
                      ^^^^^^^^
ValueError: invalid literal for int() with base 10: 'site_header'

During handling of the above exception, another exception occurred:

Traceback (most recent call last):
  File "/home/horeb/github/easygo/venv/lib/python3.11/site-packages/django/template/base.py", line 903, in _resolve_lookup
    raise VariableDoesNotExist(
django.template.base.VariableDoesNotExist: Failed lookup for key [site_header] in [{'True': True, 'False': False, 'None': None}, {'csrf_token': <SimpleLazyObject: <function csrf.<locals>._get_val at 0x7f33a2b3bec0>>, 'request': <WSGIRequest: GET '/admin/login/?next=/admin/.env/'>, 'user': <SimpleLazyObject: <function AuthenticationMiddleware.process_request.<locals>.<lambda> at 0x7f33a2d53a60>>, 'perms': PermWrapper(<SimpleLazyObject: <function AuthenticationMiddleware.process_request.<locals>.<lambda> at 0x7f33a2d53a60>>), 'messages': <FallbackStorage: request=<WSGIRequest: GET '/admin/login/?next=/admin/.env/'>>, 'DEFAULT_MESSAGE_LEVELS': {'DEBUG': 10, 'INFO': 20, 'SUCCESS': 25, 'WARNING': 30, 'ERROR': 40}}, {}, {'form': <HoneypotLoginForm bound=False, valid=Unknown, fields=(username;password)>, 'view': <admin_honeypot.views.AdminHoneypot object at 0x7f33a1db68d0>, 'app_path': '/admin/login/?next=/admin/.env/', 'next': '/admin/', 'title': 'Log in', 'LANGUAGE_CODE': 'en-us', 'LANGUAGE_BIDI': False}, {'block': <Block Node: header. Contents: [<TextNode: '\n    <div id="header">\n  '>, <Block Node: branding. Contents: []>, <TextNode: '\n        </div>\n        '>, <Block Node: usertools. Contents: [<TextNode: '\n        '>, <IfNode>, <TextNode: '\n        '>]>, <TextNode: '\n        '>, <Block Node: nav-global. Contents: []>, <TextNode: '\n    </div>\n    '>]>}, {'block': <Block Node: branding. Contents: [<TextNode: '\n<h1 id="site-name"><a hr'>, <URLNode view_name=''admin_honeypot:index'' args=[] kwargs={} as=None>, <TextNode: '">'>, <Variable Node: site_header|default:_('Django administration')>, <TextNode: '</a></h1>\n'>]>}]
DEBUG 2024-01-28 13:12:08,224 base Exception while resolving variable 'is_popup' in template 'admin_honeypot/login.html'.
Traceback (most recent call last):
  File "/home/horeb/github/easygo/venv/lib/python3.11/site-packages/django/template/base.py", line 880, in _resolve_lookup
    current = current[bit]
              ~~~~~~~^^^^^
  File "/home/horeb/github/easygo/venv/lib/python3.11/site-packages/django/template/context.py", line 83, in __getitem__
    raise KeyError(key)
KeyError: 'is_popup'

During handling of the above exception, another exception occurred:

Traceback (most recent call last):
  File "/home/horeb/github/easygo/venv/lib/python3.11/site-packages/django/template/base.py", line 886, in _resolve_lookup
    if isinstance(current, BaseContext) and getattr(
                                            ^^^^^^^^
AttributeError: type object 'RequestContext' has no attribute 'is_popup'

During handling of the above exception, another exception occurred:

Traceback (most recent call last):
  File "/home/horeb/github/easygo/venv/lib/python3.11/site-packages/django/template/base.py", line 896, in _resolve_lookup
    current = current[int(bit)]
                      ^^^^^^^^
ValueError: invalid literal for int() with base 10: 'is_popup'

During handling of the above exception, another exception occurred:

Traceback (most recent call last):
  File "/home/horeb/github/easygo/venv/lib/python3.11/site-packages/django/template/base.py", line 903, in _resolve_lookup
    raise VariableDoesNotExist(
django.template.base.VariableDoesNotExist: Failed lookup for key [is_popup] in [{'True': True, 'False': False, 'None': None}, {'csrf_token': <SimpleLazyObject: <function csrf.<locals>._get_val at 0x7f33a2b3bec0>>, 'request': <WSGIRequest: GET '/admin/login/?next=/admin/.env/'>, 'user': <SimpleLazyObject: <function AuthenticationMiddleware.process_request.<locals>.<lambda> at 0x7f33a2d53a60>>, 'perms': PermWrapper(<SimpleLazyObject: <function AuthenticationMiddleware.process_request.<locals>.<lambda> at 0x7f33a2d53a60>>), 'messages': <FallbackStorage: request=<WSGIRequest: GET '/admin/login/?next=/admin/.env/'>>, 'DEFAULT_MESSAGE_LEVELS': {'DEBUG': 10, 'INFO': 20, 'SUCCESS': 25, 'WARNING': 30, 'ERROR': 40}}, {}, {'form': <HoneypotLoginForm bound=False, valid=Unknown, fields=(username;password)>, 'view': <admin_honeypot.views.AdminHoneypot object at 0x7f33a1db68d0>, 'app_path': '/admin/login/?next=/admin/.env/', 'next': '/admin/', 'title': 'Log in', 'LANGUAGE_CODE': 'en-us', 'LANGUAGE_BIDI': False}]
DEBUG 2024-01-28 13:12:08,224 base Exception while resolving variable 'is_nav_sidebar_enabled' in template 'admin_honeypot/login.html'.
Traceback (most recent call last):
  File "/home/horeb/github/easygo/venv/lib/python3.11/site-packages/django/template/base.py", line 880, in _resolve_lookup
    current = current[bit]
              ~~~~~~~^^^^^
  File "/home/horeb/github/easygo/venv/lib/python3.11/site-packages/django/template/context.py", line 83, in __getitem__
    raise KeyError(key)
KeyError: 'is_nav_sidebar_enabled'

During handling of the above exception, another exception occurred:

Traceback (most recent call last):
  File "/home/horeb/github/easygo/venv/lib/python3.11/site-packages/django/template/base.py", line 886, in _resolve_lookup
    if isinstance(current, BaseContext) and getattr(
                                            ^^^^^^^^
AttributeError: type object 'RequestContext' has no attribute 'is_nav_sidebar_enabled'

During handling of the above exception, another exception occurred:

Traceback (most recent call last):
  File "/home/horeb/github/easygo/venv/lib/python3.11/site-packages/django/template/base.py", line 896, in _resolve_lookup
    current = current[int(bit)]
                      ^^^^^^^^
ValueError: invalid literal for int() with base 10: 'is_nav_sidebar_enabled'

During handling of the above exception, another exception occurred:

Traceback (most recent call last):
  File "/home/horeb/github/easygo/venv/lib/python3.11/site-packages/django/template/base.py", line 903, in _resolve_lookup
    raise VariableDoesNotExist(
django.template.base.VariableDoesNotExist: Failed lookup for key [is_nav_sidebar_enabled] in [{'True': True, 'False': False, 'None': None}, {'csrf_token': <SimpleLazyObject: <function csrf.<locals>._get_val at 0x7f33a2b3bec0>>, 'request': <WSGIRequest: GET '/admin/login/?next=/admin/.env/'>, 'user': <SimpleLazyObject: <function AuthenticationMiddleware.process_request.<locals>.<lambda> at 0x7f33a2d53a60>>, 'perms': PermWrapper(<SimpleLazyObject: <function AuthenticationMiddleware.process_request.<locals>.<lambda> at 0x7f33a2d53a60>>), 'messages': <FallbackStorage: request=<WSGIRequest: GET '/admin/login/?next=/admin/.env/'>>, 'DEFAULT_MESSAGE_LEVELS': {'DEBUG': 10, 'INFO': 20, 'SUCCESS': 25, 'WARNING': 30, 'ERROR': 40}}, {}, {'form': <HoneypotLoginForm bound=False, valid=Unknown, fields=(username;password)>, 'view': <admin_honeypot.views.AdminHoneypot object at 0x7f33a1db68d0>, 'app_path': '/admin/login/?next=/admin/.env/', 'next': '/admin/', 'title': 'Log in', 'LANGUAGE_CODE': 'en-us', 'LANGUAGE_BIDI': False}]
DEBUG 2024-01-28 13:12:08,225 base Exception while resolving variable 'subtitle' in template 'admin_honeypot/login.html'.
Traceback (most recent call last):
  File "/home/horeb/github/easygo/venv/lib/python3.11/site-packages/django/template/base.py", line 880, in _resolve_lookup
    current = current[bit]
              ~~~~~~~^^^^^
  File "/home/horeb/github/easygo/venv/lib/python3.11/site-packages/django/template/context.py", line 83, in __getitem__
    raise KeyError(key)
KeyError: 'subtitle'

During handling of the above exception, another exception occurred:

Traceback (most recent call last):
  File "/home/horeb/github/easygo/venv/lib/python3.11/site-packages/django/template/base.py", line 886, in _resolve_lookup
    if isinstance(current, BaseContext) and getattr(
                                            ^^^^^^^^
AttributeError: type object 'RequestContext' has no attribute 'subtitle'

During handling of the above exception, another exception occurred:

Traceback (most recent call last):
  File "/home/horeb/github/easygo/venv/lib/python3.11/site-packages/django/template/base.py", line 896, in _resolve_lookup
    current = current[int(bit)]
                      ^^^^^^^^
ValueError: invalid literal for int() with base 10: 'subtitle'

During handling of the above exception, another exception occurred:

Traceback (most recent call last):
  File "/home/horeb/github/easygo/venv/lib/python3.11/site-packages/django/template/base.py", line 903, in _resolve_lookup
    raise VariableDoesNotExist(
django.template.base.VariableDoesNotExist: Failed lookup for key [subtitle] in [{'True': True, 'False': False, 'None': None}, {'csrf_token': <SimpleLazyObject: <function csrf.<locals>._get_val at 0x7f33a2b3bec0>>, 'request': <WSGIRequest: GET '/admin/login/?next=/admin/.env/'>, 'user': <SimpleLazyObject: <function AuthenticationMiddleware.process_request.<locals>.<lambda> at 0x7f33a2d53a60>>, 'perms': PermWrapper(<SimpleLazyObject: <function AuthenticationMiddleware.process_request.<locals>.<lambda> at 0x7f33a2d53a60>>), 'messages': <FallbackStorage: request=<WSGIRequest: GET '/admin/login/?next=/admin/.env/'>>, 'DEFAULT_MESSAGE_LEVELS': {'DEBUG': 10, 'INFO': 20, 'SUCCESS': 25, 'WARNING': 30, 'ERROR': 40}}, {}, {'form': <HoneypotLoginForm bound=False, valid=Unknown, fields=(username;password)>, 'view': <admin_honeypot.views.AdminHoneypot object at 0x7f33a1db68d0>, 'app_path': '/admin/login/?next=/admin/.env/', 'next': '/admin/', 'title': 'Log in', 'LANGUAGE_CODE': 'en-us', 'LANGUAGE_BIDI': False}, {'block': <Block Node: content_subtitle. Contents: [<IfNode>]>}]
WARNING 2024-01-28 13:12:26,179 log Not Found: /.env.example
WARNING 2024-01-28 13:17:14,414 log Not Found: /robots.txt
DEBUG 2024-01-28 14:06:47,208 base Exception while resolving variable 'recaptcha_site_key' in template 'basecamp/inquiry1.html'.
Traceback (most recent call last):
  File "/home/horeb/github/easygo/venv/lib/python3.11/site-packages/django/template/base.py", line 880, in _resolve_lookup
    current = current[bit]
              ~~~~~~~^^^^^
  File "/home/horeb/github/easygo/venv/lib/python3.11/site-packages/django/template/context.py", line 83, in __getitem__
    raise KeyError(key)
KeyError: 'recaptcha_site_key'

During handling of the above exception, another exception occurred:

Traceback (most recent call last):
  File "/home/horeb/github/easygo/venv/lib/python3.11/site-packages/django/template/base.py", line 886, in _resolve_lookup
    if isinstance(current, BaseContext) and getattr(
                                            ^^^^^^^^
AttributeError: type object 'RequestContext' has no attribute 'recaptcha_site_key'

During handling of the above exception, another exception occurred:

Traceback (most recent call last):
  File "/home/horeb/github/easygo/venv/lib/python3.11/site-packages/django/template/base.py", line 896, in _resolve_lookup
    current = current[int(bit)]
                      ^^^^^^^^
ValueError: invalid literal for int() with base 10: 'recaptcha_site_key'

During handling of the above exception, another exception occurred:

Traceback (most recent call last):
  File "/home/horeb/github/easygo/venv/lib/python3.11/site-packages/django/template/base.py", line 903, in _resolve_lookup
    raise VariableDoesNotExist(
django.template.base.VariableDoesNotExist: Failed lookup for key [recaptcha_site_key] in [{'True': True, 'False': False, 'None': None}, {'csrf_token': <SimpleLazyObject: 'ttaxokOJCkaLXQ05Mt9Bm4cpfGzsAYK4ivQZF3T4bPol9bK9OKwEVZNnj0mOG26f'>, 'request': <WSGIRequest: POST '/price_detail/'>, 'user': <SimpleLazyObject: <function AuthenticationMiddleware.process_request.<locals>.<lambda> at 0x7f33a2e9aa20>>, 'perms': PermWrapper(<SimpleLazyObject: <function AuthenticationMiddleware.process_request.<locals>.<lambda> at 0x7f33a2e9aa20>>), 'messages': <FallbackStorage: request=<WSGIRequest: POST '/price_detail/'>>, 'DEFAULT_MESSAGE_LEVELS': {'DEBUG': 10, 'INFO': 20, 'SUCCESS': 25, 'WARNING': 30, 'ERROR': 40}}, {}, {'flight_date': '2024-01-29', 'direction': 'Drop off to Domestic Airport', 'suburb': 'Potts Point', 'no_of_passenger': '2'}, {'block': <Block Node: content. Contents: [<TextNode: '\n      <!-- Page content-'>, <Variable Node: flight_date>, <TextNode: '</a><br>\n\t\t\t  <a style="f'>, <Variable Node: direction>, <TextNode: '</a><br>\n\t\t\t  <a style="f'>, <Variable Node: suburb>, <TextNode: '</a><br>\n\t\t\t  <a style="f'>, <Variable Node: no_of_passenger>, <TextNode: '</a> -->\n\t\t\t  <br><br>\n  '>, <django.template.defaulttags.CsrfTokenNode object at 0x7f33a1da1e90>, <TextNode: '\n\t\t\t\t<div class="mb3 pb-1'>, <Variable Node: direction>, <TextNode: '">'>, <Variable Node: direction>, <TextNode: '</option>\t\t\t\t\t\t          '>, <Variable Node: flight_date>, <TextNode: '" type="text" >\t\t\t\t  \n   '>, <IfNode>, <TextNode: '\n\t\t\t\t  <div class="mb-3 p'>, <Variable Node: suburb>, <TextNode: '</label>\t\t\t\t\t\n\t\t\t\t</div>\n'>, <Variable Node: suburb>, <TextNode: '">'>, <Variable Node: suburb>, <TextNode: '</option>\t\t\t\t\t\n\t\t\t\t  </se'>, <Variable Node: no_of_passenger>, <TextNode: '">'>, <Variable Node: no_of_passenger>, <TextNode: '</option>\t\t\t\t  \n         '>, <Variable Node: recaptcha_site_key>, <TextNode: '"></div>\n\t\t\t\t<div id="err'>]>}]
WARNING 2024-01-28 14:18:14,579 log Not Found: /robots.txt
WARNING 2024-01-28 14:24:43,824 log Not Found: /.well-known/traffic-advice
ERROR 2024-01-28 14:26:25,027 log Internal Server Error: /p2p_single_detail/
Traceback (most recent call last):
  File "/home/horeb/github/easygo/venv/lib/python3.11/site-packages/django/core/handlers/exception.py", line 55, in inner
    response = get_response(request)
               ^^^^^^^^^^^^^^^^^^^^^
  File "/home/horeb/github/easygo/venv/lib/python3.11/site-packages/django/core/handlers/base.py", line 197, in _get_response
    response = wrapped_callback(request, *callback_args, **callback_kwargs)
               ^^^^^^^^^^^^^^^^^^^^^^^^^^^^^^^^^^^^^^^^^^^^^^^^^^^^^^^^^^^^
  File "/home/horeb/github/easygo/basecamp/views.py", line 753, in p2p_single_detail
    ''' .format(data['name'], data['email'], data['pickup_time'], data['flight_number'], data['return_pickup_time'])
                                                                                         ~~~~^^^^^^^^^^^^^^^^^^^^^^
KeyError: 'return_pickup_time'
WARNING 2024-01-28 14:54:51,573 log Not Found: /robots.txt
WARNING 2024-01-28 14:57:02,570 log Not Found: /robots.txt
WARNING 2024-01-28 15:35:18,014 log Not Found: /.well-known/acme-challenge/DLP21AYQ2F1CI0N97C_HGRSJ5_W_J2QY
WARNING 2024-01-28 15:35:18,988 log Not Found: /.well-known/acme-challenge/JHTFECU_SBTX33-DFOBURLOO_N4JJNLL
WARNING 2024-01-28 15:40:12,463 log Not Found: /.well-known/traffic-advice
WARNING 2024-01-28 15:43:14,592 log Not Found: /robots.txt
WARNING 2024-01-28 15:46:01,368 log Not Found: /robots.txt
WARNING 2024-01-28 15:46:18,239 log Not Found: /.git/config
DEBUG 2024-01-28 17:04:25,010 base Exception while resolving variable 'recaptcha_site_key' in template 'basecamp/inquiry1.html'.
Traceback (most recent call last):
  File "/home/horeb/github/easygo/venv/lib/python3.11/site-packages/django/template/base.py", line 880, in _resolve_lookup
    current = current[bit]
              ~~~~~~~^^^^^
  File "/home/horeb/github/easygo/venv/lib/python3.11/site-packages/django/template/context.py", line 83, in __getitem__
    raise KeyError(key)
KeyError: 'recaptcha_site_key'

During handling of the above exception, another exception occurred:

Traceback (most recent call last):
  File "/home/horeb/github/easygo/venv/lib/python3.11/site-packages/django/template/base.py", line 886, in _resolve_lookup
    if isinstance(current, BaseContext) and getattr(
                                            ^^^^^^^^
AttributeError: type object 'RequestContext' has no attribute 'recaptcha_site_key'

During handling of the above exception, another exception occurred:

Traceback (most recent call last):
  File "/home/horeb/github/easygo/venv/lib/python3.11/site-packages/django/template/base.py", line 896, in _resolve_lookup
    current = current[int(bit)]
                      ^^^^^^^^
ValueError: invalid literal for int() with base 10: 'recaptcha_site_key'

During handling of the above exception, another exception occurred:

Traceback (most recent call last):
  File "/home/horeb/github/easygo/venv/lib/python3.11/site-packages/django/template/base.py", line 903, in _resolve_lookup
    raise VariableDoesNotExist(
django.template.base.VariableDoesNotExist: Failed lookup for key [recaptcha_site_key] in [{'True': True, 'False': False, 'None': None}, {'csrf_token': <SimpleLazyObject: 'xkDLIOj4zqThC5EnXPZGuEFaUR1b5e0OagPUNabiJ5musI9nhhtC96qxIVUgTGBr'>, 'request': <WSGIRequest: POST '/price_detail/'>, 'user': <SimpleLazyObject: <function AuthenticationMiddleware.process_request.<locals>.<lambda> at 0x7f33a27865c0>>, 'perms': PermWrapper(<SimpleLazyObject: <function AuthenticationMiddleware.process_request.<locals>.<lambda> at 0x7f33a27865c0>>), 'messages': <FallbackStorage: request=<WSGIRequest: POST '/price_detail/'>>, 'DEFAULT_MESSAGE_LEVELS': {'DEBUG': 10, 'INFO': 20, 'SUCCESS': 25, 'WARNING': 30, 'ERROR': 40}}, {}, {'flight_date': '2024-01-29', 'direction': 'Drop off to Domestic Airport', 'suburb': 'Hotels in CBD', 'no_of_passenger': '4'}, {'block': <Block Node: content. Contents: [<TextNode: '\n      <!-- Page content-'>, <Variable Node: flight_date>, <TextNode: '</a><br>\n\t\t\t  <a style="f'>, <Variable Node: direction>, <TextNode: '</a><br>\n\t\t\t  <a style="f'>, <Variable Node: suburb>, <TextNode: '</a><br>\n\t\t\t  <a style="f'>, <Variable Node: no_of_passenger>, <TextNode: '</a> -->\n\t\t\t  <br><br>\n  '>, <django.template.defaulttags.CsrfTokenNode object at 0x7f33a21d2450>, <TextNode: '\n\t\t\t\t<div class="mb3 pb-1'>, <Variable Node: direction>, <TextNode: '">'>, <Variable Node: direction>, <TextNode: '</option>\t\t\t\t\t\t          '>, <Variable Node: flight_date>, <TextNode: '" type="text" >\t\t\t\t  \n   '>, <IfNode>, <TextNode: '\n\t\t\t\t  <div class="mb-3 p'>, <Variable Node: suburb>, <TextNode: '</label>\t\t\t\t\t\n\t\t\t\t</div>\n'>, <Variable Node: suburb>, <TextNode: '">'>, <Variable Node: suburb>, <TextNode: '</option>\t\t\t\t\t\n\t\t\t\t  </se'>, <Variable Node: no_of_passenger>, <TextNode: '">'>, <Variable Node: no_of_passenger>, <TextNode: '</option>\t\t\t\t  \n         '>, <Variable Node: recaptcha_site_key>, <TextNode: '"></div>\n\t\t\t\t<div id="err'>]>}]
WARNING 2024-01-28 17:27:47,508 log Not Found: /options-reading.php
WARNING 2024-01-28 17:27:51,537 log Not Found: /options-permalink.php
WARNING 2024-01-28 17:45:20,193 log Not Found: /shop/fr/product/moncler-style-euro-americain-manteaux-bas-femmes-cafe/
WARNING 2024-01-28 17:55:04,065 log Not Found: /.well-known/traffic-advice
