ERROR 2023-10-29 03:30:03,386 log Internal Server Error: /p2p/
Traceback (most recent call last):
  File "/home/ubuntu/github/easygo/venv/lib/python3.10/site-packages/django/core/handlers/exception.py", line 56, in inner
    response = get_response(request)
  File "/home/ubuntu/github/easygo/venv/lib/python3.10/site-packages/django/core/handlers/base.py", line 197, in _get_response
    response = wrapped_callback(request, *callback_args, **callback_kwargs)
  File "/home/ubuntu/github/easygo/basecamp/views.py", line 1166, in p2p
    email.send()
  File "/home/ubuntu/github/easygo/venv/lib/python3.10/site-packages/django/core/mail/message.py", line 298, in send
    return self.get_connection(fail_silently).send_messages([self])
  File "/home/ubuntu/github/easygo/venv/lib/python3.10/site-packages/django/core/mail/backends/smtp.py", line 124, in send_messages
    new_conn_created = self.open()
  File "/home/ubuntu/github/easygo/venv/lib/python3.10/site-packages/django/core/mail/backends/smtp.py", line 91, in open
    self.connection.login(self.username, self.password)
  File "/usr/lib/python3.10/smtplib.py", line 739, in login
    (code, resp) = self.auth(
  File "/usr/lib/python3.10/smtplib.py", line 642, in auth
    (code, resp) = self.docmd("AUTH", mechanism + " " + response)
  File "/usr/lib/python3.10/smtplib.py", line 432, in docmd
    return self.getreply()
  File "/usr/lib/python3.10/smtplib.py", line 405, in getreply
    raise SMTPServerDisconnected("Connection unexpectedly closed")
smtplib.SMTPServerDisconnected: Connection unexpectedly closed
ERROR 2023-10-29 03:30:05,232 log Internal Server Error: /p2p/
Traceback (most recent call last):
  File "/home/ubuntu/github/easygo/venv/lib/python3.10/site-packages/django/core/handlers/exception.py", line 56, in inner
    response = get_response(request)
  File "/home/ubuntu/github/easygo/venv/lib/python3.10/site-packages/django/core/handlers/base.py", line 197, in _get_response
    response = wrapped_callback(request, *callback_args, **callback_kwargs)
  File "/home/ubuntu/github/easygo/basecamp/views.py", line 1166, in p2p
    email.send()
  File "/home/ubuntu/github/easygo/venv/lib/python3.10/site-packages/django/core/mail/message.py", line 298, in send
    return self.get_connection(fail_silently).send_messages([self])
  File "/home/ubuntu/github/easygo/venv/lib/python3.10/site-packages/django/core/mail/backends/smtp.py", line 124, in send_messages
    new_conn_created = self.open()
  File "/home/ubuntu/github/easygo/venv/lib/python3.10/site-packages/django/core/mail/backends/smtp.py", line 91, in open
    self.connection.login(self.username, self.password)
  File "/usr/lib/python3.10/smtplib.py", line 739, in login
    (code, resp) = self.auth(
  File "/usr/lib/python3.10/smtplib.py", line 642, in auth
    (code, resp) = self.docmd("AUTH", mechanism + " " + response)
  File "/usr/lib/python3.10/smtplib.py", line 432, in docmd
    return self.getreply()
  File "/usr/lib/python3.10/smtplib.py", line 405, in getreply
    raise SMTPServerDisconnected("Connection unexpectedly closed")
smtplib.SMTPServerDisconnected: Connection unexpectedly closed
ERROR 2023-10-29 03:30:07,130 log Internal Server Error: /p2p/
Traceback (most recent call last):
  File "/home/ubuntu/github/easygo/venv/lib/python3.10/site-packages/django/core/handlers/exception.py", line 56, in inner
    response = get_response(request)
  File "/home/ubuntu/github/easygo/venv/lib/python3.10/site-packages/django/core/handlers/base.py", line 197, in _get_response
    response = wrapped_callback(request, *callback_args, **callback_kwargs)
  File "/home/ubuntu/github/easygo/basecamp/views.py", line 1166, in p2p
    email.send()
  File "/home/ubuntu/github/easygo/venv/lib/python3.10/site-packages/django/core/mail/message.py", line 298, in send
    return self.get_connection(fail_silently).send_messages([self])
  File "/home/ubuntu/github/easygo/venv/lib/python3.10/site-packages/django/core/mail/backends/smtp.py", line 124, in send_messages
    new_conn_created = self.open()
  File "/home/ubuntu/github/easygo/venv/lib/python3.10/site-packages/django/core/mail/backends/smtp.py", line 91, in open
    self.connection.login(self.username, self.password)
  File "/usr/lib/python3.10/smtplib.py", line 739, in login
    (code, resp) = self.auth(
  File "/usr/lib/python3.10/smtplib.py", line 642, in auth
    (code, resp) = self.docmd("AUTH", mechanism + " " + response)
  File "/usr/lib/python3.10/smtplib.py", line 432, in docmd
    return self.getreply()
  File "/usr/lib/python3.10/smtplib.py", line 405, in getreply
    raise SMTPServerDisconnected("Connection unexpectedly closed")
smtplib.SMTPServerDisconnected: Connection unexpectedly closed
ERROR 2023-10-29 03:30:09,652 log Internal Server Error: /p2p/
Traceback (most recent call last):
  File "/home/ubuntu/github/easygo/venv/lib/python3.10/site-packages/django/core/handlers/exception.py", line 56, in inner
    response = get_response(request)
  File "/home/ubuntu/github/easygo/venv/lib/python3.10/site-packages/django/core/handlers/base.py", line 197, in _get_response
    response = wrapped_callback(request, *callback_args, **callback_kwargs)
  File "/home/ubuntu/github/easygo/basecamp/views.py", line 1166, in p2p
    email.send()
  File "/home/ubuntu/github/easygo/venv/lib/python3.10/site-packages/django/core/mail/message.py", line 298, in send
    return self.get_connection(fail_silently).send_messages([self])
  File "/home/ubuntu/github/easygo/venv/lib/python3.10/site-packages/django/core/mail/backends/smtp.py", line 124, in send_messages
    new_conn_created = self.open()
  File "/home/ubuntu/github/easygo/venv/lib/python3.10/site-packages/django/core/mail/backends/smtp.py", line 91, in open
    self.connection.login(self.username, self.password)
  File "/usr/lib/python3.10/smtplib.py", line 739, in login
    (code, resp) = self.auth(
  File "/usr/lib/python3.10/smtplib.py", line 642, in auth
    (code, resp) = self.docmd("AUTH", mechanism + " " + response)
  File "/usr/lib/python3.10/smtplib.py", line 432, in docmd
    return self.getreply()
  File "/usr/lib/python3.10/smtplib.py", line 405, in getreply
    raise SMTPServerDisconnected("Connection unexpectedly closed")
smtplib.SMTPServerDisconnected: Connection unexpectedly closed
ERROR 2023-10-29 03:30:12,173 log Internal Server Error: /p2p/
Traceback (most recent call last):
  File "/home/ubuntu/github/easygo/venv/lib/python3.10/site-packages/django/core/handlers/exception.py", line 56, in inner
    response = get_response(request)
  File "/home/ubuntu/github/easygo/venv/lib/python3.10/site-packages/django/core/handlers/base.py", line 197, in _get_response
    response = wrapped_callback(request, *callback_args, **callback_kwargs)
  File "/home/ubuntu/github/easygo/basecamp/views.py", line 1166, in p2p
    email.send()
  File "/home/ubuntu/github/easygo/venv/lib/python3.10/site-packages/django/core/mail/message.py", line 298, in send
    return self.get_connection(fail_silently).send_messages([self])
  File "/home/ubuntu/github/easygo/venv/lib/python3.10/site-packages/django/core/mail/backends/smtp.py", line 124, in send_messages
    new_conn_created = self.open()
  File "/home/ubuntu/github/easygo/venv/lib/python3.10/site-packages/django/core/mail/backends/smtp.py", line 91, in open
    self.connection.login(self.username, self.password)
  File "/usr/lib/python3.10/smtplib.py", line 739, in login
    (code, resp) = self.auth(
  File "/usr/lib/python3.10/smtplib.py", line 642, in auth
    (code, resp) = self.docmd("AUTH", mechanism + " " + response)
  File "/usr/lib/python3.10/smtplib.py", line 432, in docmd
    return self.getreply()
  File "/usr/lib/python3.10/smtplib.py", line 405, in getreply
    raise SMTPServerDisconnected("Connection unexpectedly closed")
smtplib.SMTPServerDisconnected: Connection unexpectedly closed
ERROR 2023-10-29 03:30:14,698 log Internal Server Error: /p2p/
Traceback (most recent call last):
  File "/home/ubuntu/github/easygo/venv/lib/python3.10/site-packages/django/core/handlers/exception.py", line 56, in inner
    response = get_response(request)
  File "/home/ubuntu/github/easygo/venv/lib/python3.10/site-packages/django/core/handlers/base.py", line 197, in _get_response
    response = wrapped_callback(request, *callback_args, **callback_kwargs)
  File "/home/ubuntu/github/easygo/basecamp/views.py", line 1166, in p2p
    email.send()
  File "/home/ubuntu/github/easygo/venv/lib/python3.10/site-packages/django/core/mail/message.py", line 298, in send
    return self.get_connection(fail_silently).send_messages([self])
  File "/home/ubuntu/github/easygo/venv/lib/python3.10/site-packages/django/core/mail/backends/smtp.py", line 124, in send_messages
    new_conn_created = self.open()
  File "/home/ubuntu/github/easygo/venv/lib/python3.10/site-packages/django/core/mail/backends/smtp.py", line 91, in open
    self.connection.login(self.username, self.password)
  File "/usr/lib/python3.10/smtplib.py", line 739, in login
    (code, resp) = self.auth(
  File "/usr/lib/python3.10/smtplib.py", line 642, in auth
    (code, resp) = self.docmd("AUTH", mechanism + " " + response)
  File "/usr/lib/python3.10/smtplib.py", line 432, in docmd
    return self.getreply()
  File "/usr/lib/python3.10/smtplib.py", line 405, in getreply
    raise SMTPServerDisconnected("Connection unexpectedly closed")
smtplib.SMTPServerDisconnected: Connection unexpectedly closed
ERROR 2023-10-29 03:30:17,255 log Internal Server Error: /p2p/
Traceback (most recent call last):
  File "/home/ubuntu/github/easygo/venv/lib/python3.10/site-packages/django/core/handlers/exception.py", line 56, in inner
    response = get_response(request)
  File "/home/ubuntu/github/easygo/venv/lib/python3.10/site-packages/django/core/handlers/base.py", line 197, in _get_response
    response = wrapped_callback(request, *callback_args, **callback_kwargs)
  File "/home/ubuntu/github/easygo/basecamp/views.py", line 1166, in p2p
    email.send()
  File "/home/ubuntu/github/easygo/venv/lib/python3.10/site-packages/django/core/mail/message.py", line 298, in send
    return self.get_connection(fail_silently).send_messages([self])
  File "/home/ubuntu/github/easygo/venv/lib/python3.10/site-packages/django/core/mail/backends/smtp.py", line 124, in send_messages
    new_conn_created = self.open()
  File "/home/ubuntu/github/easygo/venv/lib/python3.10/site-packages/django/core/mail/backends/smtp.py", line 91, in open
    self.connection.login(self.username, self.password)
  File "/usr/lib/python3.10/smtplib.py", line 739, in login
    (code, resp) = self.auth(
  File "/usr/lib/python3.10/smtplib.py", line 642, in auth
    (code, resp) = self.docmd("AUTH", mechanism + " " + response)
  File "/usr/lib/python3.10/smtplib.py", line 432, in docmd
    return self.getreply()
  File "/usr/lib/python3.10/smtplib.py", line 405, in getreply
    raise SMTPServerDisconnected("Connection unexpectedly closed")
smtplib.SMTPServerDisconnected: Connection unexpectedly closed
ERROR 2023-10-29 03:30:19,831 log Internal Server Error: /p2p/
Traceback (most recent call last):
  File "/home/ubuntu/github/easygo/venv/lib/python3.10/site-packages/django/core/handlers/exception.py", line 56, in inner
    response = get_response(request)
  File "/home/ubuntu/github/easygo/venv/lib/python3.10/site-packages/django/core/handlers/base.py", line 197, in _get_response
    response = wrapped_callback(request, *callback_args, **callback_kwargs)
  File "/home/ubuntu/github/easygo/basecamp/views.py", line 1166, in p2p
    email.send()
  File "/home/ubuntu/github/easygo/venv/lib/python3.10/site-packages/django/core/mail/message.py", line 298, in send
    return self.get_connection(fail_silently).send_messages([self])
  File "/home/ubuntu/github/easygo/venv/lib/python3.10/site-packages/django/core/mail/backends/smtp.py", line 124, in send_messages
    new_conn_created = self.open()
  File "/home/ubuntu/github/easygo/venv/lib/python3.10/site-packages/django/core/mail/backends/smtp.py", line 91, in open
    self.connection.login(self.username, self.password)
  File "/usr/lib/python3.10/smtplib.py", line 739, in login
    (code, resp) = self.auth(
  File "/usr/lib/python3.10/smtplib.py", line 642, in auth
    (code, resp) = self.docmd("AUTH", mechanism + " " + response)
  File "/usr/lib/python3.10/smtplib.py", line 432, in docmd
    return self.getreply()
  File "/usr/lib/python3.10/smtplib.py", line 405, in getreply
    raise SMTPServerDisconnected("Connection unexpectedly closed")
smtplib.SMTPServerDisconnected: Connection unexpectedly closed
ERROR 2023-10-29 03:30:22,352 log Internal Server Error: /p2p/
Traceback (most recent call last):
  File "/home/ubuntu/github/easygo/venv/lib/python3.10/site-packages/django/core/handlers/exception.py", line 56, in inner
    response = get_response(request)
  File "/home/ubuntu/github/easygo/venv/lib/python3.10/site-packages/django/core/handlers/base.py", line 197, in _get_response
    response = wrapped_callback(request, *callback_args, **callback_kwargs)
  File "/home/ubuntu/github/easygo/basecamp/views.py", line 1166, in p2p
    email.send()
  File "/home/ubuntu/github/easygo/venv/lib/python3.10/site-packages/django/core/mail/message.py", line 298, in send
    return self.get_connection(fail_silently).send_messages([self])
  File "/home/ubuntu/github/easygo/venv/lib/python3.10/site-packages/django/core/mail/backends/smtp.py", line 124, in send_messages
    new_conn_created = self.open()
  File "/home/ubuntu/github/easygo/venv/lib/python3.10/site-packages/django/core/mail/backends/smtp.py", line 91, in open
    self.connection.login(self.username, self.password)
  File "/usr/lib/python3.10/smtplib.py", line 739, in login
    (code, resp) = self.auth(
  File "/usr/lib/python3.10/smtplib.py", line 642, in auth
    (code, resp) = self.docmd("AUTH", mechanism + " " + response)
  File "/usr/lib/python3.10/smtplib.py", line 432, in docmd
    return self.getreply()
  File "/usr/lib/python3.10/smtplib.py", line 405, in getreply
    raise SMTPServerDisconnected("Connection unexpectedly closed")
smtplib.SMTPServerDisconnected: Connection unexpectedly closed
ERROR 2023-10-29 03:30:24,871 log Internal Server Error: /p2p/
Traceback (most recent call last):
  File "/home/ubuntu/github/easygo/venv/lib/python3.10/site-packages/django/core/handlers/exception.py", line 56, in inner
    response = get_response(request)
  File "/home/ubuntu/github/easygo/venv/lib/python3.10/site-packages/django/core/handlers/base.py", line 197, in _get_response
    response = wrapped_callback(request, *callback_args, **callback_kwargs)
  File "/home/ubuntu/github/easygo/basecamp/views.py", line 1166, in p2p
    email.send()
  File "/home/ubuntu/github/easygo/venv/lib/python3.10/site-packages/django/core/mail/message.py", line 298, in send
    return self.get_connection(fail_silently).send_messages([self])
  File "/home/ubuntu/github/easygo/venv/lib/python3.10/site-packages/django/core/mail/backends/smtp.py", line 124, in send_messages
    new_conn_created = self.open()
  File "/home/ubuntu/github/easygo/venv/lib/python3.10/site-packages/django/core/mail/backends/smtp.py", line 91, in open
    self.connection.login(self.username, self.password)
  File "/usr/lib/python3.10/smtplib.py", line 739, in login
    (code, resp) = self.auth(
  File "/usr/lib/python3.10/smtplib.py", line 642, in auth
    (code, resp) = self.docmd("AUTH", mechanism + " " + response)
  File "/usr/lib/python3.10/smtplib.py", line 432, in docmd
    return self.getreply()
  File "/usr/lib/python3.10/smtplib.py", line 405, in getreply
    raise SMTPServerDisconnected("Connection unexpectedly closed")
smtplib.SMTPServerDisconnected: Connection unexpectedly closed
ERROR 2023-10-29 03:30:27,442 log Internal Server Error: /p2p/
Traceback (most recent call last):
  File "/home/ubuntu/github/easygo/venv/lib/python3.10/site-packages/django/core/handlers/exception.py", line 56, in inner
    response = get_response(request)
  File "/home/ubuntu/github/easygo/venv/lib/python3.10/site-packages/django/core/handlers/base.py", line 197, in _get_response
    response = wrapped_callback(request, *callback_args, **callback_kwargs)
  File "/home/ubuntu/github/easygo/basecamp/views.py", line 1166, in p2p
    email.send()
  File "/home/ubuntu/github/easygo/venv/lib/python3.10/site-packages/django/core/mail/message.py", line 298, in send
    return self.get_connection(fail_silently).send_messages([self])
  File "/home/ubuntu/github/easygo/venv/lib/python3.10/site-packages/django/core/mail/backends/smtp.py", line 124, in send_messages
    new_conn_created = self.open()
  File "/home/ubuntu/github/easygo/venv/lib/python3.10/site-packages/django/core/mail/backends/smtp.py", line 91, in open
    self.connection.login(self.username, self.password)
  File "/usr/lib/python3.10/smtplib.py", line 739, in login
    (code, resp) = self.auth(
  File "/usr/lib/python3.10/smtplib.py", line 642, in auth
    (code, resp) = self.docmd("AUTH", mechanism + " " + response)
  File "/usr/lib/python3.10/smtplib.py", line 432, in docmd
    return self.getreply()
  File "/usr/lib/python3.10/smtplib.py", line 405, in getreply
    raise SMTPServerDisconnected("Connection unexpectedly closed")
smtplib.SMTPServerDisconnected: Connection unexpectedly closed
ERROR 2023-10-29 03:30:29,956 log Internal Server Error: /p2p/
Traceback (most recent call last):
  File "/home/ubuntu/github/easygo/venv/lib/python3.10/site-packages/django/core/handlers/exception.py", line 56, in inner
    response = get_response(request)
  File "/home/ubuntu/github/easygo/venv/lib/python3.10/site-packages/django/core/handlers/base.py", line 197, in _get_response
    response = wrapped_callback(request, *callback_args, **callback_kwargs)
  File "/home/ubuntu/github/easygo/basecamp/views.py", line 1166, in p2p
    email.send()
  File "/home/ubuntu/github/easygo/venv/lib/python3.10/site-packages/django/core/mail/message.py", line 298, in send
    return self.get_connection(fail_silently).send_messages([self])
  File "/home/ubuntu/github/easygo/venv/lib/python3.10/site-packages/django/core/mail/backends/smtp.py", line 124, in send_messages
    new_conn_created = self.open()
  File "/home/ubuntu/github/easygo/venv/lib/python3.10/site-packages/django/core/mail/backends/smtp.py", line 91, in open
    self.connection.login(self.username, self.password)
  File "/usr/lib/python3.10/smtplib.py", line 739, in login
    (code, resp) = self.auth(
  File "/usr/lib/python3.10/smtplib.py", line 642, in auth
    (code, resp) = self.docmd("AUTH", mechanism + " " + response)
  File "/usr/lib/python3.10/smtplib.py", line 432, in docmd
    return self.getreply()
  File "/usr/lib/python3.10/smtplib.py", line 405, in getreply
    raise SMTPServerDisconnected("Connection unexpectedly closed")
smtplib.SMTPServerDisconnected: Connection unexpectedly closed
ERROR 2023-10-29 03:30:32,484 log Internal Server Error: /p2p/
Traceback (most recent call last):
  File "/home/ubuntu/github/easygo/venv/lib/python3.10/site-packages/django/core/handlers/exception.py", line 56, in inner
    response = get_response(request)
  File "/home/ubuntu/github/easygo/venv/lib/python3.10/site-packages/django/core/handlers/base.py", line 197, in _get_response
    response = wrapped_callback(request, *callback_args, **callback_kwargs)
  File "/home/ubuntu/github/easygo/basecamp/views.py", line 1166, in p2p
    email.send()
  File "/home/ubuntu/github/easygo/venv/lib/python3.10/site-packages/django/core/mail/message.py", line 298, in send
    return self.get_connection(fail_silently).send_messages([self])
  File "/home/ubuntu/github/easygo/venv/lib/python3.10/site-packages/django/core/mail/backends/smtp.py", line 124, in send_messages
    new_conn_created = self.open()
  File "/home/ubuntu/github/easygo/venv/lib/python3.10/site-packages/django/core/mail/backends/smtp.py", line 91, in open
    self.connection.login(self.username, self.password)
  File "/usr/lib/python3.10/smtplib.py", line 739, in login
    (code, resp) = self.auth(
  File "/usr/lib/python3.10/smtplib.py", line 642, in auth
    (code, resp) = self.docmd("AUTH", mechanism + " " + response)
  File "/usr/lib/python3.10/smtplib.py", line 432, in docmd
    return self.getreply()
  File "/usr/lib/python3.10/smtplib.py", line 405, in getreply
    raise SMTPServerDisconnected("Connection unexpectedly closed")
smtplib.SMTPServerDisconnected: Connection unexpectedly closed
ERROR 2023-10-29 03:30:35,770 log Internal Server Error: /p2p/
Traceback (most recent call last):
  File "/home/ubuntu/github/easygo/venv/lib/python3.10/site-packages/django/core/handlers/exception.py", line 56, in inner
    response = get_response(request)
  File "/home/ubuntu/github/easygo/venv/lib/python3.10/site-packages/django/core/handlers/base.py", line 197, in _get_response
    response = wrapped_callback(request, *callback_args, **callback_kwargs)
  File "/home/ubuntu/github/easygo/basecamp/views.py", line 1166, in p2p
    email.send()
  File "/home/ubuntu/github/easygo/venv/lib/python3.10/site-packages/django/core/mail/message.py", line 298, in send
    return self.get_connection(fail_silently).send_messages([self])
  File "/home/ubuntu/github/easygo/venv/lib/python3.10/site-packages/django/core/mail/backends/smtp.py", line 124, in send_messages
    new_conn_created = self.open()
  File "/home/ubuntu/github/easygo/venv/lib/python3.10/site-packages/django/core/mail/backends/smtp.py", line 91, in open
    self.connection.login(self.username, self.password)
  File "/usr/lib/python3.10/smtplib.py", line 739, in login
    (code, resp) = self.auth(
  File "/usr/lib/python3.10/smtplib.py", line 642, in auth
    (code, resp) = self.docmd("AUTH", mechanism + " " + response)
  File "/usr/lib/python3.10/smtplib.py", line 432, in docmd
    return self.getreply()
  File "/usr/lib/python3.10/smtplib.py", line 405, in getreply
    raise SMTPServerDisconnected("Connection unexpectedly closed")
smtplib.SMTPServerDisconnected: Connection unexpectedly closed
ERROR 2023-10-29 03:30:38,276 log Internal Server Error: /p2p/
Traceback (most recent call last):
  File "/home/ubuntu/github/easygo/venv/lib/python3.10/site-packages/django/core/handlers/exception.py", line 56, in inner
    response = get_response(request)
  File "/home/ubuntu/github/easygo/venv/lib/python3.10/site-packages/django/core/handlers/base.py", line 197, in _get_response
    response = wrapped_callback(request, *callback_args, **callback_kwargs)
  File "/home/ubuntu/github/easygo/basecamp/views.py", line 1166, in p2p
    email.send()
  File "/home/ubuntu/github/easygo/venv/lib/python3.10/site-packages/django/core/mail/message.py", line 298, in send
    return self.get_connection(fail_silently).send_messages([self])
  File "/home/ubuntu/github/easygo/venv/lib/python3.10/site-packages/django/core/mail/backends/smtp.py", line 124, in send_messages
    new_conn_created = self.open()
  File "/home/ubuntu/github/easygo/venv/lib/python3.10/site-packages/django/core/mail/backends/smtp.py", line 91, in open
    self.connection.login(self.username, self.password)
  File "/usr/lib/python3.10/smtplib.py", line 739, in login
    (code, resp) = self.auth(
  File "/usr/lib/python3.10/smtplib.py", line 642, in auth
    (code, resp) = self.docmd("AUTH", mechanism + " " + response)
  File "/usr/lib/python3.10/smtplib.py", line 432, in docmd
    return self.getreply()
  File "/usr/lib/python3.10/smtplib.py", line 405, in getreply
    raise SMTPServerDisconnected("Connection unexpectedly closed")
smtplib.SMTPServerDisconnected: Connection unexpectedly closed
ERROR 2023-10-29 03:30:40,787 log Internal Server Error: /p2p/
Traceback (most recent call last):
  File "/home/ubuntu/github/easygo/venv/lib/python3.10/site-packages/django/core/handlers/exception.py", line 56, in inner
    response = get_response(request)
  File "/home/ubuntu/github/easygo/venv/lib/python3.10/site-packages/django/core/handlers/base.py", line 197, in _get_response
    response = wrapped_callback(request, *callback_args, **callback_kwargs)
  File "/home/ubuntu/github/easygo/basecamp/views.py", line 1166, in p2p
    email.send()
  File "/home/ubuntu/github/easygo/venv/lib/python3.10/site-packages/django/core/mail/message.py", line 298, in send
    return self.get_connection(fail_silently).send_messages([self])
  File "/home/ubuntu/github/easygo/venv/lib/python3.10/site-packages/django/core/mail/backends/smtp.py", line 124, in send_messages
    new_conn_created = self.open()
  File "/home/ubuntu/github/easygo/venv/lib/python3.10/site-packages/django/core/mail/backends/smtp.py", line 91, in open
    self.connection.login(self.username, self.password)
  File "/usr/lib/python3.10/smtplib.py", line 739, in login
    (code, resp) = self.auth(
  File "/usr/lib/python3.10/smtplib.py", line 642, in auth
    (code, resp) = self.docmd("AUTH", mechanism + " " + response)
  File "/usr/lib/python3.10/smtplib.py", line 432, in docmd
    return self.getreply()
  File "/usr/lib/python3.10/smtplib.py", line 405, in getreply
    raise SMTPServerDisconnected("Connection unexpectedly closed")
smtplib.SMTPServerDisconnected: Connection unexpectedly closed
ERROR 2023-10-29 03:30:43,309 log Internal Server Error: /p2p/
Traceback (most recent call last):
  File "/home/ubuntu/github/easygo/venv/lib/python3.10/site-packages/django/core/handlers/exception.py", line 56, in inner
    response = get_response(request)
  File "/home/ubuntu/github/easygo/venv/lib/python3.10/site-packages/django/core/handlers/base.py", line 197, in _get_response
    response = wrapped_callback(request, *callback_args, **callback_kwargs)
  File "/home/ubuntu/github/easygo/basecamp/views.py", line 1166, in p2p
    email.send()
  File "/home/ubuntu/github/easygo/venv/lib/python3.10/site-packages/django/core/mail/message.py", line 298, in send
    return self.get_connection(fail_silently).send_messages([self])
  File "/home/ubuntu/github/easygo/venv/lib/python3.10/site-packages/django/core/mail/backends/smtp.py", line 124, in send_messages
    new_conn_created = self.open()
  File "/home/ubuntu/github/easygo/venv/lib/python3.10/site-packages/django/core/mail/backends/smtp.py", line 91, in open
    self.connection.login(self.username, self.password)
  File "/usr/lib/python3.10/smtplib.py", line 739, in login
    (code, resp) = self.auth(
  File "/usr/lib/python3.10/smtplib.py", line 642, in auth
    (code, resp) = self.docmd("AUTH", mechanism + " " + response)
  File "/usr/lib/python3.10/smtplib.py", line 432, in docmd
    return self.getreply()
  File "/usr/lib/python3.10/smtplib.py", line 405, in getreply
    raise SMTPServerDisconnected("Connection unexpectedly closed")
smtplib.SMTPServerDisconnected: Connection unexpectedly closed
ERROR 2023-10-29 03:30:45,836 log Internal Server Error: /p2p/
Traceback (most recent call last):
  File "/home/ubuntu/github/easygo/venv/lib/python3.10/site-packages/django/core/handlers/exception.py", line 56, in inner
    response = get_response(request)
  File "/home/ubuntu/github/easygo/venv/lib/python3.10/site-packages/django/core/handlers/base.py", line 197, in _get_response
    response = wrapped_callback(request, *callback_args, **callback_kwargs)
  File "/home/ubuntu/github/easygo/basecamp/views.py", line 1166, in p2p
    email.send()
  File "/home/ubuntu/github/easygo/venv/lib/python3.10/site-packages/django/core/mail/message.py", line 298, in send
    return self.get_connection(fail_silently).send_messages([self])
  File "/home/ubuntu/github/easygo/venv/lib/python3.10/site-packages/django/core/mail/backends/smtp.py", line 124, in send_messages
    new_conn_created = self.open()
  File "/home/ubuntu/github/easygo/venv/lib/python3.10/site-packages/django/core/mail/backends/smtp.py", line 91, in open
    self.connection.login(self.username, self.password)
  File "/usr/lib/python3.10/smtplib.py", line 739, in login
    (code, resp) = self.auth(
  File "/usr/lib/python3.10/smtplib.py", line 642, in auth
    (code, resp) = self.docmd("AUTH", mechanism + " " + response)
  File "/usr/lib/python3.10/smtplib.py", line 432, in docmd
    return self.getreply()
  File "/usr/lib/python3.10/smtplib.py", line 405, in getreply
    raise SMTPServerDisconnected("Connection unexpectedly closed")
smtplib.SMTPServerDisconnected: Connection unexpectedly closed
ERROR 2023-10-29 03:30:48,948 log Internal Server Error: /p2p/
Traceback (most recent call last):
  File "/home/ubuntu/github/easygo/venv/lib/python3.10/site-packages/django/core/handlers/exception.py", line 56, in inner
    response = get_response(request)
  File "/home/ubuntu/github/easygo/venv/lib/python3.10/site-packages/django/core/handlers/base.py", line 197, in _get_response
    response = wrapped_callback(request, *callback_args, **callback_kwargs)
  File "/home/ubuntu/github/easygo/basecamp/views.py", line 1166, in p2p
    email.send()
  File "/home/ubuntu/github/easygo/venv/lib/python3.10/site-packages/django/core/mail/message.py", line 298, in send
    return self.get_connection(fail_silently).send_messages([self])
  File "/home/ubuntu/github/easygo/venv/lib/python3.10/site-packages/django/core/mail/backends/smtp.py", line 124, in send_messages
    new_conn_created = self.open()
  File "/home/ubuntu/github/easygo/venv/lib/python3.10/site-packages/django/core/mail/backends/smtp.py", line 91, in open
    self.connection.login(self.username, self.password)
  File "/usr/lib/python3.10/smtplib.py", line 739, in login
    (code, resp) = self.auth(
  File "/usr/lib/python3.10/smtplib.py", line 642, in auth
    (code, resp) = self.docmd("AUTH", mechanism + " " + response)
  File "/usr/lib/python3.10/smtplib.py", line 432, in docmd
    return self.getreply()
  File "/usr/lib/python3.10/smtplib.py", line 405, in getreply
    raise SMTPServerDisconnected("Connection unexpectedly closed")
smtplib.SMTPServerDisconnected: Connection unexpectedly closed
ERROR 2023-10-29 03:30:51,515 log Internal Server Error: /p2p/
Traceback (most recent call last):
  File "/home/ubuntu/github/easygo/venv/lib/python3.10/site-packages/django/core/handlers/exception.py", line 56, in inner
    response = get_response(request)
  File "/home/ubuntu/github/easygo/venv/lib/python3.10/site-packages/django/core/handlers/base.py", line 197, in _get_response
    response = wrapped_callback(request, *callback_args, **callback_kwargs)
  File "/home/ubuntu/github/easygo/basecamp/views.py", line 1166, in p2p
    email.send()
  File "/home/ubuntu/github/easygo/venv/lib/python3.10/site-packages/django/core/mail/message.py", line 298, in send
    return self.get_connection(fail_silently).send_messages([self])
  File "/home/ubuntu/github/easygo/venv/lib/python3.10/site-packages/django/core/mail/backends/smtp.py", line 124, in send_messages
    new_conn_created = self.open()
  File "/home/ubuntu/github/easygo/venv/lib/python3.10/site-packages/django/core/mail/backends/smtp.py", line 91, in open
    self.connection.login(self.username, self.password)
  File "/usr/lib/python3.10/smtplib.py", line 739, in login
    (code, resp) = self.auth(
  File "/usr/lib/python3.10/smtplib.py", line 642, in auth
    (code, resp) = self.docmd("AUTH", mechanism + " " + response)
  File "/usr/lib/python3.10/smtplib.py", line 432, in docmd
    return self.getreply()
  File "/usr/lib/python3.10/smtplib.py", line 405, in getreply
    raise SMTPServerDisconnected("Connection unexpectedly closed")
smtplib.SMTPServerDisconnected: Connection unexpectedly closed
ERROR 2023-10-29 03:30:54,046 log Internal Server Error: /p2p/
Traceback (most recent call last):
  File "/home/ubuntu/github/easygo/venv/lib/python3.10/site-packages/django/core/handlers/exception.py", line 56, in inner
    response = get_response(request)
  File "/home/ubuntu/github/easygo/venv/lib/python3.10/site-packages/django/core/handlers/base.py", line 197, in _get_response
    response = wrapped_callback(request, *callback_args, **callback_kwargs)
  File "/home/ubuntu/github/easygo/basecamp/views.py", line 1166, in p2p
    email.send()
  File "/home/ubuntu/github/easygo/venv/lib/python3.10/site-packages/django/core/mail/message.py", line 298, in send
    return self.get_connection(fail_silently).send_messages([self])
  File "/home/ubuntu/github/easygo/venv/lib/python3.10/site-packages/django/core/mail/backends/smtp.py", line 124, in send_messages
    new_conn_created = self.open()
  File "/home/ubuntu/github/easygo/venv/lib/python3.10/site-packages/django/core/mail/backends/smtp.py", line 91, in open
    self.connection.login(self.username, self.password)
  File "/usr/lib/python3.10/smtplib.py", line 739, in login
    (code, resp) = self.auth(
  File "/usr/lib/python3.10/smtplib.py", line 642, in auth
    (code, resp) = self.docmd("AUTH", mechanism + " " + response)
  File "/usr/lib/python3.10/smtplib.py", line 432, in docmd
    return self.getreply()
  File "/usr/lib/python3.10/smtplib.py", line 405, in getreply
    raise SMTPServerDisconnected("Connection unexpectedly closed")
smtplib.SMTPServerDisconnected: Connection unexpectedly closed
ERROR 2023-10-29 03:30:55,891 log Internal Server Error: /p2p/
Traceback (most recent call last):
  File "/home/ubuntu/github/easygo/venv/lib/python3.10/site-packages/django/core/handlers/exception.py", line 56, in inner
    response = get_response(request)
  File "/home/ubuntu/github/easygo/venv/lib/python3.10/site-packages/django/core/handlers/base.py", line 197, in _get_response
    response = wrapped_callback(request, *callback_args, **callback_kwargs)
  File "/home/ubuntu/github/easygo/basecamp/views.py", line 1166, in p2p
    email.send()
  File "/home/ubuntu/github/easygo/venv/lib/python3.10/site-packages/django/core/mail/message.py", line 298, in send
    return self.get_connection(fail_silently).send_messages([self])
  File "/home/ubuntu/github/easygo/venv/lib/python3.10/site-packages/django/core/mail/backends/smtp.py", line 124, in send_messages
    new_conn_created = self.open()
  File "/home/ubuntu/github/easygo/venv/lib/python3.10/site-packages/django/core/mail/backends/smtp.py", line 91, in open
    self.connection.login(self.username, self.password)
  File "/usr/lib/python3.10/smtplib.py", line 739, in login
    (code, resp) = self.auth(
  File "/usr/lib/python3.10/smtplib.py", line 642, in auth
    (code, resp) = self.docmd("AUTH", mechanism + " " + response)
  File "/usr/lib/python3.10/smtplib.py", line 432, in docmd
    return self.getreply()
  File "/usr/lib/python3.10/smtplib.py", line 405, in getreply
    raise SMTPServerDisconnected("Connection unexpectedly closed")
smtplib.SMTPServerDisconnected: Connection unexpectedly closed
ERROR 2023-10-29 03:30:57,751 log Internal Server Error: /p2p/
Traceback (most recent call last):
  File "/home/ubuntu/github/easygo/venv/lib/python3.10/site-packages/django/core/handlers/exception.py", line 56, in inner
    response = get_response(request)
  File "/home/ubuntu/github/easygo/venv/lib/python3.10/site-packages/django/core/handlers/base.py", line 197, in _get_response
    response = wrapped_callback(request, *callback_args, **callback_kwargs)
  File "/home/ubuntu/github/easygo/basecamp/views.py", line 1166, in p2p
    email.send()
  File "/home/ubuntu/github/easygo/venv/lib/python3.10/site-packages/django/core/mail/message.py", line 298, in send
    return self.get_connection(fail_silently).send_messages([self])
  File "/home/ubuntu/github/easygo/venv/lib/python3.10/site-packages/django/core/mail/backends/smtp.py", line 124, in send_messages
    new_conn_created = self.open()
  File "/home/ubuntu/github/easygo/venv/lib/python3.10/site-packages/django/core/mail/backends/smtp.py", line 91, in open
    self.connection.login(self.username, self.password)
  File "/usr/lib/python3.10/smtplib.py", line 739, in login
    (code, resp) = self.auth(
  File "/usr/lib/python3.10/smtplib.py", line 642, in auth
    (code, resp) = self.docmd("AUTH", mechanism + " " + response)
  File "/usr/lib/python3.10/smtplib.py", line 432, in docmd
    return self.getreply()
  File "/usr/lib/python3.10/smtplib.py", line 405, in getreply
    raise SMTPServerDisconnected("Connection unexpectedly closed")
smtplib.SMTPServerDisconnected: Connection unexpectedly closed
ERROR 2023-10-29 03:31:00,262 log Internal Server Error: /p2p/
Traceback (most recent call last):
  File "/home/ubuntu/github/easygo/venv/lib/python3.10/site-packages/django/core/handlers/exception.py", line 56, in inner
    response = get_response(request)
  File "/home/ubuntu/github/easygo/venv/lib/python3.10/site-packages/django/core/handlers/base.py", line 197, in _get_response
    response = wrapped_callback(request, *callback_args, **callback_kwargs)
  File "/home/ubuntu/github/easygo/basecamp/views.py", line 1166, in p2p
    email.send()
  File "/home/ubuntu/github/easygo/venv/lib/python3.10/site-packages/django/core/mail/message.py", line 298, in send
    return self.get_connection(fail_silently).send_messages([self])
  File "/home/ubuntu/github/easygo/venv/lib/python3.10/site-packages/django/core/mail/backends/smtp.py", line 124, in send_messages
    new_conn_created = self.open()
  File "/home/ubuntu/github/easygo/venv/lib/python3.10/site-packages/django/core/mail/backends/smtp.py", line 91, in open
    self.connection.login(self.username, self.password)
  File "/usr/lib/python3.10/smtplib.py", line 739, in login
    (code, resp) = self.auth(
  File "/usr/lib/python3.10/smtplib.py", line 642, in auth
    (code, resp) = self.docmd("AUTH", mechanism + " " + response)
  File "/usr/lib/python3.10/smtplib.py", line 432, in docmd
    return self.getreply()
  File "/usr/lib/python3.10/smtplib.py", line 405, in getreply
    raise SMTPServerDisconnected("Connection unexpectedly closed")
smtplib.SMTPServerDisconnected: Connection unexpectedly closed
ERROR 2023-10-29 03:31:02,879 log Internal Server Error: /p2p/
Traceback (most recent call last):
  File "/home/ubuntu/github/easygo/venv/lib/python3.10/site-packages/django/core/handlers/exception.py", line 56, in inner
    response = get_response(request)
  File "/home/ubuntu/github/easygo/venv/lib/python3.10/site-packages/django/core/handlers/base.py", line 197, in _get_response
    response = wrapped_callback(request, *callback_args, **callback_kwargs)
  File "/home/ubuntu/github/easygo/basecamp/views.py", line 1166, in p2p
    email.send()
  File "/home/ubuntu/github/easygo/venv/lib/python3.10/site-packages/django/core/mail/message.py", line 298, in send
    return self.get_connection(fail_silently).send_messages([self])
  File "/home/ubuntu/github/easygo/venv/lib/python3.10/site-packages/django/core/mail/backends/smtp.py", line 124, in send_messages
    new_conn_created = self.open()
  File "/home/ubuntu/github/easygo/venv/lib/python3.10/site-packages/django/core/mail/backends/smtp.py", line 91, in open
    self.connection.login(self.username, self.password)
  File "/usr/lib/python3.10/smtplib.py", line 739, in login
    (code, resp) = self.auth(
  File "/usr/lib/python3.10/smtplib.py", line 642, in auth
    (code, resp) = self.docmd("AUTH", mechanism + " " + response)
  File "/usr/lib/python3.10/smtplib.py", line 432, in docmd
    return self.getreply()
  File "/usr/lib/python3.10/smtplib.py", line 405, in getreply
    raise SMTPServerDisconnected("Connection unexpectedly closed")
smtplib.SMTPServerDisconnected: Connection unexpectedly closed
ERROR 2023-10-29 03:31:05,382 log Internal Server Error: /p2p/
Traceback (most recent call last):
  File "/home/ubuntu/github/easygo/venv/lib/python3.10/site-packages/django/core/handlers/exception.py", line 56, in inner
    response = get_response(request)
  File "/home/ubuntu/github/easygo/venv/lib/python3.10/site-packages/django/core/handlers/base.py", line 197, in _get_response
    response = wrapped_callback(request, *callback_args, **callback_kwargs)
  File "/home/ubuntu/github/easygo/basecamp/views.py", line 1166, in p2p
    email.send()
  File "/home/ubuntu/github/easygo/venv/lib/python3.10/site-packages/django/core/mail/message.py", line 298, in send
    return self.get_connection(fail_silently).send_messages([self])
  File "/home/ubuntu/github/easygo/venv/lib/python3.10/site-packages/django/core/mail/backends/smtp.py", line 124, in send_messages
    new_conn_created = self.open()
  File "/home/ubuntu/github/easygo/venv/lib/python3.10/site-packages/django/core/mail/backends/smtp.py", line 91, in open
    self.connection.login(self.username, self.password)
  File "/usr/lib/python3.10/smtplib.py", line 739, in login
    (code, resp) = self.auth(
  File "/usr/lib/python3.10/smtplib.py", line 642, in auth
    (code, resp) = self.docmd("AUTH", mechanism + " " + response)
  File "/usr/lib/python3.10/smtplib.py", line 432, in docmd
    return self.getreply()
  File "/usr/lib/python3.10/smtplib.py", line 405, in getreply
    raise SMTPServerDisconnected("Connection unexpectedly closed")
smtplib.SMTPServerDisconnected: Connection unexpectedly closed
ERROR 2023-10-29 03:31:07,900 log Internal Server Error: /p2p/
Traceback (most recent call last):
  File "/home/ubuntu/github/easygo/venv/lib/python3.10/site-packages/django/core/handlers/exception.py", line 56, in inner
    response = get_response(request)
  File "/home/ubuntu/github/easygo/venv/lib/python3.10/site-packages/django/core/handlers/base.py", line 197, in _get_response
    response = wrapped_callback(request, *callback_args, **callback_kwargs)
  File "/home/ubuntu/github/easygo/basecamp/views.py", line 1166, in p2p
    email.send()
  File "/home/ubuntu/github/easygo/venv/lib/python3.10/site-packages/django/core/mail/message.py", line 298, in send
    return self.get_connection(fail_silently).send_messages([self])
  File "/home/ubuntu/github/easygo/venv/lib/python3.10/site-packages/django/core/mail/backends/smtp.py", line 124, in send_messages
    new_conn_created = self.open()
  File "/home/ubuntu/github/easygo/venv/lib/python3.10/site-packages/django/core/mail/backends/smtp.py", line 91, in open
    self.connection.login(self.username, self.password)
  File "/usr/lib/python3.10/smtplib.py", line 739, in login
    (code, resp) = self.auth(
  File "/usr/lib/python3.10/smtplib.py", line 642, in auth
    (code, resp) = self.docmd("AUTH", mechanism + " " + response)
  File "/usr/lib/python3.10/smtplib.py", line 432, in docmd
    return self.getreply()
  File "/usr/lib/python3.10/smtplib.py", line 405, in getreply
    raise SMTPServerDisconnected("Connection unexpectedly closed")
smtplib.SMTPServerDisconnected: Connection unexpectedly closed
ERROR 2023-10-29 03:31:10,424 log Internal Server Error: /p2p/
Traceback (most recent call last):
  File "/home/ubuntu/github/easygo/venv/lib/python3.10/site-packages/django/core/handlers/exception.py", line 56, in inner
    response = get_response(request)
  File "/home/ubuntu/github/easygo/venv/lib/python3.10/site-packages/django/core/handlers/base.py", line 197, in _get_response
    response = wrapped_callback(request, *callback_args, **callback_kwargs)
  File "/home/ubuntu/github/easygo/basecamp/views.py", line 1166, in p2p
    email.send()
  File "/home/ubuntu/github/easygo/venv/lib/python3.10/site-packages/django/core/mail/message.py", line 298, in send
    return self.get_connection(fail_silently).send_messages([self])
  File "/home/ubuntu/github/easygo/venv/lib/python3.10/site-packages/django/core/mail/backends/smtp.py", line 124, in send_messages
    new_conn_created = self.open()
  File "/home/ubuntu/github/easygo/venv/lib/python3.10/site-packages/django/core/mail/backends/smtp.py", line 91, in open
    self.connection.login(self.username, self.password)
  File "/usr/lib/python3.10/smtplib.py", line 739, in login
    (code, resp) = self.auth(
  File "/usr/lib/python3.10/smtplib.py", line 642, in auth
    (code, resp) = self.docmd("AUTH", mechanism + " " + response)
  File "/usr/lib/python3.10/smtplib.py", line 432, in docmd
    return self.getreply()
  File "/usr/lib/python3.10/smtplib.py", line 405, in getreply
    raise SMTPServerDisconnected("Connection unexpectedly closed")
smtplib.SMTPServerDisconnected: Connection unexpectedly closed
ERROR 2023-10-29 03:31:13,556 log Internal Server Error: /p2p/
Traceback (most recent call last):
  File "/home/ubuntu/github/easygo/venv/lib/python3.10/site-packages/django/core/handlers/exception.py", line 56, in inner
    response = get_response(request)
  File "/home/ubuntu/github/easygo/venv/lib/python3.10/site-packages/django/core/handlers/base.py", line 197, in _get_response
    response = wrapped_callback(request, *callback_args, **callback_kwargs)
  File "/home/ubuntu/github/easygo/basecamp/views.py", line 1166, in p2p
    email.send()
  File "/home/ubuntu/github/easygo/venv/lib/python3.10/site-packages/django/core/mail/message.py", line 298, in send
    return self.get_connection(fail_silently).send_messages([self])
  File "/home/ubuntu/github/easygo/venv/lib/python3.10/site-packages/django/core/mail/backends/smtp.py", line 124, in send_messages
    new_conn_created = self.open()
  File "/home/ubuntu/github/easygo/venv/lib/python3.10/site-packages/django/core/mail/backends/smtp.py", line 91, in open
    self.connection.login(self.username, self.password)
  File "/usr/lib/python3.10/smtplib.py", line 739, in login
    (code, resp) = self.auth(
  File "/usr/lib/python3.10/smtplib.py", line 642, in auth
    (code, resp) = self.docmd("AUTH", mechanism + " " + response)
  File "/usr/lib/python3.10/smtplib.py", line 432, in docmd
    return self.getreply()
  File "/usr/lib/python3.10/smtplib.py", line 405, in getreply
    raise SMTPServerDisconnected("Connection unexpectedly closed")
smtplib.SMTPServerDisconnected: Connection unexpectedly closed
ERROR 2023-10-29 03:31:16,066 log Internal Server Error: /p2p/
Traceback (most recent call last):
  File "/home/ubuntu/github/easygo/venv/lib/python3.10/site-packages/django/core/handlers/exception.py", line 56, in inner
    response = get_response(request)
  File "/home/ubuntu/github/easygo/venv/lib/python3.10/site-packages/django/core/handlers/base.py", line 197, in _get_response
    response = wrapped_callback(request, *callback_args, **callback_kwargs)
  File "/home/ubuntu/github/easygo/basecamp/views.py", line 1166, in p2p
    email.send()
  File "/home/ubuntu/github/easygo/venv/lib/python3.10/site-packages/django/core/mail/message.py", line 298, in send
    return self.get_connection(fail_silently).send_messages([self])
  File "/home/ubuntu/github/easygo/venv/lib/python3.10/site-packages/django/core/mail/backends/smtp.py", line 124, in send_messages
    new_conn_created = self.open()
  File "/home/ubuntu/github/easygo/venv/lib/python3.10/site-packages/django/core/mail/backends/smtp.py", line 91, in open
    self.connection.login(self.username, self.password)
  File "/usr/lib/python3.10/smtplib.py", line 739, in login
    (code, resp) = self.auth(
  File "/usr/lib/python3.10/smtplib.py", line 642, in auth
    (code, resp) = self.docmd("AUTH", mechanism + " " + response)
  File "/usr/lib/python3.10/smtplib.py", line 432, in docmd
    return self.getreply()
  File "/usr/lib/python3.10/smtplib.py", line 405, in getreply
    raise SMTPServerDisconnected("Connection unexpectedly closed")
smtplib.SMTPServerDisconnected: Connection unexpectedly closed
ERROR 2023-10-29 03:31:18,616 log Internal Server Error: /p2p/
Traceback (most recent call last):
  File "/home/ubuntu/github/easygo/venv/lib/python3.10/site-packages/django/core/handlers/exception.py", line 56, in inner
    response = get_response(request)
  File "/home/ubuntu/github/easygo/venv/lib/python3.10/site-packages/django/core/handlers/base.py", line 197, in _get_response
    response = wrapped_callback(request, *callback_args, **callback_kwargs)
  File "/home/ubuntu/github/easygo/basecamp/views.py", line 1166, in p2p
    email.send()
  File "/home/ubuntu/github/easygo/venv/lib/python3.10/site-packages/django/core/mail/message.py", line 298, in send
    return self.get_connection(fail_silently).send_messages([self])
  File "/home/ubuntu/github/easygo/venv/lib/python3.10/site-packages/django/core/mail/backends/smtp.py", line 124, in send_messages
    new_conn_created = self.open()
  File "/home/ubuntu/github/easygo/venv/lib/python3.10/site-packages/django/core/mail/backends/smtp.py", line 91, in open
    self.connection.login(self.username, self.password)
  File "/usr/lib/python3.10/smtplib.py", line 739, in login
    (code, resp) = self.auth(
  File "/usr/lib/python3.10/smtplib.py", line 642, in auth
    (code, resp) = self.docmd("AUTH", mechanism + " " + response)
  File "/usr/lib/python3.10/smtplib.py", line 432, in docmd
    return self.getreply()
  File "/usr/lib/python3.10/smtplib.py", line 405, in getreply
    raise SMTPServerDisconnected("Connection unexpectedly closed")
smtplib.SMTPServerDisconnected: Connection unexpectedly closed
ERROR 2023-10-29 03:31:21,149 log Internal Server Error: /p2p/
Traceback (most recent call last):
  File "/home/ubuntu/github/easygo/venv/lib/python3.10/site-packages/django/core/handlers/exception.py", line 56, in inner
    response = get_response(request)
  File "/home/ubuntu/github/easygo/venv/lib/python3.10/site-packages/django/core/handlers/base.py", line 197, in _get_response
    response = wrapped_callback(request, *callback_args, **callback_kwargs)
  File "/home/ubuntu/github/easygo/basecamp/views.py", line 1166, in p2p
    email.send()
  File "/home/ubuntu/github/easygo/venv/lib/python3.10/site-packages/django/core/mail/message.py", line 298, in send
    return self.get_connection(fail_silently).send_messages([self])
  File "/home/ubuntu/github/easygo/venv/lib/python3.10/site-packages/django/core/mail/backends/smtp.py", line 124, in send_messages
    new_conn_created = self.open()
  File "/home/ubuntu/github/easygo/venv/lib/python3.10/site-packages/django/core/mail/backends/smtp.py", line 91, in open
    self.connection.login(self.username, self.password)
  File "/usr/lib/python3.10/smtplib.py", line 739, in login
    (code, resp) = self.auth(
  File "/usr/lib/python3.10/smtplib.py", line 642, in auth
    (code, resp) = self.docmd("AUTH", mechanism + " " + response)
  File "/usr/lib/python3.10/smtplib.py", line 432, in docmd
    return self.getreply()
  File "/usr/lib/python3.10/smtplib.py", line 405, in getreply
    raise SMTPServerDisconnected("Connection unexpectedly closed")
smtplib.SMTPServerDisconnected: Connection unexpectedly closed
ERROR 2023-10-29 03:31:24,311 log Internal Server Error: /p2p/
Traceback (most recent call last):
  File "/home/ubuntu/github/easygo/venv/lib/python3.10/site-packages/django/core/handlers/exception.py", line 56, in inner
    response = get_response(request)
  File "/home/ubuntu/github/easygo/venv/lib/python3.10/site-packages/django/core/handlers/base.py", line 197, in _get_response
    response = wrapped_callback(request, *callback_args, **callback_kwargs)
  File "/home/ubuntu/github/easygo/basecamp/views.py", line 1166, in p2p
    email.send()
  File "/home/ubuntu/github/easygo/venv/lib/python3.10/site-packages/django/core/mail/message.py", line 298, in send
    return self.get_connection(fail_silently).send_messages([self])
  File "/home/ubuntu/github/easygo/venv/lib/python3.10/site-packages/django/core/mail/backends/smtp.py", line 124, in send_messages
    new_conn_created = self.open()
  File "/home/ubuntu/github/easygo/venv/lib/python3.10/site-packages/django/core/mail/backends/smtp.py", line 91, in open
    self.connection.login(self.username, self.password)
  File "/usr/lib/python3.10/smtplib.py", line 739, in login
    (code, resp) = self.auth(
  File "/usr/lib/python3.10/smtplib.py", line 642, in auth
    (code, resp) = self.docmd("AUTH", mechanism + " " + response)
  File "/usr/lib/python3.10/smtplib.py", line 432, in docmd
    return self.getreply()
  File "/usr/lib/python3.10/smtplib.py", line 405, in getreply
    raise SMTPServerDisconnected("Connection unexpectedly closed")
smtplib.SMTPServerDisconnected: Connection unexpectedly closed
ERROR 2023-10-29 03:31:26,166 log Internal Server Error: /p2p/
Traceback (most recent call last):
  File "/home/ubuntu/github/easygo/venv/lib/python3.10/site-packages/django/core/handlers/exception.py", line 56, in inner
    response = get_response(request)
  File "/home/ubuntu/github/easygo/venv/lib/python3.10/site-packages/django/core/handlers/base.py", line 197, in _get_response
    response = wrapped_callback(request, *callback_args, **callback_kwargs)
  File "/home/ubuntu/github/easygo/basecamp/views.py", line 1166, in p2p
    email.send()
  File "/home/ubuntu/github/easygo/venv/lib/python3.10/site-packages/django/core/mail/message.py", line 298, in send
    return self.get_connection(fail_silently).send_messages([self])
  File "/home/ubuntu/github/easygo/venv/lib/python3.10/site-packages/django/core/mail/backends/smtp.py", line 124, in send_messages
    new_conn_created = self.open()
  File "/home/ubuntu/github/easygo/venv/lib/python3.10/site-packages/django/core/mail/backends/smtp.py", line 91, in open
    self.connection.login(self.username, self.password)
  File "/usr/lib/python3.10/smtplib.py", line 739, in login
    (code, resp) = self.auth(
  File "/usr/lib/python3.10/smtplib.py", line 642, in auth
    (code, resp) = self.docmd("AUTH", mechanism + " " + response)
  File "/usr/lib/python3.10/smtplib.py", line 432, in docmd
    return self.getreply()
  File "/usr/lib/python3.10/smtplib.py", line 405, in getreply
    raise SMTPServerDisconnected("Connection unexpectedly closed")
smtplib.SMTPServerDisconnected: Connection unexpectedly closed
ERROR 2023-10-29 03:31:28,033 log Internal Server Error: /p2p/
Traceback (most recent call last):
  File "/home/ubuntu/github/easygo/venv/lib/python3.10/site-packages/django/core/handlers/exception.py", line 56, in inner
    response = get_response(request)
  File "/home/ubuntu/github/easygo/venv/lib/python3.10/site-packages/django/core/handlers/base.py", line 197, in _get_response
    response = wrapped_callback(request, *callback_args, **callback_kwargs)
  File "/home/ubuntu/github/easygo/basecamp/views.py", line 1166, in p2p
    email.send()
  File "/home/ubuntu/github/easygo/venv/lib/python3.10/site-packages/django/core/mail/message.py", line 298, in send
    return self.get_connection(fail_silently).send_messages([self])
  File "/home/ubuntu/github/easygo/venv/lib/python3.10/site-packages/django/core/mail/backends/smtp.py", line 124, in send_messages
    new_conn_created = self.open()
  File "/home/ubuntu/github/easygo/venv/lib/python3.10/site-packages/django/core/mail/backends/smtp.py", line 91, in open
    self.connection.login(self.username, self.password)
  File "/usr/lib/python3.10/smtplib.py", line 739, in login
    (code, resp) = self.auth(
  File "/usr/lib/python3.10/smtplib.py", line 642, in auth
    (code, resp) = self.docmd("AUTH", mechanism + " " + response)
  File "/usr/lib/python3.10/smtplib.py", line 432, in docmd
    return self.getreply()
  File "/usr/lib/python3.10/smtplib.py", line 405, in getreply
    raise SMTPServerDisconnected("Connection unexpectedly closed")
smtplib.SMTPServerDisconnected: Connection unexpectedly closed
ERROR 2023-10-29 03:31:30,588 log Internal Server Error: /p2p/
Traceback (most recent call last):
  File "/home/ubuntu/github/easygo/venv/lib/python3.10/site-packages/django/core/handlers/exception.py", line 56, in inner
    response = get_response(request)
  File "/home/ubuntu/github/easygo/venv/lib/python3.10/site-packages/django/core/handlers/base.py", line 197, in _get_response
    response = wrapped_callback(request, *callback_args, **callback_kwargs)
  File "/home/ubuntu/github/easygo/basecamp/views.py", line 1166, in p2p
    email.send()
  File "/home/ubuntu/github/easygo/venv/lib/python3.10/site-packages/django/core/mail/message.py", line 298, in send
    return self.get_connection(fail_silently).send_messages([self])
  File "/home/ubuntu/github/easygo/venv/lib/python3.10/site-packages/django/core/mail/backends/smtp.py", line 124, in send_messages
    new_conn_created = self.open()
  File "/home/ubuntu/github/easygo/venv/lib/python3.10/site-packages/django/core/mail/backends/smtp.py", line 91, in open
    self.connection.login(self.username, self.password)
  File "/usr/lib/python3.10/smtplib.py", line 739, in login
    (code, resp) = self.auth(
  File "/usr/lib/python3.10/smtplib.py", line 642, in auth
    (code, resp) = self.docmd("AUTH", mechanism + " " + response)
  File "/usr/lib/python3.10/smtplib.py", line 432, in docmd
    return self.getreply()
  File "/usr/lib/python3.10/smtplib.py", line 405, in getreply
    raise SMTPServerDisconnected("Connection unexpectedly closed")
smtplib.SMTPServerDisconnected: Connection unexpectedly closed
ERROR 2023-10-29 03:31:33,113 log Internal Server Error: /p2p/
Traceback (most recent call last):
  File "/home/ubuntu/github/easygo/venv/lib/python3.10/site-packages/django/core/handlers/exception.py", line 56, in inner
    response = get_response(request)
  File "/home/ubuntu/github/easygo/venv/lib/python3.10/site-packages/django/core/handlers/base.py", line 197, in _get_response
    response = wrapped_callback(request, *callback_args, **callback_kwargs)
  File "/home/ubuntu/github/easygo/basecamp/views.py", line 1166, in p2p
    email.send()
  File "/home/ubuntu/github/easygo/venv/lib/python3.10/site-packages/django/core/mail/message.py", line 298, in send
    return self.get_connection(fail_silently).send_messages([self])
  File "/home/ubuntu/github/easygo/venv/lib/python3.10/site-packages/django/core/mail/backends/smtp.py", line 124, in send_messages
    new_conn_created = self.open()
  File "/home/ubuntu/github/easygo/venv/lib/python3.10/site-packages/django/core/mail/backends/smtp.py", line 91, in open
    self.connection.login(self.username, self.password)
  File "/usr/lib/python3.10/smtplib.py", line 739, in login
    (code, resp) = self.auth(
  File "/usr/lib/python3.10/smtplib.py", line 642, in auth
    (code, resp) = self.docmd("AUTH", mechanism + " " + response)
  File "/usr/lib/python3.10/smtplib.py", line 432, in docmd
    return self.getreply()
  File "/usr/lib/python3.10/smtplib.py", line 405, in getreply
    raise SMTPServerDisconnected("Connection unexpectedly closed")
smtplib.SMTPServerDisconnected: Connection unexpectedly closed
ERROR 2023-10-29 03:31:36,256 log Internal Server Error: /p2p/
Traceback (most recent call last):
  File "/home/ubuntu/github/easygo/venv/lib/python3.10/site-packages/django/core/handlers/exception.py", line 56, in inner
    response = get_response(request)
  File "/home/ubuntu/github/easygo/venv/lib/python3.10/site-packages/django/core/handlers/base.py", line 197, in _get_response
    response = wrapped_callback(request, *callback_args, **callback_kwargs)
  File "/home/ubuntu/github/easygo/basecamp/views.py", line 1166, in p2p
    email.send()
  File "/home/ubuntu/github/easygo/venv/lib/python3.10/site-packages/django/core/mail/message.py", line 298, in send
    return self.get_connection(fail_silently).send_messages([self])
  File "/home/ubuntu/github/easygo/venv/lib/python3.10/site-packages/django/core/mail/backends/smtp.py", line 124, in send_messages
    new_conn_created = self.open()
  File "/home/ubuntu/github/easygo/venv/lib/python3.10/site-packages/django/core/mail/backends/smtp.py", line 91, in open
    self.connection.login(self.username, self.password)
  File "/usr/lib/python3.10/smtplib.py", line 739, in login
    (code, resp) = self.auth(
  File "/usr/lib/python3.10/smtplib.py", line 642, in auth
    (code, resp) = self.docmd("AUTH", mechanism + " " + response)
  File "/usr/lib/python3.10/smtplib.py", line 432, in docmd
    return self.getreply()
  File "/usr/lib/python3.10/smtplib.py", line 405, in getreply
    raise SMTPServerDisconnected("Connection unexpectedly closed")
smtplib.SMTPServerDisconnected: Connection unexpectedly closed
ERROR 2023-10-29 03:31:38,833 log Internal Server Error: /p2p/
Traceback (most recent call last):
  File "/home/ubuntu/github/easygo/venv/lib/python3.10/site-packages/django/core/handlers/exception.py", line 56, in inner
    response = get_response(request)
  File "/home/ubuntu/github/easygo/venv/lib/python3.10/site-packages/django/core/handlers/base.py", line 197, in _get_response
    response = wrapped_callback(request, *callback_args, **callback_kwargs)
  File "/home/ubuntu/github/easygo/basecamp/views.py", line 1166, in p2p
    email.send()
  File "/home/ubuntu/github/easygo/venv/lib/python3.10/site-packages/django/core/mail/message.py", line 298, in send
    return self.get_connection(fail_silently).send_messages([self])
  File "/home/ubuntu/github/easygo/venv/lib/python3.10/site-packages/django/core/mail/backends/smtp.py", line 124, in send_messages
    new_conn_created = self.open()
  File "/home/ubuntu/github/easygo/venv/lib/python3.10/site-packages/django/core/mail/backends/smtp.py", line 91, in open
    self.connection.login(self.username, self.password)
  File "/usr/lib/python3.10/smtplib.py", line 739, in login
    (code, resp) = self.auth(
  File "/usr/lib/python3.10/smtplib.py", line 642, in auth
    (code, resp) = self.docmd("AUTH", mechanism + " " + response)
  File "/usr/lib/python3.10/smtplib.py", line 432, in docmd
    return self.getreply()
  File "/usr/lib/python3.10/smtplib.py", line 405, in getreply
    raise SMTPServerDisconnected("Connection unexpectedly closed")
smtplib.SMTPServerDisconnected: Connection unexpectedly closed
ERROR 2023-10-29 03:31:42,115 log Internal Server Error: /p2p/
Traceback (most recent call last):
  File "/home/ubuntu/github/easygo/venv/lib/python3.10/site-packages/django/core/handlers/exception.py", line 56, in inner
    response = get_response(request)
  File "/home/ubuntu/github/easygo/venv/lib/python3.10/site-packages/django/core/handlers/base.py", line 197, in _get_response
    response = wrapped_callback(request, *callback_args, **callback_kwargs)
  File "/home/ubuntu/github/easygo/basecamp/views.py", line 1166, in p2p
    email.send()
  File "/home/ubuntu/github/easygo/venv/lib/python3.10/site-packages/django/core/mail/message.py", line 298, in send
    return self.get_connection(fail_silently).send_messages([self])
  File "/home/ubuntu/github/easygo/venv/lib/python3.10/site-packages/django/core/mail/backends/smtp.py", line 124, in send_messages
    new_conn_created = self.open()
  File "/home/ubuntu/github/easygo/venv/lib/python3.10/site-packages/django/core/mail/backends/smtp.py", line 91, in open
    self.connection.login(self.username, self.password)
  File "/usr/lib/python3.10/smtplib.py", line 739, in login
    (code, resp) = self.auth(
  File "/usr/lib/python3.10/smtplib.py", line 642, in auth
    (code, resp) = self.docmd("AUTH", mechanism + " " + response)
  File "/usr/lib/python3.10/smtplib.py", line 432, in docmd
    return self.getreply()
  File "/usr/lib/python3.10/smtplib.py", line 405, in getreply
    raise SMTPServerDisconnected("Connection unexpectedly closed")
smtplib.SMTPServerDisconnected: Connection unexpectedly closed
ERROR 2023-10-29 03:31:44,639 log Internal Server Error: /p2p/
Traceback (most recent call last):
  File "/home/ubuntu/github/easygo/venv/lib/python3.10/site-packages/django/core/handlers/exception.py", line 56, in inner
    response = get_response(request)
  File "/home/ubuntu/github/easygo/venv/lib/python3.10/site-packages/django/core/handlers/base.py", line 197, in _get_response
    response = wrapped_callback(request, *callback_args, **callback_kwargs)
  File "/home/ubuntu/github/easygo/basecamp/views.py", line 1166, in p2p
    email.send()
  File "/home/ubuntu/github/easygo/venv/lib/python3.10/site-packages/django/core/mail/message.py", line 298, in send
    return self.get_connection(fail_silently).send_messages([self])
  File "/home/ubuntu/github/easygo/venv/lib/python3.10/site-packages/django/core/mail/backends/smtp.py", line 124, in send_messages
    new_conn_created = self.open()
  File "/home/ubuntu/github/easygo/venv/lib/python3.10/site-packages/django/core/mail/backends/smtp.py", line 91, in open
    self.connection.login(self.username, self.password)
  File "/usr/lib/python3.10/smtplib.py", line 739, in login
    (code, resp) = self.auth(
  File "/usr/lib/python3.10/smtplib.py", line 642, in auth
    (code, resp) = self.docmd("AUTH", mechanism + " " + response)
  File "/usr/lib/python3.10/smtplib.py", line 432, in docmd
    return self.getreply()
  File "/usr/lib/python3.10/smtplib.py", line 405, in getreply
    raise SMTPServerDisconnected("Connection unexpectedly closed")
smtplib.SMTPServerDisconnected: Connection unexpectedly closed
ERROR 2023-10-29 03:31:47,158 log Internal Server Error: /p2p/
Traceback (most recent call last):
  File "/home/ubuntu/github/easygo/venv/lib/python3.10/site-packages/django/core/handlers/exception.py", line 56, in inner
    response = get_response(request)
  File "/home/ubuntu/github/easygo/venv/lib/python3.10/site-packages/django/core/handlers/base.py", line 197, in _get_response
    response = wrapped_callback(request, *callback_args, **callback_kwargs)
  File "/home/ubuntu/github/easygo/basecamp/views.py", line 1166, in p2p
    email.send()
  File "/home/ubuntu/github/easygo/venv/lib/python3.10/site-packages/django/core/mail/message.py", line 298, in send
    return self.get_connection(fail_silently).send_messages([self])
  File "/home/ubuntu/github/easygo/venv/lib/python3.10/site-packages/django/core/mail/backends/smtp.py", line 124, in send_messages
    new_conn_created = self.open()
  File "/home/ubuntu/github/easygo/venv/lib/python3.10/site-packages/django/core/mail/backends/smtp.py", line 91, in open
    self.connection.login(self.username, self.password)
  File "/usr/lib/python3.10/smtplib.py", line 739, in login
    (code, resp) = self.auth(
  File "/usr/lib/python3.10/smtplib.py", line 642, in auth
    (code, resp) = self.docmd("AUTH", mechanism + " " + response)
  File "/usr/lib/python3.10/smtplib.py", line 432, in docmd
    return self.getreply()
  File "/usr/lib/python3.10/smtplib.py", line 405, in getreply
    raise SMTPServerDisconnected("Connection unexpectedly closed")
smtplib.SMTPServerDisconnected: Connection unexpectedly closed
ERROR 2023-10-29 03:31:49,686 log Internal Server Error: /p2p/
Traceback (most recent call last):
  File "/home/ubuntu/github/easygo/venv/lib/python3.10/site-packages/django/core/handlers/exception.py", line 56, in inner
    response = get_response(request)
  File "/home/ubuntu/github/easygo/venv/lib/python3.10/site-packages/django/core/handlers/base.py", line 197, in _get_response
    response = wrapped_callback(request, *callback_args, **callback_kwargs)
  File "/home/ubuntu/github/easygo/basecamp/views.py", line 1166, in p2p
    email.send()
  File "/home/ubuntu/github/easygo/venv/lib/python3.10/site-packages/django/core/mail/message.py", line 298, in send
    return self.get_connection(fail_silently).send_messages([self])
  File "/home/ubuntu/github/easygo/venv/lib/python3.10/site-packages/django/core/mail/backends/smtp.py", line 124, in send_messages
    new_conn_created = self.open()
  File "/home/ubuntu/github/easygo/venv/lib/python3.10/site-packages/django/core/mail/backends/smtp.py", line 91, in open
    self.connection.login(self.username, self.password)
  File "/usr/lib/python3.10/smtplib.py", line 739, in login
    (code, resp) = self.auth(
  File "/usr/lib/python3.10/smtplib.py", line 642, in auth
    (code, resp) = self.docmd("AUTH", mechanism + " " + response)
  File "/usr/lib/python3.10/smtplib.py", line 432, in docmd
    return self.getreply()
  File "/usr/lib/python3.10/smtplib.py", line 405, in getreply
    raise SMTPServerDisconnected("Connection unexpectedly closed")
smtplib.SMTPServerDisconnected: Connection unexpectedly closed
ERROR 2023-10-29 03:31:52,198 log Internal Server Error: /p2p/
Traceback (most recent call last):
  File "/home/ubuntu/github/easygo/venv/lib/python3.10/site-packages/django/core/handlers/exception.py", line 56, in inner
    response = get_response(request)
  File "/home/ubuntu/github/easygo/venv/lib/python3.10/site-packages/django/core/handlers/base.py", line 197, in _get_response
    response = wrapped_callback(request, *callback_args, **callback_kwargs)
  File "/home/ubuntu/github/easygo/basecamp/views.py", line 1166, in p2p
    email.send()
  File "/home/ubuntu/github/easygo/venv/lib/python3.10/site-packages/django/core/mail/message.py", line 298, in send
    return self.get_connection(fail_silently).send_messages([self])
  File "/home/ubuntu/github/easygo/venv/lib/python3.10/site-packages/django/core/mail/backends/smtp.py", line 124, in send_messages
    new_conn_created = self.open()
  File "/home/ubuntu/github/easygo/venv/lib/python3.10/site-packages/django/core/mail/backends/smtp.py", line 91, in open
    self.connection.login(self.username, self.password)
  File "/usr/lib/python3.10/smtplib.py", line 739, in login
    (code, resp) = self.auth(
  File "/usr/lib/python3.10/smtplib.py", line 642, in auth
    (code, resp) = self.docmd("AUTH", mechanism + " " + response)
  File "/usr/lib/python3.10/smtplib.py", line 432, in docmd
    return self.getreply()
  File "/usr/lib/python3.10/smtplib.py", line 405, in getreply
    raise SMTPServerDisconnected("Connection unexpectedly closed")
smtplib.SMTPServerDisconnected: Connection unexpectedly closed
ERROR 2023-10-29 03:31:54,766 log Internal Server Error: /p2p/
Traceback (most recent call last):
  File "/home/ubuntu/github/easygo/venv/lib/python3.10/site-packages/django/core/handlers/exception.py", line 56, in inner
    response = get_response(request)
  File "/home/ubuntu/github/easygo/venv/lib/python3.10/site-packages/django/core/handlers/base.py", line 197, in _get_response
    response = wrapped_callback(request, *callback_args, **callback_kwargs)
  File "/home/ubuntu/github/easygo/basecamp/views.py", line 1166, in p2p
    email.send()
  File "/home/ubuntu/github/easygo/venv/lib/python3.10/site-packages/django/core/mail/message.py", line 298, in send
    return self.get_connection(fail_silently).send_messages([self])
  File "/home/ubuntu/github/easygo/venv/lib/python3.10/site-packages/django/core/mail/backends/smtp.py", line 124, in send_messages
    new_conn_created = self.open()
  File "/home/ubuntu/github/easygo/venv/lib/python3.10/site-packages/django/core/mail/backends/smtp.py", line 91, in open
    self.connection.login(self.username, self.password)
  File "/usr/lib/python3.10/smtplib.py", line 739, in login
    (code, resp) = self.auth(
  File "/usr/lib/python3.10/smtplib.py", line 642, in auth
    (code, resp) = self.docmd("AUTH", mechanism + " " + response)
  File "/usr/lib/python3.10/smtplib.py", line 432, in docmd
    return self.getreply()
  File "/usr/lib/python3.10/smtplib.py", line 405, in getreply
    raise SMTPServerDisconnected("Connection unexpectedly closed")
smtplib.SMTPServerDisconnected: Connection unexpectedly closed
ERROR 2023-10-29 03:31:57,286 log Internal Server Error: /p2p/
Traceback (most recent call last):
  File "/home/ubuntu/github/easygo/venv/lib/python3.10/site-packages/django/core/handlers/exception.py", line 56, in inner
    response = get_response(request)
  File "/home/ubuntu/github/easygo/venv/lib/python3.10/site-packages/django/core/handlers/base.py", line 197, in _get_response
    response = wrapped_callback(request, *callback_args, **callback_kwargs)
  File "/home/ubuntu/github/easygo/basecamp/views.py", line 1166, in p2p
    email.send()
  File "/home/ubuntu/github/easygo/venv/lib/python3.10/site-packages/django/core/mail/message.py", line 298, in send
    return self.get_connection(fail_silently).send_messages([self])
  File "/home/ubuntu/github/easygo/venv/lib/python3.10/site-packages/django/core/mail/backends/smtp.py", line 124, in send_messages
    new_conn_created = self.open()
  File "/home/ubuntu/github/easygo/venv/lib/python3.10/site-packages/django/core/mail/backends/smtp.py", line 91, in open
    self.connection.login(self.username, self.password)
  File "/usr/lib/python3.10/smtplib.py", line 739, in login
    (code, resp) = self.auth(
  File "/usr/lib/python3.10/smtplib.py", line 642, in auth
    (code, resp) = self.docmd("AUTH", mechanism + " " + response)
  File "/usr/lib/python3.10/smtplib.py", line 432, in docmd
    return self.getreply()
  File "/usr/lib/python3.10/smtplib.py", line 405, in getreply
    raise SMTPServerDisconnected("Connection unexpectedly closed")
smtplib.SMTPServerDisconnected: Connection unexpectedly closed
ERROR 2023-10-29 03:31:59,804 log Internal Server Error: /p2p/
Traceback (most recent call last):
  File "/home/ubuntu/github/easygo/venv/lib/python3.10/site-packages/django/core/handlers/exception.py", line 56, in inner
    response = get_response(request)
  File "/home/ubuntu/github/easygo/venv/lib/python3.10/site-packages/django/core/handlers/base.py", line 197, in _get_response
    response = wrapped_callback(request, *callback_args, **callback_kwargs)
  File "/home/ubuntu/github/easygo/basecamp/views.py", line 1166, in p2p
    email.send()
  File "/home/ubuntu/github/easygo/venv/lib/python3.10/site-packages/django/core/mail/message.py", line 298, in send
    return self.get_connection(fail_silently).send_messages([self])
  File "/home/ubuntu/github/easygo/venv/lib/python3.10/site-packages/django/core/mail/backends/smtp.py", line 124, in send_messages
    new_conn_created = self.open()
  File "/home/ubuntu/github/easygo/venv/lib/python3.10/site-packages/django/core/mail/backends/smtp.py", line 91, in open
    self.connection.login(self.username, self.password)
  File "/usr/lib/python3.10/smtplib.py", line 739, in login
    (code, resp) = self.auth(
  File "/usr/lib/python3.10/smtplib.py", line 642, in auth
    (code, resp) = self.docmd("AUTH", mechanism + " " + response)
  File "/usr/lib/python3.10/smtplib.py", line 432, in docmd
    return self.getreply()
  File "/usr/lib/python3.10/smtplib.py", line 405, in getreply
    raise SMTPServerDisconnected("Connection unexpectedly closed")
smtplib.SMTPServerDisconnected: Connection unexpectedly closed
ERROR 2023-10-29 03:32:02,321 log Internal Server Error: /p2p/
Traceback (most recent call last):
  File "/home/ubuntu/github/easygo/venv/lib/python3.10/site-packages/django/core/handlers/exception.py", line 56, in inner
    response = get_response(request)
  File "/home/ubuntu/github/easygo/venv/lib/python3.10/site-packages/django/core/handlers/base.py", line 197, in _get_response
    response = wrapped_callback(request, *callback_args, **callback_kwargs)
  File "/home/ubuntu/github/easygo/basecamp/views.py", line 1166, in p2p
    email.send()
  File "/home/ubuntu/github/easygo/venv/lib/python3.10/site-packages/django/core/mail/message.py", line 298, in send
    return self.get_connection(fail_silently).send_messages([self])
  File "/home/ubuntu/github/easygo/venv/lib/python3.10/site-packages/django/core/mail/backends/smtp.py", line 124, in send_messages
    new_conn_created = self.open()
  File "/home/ubuntu/github/easygo/venv/lib/python3.10/site-packages/django/core/mail/backends/smtp.py", line 91, in open
    self.connection.login(self.username, self.password)
  File "/usr/lib/python3.10/smtplib.py", line 739, in login
    (code, resp) = self.auth(
  File "/usr/lib/python3.10/smtplib.py", line 642, in auth
    (code, resp) = self.docmd("AUTH", mechanism + " " + response)
  File "/usr/lib/python3.10/smtplib.py", line 432, in docmd
    return self.getreply()
  File "/usr/lib/python3.10/smtplib.py", line 405, in getreply
    raise SMTPServerDisconnected("Connection unexpectedly closed")
smtplib.SMTPServerDisconnected: Connection unexpectedly closed
ERROR 2023-10-29 03:32:04,858 log Internal Server Error: /p2p/
Traceback (most recent call last):
  File "/home/ubuntu/github/easygo/venv/lib/python3.10/site-packages/django/core/handlers/exception.py", line 56, in inner
    response = get_response(request)
  File "/home/ubuntu/github/easygo/venv/lib/python3.10/site-packages/django/core/handlers/base.py", line 197, in _get_response
    response = wrapped_callback(request, *callback_args, **callback_kwargs)
  File "/home/ubuntu/github/easygo/basecamp/views.py", line 1166, in p2p
    email.send()
  File "/home/ubuntu/github/easygo/venv/lib/python3.10/site-packages/django/core/mail/message.py", line 298, in send
    return self.get_connection(fail_silently).send_messages([self])
  File "/home/ubuntu/github/easygo/venv/lib/python3.10/site-packages/django/core/mail/backends/smtp.py", line 124, in send_messages
    new_conn_created = self.open()
  File "/home/ubuntu/github/easygo/venv/lib/python3.10/site-packages/django/core/mail/backends/smtp.py", line 91, in open
    self.connection.login(self.username, self.password)
  File "/usr/lib/python3.10/smtplib.py", line 739, in login
    (code, resp) = self.auth(
  File "/usr/lib/python3.10/smtplib.py", line 642, in auth
    (code, resp) = self.docmd("AUTH", mechanism + " " + response)
  File "/usr/lib/python3.10/smtplib.py", line 432, in docmd
    return self.getreply()
  File "/usr/lib/python3.10/smtplib.py", line 405, in getreply
    raise SMTPServerDisconnected("Connection unexpectedly closed")
smtplib.SMTPServerDisconnected: Connection unexpectedly closed
ERROR 2023-10-29 03:32:07,383 log Internal Server Error: /p2p/
Traceback (most recent call last):
  File "/home/ubuntu/github/easygo/venv/lib/python3.10/site-packages/django/core/handlers/exception.py", line 56, in inner
    response = get_response(request)
  File "/home/ubuntu/github/easygo/venv/lib/python3.10/site-packages/django/core/handlers/base.py", line 197, in _get_response
    response = wrapped_callback(request, *callback_args, **callback_kwargs)
  File "/home/ubuntu/github/easygo/basecamp/views.py", line 1166, in p2p
    email.send()
  File "/home/ubuntu/github/easygo/venv/lib/python3.10/site-packages/django/core/mail/message.py", line 298, in send
    return self.get_connection(fail_silently).send_messages([self])
  File "/home/ubuntu/github/easygo/venv/lib/python3.10/site-packages/django/core/mail/backends/smtp.py", line 124, in send_messages
    new_conn_created = self.open()
  File "/home/ubuntu/github/easygo/venv/lib/python3.10/site-packages/django/core/mail/backends/smtp.py", line 91, in open
    self.connection.login(self.username, self.password)
  File "/usr/lib/python3.10/smtplib.py", line 739, in login
    (code, resp) = self.auth(
  File "/usr/lib/python3.10/smtplib.py", line 642, in auth
    (code, resp) = self.docmd("AUTH", mechanism + " " + response)
  File "/usr/lib/python3.10/smtplib.py", line 432, in docmd
    return self.getreply()
  File "/usr/lib/python3.10/smtplib.py", line 405, in getreply
    raise SMTPServerDisconnected("Connection unexpectedly closed")
smtplib.SMTPServerDisconnected: Connection unexpectedly closed
ERROR 2023-10-29 03:32:09,899 log Internal Server Error: /p2p/
Traceback (most recent call last):
  File "/home/ubuntu/github/easygo/venv/lib/python3.10/site-packages/django/core/handlers/exception.py", line 56, in inner
    response = get_response(request)
  File "/home/ubuntu/github/easygo/venv/lib/python3.10/site-packages/django/core/handlers/base.py", line 197, in _get_response
    response = wrapped_callback(request, *callback_args, **callback_kwargs)
  File "/home/ubuntu/github/easygo/basecamp/views.py", line 1166, in p2p
    email.send()
  File "/home/ubuntu/github/easygo/venv/lib/python3.10/site-packages/django/core/mail/message.py", line 298, in send
    return self.get_connection(fail_silently).send_messages([self])
  File "/home/ubuntu/github/easygo/venv/lib/python3.10/site-packages/django/core/mail/backends/smtp.py", line 124, in send_messages
    new_conn_created = self.open()
  File "/home/ubuntu/github/easygo/venv/lib/python3.10/site-packages/django/core/mail/backends/smtp.py", line 91, in open
    self.connection.login(self.username, self.password)
  File "/usr/lib/python3.10/smtplib.py", line 739, in login
    (code, resp) = self.auth(
  File "/usr/lib/python3.10/smtplib.py", line 642, in auth
    (code, resp) = self.docmd("AUTH", mechanism + " " + response)
  File "/usr/lib/python3.10/smtplib.py", line 432, in docmd
    return self.getreply()
  File "/usr/lib/python3.10/smtplib.py", line 405, in getreply
    raise SMTPServerDisconnected("Connection unexpectedly closed")
smtplib.SMTPServerDisconnected: Connection unexpectedly closed
ERROR 2023-10-29 03:32:12,411 log Internal Server Error: /p2p/
Traceback (most recent call last):
  File "/home/ubuntu/github/easygo/venv/lib/python3.10/site-packages/django/core/handlers/exception.py", line 56, in inner
    response = get_response(request)
  File "/home/ubuntu/github/easygo/venv/lib/python3.10/site-packages/django/core/handlers/base.py", line 197, in _get_response
    response = wrapped_callback(request, *callback_args, **callback_kwargs)
  File "/home/ubuntu/github/easygo/basecamp/views.py", line 1166, in p2p
    email.send()
  File "/home/ubuntu/github/easygo/venv/lib/python3.10/site-packages/django/core/mail/message.py", line 298, in send
    return self.get_connection(fail_silently).send_messages([self])
  File "/home/ubuntu/github/easygo/venv/lib/python3.10/site-packages/django/core/mail/backends/smtp.py", line 124, in send_messages
    new_conn_created = self.open()
  File "/home/ubuntu/github/easygo/venv/lib/python3.10/site-packages/django/core/mail/backends/smtp.py", line 91, in open
    self.connection.login(self.username, self.password)
  File "/usr/lib/python3.10/smtplib.py", line 739, in login
    (code, resp) = self.auth(
  File "/usr/lib/python3.10/smtplib.py", line 642, in auth
    (code, resp) = self.docmd("AUTH", mechanism + " " + response)
  File "/usr/lib/python3.10/smtplib.py", line 432, in docmd
    return self.getreply()
  File "/usr/lib/python3.10/smtplib.py", line 405, in getreply
    raise SMTPServerDisconnected("Connection unexpectedly closed")
smtplib.SMTPServerDisconnected: Connection unexpectedly closed
WARNING 2023-10-29 03:32:13,409 log Forbidden (CSRF token from POST has incorrect length.): /p2p/
WARNING 2023-10-29 03:32:13,727 log Forbidden (CSRF token from POST has incorrect length.): /p2p/
WARNING 2023-10-29 03:32:14,047 log Forbidden (CSRF token from POST has incorrect length.): /p2p/
WARNING 2023-10-29 03:32:15,033 log Forbidden (CSRF token from POST has incorrect length.): /p2p/
WARNING 2023-10-29 03:32:16,021 log Forbidden (CSRF token from POST has incorrect length.): /p2p/
WARNING 2023-10-29 03:32:17,006 log Forbidden (CSRF token from POST has incorrect length.): /p2p/
WARNING 2023-10-29 03:32:17,991 log Forbidden (CSRF token from POST has incorrect length.): /p2p/
WARNING 2023-10-29 03:32:18,983 log Forbidden (CSRF token from POST has incorrect length.): /p2p/
WARNING 2023-10-29 03:32:19,966 log Forbidden (CSRF token from POST has incorrect length.): /p2p/
WARNING 2023-10-29 03:32:20,958 log Forbidden (CSRF token from POST has incorrect length.): /p2p/
WARNING 2023-10-29 03:32:21,942 log Forbidden (CSRF token from POST has incorrect length.): /p2p/
WARNING 2023-10-29 03:32:22,927 log Forbidden (CSRF token from POST has incorrect length.): /p2p/
ERROR 2023-10-29 03:32:25,443 log Internal Server Error: /p2p/
Traceback (most recent call last):
  File "/home/ubuntu/github/easygo/venv/lib/python3.10/site-packages/django/core/handlers/exception.py", line 56, in inner
    response = get_response(request)
  File "/home/ubuntu/github/easygo/venv/lib/python3.10/site-packages/django/core/handlers/base.py", line 197, in _get_response
    response = wrapped_callback(request, *callback_args, **callback_kwargs)
  File "/home/ubuntu/github/easygo/basecamp/views.py", line 1166, in p2p
    email.send()
  File "/home/ubuntu/github/easygo/venv/lib/python3.10/site-packages/django/core/mail/message.py", line 298, in send
    return self.get_connection(fail_silently).send_messages([self])
  File "/home/ubuntu/github/easygo/venv/lib/python3.10/site-packages/django/core/mail/backends/smtp.py", line 124, in send_messages
    new_conn_created = self.open()
  File "/home/ubuntu/github/easygo/venv/lib/python3.10/site-packages/django/core/mail/backends/smtp.py", line 91, in open
    self.connection.login(self.username, self.password)
  File "/usr/lib/python3.10/smtplib.py", line 739, in login
    (code, resp) = self.auth(
  File "/usr/lib/python3.10/smtplib.py", line 642, in auth
    (code, resp) = self.docmd("AUTH", mechanism + " " + response)
  File "/usr/lib/python3.10/smtplib.py", line 432, in docmd
    return self.getreply()
  File "/usr/lib/python3.10/smtplib.py", line 405, in getreply
    raise SMTPServerDisconnected("Connection unexpectedly closed")
smtplib.SMTPServerDisconnected: Connection unexpectedly closed
ERROR 2023-10-29 03:32:27,343 log Internal Server Error: /p2p/
Traceback (most recent call last):
  File "/home/ubuntu/github/easygo/venv/lib/python3.10/site-packages/django/core/handlers/exception.py", line 56, in inner
    response = get_response(request)
  File "/home/ubuntu/github/easygo/venv/lib/python3.10/site-packages/django/core/handlers/base.py", line 197, in _get_response
    response = wrapped_callback(request, *callback_args, **callback_kwargs)
  File "/home/ubuntu/github/easygo/basecamp/views.py", line 1166, in p2p
    email.send()
  File "/home/ubuntu/github/easygo/venv/lib/python3.10/site-packages/django/core/mail/message.py", line 298, in send
    return self.get_connection(fail_silently).send_messages([self])
  File "/home/ubuntu/github/easygo/venv/lib/python3.10/site-packages/django/core/mail/backends/smtp.py", line 124, in send_messages
    new_conn_created = self.open()
  File "/home/ubuntu/github/easygo/venv/lib/python3.10/site-packages/django/core/mail/backends/smtp.py", line 91, in open
    self.connection.login(self.username, self.password)
  File "/usr/lib/python3.10/smtplib.py", line 739, in login
    (code, resp) = self.auth(
  File "/usr/lib/python3.10/smtplib.py", line 642, in auth
    (code, resp) = self.docmd("AUTH", mechanism + " " + response)
  File "/usr/lib/python3.10/smtplib.py", line 432, in docmd
    return self.getreply()
  File "/usr/lib/python3.10/smtplib.py", line 405, in getreply
    raise SMTPServerDisconnected("Connection unexpectedly closed")
smtplib.SMTPServerDisconnected: Connection unexpectedly closed
ERROR 2023-10-29 03:32:29,203 log Internal Server Error: /p2p/
Traceback (most recent call last):
  File "/home/ubuntu/github/easygo/venv/lib/python3.10/site-packages/django/core/handlers/exception.py", line 56, in inner
    response = get_response(request)
  File "/home/ubuntu/github/easygo/venv/lib/python3.10/site-packages/django/core/handlers/base.py", line 197, in _get_response
    response = wrapped_callback(request, *callback_args, **callback_kwargs)
  File "/home/ubuntu/github/easygo/basecamp/views.py", line 1166, in p2p
    email.send()
  File "/home/ubuntu/github/easygo/venv/lib/python3.10/site-packages/django/core/mail/message.py", line 298, in send
    return self.get_connection(fail_silently).send_messages([self])
  File "/home/ubuntu/github/easygo/venv/lib/python3.10/site-packages/django/core/mail/backends/smtp.py", line 124, in send_messages
    new_conn_created = self.open()
  File "/home/ubuntu/github/easygo/venv/lib/python3.10/site-packages/django/core/mail/backends/smtp.py", line 91, in open
    self.connection.login(self.username, self.password)
  File "/usr/lib/python3.10/smtplib.py", line 739, in login
    (code, resp) = self.auth(
  File "/usr/lib/python3.10/smtplib.py", line 642, in auth
    (code, resp) = self.docmd("AUTH", mechanism + " " + response)
  File "/usr/lib/python3.10/smtplib.py", line 432, in docmd
    return self.getreply()
  File "/usr/lib/python3.10/smtplib.py", line 405, in getreply
    raise SMTPServerDisconnected("Connection unexpectedly closed")
smtplib.SMTPServerDisconnected: Connection unexpectedly closed
ERROR 2023-10-29 03:32:31,719 log Internal Server Error: /p2p/
Traceback (most recent call last):
  File "/home/ubuntu/github/easygo/venv/lib/python3.10/site-packages/django/core/handlers/exception.py", line 56, in inner
    response = get_response(request)
  File "/home/ubuntu/github/easygo/venv/lib/python3.10/site-packages/django/core/handlers/base.py", line 197, in _get_response
    response = wrapped_callback(request, *callback_args, **callback_kwargs)
  File "/home/ubuntu/github/easygo/basecamp/views.py", line 1166, in p2p
    email.send()
  File "/home/ubuntu/github/easygo/venv/lib/python3.10/site-packages/django/core/mail/message.py", line 298, in send
    return self.get_connection(fail_silently).send_messages([self])
  File "/home/ubuntu/github/easygo/venv/lib/python3.10/site-packages/django/core/mail/backends/smtp.py", line 124, in send_messages
    new_conn_created = self.open()
  File "/home/ubuntu/github/easygo/venv/lib/python3.10/site-packages/django/core/mail/backends/smtp.py", line 91, in open
    self.connection.login(self.username, self.password)
  File "/usr/lib/python3.10/smtplib.py", line 739, in login
    (code, resp) = self.auth(
  File "/usr/lib/python3.10/smtplib.py", line 642, in auth
    (code, resp) = self.docmd("AUTH", mechanism + " " + response)
  File "/usr/lib/python3.10/smtplib.py", line 432, in docmd
    return self.getreply()
  File "/usr/lib/python3.10/smtplib.py", line 405, in getreply
    raise SMTPServerDisconnected("Connection unexpectedly closed")
smtplib.SMTPServerDisconnected: Connection unexpectedly closed
ERROR 2023-10-29 03:32:34,242 log Internal Server Error: /p2p/
Traceback (most recent call last):
  File "/home/ubuntu/github/easygo/venv/lib/python3.10/site-packages/django/core/handlers/exception.py", line 56, in inner
    response = get_response(request)
  File "/home/ubuntu/github/easygo/venv/lib/python3.10/site-packages/django/core/handlers/base.py", line 197, in _get_response
    response = wrapped_callback(request, *callback_args, **callback_kwargs)
  File "/home/ubuntu/github/easygo/basecamp/views.py", line 1166, in p2p
    email.send()
  File "/home/ubuntu/github/easygo/venv/lib/python3.10/site-packages/django/core/mail/message.py", line 298, in send
    return self.get_connection(fail_silently).send_messages([self])
  File "/home/ubuntu/github/easygo/venv/lib/python3.10/site-packages/django/core/mail/backends/smtp.py", line 124, in send_messages
    new_conn_created = self.open()
  File "/home/ubuntu/github/easygo/venv/lib/python3.10/site-packages/django/core/mail/backends/smtp.py", line 91, in open
    self.connection.login(self.username, self.password)
  File "/usr/lib/python3.10/smtplib.py", line 739, in login
    (code, resp) = self.auth(
  File "/usr/lib/python3.10/smtplib.py", line 642, in auth
    (code, resp) = self.docmd("AUTH", mechanism + " " + response)
  File "/usr/lib/python3.10/smtplib.py", line 432, in docmd
    return self.getreply()
  File "/usr/lib/python3.10/smtplib.py", line 405, in getreply
    raise SMTPServerDisconnected("Connection unexpectedly closed")
smtplib.SMTPServerDisconnected: Connection unexpectedly closed
ERROR 2023-10-29 03:32:37,395 log Internal Server Error: /p2p/
Traceback (most recent call last):
  File "/home/ubuntu/github/easygo/venv/lib/python3.10/site-packages/django/core/handlers/exception.py", line 56, in inner
    response = get_response(request)
  File "/home/ubuntu/github/easygo/venv/lib/python3.10/site-packages/django/core/handlers/base.py", line 197, in _get_response
    response = wrapped_callback(request, *callback_args, **callback_kwargs)
  File "/home/ubuntu/github/easygo/basecamp/views.py", line 1166, in p2p
    email.send()
  File "/home/ubuntu/github/easygo/venv/lib/python3.10/site-packages/django/core/mail/message.py", line 298, in send
    return self.get_connection(fail_silently).send_messages([self])
  File "/home/ubuntu/github/easygo/venv/lib/python3.10/site-packages/django/core/mail/backends/smtp.py", line 124, in send_messages
    new_conn_created = self.open()
  File "/home/ubuntu/github/easygo/venv/lib/python3.10/site-packages/django/core/mail/backends/smtp.py", line 91, in open
    self.connection.login(self.username, self.password)
  File "/usr/lib/python3.10/smtplib.py", line 739, in login
    (code, resp) = self.auth(
  File "/usr/lib/python3.10/smtplib.py", line 642, in auth
    (code, resp) = self.docmd("AUTH", mechanism + " " + response)
  File "/usr/lib/python3.10/smtplib.py", line 432, in docmd
    return self.getreply()
  File "/usr/lib/python3.10/smtplib.py", line 405, in getreply
    raise SMTPServerDisconnected("Connection unexpectedly closed")
smtplib.SMTPServerDisconnected: Connection unexpectedly closed
ERROR 2023-10-29 03:32:39,967 log Internal Server Error: /p2p/
Traceback (most recent call last):
  File "/home/ubuntu/github/easygo/venv/lib/python3.10/site-packages/django/core/handlers/exception.py", line 56, in inner
    response = get_response(request)
  File "/home/ubuntu/github/easygo/venv/lib/python3.10/site-packages/django/core/handlers/base.py", line 197, in _get_response
    response = wrapped_callback(request, *callback_args, **callback_kwargs)
  File "/home/ubuntu/github/easygo/basecamp/views.py", line 1166, in p2p
    email.send()
  File "/home/ubuntu/github/easygo/venv/lib/python3.10/site-packages/django/core/mail/message.py", line 298, in send
    return self.get_connection(fail_silently).send_messages([self])
  File "/home/ubuntu/github/easygo/venv/lib/python3.10/site-packages/django/core/mail/backends/smtp.py", line 124, in send_messages
    new_conn_created = self.open()
  File "/home/ubuntu/github/easygo/venv/lib/python3.10/site-packages/django/core/mail/backends/smtp.py", line 91, in open
    self.connection.login(self.username, self.password)
  File "/usr/lib/python3.10/smtplib.py", line 739, in login
    (code, resp) = self.auth(
  File "/usr/lib/python3.10/smtplib.py", line 642, in auth
    (code, resp) = self.docmd("AUTH", mechanism + " " + response)
  File "/usr/lib/python3.10/smtplib.py", line 432, in docmd
    return self.getreply()
  File "/usr/lib/python3.10/smtplib.py", line 405, in getreply
    raise SMTPServerDisconnected("Connection unexpectedly closed")
smtplib.SMTPServerDisconnected: Connection unexpectedly closed
ERROR 2023-10-29 03:32:42,487 log Internal Server Error: /p2p/
Traceback (most recent call last):
  File "/home/ubuntu/github/easygo/venv/lib/python3.10/site-packages/django/core/handlers/exception.py", line 56, in inner
    response = get_response(request)
  File "/home/ubuntu/github/easygo/venv/lib/python3.10/site-packages/django/core/handlers/base.py", line 197, in _get_response
    response = wrapped_callback(request, *callback_args, **callback_kwargs)
  File "/home/ubuntu/github/easygo/basecamp/views.py", line 1166, in p2p
    email.send()
  File "/home/ubuntu/github/easygo/venv/lib/python3.10/site-packages/django/core/mail/message.py", line 298, in send
    return self.get_connection(fail_silently).send_messages([self])
  File "/home/ubuntu/github/easygo/venv/lib/python3.10/site-packages/django/core/mail/backends/smtp.py", line 124, in send_messages
    new_conn_created = self.open()
  File "/home/ubuntu/github/easygo/venv/lib/python3.10/site-packages/django/core/mail/backends/smtp.py", line 91, in open
    self.connection.login(self.username, self.password)
  File "/usr/lib/python3.10/smtplib.py", line 739, in login
    (code, resp) = self.auth(
  File "/usr/lib/python3.10/smtplib.py", line 642, in auth
    (code, resp) = self.docmd("AUTH", mechanism + " " + response)
  File "/usr/lib/python3.10/smtplib.py", line 432, in docmd
    return self.getreply()
  File "/usr/lib/python3.10/smtplib.py", line 405, in getreply
    raise SMTPServerDisconnected("Connection unexpectedly closed")
smtplib.SMTPServerDisconnected: Connection unexpectedly closed
ERROR 2023-10-29 03:32:45,059 log Internal Server Error: /p2p/
Traceback (most recent call last):
  File "/home/ubuntu/github/easygo/venv/lib/python3.10/site-packages/django/core/handlers/exception.py", line 56, in inner
    response = get_response(request)
  File "/home/ubuntu/github/easygo/venv/lib/python3.10/site-packages/django/core/handlers/base.py", line 197, in _get_response
    response = wrapped_callback(request, *callback_args, **callback_kwargs)
  File "/home/ubuntu/github/easygo/basecamp/views.py", line 1166, in p2p
    email.send()
  File "/home/ubuntu/github/easygo/venv/lib/python3.10/site-packages/django/core/mail/message.py", line 298, in send
    return self.get_connection(fail_silently).send_messages([self])
  File "/home/ubuntu/github/easygo/venv/lib/python3.10/site-packages/django/core/mail/backends/smtp.py", line 124, in send_messages
    new_conn_created = self.open()
  File "/home/ubuntu/github/easygo/venv/lib/python3.10/site-packages/django/core/mail/backends/smtp.py", line 91, in open
    self.connection.login(self.username, self.password)
  File "/usr/lib/python3.10/smtplib.py", line 739, in login
    (code, resp) = self.auth(
  File "/usr/lib/python3.10/smtplib.py", line 642, in auth
    (code, resp) = self.docmd("AUTH", mechanism + " " + response)
  File "/usr/lib/python3.10/smtplib.py", line 432, in docmd
    return self.getreply()
  File "/usr/lib/python3.10/smtplib.py", line 405, in getreply
    raise SMTPServerDisconnected("Connection unexpectedly closed")
smtplib.SMTPServerDisconnected: Connection unexpectedly closed
ERROR 2023-10-29 03:32:47,632 log Internal Server Error: /p2p/
Traceback (most recent call last):
  File "/home/ubuntu/github/easygo/venv/lib/python3.10/site-packages/django/core/handlers/exception.py", line 56, in inner
    response = get_response(request)
  File "/home/ubuntu/github/easygo/venv/lib/python3.10/site-packages/django/core/handlers/base.py", line 197, in _get_response
    response = wrapped_callback(request, *callback_args, **callback_kwargs)
  File "/home/ubuntu/github/easygo/basecamp/views.py", line 1166, in p2p
    email.send()
  File "/home/ubuntu/github/easygo/venv/lib/python3.10/site-packages/django/core/mail/message.py", line 298, in send
    return self.get_connection(fail_silently).send_messages([self])
  File "/home/ubuntu/github/easygo/venv/lib/python3.10/site-packages/django/core/mail/backends/smtp.py", line 124, in send_messages
    new_conn_created = self.open()
  File "/home/ubuntu/github/easygo/venv/lib/python3.10/site-packages/django/core/mail/backends/smtp.py", line 91, in open
    self.connection.login(self.username, self.password)
  File "/usr/lib/python3.10/smtplib.py", line 739, in login
    (code, resp) = self.auth(
  File "/usr/lib/python3.10/smtplib.py", line 642, in auth
    (code, resp) = self.docmd("AUTH", mechanism + " " + response)
  File "/usr/lib/python3.10/smtplib.py", line 432, in docmd
    return self.getreply()
  File "/usr/lib/python3.10/smtplib.py", line 405, in getreply
    raise SMTPServerDisconnected("Connection unexpectedly closed")
smtplib.SMTPServerDisconnected: Connection unexpectedly closed
ERROR 2023-10-29 03:32:50,246 log Internal Server Error: /p2p/
Traceback (most recent call last):
  File "/home/ubuntu/github/easygo/venv/lib/python3.10/site-packages/django/core/handlers/exception.py", line 56, in inner
    response = get_response(request)
  File "/home/ubuntu/github/easygo/venv/lib/python3.10/site-packages/django/core/handlers/base.py", line 197, in _get_response
    response = wrapped_callback(request, *callback_args, **callback_kwargs)
  File "/home/ubuntu/github/easygo/basecamp/views.py", line 1166, in p2p
    email.send()
  File "/home/ubuntu/github/easygo/venv/lib/python3.10/site-packages/django/core/mail/message.py", line 298, in send
    return self.get_connection(fail_silently).send_messages([self])
  File "/home/ubuntu/github/easygo/venv/lib/python3.10/site-packages/django/core/mail/backends/smtp.py", line 124, in send_messages
    new_conn_created = self.open()
  File "/home/ubuntu/github/easygo/venv/lib/python3.10/site-packages/django/core/mail/backends/smtp.py", line 91, in open
    self.connection.login(self.username, self.password)
  File "/usr/lib/python3.10/smtplib.py", line 739, in login
    (code, resp) = self.auth(
  File "/usr/lib/python3.10/smtplib.py", line 642, in auth
    (code, resp) = self.docmd("AUTH", mechanism + " " + response)
  File "/usr/lib/python3.10/smtplib.py", line 432, in docmd
    return self.getreply()
  File "/usr/lib/python3.10/smtplib.py", line 405, in getreply
    raise SMTPServerDisconnected("Connection unexpectedly closed")
smtplib.SMTPServerDisconnected: Connection unexpectedly closed
ERROR 2023-10-29 03:32:53,446 log Internal Server Error: /p2p/
Traceback (most recent call last):
  File "/home/ubuntu/github/easygo/venv/lib/python3.10/site-packages/django/core/handlers/exception.py", line 56, in inner
    response = get_response(request)
  File "/home/ubuntu/github/easygo/venv/lib/python3.10/site-packages/django/core/handlers/base.py", line 197, in _get_response
    response = wrapped_callback(request, *callback_args, **callback_kwargs)
  File "/home/ubuntu/github/easygo/basecamp/views.py", line 1166, in p2p
    email.send()
  File "/home/ubuntu/github/easygo/venv/lib/python3.10/site-packages/django/core/mail/message.py", line 298, in send
    return self.get_connection(fail_silently).send_messages([self])
  File "/home/ubuntu/github/easygo/venv/lib/python3.10/site-packages/django/core/mail/backends/smtp.py", line 124, in send_messages
    new_conn_created = self.open()
  File "/home/ubuntu/github/easygo/venv/lib/python3.10/site-packages/django/core/mail/backends/smtp.py", line 91, in open
    self.connection.login(self.username, self.password)
  File "/usr/lib/python3.10/smtplib.py", line 739, in login
    (code, resp) = self.auth(
  File "/usr/lib/python3.10/smtplib.py", line 642, in auth
    (code, resp) = self.docmd("AUTH", mechanism + " " + response)
  File "/usr/lib/python3.10/smtplib.py", line 432, in docmd
    return self.getreply()
  File "/usr/lib/python3.10/smtplib.py", line 405, in getreply
    raise SMTPServerDisconnected("Connection unexpectedly closed")
smtplib.SMTPServerDisconnected: Connection unexpectedly closed
ERROR 2023-10-29 03:32:56,021 log Internal Server Error: /p2p/
Traceback (most recent call last):
  File "/home/ubuntu/github/easygo/venv/lib/python3.10/site-packages/django/core/handlers/exception.py", line 56, in inner
    response = get_response(request)
  File "/home/ubuntu/github/easygo/venv/lib/python3.10/site-packages/django/core/handlers/base.py", line 197, in _get_response
    response = wrapped_callback(request, *callback_args, **callback_kwargs)
  File "/home/ubuntu/github/easygo/basecamp/views.py", line 1166, in p2p
    email.send()
  File "/home/ubuntu/github/easygo/venv/lib/python3.10/site-packages/django/core/mail/message.py", line 298, in send
    return self.get_connection(fail_silently).send_messages([self])
  File "/home/ubuntu/github/easygo/venv/lib/python3.10/site-packages/django/core/mail/backends/smtp.py", line 124, in send_messages
    new_conn_created = self.open()
  File "/home/ubuntu/github/easygo/venv/lib/python3.10/site-packages/django/core/mail/backends/smtp.py", line 91, in open
    self.connection.login(self.username, self.password)
  File "/usr/lib/python3.10/smtplib.py", line 739, in login
    (code, resp) = self.auth(
  File "/usr/lib/python3.10/smtplib.py", line 642, in auth
    (code, resp) = self.docmd("AUTH", mechanism + " " + response)
  File "/usr/lib/python3.10/smtplib.py", line 432, in docmd
    return self.getreply()
  File "/usr/lib/python3.10/smtplib.py", line 405, in getreply
    raise SMTPServerDisconnected("Connection unexpectedly closed")
smtplib.SMTPServerDisconnected: Connection unexpectedly closed
ERROR 2023-10-29 03:32:58,543 log Internal Server Error: /p2p/
Traceback (most recent call last):
  File "/home/ubuntu/github/easygo/venv/lib/python3.10/site-packages/django/core/handlers/exception.py", line 56, in inner
    response = get_response(request)
  File "/home/ubuntu/github/easygo/venv/lib/python3.10/site-packages/django/core/handlers/base.py", line 197, in _get_response
    response = wrapped_callback(request, *callback_args, **callback_kwargs)
  File "/home/ubuntu/github/easygo/basecamp/views.py", line 1166, in p2p
    email.send()
  File "/home/ubuntu/github/easygo/venv/lib/python3.10/site-packages/django/core/mail/message.py", line 298, in send
    return self.get_connection(fail_silently).send_messages([self])
  File "/home/ubuntu/github/easygo/venv/lib/python3.10/site-packages/django/core/mail/backends/smtp.py", line 124, in send_messages
    new_conn_created = self.open()
  File "/home/ubuntu/github/easygo/venv/lib/python3.10/site-packages/django/core/mail/backends/smtp.py", line 91, in open
    self.connection.login(self.username, self.password)
  File "/usr/lib/python3.10/smtplib.py", line 739, in login
    (code, resp) = self.auth(
  File "/usr/lib/python3.10/smtplib.py", line 642, in auth
    (code, resp) = self.docmd("AUTH", mechanism + " " + response)
  File "/usr/lib/python3.10/smtplib.py", line 432, in docmd
    return self.getreply()
  File "/usr/lib/python3.10/smtplib.py", line 405, in getreply
    raise SMTPServerDisconnected("Connection unexpectedly closed")
smtplib.SMTPServerDisconnected: Connection unexpectedly closed
ERROR 2023-10-29 03:33:01,077 log Internal Server Error: /p2p/
Traceback (most recent call last):
  File "/home/ubuntu/github/easygo/venv/lib/python3.10/site-packages/django/core/handlers/exception.py", line 56, in inner
    response = get_response(request)
  File "/home/ubuntu/github/easygo/venv/lib/python3.10/site-packages/django/core/handlers/base.py", line 197, in _get_response
    response = wrapped_callback(request, *callback_args, **callback_kwargs)
  File "/home/ubuntu/github/easygo/basecamp/views.py", line 1166, in p2p
    email.send()
  File "/home/ubuntu/github/easygo/venv/lib/python3.10/site-packages/django/core/mail/message.py", line 298, in send
    return self.get_connection(fail_silently).send_messages([self])
  File "/home/ubuntu/github/easygo/venv/lib/python3.10/site-packages/django/core/mail/backends/smtp.py", line 124, in send_messages
    new_conn_created = self.open()
  File "/home/ubuntu/github/easygo/venv/lib/python3.10/site-packages/django/core/mail/backends/smtp.py", line 91, in open
    self.connection.login(self.username, self.password)
  File "/usr/lib/python3.10/smtplib.py", line 739, in login
    (code, resp) = self.auth(
  File "/usr/lib/python3.10/smtplib.py", line 642, in auth
    (code, resp) = self.docmd("AUTH", mechanism + " " + response)
  File "/usr/lib/python3.10/smtplib.py", line 432, in docmd
    return self.getreply()
  File "/usr/lib/python3.10/smtplib.py", line 405, in getreply
    raise SMTPServerDisconnected("Connection unexpectedly closed")
smtplib.SMTPServerDisconnected: Connection unexpectedly closed
ERROR 2023-10-29 03:33:03,637 log Internal Server Error: /p2p/
Traceback (most recent call last):
  File "/home/ubuntu/github/easygo/venv/lib/python3.10/site-packages/django/core/handlers/exception.py", line 56, in inner
    response = get_response(request)
  File "/home/ubuntu/github/easygo/venv/lib/python3.10/site-packages/django/core/handlers/base.py", line 197, in _get_response
    response = wrapped_callback(request, *callback_args, **callback_kwargs)
  File "/home/ubuntu/github/easygo/basecamp/views.py", line 1166, in p2p
    email.send()
  File "/home/ubuntu/github/easygo/venv/lib/python3.10/site-packages/django/core/mail/message.py", line 298, in send
    return self.get_connection(fail_silently).send_messages([self])
  File "/home/ubuntu/github/easygo/venv/lib/python3.10/site-packages/django/core/mail/backends/smtp.py", line 124, in send_messages
    new_conn_created = self.open()
  File "/home/ubuntu/github/easygo/venv/lib/python3.10/site-packages/django/core/mail/backends/smtp.py", line 91, in open
    self.connection.login(self.username, self.password)
  File "/usr/lib/python3.10/smtplib.py", line 739, in login
    (code, resp) = self.auth(
  File "/usr/lib/python3.10/smtplib.py", line 642, in auth
    (code, resp) = self.docmd("AUTH", mechanism + " " + response)
  File "/usr/lib/python3.10/smtplib.py", line 432, in docmd
    return self.getreply()
  File "/usr/lib/python3.10/smtplib.py", line 405, in getreply
    raise SMTPServerDisconnected("Connection unexpectedly closed")
smtplib.SMTPServerDisconnected: Connection unexpectedly closed
ERROR 2023-10-29 03:33:06,161 log Internal Server Error: /p2p/
Traceback (most recent call last):
  File "/home/ubuntu/github/easygo/venv/lib/python3.10/site-packages/django/core/handlers/exception.py", line 56, in inner
    response = get_response(request)
  File "/home/ubuntu/github/easygo/venv/lib/python3.10/site-packages/django/core/handlers/base.py", line 197, in _get_response
    response = wrapped_callback(request, *callback_args, **callback_kwargs)
  File "/home/ubuntu/github/easygo/basecamp/views.py", line 1166, in p2p
    email.send()
  File "/home/ubuntu/github/easygo/venv/lib/python3.10/site-packages/django/core/mail/message.py", line 298, in send
    return self.get_connection(fail_silently).send_messages([self])
  File "/home/ubuntu/github/easygo/venv/lib/python3.10/site-packages/django/core/mail/backends/smtp.py", line 124, in send_messages
    new_conn_created = self.open()
  File "/home/ubuntu/github/easygo/venv/lib/python3.10/site-packages/django/core/mail/backends/smtp.py", line 91, in open
    self.connection.login(self.username, self.password)
  File "/usr/lib/python3.10/smtplib.py", line 739, in login
    (code, resp) = self.auth(
  File "/usr/lib/python3.10/smtplib.py", line 642, in auth
    (code, resp) = self.docmd("AUTH", mechanism + " " + response)
  File "/usr/lib/python3.10/smtplib.py", line 432, in docmd
    return self.getreply()
  File "/usr/lib/python3.10/smtplib.py", line 405, in getreply
    raise SMTPServerDisconnected("Connection unexpectedly closed")
smtplib.SMTPServerDisconnected: Connection unexpectedly closed
ERROR 2023-10-29 03:33:08,685 log Internal Server Error: /p2p/
Traceback (most recent call last):
  File "/home/ubuntu/github/easygo/venv/lib/python3.10/site-packages/django/core/handlers/exception.py", line 56, in inner
    response = get_response(request)
  File "/home/ubuntu/github/easygo/venv/lib/python3.10/site-packages/django/core/handlers/base.py", line 197, in _get_response
    response = wrapped_callback(request, *callback_args, **callback_kwargs)
  File "/home/ubuntu/github/easygo/basecamp/views.py", line 1166, in p2p
    email.send()
  File "/home/ubuntu/github/easygo/venv/lib/python3.10/site-packages/django/core/mail/message.py", line 298, in send
    return self.get_connection(fail_silently).send_messages([self])
  File "/home/ubuntu/github/easygo/venv/lib/python3.10/site-packages/django/core/mail/backends/smtp.py", line 124, in send_messages
    new_conn_created = self.open()
  File "/home/ubuntu/github/easygo/venv/lib/python3.10/site-packages/django/core/mail/backends/smtp.py", line 91, in open
    self.connection.login(self.username, self.password)
  File "/usr/lib/python3.10/smtplib.py", line 739, in login
    (code, resp) = self.auth(
  File "/usr/lib/python3.10/smtplib.py", line 642, in auth
    (code, resp) = self.docmd("AUTH", mechanism + " " + response)
  File "/usr/lib/python3.10/smtplib.py", line 432, in docmd
    return self.getreply()
  File "/usr/lib/python3.10/smtplib.py", line 405, in getreply
    raise SMTPServerDisconnected("Connection unexpectedly closed")
smtplib.SMTPServerDisconnected: Connection unexpectedly closed
ERROR 2023-10-29 03:33:11,219 log Internal Server Error: /p2p/
Traceback (most recent call last):
  File "/home/ubuntu/github/easygo/venv/lib/python3.10/site-packages/django/core/handlers/exception.py", line 56, in inner
    response = get_response(request)
  File "/home/ubuntu/github/easygo/venv/lib/python3.10/site-packages/django/core/handlers/base.py", line 197, in _get_response
    response = wrapped_callback(request, *callback_args, **callback_kwargs)
  File "/home/ubuntu/github/easygo/basecamp/views.py", line 1166, in p2p
    email.send()
  File "/home/ubuntu/github/easygo/venv/lib/python3.10/site-packages/django/core/mail/message.py", line 298, in send
    return self.get_connection(fail_silently).send_messages([self])
  File "/home/ubuntu/github/easygo/venv/lib/python3.10/site-packages/django/core/mail/backends/smtp.py", line 124, in send_messages
    new_conn_created = self.open()
  File "/home/ubuntu/github/easygo/venv/lib/python3.10/site-packages/django/core/mail/backends/smtp.py", line 91, in open
    self.connection.login(self.username, self.password)
  File "/usr/lib/python3.10/smtplib.py", line 739, in login
    (code, resp) = self.auth(
  File "/usr/lib/python3.10/smtplib.py", line 642, in auth
    (code, resp) = self.docmd("AUTH", mechanism + " " + response)
  File "/usr/lib/python3.10/smtplib.py", line 432, in docmd
    return self.getreply()
  File "/usr/lib/python3.10/smtplib.py", line 405, in getreply
    raise SMTPServerDisconnected("Connection unexpectedly closed")
smtplib.SMTPServerDisconnected: Connection unexpectedly closed
ERROR 2023-10-29 03:33:13,744 log Internal Server Error: /p2p/
Traceback (most recent call last):
  File "/home/ubuntu/github/easygo/venv/lib/python3.10/site-packages/django/core/handlers/exception.py", line 56, in inner
    response = get_response(request)
  File "/home/ubuntu/github/easygo/venv/lib/python3.10/site-packages/django/core/handlers/base.py", line 197, in _get_response
    response = wrapped_callback(request, *callback_args, **callback_kwargs)
  File "/home/ubuntu/github/easygo/basecamp/views.py", line 1166, in p2p
    email.send()
  File "/home/ubuntu/github/easygo/venv/lib/python3.10/site-packages/django/core/mail/message.py", line 298, in send
    return self.get_connection(fail_silently).send_messages([self])
  File "/home/ubuntu/github/easygo/venv/lib/python3.10/site-packages/django/core/mail/backends/smtp.py", line 124, in send_messages
    new_conn_created = self.open()
  File "/home/ubuntu/github/easygo/venv/lib/python3.10/site-packages/django/core/mail/backends/smtp.py", line 91, in open
    self.connection.login(self.username, self.password)
  File "/usr/lib/python3.10/smtplib.py", line 739, in login
    (code, resp) = self.auth(
  File "/usr/lib/python3.10/smtplib.py", line 642, in auth
    (code, resp) = self.docmd("AUTH", mechanism + " " + response)
  File "/usr/lib/python3.10/smtplib.py", line 432, in docmd
    return self.getreply()
  File "/usr/lib/python3.10/smtplib.py", line 405, in getreply
    raise SMTPServerDisconnected("Connection unexpectedly closed")
smtplib.SMTPServerDisconnected: Connection unexpectedly closed
ERROR 2023-10-29 03:33:16,271 log Internal Server Error: /p2p/
Traceback (most recent call last):
  File "/home/ubuntu/github/easygo/venv/lib/python3.10/site-packages/django/core/handlers/exception.py", line 56, in inner
    response = get_response(request)
  File "/home/ubuntu/github/easygo/venv/lib/python3.10/site-packages/django/core/handlers/base.py", line 197, in _get_response
    response = wrapped_callback(request, *callback_args, **callback_kwargs)
  File "/home/ubuntu/github/easygo/basecamp/views.py", line 1166, in p2p
    email.send()
  File "/home/ubuntu/github/easygo/venv/lib/python3.10/site-packages/django/core/mail/message.py", line 298, in send
    return self.get_connection(fail_silently).send_messages([self])
  File "/home/ubuntu/github/easygo/venv/lib/python3.10/site-packages/django/core/mail/backends/smtp.py", line 124, in send_messages
    new_conn_created = self.open()
  File "/home/ubuntu/github/easygo/venv/lib/python3.10/site-packages/django/core/mail/backends/smtp.py", line 91, in open
    self.connection.login(self.username, self.password)
  File "/usr/lib/python3.10/smtplib.py", line 739, in login
    (code, resp) = self.auth(
  File "/usr/lib/python3.10/smtplib.py", line 642, in auth
    (code, resp) = self.docmd("AUTH", mechanism + " " + response)
  File "/usr/lib/python3.10/smtplib.py", line 432, in docmd
    return self.getreply()
  File "/usr/lib/python3.10/smtplib.py", line 405, in getreply
    raise SMTPServerDisconnected("Connection unexpectedly closed")
smtplib.SMTPServerDisconnected: Connection unexpectedly closed
ERROR 2023-10-29 03:33:18,123 log Internal Server Error: /p2p/
Traceback (most recent call last):
  File "/home/ubuntu/github/easygo/venv/lib/python3.10/site-packages/django/core/handlers/exception.py", line 56, in inner
    response = get_response(request)
  File "/home/ubuntu/github/easygo/venv/lib/python3.10/site-packages/django/core/handlers/base.py", line 197, in _get_response
    response = wrapped_callback(request, *callback_args, **callback_kwargs)
  File "/home/ubuntu/github/easygo/basecamp/views.py", line 1166, in p2p
    email.send()
  File "/home/ubuntu/github/easygo/venv/lib/python3.10/site-packages/django/core/mail/message.py", line 298, in send
    return self.get_connection(fail_silently).send_messages([self])
  File "/home/ubuntu/github/easygo/venv/lib/python3.10/site-packages/django/core/mail/backends/smtp.py", line 124, in send_messages
    new_conn_created = self.open()
  File "/home/ubuntu/github/easygo/venv/lib/python3.10/site-packages/django/core/mail/backends/smtp.py", line 91, in open
    self.connection.login(self.username, self.password)
  File "/usr/lib/python3.10/smtplib.py", line 739, in login
    (code, resp) = self.auth(
  File "/usr/lib/python3.10/smtplib.py", line 642, in auth
    (code, resp) = self.docmd("AUTH", mechanism + " " + response)
  File "/usr/lib/python3.10/smtplib.py", line 432, in docmd
    return self.getreply()
  File "/usr/lib/python3.10/smtplib.py", line 405, in getreply
    raise SMTPServerDisconnected("Connection unexpectedly closed")
smtplib.SMTPServerDisconnected: Connection unexpectedly closed
ERROR 2023-10-29 03:33:20,057 log Internal Server Error: /p2p/
Traceback (most recent call last):
  File "/home/ubuntu/github/easygo/venv/lib/python3.10/site-packages/django/core/handlers/exception.py", line 56, in inner
    response = get_response(request)
  File "/home/ubuntu/github/easygo/venv/lib/python3.10/site-packages/django/core/handlers/base.py", line 197, in _get_response
    response = wrapped_callback(request, *callback_args, **callback_kwargs)
  File "/home/ubuntu/github/easygo/basecamp/views.py", line 1166, in p2p
    email.send()
  File "/home/ubuntu/github/easygo/venv/lib/python3.10/site-packages/django/core/mail/message.py", line 298, in send
    return self.get_connection(fail_silently).send_messages([self])
  File "/home/ubuntu/github/easygo/venv/lib/python3.10/site-packages/django/core/mail/backends/smtp.py", line 124, in send_messages
    new_conn_created = self.open()
  File "/home/ubuntu/github/easygo/venv/lib/python3.10/site-packages/django/core/mail/backends/smtp.py", line 91, in open
    self.connection.login(self.username, self.password)
  File "/usr/lib/python3.10/smtplib.py", line 739, in login
    (code, resp) = self.auth(
  File "/usr/lib/python3.10/smtplib.py", line 642, in auth
    (code, resp) = self.docmd("AUTH", mechanism + " " + response)
  File "/usr/lib/python3.10/smtplib.py", line 432, in docmd
    return self.getreply()
  File "/usr/lib/python3.10/smtplib.py", line 405, in getreply
    raise SMTPServerDisconnected("Connection unexpectedly closed")
smtplib.SMTPServerDisconnected: Connection unexpectedly closed
ERROR 2023-10-29 03:33:22,622 log Internal Server Error: /p2p/
Traceback (most recent call last):
  File "/home/ubuntu/github/easygo/venv/lib/python3.10/site-packages/django/core/handlers/exception.py", line 56, in inner
    response = get_response(request)
  File "/home/ubuntu/github/easygo/venv/lib/python3.10/site-packages/django/core/handlers/base.py", line 197, in _get_response
    response = wrapped_callback(request, *callback_args, **callback_kwargs)
  File "/home/ubuntu/github/easygo/basecamp/views.py", line 1166, in p2p
    email.send()
  File "/home/ubuntu/github/easygo/venv/lib/python3.10/site-packages/django/core/mail/message.py", line 298, in send
    return self.get_connection(fail_silently).send_messages([self])
  File "/home/ubuntu/github/easygo/venv/lib/python3.10/site-packages/django/core/mail/backends/smtp.py", line 124, in send_messages
    new_conn_created = self.open()
  File "/home/ubuntu/github/easygo/venv/lib/python3.10/site-packages/django/core/mail/backends/smtp.py", line 91, in open
    self.connection.login(self.username, self.password)
  File "/usr/lib/python3.10/smtplib.py", line 739, in login
    (code, resp) = self.auth(
  File "/usr/lib/python3.10/smtplib.py", line 642, in auth
    (code, resp) = self.docmd("AUTH", mechanism + " " + response)
  File "/usr/lib/python3.10/smtplib.py", line 432, in docmd
    return self.getreply()
  File "/usr/lib/python3.10/smtplib.py", line 405, in getreply
    raise SMTPServerDisconnected("Connection unexpectedly closed")
smtplib.SMTPServerDisconnected: Connection unexpectedly closed
ERROR 2023-10-29 03:33:25,165 log Internal Server Error: /p2p/
Traceback (most recent call last):
  File "/home/ubuntu/github/easygo/venv/lib/python3.10/site-packages/django/core/handlers/exception.py", line 56, in inner
    response = get_response(request)
  File "/home/ubuntu/github/easygo/venv/lib/python3.10/site-packages/django/core/handlers/base.py", line 197, in _get_response
    response = wrapped_callback(request, *callback_args, **callback_kwargs)
  File "/home/ubuntu/github/easygo/basecamp/views.py", line 1166, in p2p
    email.send()
  File "/home/ubuntu/github/easygo/venv/lib/python3.10/site-packages/django/core/mail/message.py", line 298, in send
    return self.get_connection(fail_silently).send_messages([self])
  File "/home/ubuntu/github/easygo/venv/lib/python3.10/site-packages/django/core/mail/backends/smtp.py", line 124, in send_messages
    new_conn_created = self.open()
  File "/home/ubuntu/github/easygo/venv/lib/python3.10/site-packages/django/core/mail/backends/smtp.py", line 91, in open
    self.connection.login(self.username, self.password)
  File "/usr/lib/python3.10/smtplib.py", line 739, in login
    (code, resp) = self.auth(
  File "/usr/lib/python3.10/smtplib.py", line 642, in auth
    (code, resp) = self.docmd("AUTH", mechanism + " " + response)
  File "/usr/lib/python3.10/smtplib.py", line 432, in docmd
    return self.getreply()
  File "/usr/lib/python3.10/smtplib.py", line 405, in getreply
    raise SMTPServerDisconnected("Connection unexpectedly closed")
smtplib.SMTPServerDisconnected: Connection unexpectedly closed
ERROR 2023-10-29 03:33:27,681 log Internal Server Error: /p2p/
Traceback (most recent call last):
  File "/home/ubuntu/github/easygo/venv/lib/python3.10/site-packages/django/core/handlers/exception.py", line 56, in inner
    response = get_response(request)
  File "/home/ubuntu/github/easygo/venv/lib/python3.10/site-packages/django/core/handlers/base.py", line 197, in _get_response
    response = wrapped_callback(request, *callback_args, **callback_kwargs)
  File "/home/ubuntu/github/easygo/basecamp/views.py", line 1166, in p2p
    email.send()
  File "/home/ubuntu/github/easygo/venv/lib/python3.10/site-packages/django/core/mail/message.py", line 298, in send
    return self.get_connection(fail_silently).send_messages([self])
  File "/home/ubuntu/github/easygo/venv/lib/python3.10/site-packages/django/core/mail/backends/smtp.py", line 124, in send_messages
    new_conn_created = self.open()
  File "/home/ubuntu/github/easygo/venv/lib/python3.10/site-packages/django/core/mail/backends/smtp.py", line 91, in open
    self.connection.login(self.username, self.password)
  File "/usr/lib/python3.10/smtplib.py", line 739, in login
    (code, resp) = self.auth(
  File "/usr/lib/python3.10/smtplib.py", line 642, in auth
    (code, resp) = self.docmd("AUTH", mechanism + " " + response)
  File "/usr/lib/python3.10/smtplib.py", line 432, in docmd
    return self.getreply()
  File "/usr/lib/python3.10/smtplib.py", line 405, in getreply
    raise SMTPServerDisconnected("Connection unexpectedly closed")
smtplib.SMTPServerDisconnected: Connection unexpectedly closed
ERROR 2023-10-29 03:33:30,208 log Internal Server Error: /p2p/
Traceback (most recent call last):
  File "/home/ubuntu/github/easygo/venv/lib/python3.10/site-packages/django/core/handlers/exception.py", line 56, in inner
    response = get_response(request)
  File "/home/ubuntu/github/easygo/venv/lib/python3.10/site-packages/django/core/handlers/base.py", line 197, in _get_response
    response = wrapped_callback(request, *callback_args, **callback_kwargs)
  File "/home/ubuntu/github/easygo/basecamp/views.py", line 1166, in p2p
    email.send()
  File "/home/ubuntu/github/easygo/venv/lib/python3.10/site-packages/django/core/mail/message.py", line 298, in send
    return self.get_connection(fail_silently).send_messages([self])
  File "/home/ubuntu/github/easygo/venv/lib/python3.10/site-packages/django/core/mail/backends/smtp.py", line 124, in send_messages
    new_conn_created = self.open()
  File "/home/ubuntu/github/easygo/venv/lib/python3.10/site-packages/django/core/mail/backends/smtp.py", line 91, in open
    self.connection.login(self.username, self.password)
  File "/usr/lib/python3.10/smtplib.py", line 739, in login
    (code, resp) = self.auth(
  File "/usr/lib/python3.10/smtplib.py", line 642, in auth
    (code, resp) = self.docmd("AUTH", mechanism + " " + response)
  File "/usr/lib/python3.10/smtplib.py", line 432, in docmd
    return self.getreply()
  File "/usr/lib/python3.10/smtplib.py", line 405, in getreply
    raise SMTPServerDisconnected("Connection unexpectedly closed")
smtplib.SMTPServerDisconnected: Connection unexpectedly closed
ERROR 2023-10-29 03:33:32,732 log Internal Server Error: /p2p/
Traceback (most recent call last):
  File "/home/ubuntu/github/easygo/venv/lib/python3.10/site-packages/django/core/handlers/exception.py", line 56, in inner
    response = get_response(request)
  File "/home/ubuntu/github/easygo/venv/lib/python3.10/site-packages/django/core/handlers/base.py", line 197, in _get_response
    response = wrapped_callback(request, *callback_args, **callback_kwargs)
  File "/home/ubuntu/github/easygo/basecamp/views.py", line 1166, in p2p
    email.send()
  File "/home/ubuntu/github/easygo/venv/lib/python3.10/site-packages/django/core/mail/message.py", line 298, in send
    return self.get_connection(fail_silently).send_messages([self])
  File "/home/ubuntu/github/easygo/venv/lib/python3.10/site-packages/django/core/mail/backends/smtp.py", line 124, in send_messages
    new_conn_created = self.open()
  File "/home/ubuntu/github/easygo/venv/lib/python3.10/site-packages/django/core/mail/backends/smtp.py", line 91, in open
    self.connection.login(self.username, self.password)
  File "/usr/lib/python3.10/smtplib.py", line 739, in login
    (code, resp) = self.auth(
  File "/usr/lib/python3.10/smtplib.py", line 642, in auth
    (code, resp) = self.docmd("AUTH", mechanism + " " + response)
  File "/usr/lib/python3.10/smtplib.py", line 432, in docmd
    return self.getreply()
  File "/usr/lib/python3.10/smtplib.py", line 405, in getreply
    raise SMTPServerDisconnected("Connection unexpectedly closed")
smtplib.SMTPServerDisconnected: Connection unexpectedly closed
ERROR 2023-10-29 03:33:35,253 log Internal Server Error: /p2p/
Traceback (most recent call last):
  File "/home/ubuntu/github/easygo/venv/lib/python3.10/site-packages/django/core/handlers/exception.py", line 56, in inner
    response = get_response(request)
  File "/home/ubuntu/github/easygo/venv/lib/python3.10/site-packages/django/core/handlers/base.py", line 197, in _get_response
    response = wrapped_callback(request, *callback_args, **callback_kwargs)
  File "/home/ubuntu/github/easygo/basecamp/views.py", line 1166, in p2p
    email.send()
  File "/home/ubuntu/github/easygo/venv/lib/python3.10/site-packages/django/core/mail/message.py", line 298, in send
    return self.get_connection(fail_silently).send_messages([self])
  File "/home/ubuntu/github/easygo/venv/lib/python3.10/site-packages/django/core/mail/backends/smtp.py", line 124, in send_messages
    new_conn_created = self.open()
  File "/home/ubuntu/github/easygo/venv/lib/python3.10/site-packages/django/core/mail/backends/smtp.py", line 91, in open
    self.connection.login(self.username, self.password)
  File "/usr/lib/python3.10/smtplib.py", line 739, in login
    (code, resp) = self.auth(
  File "/usr/lib/python3.10/smtplib.py", line 642, in auth
    (code, resp) = self.docmd("AUTH", mechanism + " " + response)
  File "/usr/lib/python3.10/smtplib.py", line 432, in docmd
    return self.getreply()
  File "/usr/lib/python3.10/smtplib.py", line 405, in getreply
    raise SMTPServerDisconnected("Connection unexpectedly closed")
smtplib.SMTPServerDisconnected: Connection unexpectedly closed
ERROR 2023-10-29 03:33:37,783 log Internal Server Error: /p2p/
Traceback (most recent call last):
  File "/home/ubuntu/github/easygo/venv/lib/python3.10/site-packages/django/core/handlers/exception.py", line 56, in inner
    response = get_response(request)
  File "/home/ubuntu/github/easygo/venv/lib/python3.10/site-packages/django/core/handlers/base.py", line 197, in _get_response
    response = wrapped_callback(request, *callback_args, **callback_kwargs)
  File "/home/ubuntu/github/easygo/basecamp/views.py", line 1166, in p2p
    email.send()
  File "/home/ubuntu/github/easygo/venv/lib/python3.10/site-packages/django/core/mail/message.py", line 298, in send
    return self.get_connection(fail_silently).send_messages([self])
  File "/home/ubuntu/github/easygo/venv/lib/python3.10/site-packages/django/core/mail/backends/smtp.py", line 124, in send_messages
    new_conn_created = self.open()
  File "/home/ubuntu/github/easygo/venv/lib/python3.10/site-packages/django/core/mail/backends/smtp.py", line 91, in open
    self.connection.login(self.username, self.password)
  File "/usr/lib/python3.10/smtplib.py", line 739, in login
    (code, resp) = self.auth(
  File "/usr/lib/python3.10/smtplib.py", line 642, in auth
    (code, resp) = self.docmd("AUTH", mechanism + " " + response)
  File "/usr/lib/python3.10/smtplib.py", line 432, in docmd
    return self.getreply()
  File "/usr/lib/python3.10/smtplib.py", line 405, in getreply
    raise SMTPServerDisconnected("Connection unexpectedly closed")
smtplib.SMTPServerDisconnected: Connection unexpectedly closed
ERROR 2023-10-29 03:33:40,300 log Internal Server Error: /p2p/
Traceback (most recent call last):
  File "/home/ubuntu/github/easygo/venv/lib/python3.10/site-packages/django/core/handlers/exception.py", line 56, in inner
    response = get_response(request)
  File "/home/ubuntu/github/easygo/venv/lib/python3.10/site-packages/django/core/handlers/base.py", line 197, in _get_response
    response = wrapped_callback(request, *callback_args, **callback_kwargs)
  File "/home/ubuntu/github/easygo/basecamp/views.py", line 1166, in p2p
    email.send()
  File "/home/ubuntu/github/easygo/venv/lib/python3.10/site-packages/django/core/mail/message.py", line 298, in send
    return self.get_connection(fail_silently).send_messages([self])
  File "/home/ubuntu/github/easygo/venv/lib/python3.10/site-packages/django/core/mail/backends/smtp.py", line 124, in send_messages
    new_conn_created = self.open()
  File "/home/ubuntu/github/easygo/venv/lib/python3.10/site-packages/django/core/mail/backends/smtp.py", line 91, in open
    self.connection.login(self.username, self.password)
  File "/usr/lib/python3.10/smtplib.py", line 739, in login
    (code, resp) = self.auth(
  File "/usr/lib/python3.10/smtplib.py", line 642, in auth
    (code, resp) = self.docmd("AUTH", mechanism + " " + response)
  File "/usr/lib/python3.10/smtplib.py", line 432, in docmd
    return self.getreply()
  File "/usr/lib/python3.10/smtplib.py", line 405, in getreply
    raise SMTPServerDisconnected("Connection unexpectedly closed")
smtplib.SMTPServerDisconnected: Connection unexpectedly closed
ERROR 2023-10-29 03:33:42,833 log Internal Server Error: /p2p/
Traceback (most recent call last):
  File "/home/ubuntu/github/easygo/venv/lib/python3.10/site-packages/django/core/handlers/exception.py", line 56, in inner
    response = get_response(request)
  File "/home/ubuntu/github/easygo/venv/lib/python3.10/site-packages/django/core/handlers/base.py", line 197, in _get_response
    response = wrapped_callback(request, *callback_args, **callback_kwargs)
  File "/home/ubuntu/github/easygo/basecamp/views.py", line 1166, in p2p
    email.send()
  File "/home/ubuntu/github/easygo/venv/lib/python3.10/site-packages/django/core/mail/message.py", line 298, in send
    return self.get_connection(fail_silently).send_messages([self])
  File "/home/ubuntu/github/easygo/venv/lib/python3.10/site-packages/django/core/mail/backends/smtp.py", line 124, in send_messages
    new_conn_created = self.open()
  File "/home/ubuntu/github/easygo/venv/lib/python3.10/site-packages/django/core/mail/backends/smtp.py", line 91, in open
    self.connection.login(self.username, self.password)
  File "/usr/lib/python3.10/smtplib.py", line 739, in login
    (code, resp) = self.auth(
  File "/usr/lib/python3.10/smtplib.py", line 642, in auth
    (code, resp) = self.docmd("AUTH", mechanism + " " + response)
  File "/usr/lib/python3.10/smtplib.py", line 432, in docmd
    return self.getreply()
  File "/usr/lib/python3.10/smtplib.py", line 405, in getreply
    raise SMTPServerDisconnected("Connection unexpectedly closed")
smtplib.SMTPServerDisconnected: Connection unexpectedly closed
ERROR 2023-10-29 03:33:45,385 log Internal Server Error: /p2p/
Traceback (most recent call last):
  File "/home/ubuntu/github/easygo/venv/lib/python3.10/site-packages/django/core/handlers/exception.py", line 56, in inner
    response = get_response(request)
  File "/home/ubuntu/github/easygo/venv/lib/python3.10/site-packages/django/core/handlers/base.py", line 197, in _get_response
    response = wrapped_callback(request, *callback_args, **callback_kwargs)
  File "/home/ubuntu/github/easygo/basecamp/views.py", line 1166, in p2p
    email.send()
  File "/home/ubuntu/github/easygo/venv/lib/python3.10/site-packages/django/core/mail/message.py", line 298, in send
    return self.get_connection(fail_silently).send_messages([self])
  File "/home/ubuntu/github/easygo/venv/lib/python3.10/site-packages/django/core/mail/backends/smtp.py", line 124, in send_messages
    new_conn_created = self.open()
  File "/home/ubuntu/github/easygo/venv/lib/python3.10/site-packages/django/core/mail/backends/smtp.py", line 91, in open
    self.connection.login(self.username, self.password)
  File "/usr/lib/python3.10/smtplib.py", line 739, in login
    (code, resp) = self.auth(
  File "/usr/lib/python3.10/smtplib.py", line 642, in auth
    (code, resp) = self.docmd("AUTH", mechanism + " " + response)
  File "/usr/lib/python3.10/smtplib.py", line 432, in docmd
    return self.getreply()
  File "/usr/lib/python3.10/smtplib.py", line 405, in getreply
    raise SMTPServerDisconnected("Connection unexpectedly closed")
smtplib.SMTPServerDisconnected: Connection unexpectedly closed
ERROR 2023-10-29 03:33:47,930 log Internal Server Error: /p2p/
Traceback (most recent call last):
  File "/home/ubuntu/github/easygo/venv/lib/python3.10/site-packages/django/core/handlers/exception.py", line 56, in inner
    response = get_response(request)
  File "/home/ubuntu/github/easygo/venv/lib/python3.10/site-packages/django/core/handlers/base.py", line 197, in _get_response
    response = wrapped_callback(request, *callback_args, **callback_kwargs)
  File "/home/ubuntu/github/easygo/basecamp/views.py", line 1166, in p2p
    email.send()
  File "/home/ubuntu/github/easygo/venv/lib/python3.10/site-packages/django/core/mail/message.py", line 298, in send
    return self.get_connection(fail_silently).send_messages([self])
  File "/home/ubuntu/github/easygo/venv/lib/python3.10/site-packages/django/core/mail/backends/smtp.py", line 124, in send_messages
    new_conn_created = self.open()
  File "/home/ubuntu/github/easygo/venv/lib/python3.10/site-packages/django/core/mail/backends/smtp.py", line 91, in open
    self.connection.login(self.username, self.password)
  File "/usr/lib/python3.10/smtplib.py", line 739, in login
    (code, resp) = self.auth(
  File "/usr/lib/python3.10/smtplib.py", line 642, in auth
    (code, resp) = self.docmd("AUTH", mechanism + " " + response)
  File "/usr/lib/python3.10/smtplib.py", line 432, in docmd
    return self.getreply()
  File "/usr/lib/python3.10/smtplib.py", line 405, in getreply
    raise SMTPServerDisconnected("Connection unexpectedly closed")
smtplib.SMTPServerDisconnected: Connection unexpectedly closed
ERROR 2023-10-29 03:33:50,493 log Internal Server Error: /p2p/
Traceback (most recent call last):
  File "/home/ubuntu/github/easygo/venv/lib/python3.10/site-packages/django/core/handlers/exception.py", line 56, in inner
    response = get_response(request)
  File "/home/ubuntu/github/easygo/venv/lib/python3.10/site-packages/django/core/handlers/base.py", line 197, in _get_response
    response = wrapped_callback(request, *callback_args, **callback_kwargs)
  File "/home/ubuntu/github/easygo/basecamp/views.py", line 1166, in p2p
    email.send()
  File "/home/ubuntu/github/easygo/venv/lib/python3.10/site-packages/django/core/mail/message.py", line 298, in send
    return self.get_connection(fail_silently).send_messages([self])
  File "/home/ubuntu/github/easygo/venv/lib/python3.10/site-packages/django/core/mail/backends/smtp.py", line 124, in send_messages
    new_conn_created = self.open()
  File "/home/ubuntu/github/easygo/venv/lib/python3.10/site-packages/django/core/mail/backends/smtp.py", line 91, in open
    self.connection.login(self.username, self.password)
  File "/usr/lib/python3.10/smtplib.py", line 739, in login
    (code, resp) = self.auth(
  File "/usr/lib/python3.10/smtplib.py", line 642, in auth
    (code, resp) = self.docmd("AUTH", mechanism + " " + response)
  File "/usr/lib/python3.10/smtplib.py", line 432, in docmd
    return self.getreply()
  File "/usr/lib/python3.10/smtplib.py", line 405, in getreply
    raise SMTPServerDisconnected("Connection unexpectedly closed")
smtplib.SMTPServerDisconnected: Connection unexpectedly closed
ERROR 2023-10-29 03:33:53,024 log Internal Server Error: /p2p/
Traceback (most recent call last):
  File "/home/ubuntu/github/easygo/venv/lib/python3.10/site-packages/django/core/handlers/exception.py", line 56, in inner
    response = get_response(request)
  File "/home/ubuntu/github/easygo/venv/lib/python3.10/site-packages/django/core/handlers/base.py", line 197, in _get_response
    response = wrapped_callback(request, *callback_args, **callback_kwargs)
  File "/home/ubuntu/github/easygo/basecamp/views.py", line 1166, in p2p
    email.send()
  File "/home/ubuntu/github/easygo/venv/lib/python3.10/site-packages/django/core/mail/message.py", line 298, in send
    return self.get_connection(fail_silently).send_messages([self])
  File "/home/ubuntu/github/easygo/venv/lib/python3.10/site-packages/django/core/mail/backends/smtp.py", line 124, in send_messages
    new_conn_created = self.open()
  File "/home/ubuntu/github/easygo/venv/lib/python3.10/site-packages/django/core/mail/backends/smtp.py", line 91, in open
    self.connection.login(self.username, self.password)
  File "/usr/lib/python3.10/smtplib.py", line 739, in login
    (code, resp) = self.auth(
  File "/usr/lib/python3.10/smtplib.py", line 642, in auth
    (code, resp) = self.docmd("AUTH", mechanism + " " + response)
  File "/usr/lib/python3.10/smtplib.py", line 432, in docmd
    return self.getreply()
  File "/usr/lib/python3.10/smtplib.py", line 405, in getreply
    raise SMTPServerDisconnected("Connection unexpectedly closed")
smtplib.SMTPServerDisconnected: Connection unexpectedly closed
ERROR 2023-10-29 03:33:55,583 log Internal Server Error: /p2p/
Traceback (most recent call last):
  File "/home/ubuntu/github/easygo/venv/lib/python3.10/site-packages/django/core/handlers/exception.py", line 56, in inner
    response = get_response(request)
  File "/home/ubuntu/github/easygo/venv/lib/python3.10/site-packages/django/core/handlers/base.py", line 197, in _get_response
    response = wrapped_callback(request, *callback_args, **callback_kwargs)
  File "/home/ubuntu/github/easygo/basecamp/views.py", line 1166, in p2p
    email.send()
  File "/home/ubuntu/github/easygo/venv/lib/python3.10/site-packages/django/core/mail/message.py", line 298, in send
    return self.get_connection(fail_silently).send_messages([self])
  File "/home/ubuntu/github/easygo/venv/lib/python3.10/site-packages/django/core/mail/backends/smtp.py", line 124, in send_messages
    new_conn_created = self.open()
  File "/home/ubuntu/github/easygo/venv/lib/python3.10/site-packages/django/core/mail/backends/smtp.py", line 91, in open
    self.connection.login(self.username, self.password)
  File "/usr/lib/python3.10/smtplib.py", line 739, in login
    (code, resp) = self.auth(
  File "/usr/lib/python3.10/smtplib.py", line 642, in auth
    (code, resp) = self.docmd("AUTH", mechanism + " " + response)
  File "/usr/lib/python3.10/smtplib.py", line 432, in docmd
    return self.getreply()
  File "/usr/lib/python3.10/smtplib.py", line 405, in getreply
    raise SMTPServerDisconnected("Connection unexpectedly closed")
smtplib.SMTPServerDisconnected: Connection unexpectedly closed
ERROR 2023-10-29 03:33:58,114 log Internal Server Error: /p2p/
Traceback (most recent call last):
  File "/home/ubuntu/github/easygo/venv/lib/python3.10/site-packages/django/core/handlers/exception.py", line 56, in inner
    response = get_response(request)
  File "/home/ubuntu/github/easygo/venv/lib/python3.10/site-packages/django/core/handlers/base.py", line 197, in _get_response
    response = wrapped_callback(request, *callback_args, **callback_kwargs)
  File "/home/ubuntu/github/easygo/basecamp/views.py", line 1166, in p2p
    email.send()
  File "/home/ubuntu/github/easygo/venv/lib/python3.10/site-packages/django/core/mail/message.py", line 298, in send
    return self.get_connection(fail_silently).send_messages([self])
  File "/home/ubuntu/github/easygo/venv/lib/python3.10/site-packages/django/core/mail/backends/smtp.py", line 124, in send_messages
    new_conn_created = self.open()
  File "/home/ubuntu/github/easygo/venv/lib/python3.10/site-packages/django/core/mail/backends/smtp.py", line 91, in open
    self.connection.login(self.username, self.password)
  File "/usr/lib/python3.10/smtplib.py", line 739, in login
    (code, resp) = self.auth(
  File "/usr/lib/python3.10/smtplib.py", line 642, in auth
    (code, resp) = self.docmd("AUTH", mechanism + " " + response)
  File "/usr/lib/python3.10/smtplib.py", line 432, in docmd
    return self.getreply()
  File "/usr/lib/python3.10/smtplib.py", line 405, in getreply
    raise SMTPServerDisconnected("Connection unexpectedly closed")
smtplib.SMTPServerDisconnected: Connection unexpectedly closed
ERROR 2023-10-29 03:34:00,624 log Internal Server Error: /p2p/
Traceback (most recent call last):
  File "/home/ubuntu/github/easygo/venv/lib/python3.10/site-packages/django/core/handlers/exception.py", line 56, in inner
    response = get_response(request)
  File "/home/ubuntu/github/easygo/venv/lib/python3.10/site-packages/django/core/handlers/base.py", line 197, in _get_response
    response = wrapped_callback(request, *callback_args, **callback_kwargs)
  File "/home/ubuntu/github/easygo/basecamp/views.py", line 1166, in p2p
    email.send()
  File "/home/ubuntu/github/easygo/venv/lib/python3.10/site-packages/django/core/mail/message.py", line 298, in send
    return self.get_connection(fail_silently).send_messages([self])
  File "/home/ubuntu/github/easygo/venv/lib/python3.10/site-packages/django/core/mail/backends/smtp.py", line 124, in send_messages
    new_conn_created = self.open()
  File "/home/ubuntu/github/easygo/venv/lib/python3.10/site-packages/django/core/mail/backends/smtp.py", line 91, in open
    self.connection.login(self.username, self.password)
  File "/usr/lib/python3.10/smtplib.py", line 739, in login
    (code, resp) = self.auth(
  File "/usr/lib/python3.10/smtplib.py", line 642, in auth
    (code, resp) = self.docmd("AUTH", mechanism + " " + response)
  File "/usr/lib/python3.10/smtplib.py", line 432, in docmd
    return self.getreply()
  File "/usr/lib/python3.10/smtplib.py", line 405, in getreply
    raise SMTPServerDisconnected("Connection unexpectedly closed")
smtplib.SMTPServerDisconnected: Connection unexpectedly closed
ERROR 2023-10-29 03:34:03,514 log Internal Server Error: /p2p/
Traceback (most recent call last):
  File "/home/ubuntu/github/easygo/venv/lib/python3.10/site-packages/django/core/handlers/exception.py", line 56, in inner
    response = get_response(request)
  File "/home/ubuntu/github/easygo/venv/lib/python3.10/site-packages/django/core/handlers/base.py", line 197, in _get_response
    response = wrapped_callback(request, *callback_args, **callback_kwargs)
  File "/home/ubuntu/github/easygo/basecamp/views.py", line 1166, in p2p
    email.send()
  File "/home/ubuntu/github/easygo/venv/lib/python3.10/site-packages/django/core/mail/message.py", line 298, in send
    return self.get_connection(fail_silently).send_messages([self])
  File "/home/ubuntu/github/easygo/venv/lib/python3.10/site-packages/django/core/mail/backends/smtp.py", line 124, in send_messages
    new_conn_created = self.open()
  File "/home/ubuntu/github/easygo/venv/lib/python3.10/site-packages/django/core/mail/backends/smtp.py", line 91, in open
    self.connection.login(self.username, self.password)
  File "/usr/lib/python3.10/smtplib.py", line 739, in login
    (code, resp) = self.auth(
  File "/usr/lib/python3.10/smtplib.py", line 642, in auth
    (code, resp) = self.docmd("AUTH", mechanism + " " + response)
  File "/usr/lib/python3.10/smtplib.py", line 432, in docmd
    return self.getreply()
  File "/usr/lib/python3.10/smtplib.py", line 405, in getreply
    raise SMTPServerDisconnected("Connection unexpectedly closed")
smtplib.SMTPServerDisconnected: Connection unexpectedly closed
ERROR 2023-10-29 03:34:06,048 log Internal Server Error: /p2p/
Traceback (most recent call last):
  File "/home/ubuntu/github/easygo/venv/lib/python3.10/site-packages/django/core/handlers/exception.py", line 56, in inner
    response = get_response(request)
  File "/home/ubuntu/github/easygo/venv/lib/python3.10/site-packages/django/core/handlers/base.py", line 197, in _get_response
    response = wrapped_callback(request, *callback_args, **callback_kwargs)
  File "/home/ubuntu/github/easygo/basecamp/views.py", line 1166, in p2p
    email.send()
  File "/home/ubuntu/github/easygo/venv/lib/python3.10/site-packages/django/core/mail/message.py", line 298, in send
    return self.get_connection(fail_silently).send_messages([self])
  File "/home/ubuntu/github/easygo/venv/lib/python3.10/site-packages/django/core/mail/backends/smtp.py", line 124, in send_messages
    new_conn_created = self.open()
  File "/home/ubuntu/github/easygo/venv/lib/python3.10/site-packages/django/core/mail/backends/smtp.py", line 91, in open
    self.connection.login(self.username, self.password)
  File "/usr/lib/python3.10/smtplib.py", line 739, in login
    (code, resp) = self.auth(
  File "/usr/lib/python3.10/smtplib.py", line 642, in auth
    (code, resp) = self.docmd("AUTH", mechanism + " " + response)
  File "/usr/lib/python3.10/smtplib.py", line 432, in docmd
    return self.getreply()
  File "/usr/lib/python3.10/smtplib.py", line 405, in getreply
    raise SMTPServerDisconnected("Connection unexpectedly closed")
smtplib.SMTPServerDisconnected: Connection unexpectedly closed
ERROR 2023-10-29 03:34:07,951 log Internal Server Error: /p2p/
Traceback (most recent call last):
  File "/home/ubuntu/github/easygo/venv/lib/python3.10/site-packages/django/core/handlers/exception.py", line 56, in inner
    response = get_response(request)
  File "/home/ubuntu/github/easygo/venv/lib/python3.10/site-packages/django/core/handlers/base.py", line 197, in _get_response
    response = wrapped_callback(request, *callback_args, **callback_kwargs)
  File "/home/ubuntu/github/easygo/basecamp/views.py", line 1166, in p2p
    email.send()
  File "/home/ubuntu/github/easygo/venv/lib/python3.10/site-packages/django/core/mail/message.py", line 298, in send
    return self.get_connection(fail_silently).send_messages([self])
  File "/home/ubuntu/github/easygo/venv/lib/python3.10/site-packages/django/core/mail/backends/smtp.py", line 124, in send_messages
    new_conn_created = self.open()
  File "/home/ubuntu/github/easygo/venv/lib/python3.10/site-packages/django/core/mail/backends/smtp.py", line 91, in open
    self.connection.login(self.username, self.password)
  File "/usr/lib/python3.10/smtplib.py", line 739, in login
    (code, resp) = self.auth(
  File "/usr/lib/python3.10/smtplib.py", line 642, in auth
    (code, resp) = self.docmd("AUTH", mechanism + " " + response)
  File "/usr/lib/python3.10/smtplib.py", line 432, in docmd
    return self.getreply()
  File "/usr/lib/python3.10/smtplib.py", line 405, in getreply
    raise SMTPServerDisconnected("Connection unexpectedly closed")
smtplib.SMTPServerDisconnected: Connection unexpectedly closed
ERROR 2023-10-29 03:34:09,806 log Internal Server Error: /p2p/
Traceback (most recent call last):
  File "/home/ubuntu/github/easygo/venv/lib/python3.10/site-packages/django/core/handlers/exception.py", line 56, in inner
    response = get_response(request)
  File "/home/ubuntu/github/easygo/venv/lib/python3.10/site-packages/django/core/handlers/base.py", line 197, in _get_response
    response = wrapped_callback(request, *callback_args, **callback_kwargs)
  File "/home/ubuntu/github/easygo/basecamp/views.py", line 1166, in p2p
    email.send()
  File "/home/ubuntu/github/easygo/venv/lib/python3.10/site-packages/django/core/mail/message.py", line 298, in send
    return self.get_connection(fail_silently).send_messages([self])
  File "/home/ubuntu/github/easygo/venv/lib/python3.10/site-packages/django/core/mail/backends/smtp.py", line 124, in send_messages
    new_conn_created = self.open()
  File "/home/ubuntu/github/easygo/venv/lib/python3.10/site-packages/django/core/mail/backends/smtp.py", line 91, in open
    self.connection.login(self.username, self.password)
  File "/usr/lib/python3.10/smtplib.py", line 739, in login
    (code, resp) = self.auth(
  File "/usr/lib/python3.10/smtplib.py", line 642, in auth
    (code, resp) = self.docmd("AUTH", mechanism + " " + response)
  File "/usr/lib/python3.10/smtplib.py", line 432, in docmd
    return self.getreply()
  File "/usr/lib/python3.10/smtplib.py", line 405, in getreply
    raise SMTPServerDisconnected("Connection unexpectedly closed")
smtplib.SMTPServerDisconnected: Connection unexpectedly closed
ERROR 2023-10-29 03:34:12,328 log Internal Server Error: /p2p/
Traceback (most recent call last):
  File "/home/ubuntu/github/easygo/venv/lib/python3.10/site-packages/django/core/handlers/exception.py", line 56, in inner
    response = get_response(request)
  File "/home/ubuntu/github/easygo/venv/lib/python3.10/site-packages/django/core/handlers/base.py", line 197, in _get_response
    response = wrapped_callback(request, *callback_args, **callback_kwargs)
  File "/home/ubuntu/github/easygo/basecamp/views.py", line 1166, in p2p
    email.send()
  File "/home/ubuntu/github/easygo/venv/lib/python3.10/site-packages/django/core/mail/message.py", line 298, in send
    return self.get_connection(fail_silently).send_messages([self])
  File "/home/ubuntu/github/easygo/venv/lib/python3.10/site-packages/django/core/mail/backends/smtp.py", line 124, in send_messages
    new_conn_created = self.open()
  File "/home/ubuntu/github/easygo/venv/lib/python3.10/site-packages/django/core/mail/backends/smtp.py", line 91, in open
    self.connection.login(self.username, self.password)
  File "/usr/lib/python3.10/smtplib.py", line 739, in login
    (code, resp) = self.auth(
  File "/usr/lib/python3.10/smtplib.py", line 642, in auth
    (code, resp) = self.docmd("AUTH", mechanism + " " + response)
  File "/usr/lib/python3.10/smtplib.py", line 432, in docmd
    return self.getreply()
  File "/usr/lib/python3.10/smtplib.py", line 405, in getreply
    raise SMTPServerDisconnected("Connection unexpectedly closed")
smtplib.SMTPServerDisconnected: Connection unexpectedly closed
ERROR 2023-10-29 03:34:14,852 log Internal Server Error: /p2p/
Traceback (most recent call last):
  File "/home/ubuntu/github/easygo/venv/lib/python3.10/site-packages/django/core/handlers/exception.py", line 56, in inner
    response = get_response(request)
  File "/home/ubuntu/github/easygo/venv/lib/python3.10/site-packages/django/core/handlers/base.py", line 197, in _get_response
    response = wrapped_callback(request, *callback_args, **callback_kwargs)
  File "/home/ubuntu/github/easygo/basecamp/views.py", line 1166, in p2p
    email.send()
  File "/home/ubuntu/github/easygo/venv/lib/python3.10/site-packages/django/core/mail/message.py", line 298, in send
    return self.get_connection(fail_silently).send_messages([self])
  File "/home/ubuntu/github/easygo/venv/lib/python3.10/site-packages/django/core/mail/backends/smtp.py", line 124, in send_messages
    new_conn_created = self.open()
  File "/home/ubuntu/github/easygo/venv/lib/python3.10/site-packages/django/core/mail/backends/smtp.py", line 91, in open
    self.connection.login(self.username, self.password)
  File "/usr/lib/python3.10/smtplib.py", line 739, in login
    (code, resp) = self.auth(
  File "/usr/lib/python3.10/smtplib.py", line 642, in auth
    (code, resp) = self.docmd("AUTH", mechanism + " " + response)
  File "/usr/lib/python3.10/smtplib.py", line 432, in docmd
    return self.getreply()
  File "/usr/lib/python3.10/smtplib.py", line 405, in getreply
    raise SMTPServerDisconnected("Connection unexpectedly closed")
smtplib.SMTPServerDisconnected: Connection unexpectedly closed
ERROR 2023-10-29 03:34:17,385 log Internal Server Error: /p2p/
Traceback (most recent call last):
  File "/home/ubuntu/github/easygo/venv/lib/python3.10/site-packages/django/core/handlers/exception.py", line 56, in inner
    response = get_response(request)
  File "/home/ubuntu/github/easygo/venv/lib/python3.10/site-packages/django/core/handlers/base.py", line 197, in _get_response
    response = wrapped_callback(request, *callback_args, **callback_kwargs)
  File "/home/ubuntu/github/easygo/basecamp/views.py", line 1166, in p2p
    email.send()
  File "/home/ubuntu/github/easygo/venv/lib/python3.10/site-packages/django/core/mail/message.py", line 298, in send
    return self.get_connection(fail_silently).send_messages([self])
  File "/home/ubuntu/github/easygo/venv/lib/python3.10/site-packages/django/core/mail/backends/smtp.py", line 124, in send_messages
    new_conn_created = self.open()
  File "/home/ubuntu/github/easygo/venv/lib/python3.10/site-packages/django/core/mail/backends/smtp.py", line 91, in open
    self.connection.login(self.username, self.password)
  File "/usr/lib/python3.10/smtplib.py", line 739, in login
    (code, resp) = self.auth(
  File "/usr/lib/python3.10/smtplib.py", line 642, in auth
    (code, resp) = self.docmd("AUTH", mechanism + " " + response)
  File "/usr/lib/python3.10/smtplib.py", line 432, in docmd
    return self.getreply()
  File "/usr/lib/python3.10/smtplib.py", line 405, in getreply
    raise SMTPServerDisconnected("Connection unexpectedly closed")
smtplib.SMTPServerDisconnected: Connection unexpectedly closed
ERROR 2023-10-29 03:34:19,891 log Internal Server Error: /p2p/
Traceback (most recent call last):
  File "/home/ubuntu/github/easygo/venv/lib/python3.10/site-packages/django/core/handlers/exception.py", line 56, in inner
    response = get_response(request)
  File "/home/ubuntu/github/easygo/venv/lib/python3.10/site-packages/django/core/handlers/base.py", line 197, in _get_response
    response = wrapped_callback(request, *callback_args, **callback_kwargs)
  File "/home/ubuntu/github/easygo/basecamp/views.py", line 1166, in p2p
    email.send()
  File "/home/ubuntu/github/easygo/venv/lib/python3.10/site-packages/django/core/mail/message.py", line 298, in send
    return self.get_connection(fail_silently).send_messages([self])
  File "/home/ubuntu/github/easygo/venv/lib/python3.10/site-packages/django/core/mail/backends/smtp.py", line 124, in send_messages
    new_conn_created = self.open()
  File "/home/ubuntu/github/easygo/venv/lib/python3.10/site-packages/django/core/mail/backends/smtp.py", line 91, in open
    self.connection.login(self.username, self.password)
  File "/usr/lib/python3.10/smtplib.py", line 739, in login
    (code, resp) = self.auth(
  File "/usr/lib/python3.10/smtplib.py", line 642, in auth
    (code, resp) = self.docmd("AUTH", mechanism + " " + response)
  File "/usr/lib/python3.10/smtplib.py", line 432, in docmd
    return self.getreply()
  File "/usr/lib/python3.10/smtplib.py", line 405, in getreply
    raise SMTPServerDisconnected("Connection unexpectedly closed")
smtplib.SMTPServerDisconnected: Connection unexpectedly closed
ERROR 2023-10-29 03:34:22,411 log Internal Server Error: /p2p/
Traceback (most recent call last):
  File "/home/ubuntu/github/easygo/venv/lib/python3.10/site-packages/django/core/handlers/exception.py", line 56, in inner
    response = get_response(request)
  File "/home/ubuntu/github/easygo/venv/lib/python3.10/site-packages/django/core/handlers/base.py", line 197, in _get_response
    response = wrapped_callback(request, *callback_args, **callback_kwargs)
  File "/home/ubuntu/github/easygo/basecamp/views.py", line 1166, in p2p
    email.send()
  File "/home/ubuntu/github/easygo/venv/lib/python3.10/site-packages/django/core/mail/message.py", line 298, in send
    return self.get_connection(fail_silently).send_messages([self])
  File "/home/ubuntu/github/easygo/venv/lib/python3.10/site-packages/django/core/mail/backends/smtp.py", line 124, in send_messages
    new_conn_created = self.open()
  File "/home/ubuntu/github/easygo/venv/lib/python3.10/site-packages/django/core/mail/backends/smtp.py", line 91, in open
    self.connection.login(self.username, self.password)
  File "/usr/lib/python3.10/smtplib.py", line 739, in login
    (code, resp) = self.auth(
  File "/usr/lib/python3.10/smtplib.py", line 642, in auth
    (code, resp) = self.docmd("AUTH", mechanism + " " + response)
  File "/usr/lib/python3.10/smtplib.py", line 432, in docmd
    return self.getreply()
  File "/usr/lib/python3.10/smtplib.py", line 405, in getreply
    raise SMTPServerDisconnected("Connection unexpectedly closed")
smtplib.SMTPServerDisconnected: Connection unexpectedly closed
ERROR 2023-10-29 03:34:25,469 log Internal Server Error: /p2p/
Traceback (most recent call last):
  File "/home/ubuntu/github/easygo/venv/lib/python3.10/site-packages/django/core/handlers/exception.py", line 56, in inner
    response = get_response(request)
  File "/home/ubuntu/github/easygo/venv/lib/python3.10/site-packages/django/core/handlers/base.py", line 197, in _get_response
    response = wrapped_callback(request, *callback_args, **callback_kwargs)
  File "/home/ubuntu/github/easygo/basecamp/views.py", line 1166, in p2p
    email.send()
  File "/home/ubuntu/github/easygo/venv/lib/python3.10/site-packages/django/core/mail/message.py", line 298, in send
    return self.get_connection(fail_silently).send_messages([self])
  File "/home/ubuntu/github/easygo/venv/lib/python3.10/site-packages/django/core/mail/backends/smtp.py", line 124, in send_messages
    new_conn_created = self.open()
  File "/home/ubuntu/github/easygo/venv/lib/python3.10/site-packages/django/core/mail/backends/smtp.py", line 91, in open
    self.connection.login(self.username, self.password)
  File "/usr/lib/python3.10/smtplib.py", line 739, in login
    (code, resp) = self.auth(
  File "/usr/lib/python3.10/smtplib.py", line 642, in auth
    (code, resp) = self.docmd("AUTH", mechanism + " " + response)
  File "/usr/lib/python3.10/smtplib.py", line 432, in docmd
    return self.getreply()
  File "/usr/lib/python3.10/smtplib.py", line 405, in getreply
    raise SMTPServerDisconnected("Connection unexpectedly closed")
smtplib.SMTPServerDisconnected: Connection unexpectedly closed
ERROR 2023-10-29 03:34:28,071 log Internal Server Error: /p2p/
Traceback (most recent call last):
  File "/home/ubuntu/github/easygo/venv/lib/python3.10/site-packages/django/core/handlers/exception.py", line 56, in inner
    response = get_response(request)
  File "/home/ubuntu/github/easygo/venv/lib/python3.10/site-packages/django/core/handlers/base.py", line 197, in _get_response
    response = wrapped_callback(request, *callback_args, **callback_kwargs)
  File "/home/ubuntu/github/easygo/basecamp/views.py", line 1166, in p2p
    email.send()
  File "/home/ubuntu/github/easygo/venv/lib/python3.10/site-packages/django/core/mail/message.py", line 298, in send
    return self.get_connection(fail_silently).send_messages([self])
  File "/home/ubuntu/github/easygo/venv/lib/python3.10/site-packages/django/core/mail/backends/smtp.py", line 124, in send_messages
    new_conn_created = self.open()
  File "/home/ubuntu/github/easygo/venv/lib/python3.10/site-packages/django/core/mail/backends/smtp.py", line 91, in open
    self.connection.login(self.username, self.password)
  File "/usr/lib/python3.10/smtplib.py", line 739, in login
    (code, resp) = self.auth(
  File "/usr/lib/python3.10/smtplib.py", line 642, in auth
    (code, resp) = self.docmd("AUTH", mechanism + " " + response)
  File "/usr/lib/python3.10/smtplib.py", line 432, in docmd
    return self.getreply()
  File "/usr/lib/python3.10/smtplib.py", line 405, in getreply
    raise SMTPServerDisconnected("Connection unexpectedly closed")
smtplib.SMTPServerDisconnected: Connection unexpectedly closed
ERROR 2023-10-29 03:34:30,598 log Internal Server Error: /p2p/
Traceback (most recent call last):
  File "/home/ubuntu/github/easygo/venv/lib/python3.10/site-packages/django/core/handlers/exception.py", line 56, in inner
    response = get_response(request)
  File "/home/ubuntu/github/easygo/venv/lib/python3.10/site-packages/django/core/handlers/base.py", line 197, in _get_response
    response = wrapped_callback(request, *callback_args, **callback_kwargs)
  File "/home/ubuntu/github/easygo/basecamp/views.py", line 1166, in p2p
    email.send()
  File "/home/ubuntu/github/easygo/venv/lib/python3.10/site-packages/django/core/mail/message.py", line 298, in send
    return self.get_connection(fail_silently).send_messages([self])
  File "/home/ubuntu/github/easygo/venv/lib/python3.10/site-packages/django/core/mail/backends/smtp.py", line 124, in send_messages
    new_conn_created = self.open()
  File "/home/ubuntu/github/easygo/venv/lib/python3.10/site-packages/django/core/mail/backends/smtp.py", line 91, in open
    self.connection.login(self.username, self.password)
  File "/usr/lib/python3.10/smtplib.py", line 739, in login
    (code, resp) = self.auth(
  File "/usr/lib/python3.10/smtplib.py", line 642, in auth
    (code, resp) = self.docmd("AUTH", mechanism + " " + response)
  File "/usr/lib/python3.10/smtplib.py", line 432, in docmd
    return self.getreply()
  File "/usr/lib/python3.10/smtplib.py", line 405, in getreply
    raise SMTPServerDisconnected("Connection unexpectedly closed")
smtplib.SMTPServerDisconnected: Connection unexpectedly closed
ERROR 2023-10-29 03:34:33,123 log Internal Server Error: /p2p/
Traceback (most recent call last):
  File "/home/ubuntu/github/easygo/venv/lib/python3.10/site-packages/django/core/handlers/exception.py", line 56, in inner
    response = get_response(request)
  File "/home/ubuntu/github/easygo/venv/lib/python3.10/site-packages/django/core/handlers/base.py", line 197, in _get_response
    response = wrapped_callback(request, *callback_args, **callback_kwargs)
  File "/home/ubuntu/github/easygo/basecamp/views.py", line 1166, in p2p
    email.send()
  File "/home/ubuntu/github/easygo/venv/lib/python3.10/site-packages/django/core/mail/message.py", line 298, in send
    return self.get_connection(fail_silently).send_messages([self])
  File "/home/ubuntu/github/easygo/venv/lib/python3.10/site-packages/django/core/mail/backends/smtp.py", line 124, in send_messages
    new_conn_created = self.open()
  File "/home/ubuntu/github/easygo/venv/lib/python3.10/site-packages/django/core/mail/backends/smtp.py", line 91, in open
    self.connection.login(self.username, self.password)
  File "/usr/lib/python3.10/smtplib.py", line 739, in login
    (code, resp) = self.auth(
  File "/usr/lib/python3.10/smtplib.py", line 642, in auth
    (code, resp) = self.docmd("AUTH", mechanism + " " + response)
  File "/usr/lib/python3.10/smtplib.py", line 432, in docmd
    return self.getreply()
  File "/usr/lib/python3.10/smtplib.py", line 405, in getreply
    raise SMTPServerDisconnected("Connection unexpectedly closed")
smtplib.SMTPServerDisconnected: Connection unexpectedly closed
ERROR 2023-10-29 03:34:35,696 log Internal Server Error: /p2p/
Traceback (most recent call last):
  File "/home/ubuntu/github/easygo/venv/lib/python3.10/site-packages/django/core/handlers/exception.py", line 56, in inner
    response = get_response(request)
  File "/home/ubuntu/github/easygo/venv/lib/python3.10/site-packages/django/core/handlers/base.py", line 197, in _get_response
    response = wrapped_callback(request, *callback_args, **callback_kwargs)
  File "/home/ubuntu/github/easygo/basecamp/views.py", line 1166, in p2p
    email.send()
  File "/home/ubuntu/github/easygo/venv/lib/python3.10/site-packages/django/core/mail/message.py", line 298, in send
    return self.get_connection(fail_silently).send_messages([self])
  File "/home/ubuntu/github/easygo/venv/lib/python3.10/site-packages/django/core/mail/backends/smtp.py", line 124, in send_messages
    new_conn_created = self.open()
  File "/home/ubuntu/github/easygo/venv/lib/python3.10/site-packages/django/core/mail/backends/smtp.py", line 91, in open
    self.connection.login(self.username, self.password)
  File "/usr/lib/python3.10/smtplib.py", line 739, in login
    (code, resp) = self.auth(
  File "/usr/lib/python3.10/smtplib.py", line 642, in auth
    (code, resp) = self.docmd("AUTH", mechanism + " " + response)
  File "/usr/lib/python3.10/smtplib.py", line 432, in docmd
    return self.getreply()
  File "/usr/lib/python3.10/smtplib.py", line 405, in getreply
    raise SMTPServerDisconnected("Connection unexpectedly closed")
smtplib.SMTPServerDisconnected: Connection unexpectedly closed
ERROR 2023-10-29 03:34:38,201 log Internal Server Error: /p2p/
Traceback (most recent call last):
  File "/home/ubuntu/github/easygo/venv/lib/python3.10/site-packages/django/core/handlers/exception.py", line 56, in inner
    response = get_response(request)
  File "/home/ubuntu/github/easygo/venv/lib/python3.10/site-packages/django/core/handlers/base.py", line 197, in _get_response
    response = wrapped_callback(request, *callback_args, **callback_kwargs)
  File "/home/ubuntu/github/easygo/basecamp/views.py", line 1166, in p2p
    email.send()
  File "/home/ubuntu/github/easygo/venv/lib/python3.10/site-packages/django/core/mail/message.py", line 298, in send
    return self.get_connection(fail_silently).send_messages([self])
  File "/home/ubuntu/github/easygo/venv/lib/python3.10/site-packages/django/core/mail/backends/smtp.py", line 124, in send_messages
    new_conn_created = self.open()
  File "/home/ubuntu/github/easygo/venv/lib/python3.10/site-packages/django/core/mail/backends/smtp.py", line 91, in open
    self.connection.login(self.username, self.password)
  File "/usr/lib/python3.10/smtplib.py", line 739, in login
    (code, resp) = self.auth(
  File "/usr/lib/python3.10/smtplib.py", line 642, in auth
    (code, resp) = self.docmd("AUTH", mechanism + " " + response)
  File "/usr/lib/python3.10/smtplib.py", line 432, in docmd
    return self.getreply()
  File "/usr/lib/python3.10/smtplib.py", line 405, in getreply
    raise SMTPServerDisconnected("Connection unexpectedly closed")
smtplib.SMTPServerDisconnected: Connection unexpectedly closed
ERROR 2023-10-29 03:34:40,731 log Internal Server Error: /p2p/
Traceback (most recent call last):
  File "/home/ubuntu/github/easygo/venv/lib/python3.10/site-packages/django/core/handlers/exception.py", line 56, in inner
    response = get_response(request)
  File "/home/ubuntu/github/easygo/venv/lib/python3.10/site-packages/django/core/handlers/base.py", line 197, in _get_response
    response = wrapped_callback(request, *callback_args, **callback_kwargs)
  File "/home/ubuntu/github/easygo/basecamp/views.py", line 1166, in p2p
    email.send()
  File "/home/ubuntu/github/easygo/venv/lib/python3.10/site-packages/django/core/mail/message.py", line 298, in send
    return self.get_connection(fail_silently).send_messages([self])
  File "/home/ubuntu/github/easygo/venv/lib/python3.10/site-packages/django/core/mail/backends/smtp.py", line 124, in send_messages
    new_conn_created = self.open()
  File "/home/ubuntu/github/easygo/venv/lib/python3.10/site-packages/django/core/mail/backends/smtp.py", line 91, in open
    self.connection.login(self.username, self.password)
  File "/usr/lib/python3.10/smtplib.py", line 739, in login
    (code, resp) = self.auth(
  File "/usr/lib/python3.10/smtplib.py", line 642, in auth
    (code, resp) = self.docmd("AUTH", mechanism + " " + response)
  File "/usr/lib/python3.10/smtplib.py", line 432, in docmd
    return self.getreply()
  File "/usr/lib/python3.10/smtplib.py", line 405, in getreply
    raise SMTPServerDisconnected("Connection unexpectedly closed")
smtplib.SMTPServerDisconnected: Connection unexpectedly closed
ERROR 2023-10-29 03:34:43,250 log Internal Server Error: /p2p/
Traceback (most recent call last):
  File "/home/ubuntu/github/easygo/venv/lib/python3.10/site-packages/django/core/handlers/exception.py", line 56, in inner
    response = get_response(request)
  File "/home/ubuntu/github/easygo/venv/lib/python3.10/site-packages/django/core/handlers/base.py", line 197, in _get_response
    response = wrapped_callback(request, *callback_args, **callback_kwargs)
  File "/home/ubuntu/github/easygo/basecamp/views.py", line 1166, in p2p
    email.send()
  File "/home/ubuntu/github/easygo/venv/lib/python3.10/site-packages/django/core/mail/message.py", line 298, in send
    return self.get_connection(fail_silently).send_messages([self])
  File "/home/ubuntu/github/easygo/venv/lib/python3.10/site-packages/django/core/mail/backends/smtp.py", line 124, in send_messages
    new_conn_created = self.open()
  File "/home/ubuntu/github/easygo/venv/lib/python3.10/site-packages/django/core/mail/backends/smtp.py", line 91, in open
    self.connection.login(self.username, self.password)
  File "/usr/lib/python3.10/smtplib.py", line 739, in login
    (code, resp) = self.auth(
  File "/usr/lib/python3.10/smtplib.py", line 642, in auth
    (code, resp) = self.docmd("AUTH", mechanism + " " + response)
  File "/usr/lib/python3.10/smtplib.py", line 432, in docmd
    return self.getreply()
  File "/usr/lib/python3.10/smtplib.py", line 405, in getreply
    raise SMTPServerDisconnected("Connection unexpectedly closed")
smtplib.SMTPServerDisconnected: Connection unexpectedly closed
ERROR 2023-10-29 03:34:45,758 log Internal Server Error: /p2p/
Traceback (most recent call last):
  File "/home/ubuntu/github/easygo/venv/lib/python3.10/site-packages/django/core/handlers/exception.py", line 56, in inner
    response = get_response(request)
  File "/home/ubuntu/github/easygo/venv/lib/python3.10/site-packages/django/core/handlers/base.py", line 197, in _get_response
    response = wrapped_callback(request, *callback_args, **callback_kwargs)
  File "/home/ubuntu/github/easygo/basecamp/views.py", line 1166, in p2p
    email.send()
  File "/home/ubuntu/github/easygo/venv/lib/python3.10/site-packages/django/core/mail/message.py", line 298, in send
    return self.get_connection(fail_silently).send_messages([self])
  File "/home/ubuntu/github/easygo/venv/lib/python3.10/site-packages/django/core/mail/backends/smtp.py", line 124, in send_messages
    new_conn_created = self.open()
  File "/home/ubuntu/github/easygo/venv/lib/python3.10/site-packages/django/core/mail/backends/smtp.py", line 91, in open
    self.connection.login(self.username, self.password)
  File "/usr/lib/python3.10/smtplib.py", line 739, in login
    (code, resp) = self.auth(
  File "/usr/lib/python3.10/smtplib.py", line 642, in auth
    (code, resp) = self.docmd("AUTH", mechanism + " " + response)
  File "/usr/lib/python3.10/smtplib.py", line 432, in docmd
    return self.getreply()
  File "/usr/lib/python3.10/smtplib.py", line 405, in getreply
    raise SMTPServerDisconnected("Connection unexpectedly closed")
smtplib.SMTPServerDisconnected: Connection unexpectedly closed
ERROR 2023-10-29 03:34:48,264 log Internal Server Error: /p2p/
Traceback (most recent call last):
  File "/home/ubuntu/github/easygo/venv/lib/python3.10/site-packages/django/core/handlers/exception.py", line 56, in inner
    response = get_response(request)
  File "/home/ubuntu/github/easygo/venv/lib/python3.10/site-packages/django/core/handlers/base.py", line 197, in _get_response
    response = wrapped_callback(request, *callback_args, **callback_kwargs)
  File "/home/ubuntu/github/easygo/basecamp/views.py", line 1166, in p2p
    email.send()
  File "/home/ubuntu/github/easygo/venv/lib/python3.10/site-packages/django/core/mail/message.py", line 298, in send
    return self.get_connection(fail_silently).send_messages([self])
  File "/home/ubuntu/github/easygo/venv/lib/python3.10/site-packages/django/core/mail/backends/smtp.py", line 124, in send_messages
    new_conn_created = self.open()
  File "/home/ubuntu/github/easygo/venv/lib/python3.10/site-packages/django/core/mail/backends/smtp.py", line 91, in open
    self.connection.login(self.username, self.password)
  File "/usr/lib/python3.10/smtplib.py", line 739, in login
    (code, resp) = self.auth(
  File "/usr/lib/python3.10/smtplib.py", line 642, in auth
    (code, resp) = self.docmd("AUTH", mechanism + " " + response)
  File "/usr/lib/python3.10/smtplib.py", line 432, in docmd
    return self.getreply()
  File "/usr/lib/python3.10/smtplib.py", line 405, in getreply
    raise SMTPServerDisconnected("Connection unexpectedly closed")
smtplib.SMTPServerDisconnected: Connection unexpectedly closed
ERROR 2023-10-29 03:34:50,794 log Internal Server Error: /p2p/
Traceback (most recent call last):
  File "/home/ubuntu/github/easygo/venv/lib/python3.10/site-packages/django/core/handlers/exception.py", line 56, in inner
    response = get_response(request)
  File "/home/ubuntu/github/easygo/venv/lib/python3.10/site-packages/django/core/handlers/base.py", line 197, in _get_response
    response = wrapped_callback(request, *callback_args, **callback_kwargs)
  File "/home/ubuntu/github/easygo/basecamp/views.py", line 1166, in p2p
    email.send()
  File "/home/ubuntu/github/easygo/venv/lib/python3.10/site-packages/django/core/mail/message.py", line 298, in send
    return self.get_connection(fail_silently).send_messages([self])
  File "/home/ubuntu/github/easygo/venv/lib/python3.10/site-packages/django/core/mail/backends/smtp.py", line 124, in send_messages
    new_conn_created = self.open()
  File "/home/ubuntu/github/easygo/venv/lib/python3.10/site-packages/django/core/mail/backends/smtp.py", line 91, in open
    self.connection.login(self.username, self.password)
  File "/usr/lib/python3.10/smtplib.py", line 739, in login
    (code, resp) = self.auth(
  File "/usr/lib/python3.10/smtplib.py", line 642, in auth
    (code, resp) = self.docmd("AUTH", mechanism + " " + response)
  File "/usr/lib/python3.10/smtplib.py", line 432, in docmd
    return self.getreply()
  File "/usr/lib/python3.10/smtplib.py", line 405, in getreply
    raise SMTPServerDisconnected("Connection unexpectedly closed")
smtplib.SMTPServerDisconnected: Connection unexpectedly closed
ERROR 2023-10-29 03:34:53,308 log Internal Server Error: /p2p/
Traceback (most recent call last):
  File "/home/ubuntu/github/easygo/venv/lib/python3.10/site-packages/django/core/handlers/exception.py", line 56, in inner
    response = get_response(request)
  File "/home/ubuntu/github/easygo/venv/lib/python3.10/site-packages/django/core/handlers/base.py", line 197, in _get_response
    response = wrapped_callback(request, *callback_args, **callback_kwargs)
  File "/home/ubuntu/github/easygo/basecamp/views.py", line 1166, in p2p
    email.send()
  File "/home/ubuntu/github/easygo/venv/lib/python3.10/site-packages/django/core/mail/message.py", line 298, in send
    return self.get_connection(fail_silently).send_messages([self])
  File "/home/ubuntu/github/easygo/venv/lib/python3.10/site-packages/django/core/mail/backends/smtp.py", line 124, in send_messages
    new_conn_created = self.open()
  File "/home/ubuntu/github/easygo/venv/lib/python3.10/site-packages/django/core/mail/backends/smtp.py", line 91, in open
    self.connection.login(self.username, self.password)
  File "/usr/lib/python3.10/smtplib.py", line 739, in login
    (code, resp) = self.auth(
  File "/usr/lib/python3.10/smtplib.py", line 642, in auth
    (code, resp) = self.docmd("AUTH", mechanism + " " + response)
  File "/usr/lib/python3.10/smtplib.py", line 432, in docmd
    return self.getreply()
  File "/usr/lib/python3.10/smtplib.py", line 405, in getreply
    raise SMTPServerDisconnected("Connection unexpectedly closed")
smtplib.SMTPServerDisconnected: Connection unexpectedly closed
WARNING 2023-10-29 03:44:35,167 log Not Found: /robots.txt
WARNING 2023-10-29 03:57:07,746 log Not Found: /airport-transfers-dural/
WARNING 2023-10-29 03:57:16,639 log Not Found: /robots.txt
WARNING 2023-10-29 04:23:09,438 log Forbidden (Referer checking failed - no Referer.): /inquiry_details/
WARNING 2023-10-29 04:23:10,309 log Forbidden (Referer checking failed - no Referer.): /inquiry_details/
WARNING 2023-10-29 04:23:11,073 log Forbidden (Referer checking failed - no Referer.): /inquiry_details/
WARNING 2023-10-29 04:23:12,678 log Forbidden (Referer checking failed - no Referer.): /inquiry_details1/
WARNING 2023-10-29 04:23:13,345 log Forbidden (Referer checking failed - no Referer.): /inquiry_details1/
WARNING 2023-10-29 04:23:14,014 log Forbidden (Referer checking failed - no Referer.): /inquiry_details1/
WARNING 2023-10-29 04:23:32,544 log Not Found: /products/registry/
WARNING 2023-10-29 04:23:37,574 log Not Found: /technology/
WARNING 2023-10-29 04:23:38,241 log Not Found: /products/news/
WARNING 2023-10-29 04:23:38,907 log Not Found: /technology/developers/
WARNING 2023-10-29 04:23:42,512 log Forbidden (Referer checking failed - no Referer.): /inquiry_details2/
WARNING 2023-10-29 04:23:43,498 log Forbidden (Referer checking failed - no Referer.): /inquiry_details2/
WARNING 2023-10-29 04:23:44,167 log Forbidden (Referer checking failed - no Referer.): /inquiry_details2/
WARNING 2023-10-29 04:28:30,236 log Not Found: /robots.txt
WARNING 2023-10-29 04:29:16,504 log Not Found: /.env
WARNING 2023-10-29 04:29:17,919 log Forbidden (Referer checking failed - no Referer.): /
WARNING 2023-10-29 04:29:22,381 log Not Found: /vendor/phpunit/phpunit/src/Util/PHP/eval-stdin.php
WARNING 2023-10-29 04:40:03,396 log Not Found: /.git/config
WARNING 2023-10-29 04:50:24,645 log Not Found: /robots.txt
WARNING 2023-10-29 04:51:52,089 log Not Found: /robots.txt
WARNING 2023-10-29 05:00:23,574 log Not Found: /Core/Skin/Login.aspx
WARNING 2023-10-29 06:04:21,771 log Not Found: /robots.txt
WARNING 2023-10-29 06:16:43,906 log Not Found: /apple-touch-icon-precomposed.png
WARNING 2023-10-29 06:16:43,914 log Not Found: /apple-touch-icon.png
WARNING 2023-10-29 06:21:07,296 log Not Found: /shop/sv/product-category/moncler-stovlar/
WARNING 2023-10-29 06:37:20,650 log Not Found: /Core/Skin/Login.aspx
WARNING 2023-10-29 06:39:38,789 log Not Found: /shop/nn/product/moncler-auburn-10/
WARNING 2023-10-29 06:50:54,430 log Not Found: /robots.txt
WARNING 2023-10-29 07:42:25,329 log Not Found: /airport-transfers-drummoyne/
WARNING 2023-10-29 08:12:21,433 log Not Found: /Core/Skin/Login.aspx
WARNING 2023-10-29 08:20:57,432 log Not Found: /wp-login.php
WARNING 2023-10-29 08:33:57,941 log Forbidden (Referer checking failed - no Referer.): /inquiry_details/
WARNING 2023-10-29 08:33:58,396 log Forbidden (Referer checking failed - no Referer.): /inquiry_details/
WARNING 2023-10-29 08:33:58,852 log Forbidden (Referer checking failed - no Referer.): /inquiry_details/
WARNING 2023-10-29 08:33:59,806 log Forbidden (Referer checking failed - no Referer.): /inquiry_details2/
WARNING 2023-10-29 08:34:00,259 log Forbidden (Referer checking failed - no Referer.): /inquiry_details2/
WARNING 2023-10-29 08:34:00,716 log Forbidden (Referer checking failed - no Referer.): /inquiry_details2/
WARNING 2023-10-29 08:34:09,556 log Not Found: /products/news/
WARNING 2023-10-29 08:34:12,972 log Not Found: /technology/developers/
WARNING 2023-10-29 08:34:13,433 log Not Found: /products/registry/
WARNING 2023-10-29 08:34:13,897 log Not Found: /technology/families/
WARNING 2023-10-29 08:34:16,823 log Forbidden (Referer checking failed - no Referer.): /inquiry_details1/
WARNING 2023-10-29 08:34:17,288 log Forbidden (Referer checking failed - no Referer.): /inquiry_details1/
WARNING 2023-10-29 08:34:17,768 log Forbidden (Referer checking failed - no Referer.): /inquiry_details1/
WARNING 2023-10-29 08:52:08,161 log Not Found: /robots.txt
WARNING 2023-10-29 09:12:34,631 log Not Found: /.env
WARNING 2023-10-29 09:12:36,013 log Forbidden (Referer checking failed - no Referer.): /
WARNING 2023-10-29 09:47:13,975 log Not Found: /Core/Skin/Login.aspx
WARNING 2023-10-29 10:04:05,822 log Not Found: /apple-touch-icon.png
WARNING 2023-10-29 10:04:05,834 log Not Found: /apple-touch-icon-precomposed.png
WARNING 2023-10-29 10:04:06,124 log Not Found: /apple-touch-icon.png
WARNING 2023-10-29 10:04:06,137 log Not Found: /apple-touch-icon-precomposed.png
ERROR 2023-10-29 10:22:37,335 exception Invalid HTTP_HOST header: 'instance-data'. You may need to add 'instance-data' to ALLOWED_HOSTS.
WARNING 2023-10-29 10:22:37,338 log Bad Request: /latest/meta-data/
WARNING 2023-10-29 10:28:29,434 log Not Found: /robots.txt
WARNING 2023-10-29 10:31:12,104 log Not Found: /phpinfo.php
WARNING 2023-10-29 10:31:13,838 log Not Found: /info.php
WARNING 2023-10-29 10:31:14,857 log Not Found: /phpinfo
WARNING 2023-10-29 10:31:15,694 log Not Found: /php.php
WARNING 2023-10-29 10:31:16,133 log Not Found: /php_info.php
WARNING 2023-10-29 10:31:17,146 log Not Found: /phptest.php
WARNING 2023-10-29 10:31:18,166 log Not Found: /dashboard/phpinfo.php
WARNING 2023-10-29 10:31:19,037 log Not Found: /infophp.php
WARNING 2023-10-29 10:31:19,610 log Not Found: /p.php
WARNING 2023-10-29 10:31:20,761 log Not Found: /_profiler/phpinfo
WARNING 2023-10-29 10:31:21,342 log Not Found: /info.php
WARNING 2023-10-29 10:31:22,066 log Not Found: /pinfo.php
WARNING 2023-10-29 10:31:22,910 log Not Found: /scripts/phpinfo.php
WARNING 2023-10-29 10:31:23,884 log Not Found: /phpinfo.php
WARNING 2023-10-29 10:31:25,994 log Not Found: /phpinfo/phpinfo.php
WARNING 2023-10-29 10:31:26,624 log Not Found: /information.php
WARNING 2023-10-29 10:31:28,338 log Not Found: /phpinformation
WARNING 2023-10-29 10:31:29,762 log Not Found: /php-info.php
WARNING 2023-10-29 10:31:31,291 log Not Found: /phpversion.php
WARNING 2023-10-29 10:31:32,129 log Not Found: /webdav/phpinfo.php
WARNING 2023-10-29 10:31:32,846 log Not Found: /webdav/phpinfo
WARNING 2023-10-29 10:31:33,967 log Not Found: /webdav/info.php
WARNING 2023-10-29 10:31:34,688 log Not Found: /testphpinfo.php
WARNING 2023-10-29 10:31:35,153 log Not Found: /testphpinfo
WARNING 2023-10-29 10:31:35,606 log Not Found: /admin.php
WARNING 2023-10-29 10:31:36,532 log Not Found: /_phpinfo.php
WARNING 2023-10-29 10:31:37,187 log Not Found: /PHPConf.php
WARNING 2023-10-29 10:31:39,761 log Not Found: /viewinfo.php
WARNING 2023-10-29 10:31:42,323 log Not Found: /info/phpinfo.php
WARNING 2023-10-29 10:31:44,083 log Not Found: /info/info.php
WARNING 2023-10-29 10:31:44,971 log Not Found: /.env
WARNING 2023-10-29 10:31:46,118 log Not Found: /.env.save
WARNING 2023-10-29 10:31:47,573 log Not Found: /.env.old
WARNING 2023-10-29 10:31:48,697 log Not Found: /.env.prod
WARNING 2023-10-29 10:31:49,471 log Not Found: /.env.production
WARNING 2023-10-29 10:31:50,697 log Not Found: /.env.development
WARNING 2023-10-29 10:31:51,515 log Not Found: /laravel/.env
WARNING 2023-10-29 10:31:52,618 log Not Found: /admin-app/.env
WARNING 2023-10-29 10:31:53,120 log Not Found: /api/.env
WARNING 2023-10-29 10:31:53,566 log Not Found: /app/.env
WARNING 2023-10-29 10:31:54,001 log Not Found: /development/.env
WARNING 2023-10-29 10:31:54,437 log Not Found: /apps/.env
WARNING 2023-10-29 10:31:55,014 log Not Found: /.aws/credentials
WARNING 2023-10-29 10:31:55,618 log Not Found: /private/.env
WARNING 2023-10-29 10:31:56,057 log Not Found: /system/.env
WARNING 2023-10-29 10:31:56,695 log Not Found: /docker/.env
WARNING 2023-10-29 10:31:58,607 log Not Found: /cms/.env
WARNING 2023-10-29 10:32:01,029 log Not Found: /script/.env
WARNING 2023-10-29 10:32:02,444 log Not Found: /live_env
WARNING 2023-10-29 10:32:04,314 log Not Found: /application/.env
WARNING 2023-10-29 10:32:06,219 log Not Found: /.env.project
WARNING 2023-10-29 10:32:08,537 log Not Found: /.env.dist
WARNING 2023-10-29 10:32:10,187 log Not Found: /back/.env
WARNING 2023-10-29 10:32:12,958 log Not Found: /core/.env
WARNING 2023-10-29 10:32:13,882 log Not Found: /docker/.env
WARNING 2023-10-29 10:32:15,785 log Not Found: /fedex/.env
WARNING 2023-10-29 10:32:17,198 log Not Found: /local/.env
WARNING 2023-10-29 10:32:19,396 log Not Found: /rest/.env
WARNING 2023-10-29 10:32:21,306 log Not Found: /shared/.env
WARNING 2023-10-29 10:32:23,297 log Not Found: /sources/.env
WARNING 2023-10-29 10:32:25,865 log Not Found: /enviroments/.env.production
WARNING 2023-10-29 10:32:26,994 log Not Found: /enviroments/.env
WARNING 2023-10-29 10:32:28,534 log Forbidden (Referer checking failed - no Referer.): /
WARNING 2023-10-29 10:38:06,281 log Not Found: /shop/size/s/
WARNING 2023-10-29 10:55:05,414 log Not Found: /robots.txt
WARNING 2023-10-29 11:07:38,199 log Not Found: /.env
WARNING 2023-10-29 11:07:53,450 log Forbidden (Referer checking failed - no Referer.): /
WARNING 2023-10-29 11:08:03,162 log Not Found: /sendgrid/.env
WARNING 2023-10-29 11:08:10,116 log Forbidden (Referer checking failed - no Referer.): /
WARNING 2023-10-29 11:22:05,959 log Not Found: /Core/Skin/Login.aspx
WARNING 2023-10-29 11:45:16,796 log Not Found: /shop/nn/kurv-2/
WARNING 2023-10-29 12:16:54,289 log Not Found: //.env
WARNING 2023-10-29 12:17:38,563 log Forbidden (Referer checking failed - no Referer.): /
WARNING 2023-10-29 12:20:43,559 log Not Found: /apple-touch-icon.png
WARNING 2023-10-29 12:20:43,563 log Not Found: /apple-touch-icon-precomposed.png
WARNING 2023-10-29 12:24:04,962 log Not Found: /robots.txt
WARNING 2023-10-29 12:34:02,687 log Not Found: /.env
WARNING 2023-10-29 12:34:03,859 log Forbidden (Referer checking failed - no Referer.): /
WARNING 2023-10-29 12:37:27,141 log Not Found: /webui/
WARNING 2023-10-29 12:45:24,474 log Not Found: /vpn/index.html
WARNING 2023-10-29 12:46:17,731 log Not Found: /geoserver/web/
WARNING 2023-10-29 12:46:49,383 log Not Found: /.git/config
WARNING 2023-10-29 12:57:23,699 log Not Found: /Core/Skin/Login.aspx
ERROR 2023-10-29 13:19:59,002 log Internal Server Error: /paypal_ipn/
WARNING 2023-10-29 13:23:09,907 log Not Found: /robots.txt
WARNING 2023-10-29 13:23:13,608 log Not Found: /shop/size/us7-eu38/
WARNING 2023-10-29 13:30:13,393 log Not Found: /robots.txt
WARNING 2023-10-29 13:30:14,016 log Not Found: /robots.txt
WARNING 2023-10-29 13:30:18,275 log Not Found: /robots.txt
WARNING 2023-10-29 13:30:25,258 log Not Found: /robots.txt
WARNING 2023-10-29 13:30:25,910 log Not Found: /robots.txt
WARNING 2023-10-29 13:34:35,240 log Not Found: /shop/es/product/moncler-bady-13/
WARNING 2023-10-29 13:40:33,601 log Not Found: /robots.txt
WARNING 2023-10-29 13:40:43,649 log Not Found: /home/url(/static/basecamp/photos/easygo-home-page3.webp)
WARNING 2023-10-29 13:41:17,423 log Not Found: /robots.txt
WARNING 2023-10-29 13:41:19,685 log Not Found: /home/url(/static/basecamp/photos/back10.PNG.webp)
WARNING 2023-10-29 13:42:11,456 log Not Found: /home/url(/static/basecamp/photos/easygo-home-page3.webp)
WARNING 2023-10-29 13:42:51,206 log Not Found: /home/url(/static/basecamp/photos/back10.PNG.webp)
WARNING 2023-10-29 13:44:43,119 log Not Found: /robots.txt
WARNING 2023-10-29 14:11:10,066 log Not Found: /shop/product/2014-new-moncler-pety-top-quality-womens-down-vests-mauve/
WARNING 2023-10-29 14:29:11,195 log Not Found: /robots.txt
WARNING 2023-10-29 14:32:44,240 log Not Found: /Core/Skin/Login.aspx
WARNING 2023-10-29 14:35:02,138 log Not Found: /.well-known/acme-challenge/817QB-J4B_O9BF4DVK3HT1CLTQFNTB4G
WARNING 2023-10-29 14:35:03,161 log Not Found: /.well-known/acme-challenge/4H1M7P-IGS__1NBGTAORA3IIUFXTK7X_
WARNING 2023-10-29 14:47:12,994 log Not Found: /robots.txt
WARNING 2023-10-29 14:48:12,611 log Not Found: /robots.txt
WARNING 2023-10-29 15:08:42,101 log Not Found: /shop/product/moncler-armoise-coat-for-women-grey-long/
WARNING 2023-10-29 15:28:11,298 log Not Found: /ab2g
WARNING 2023-10-29 15:28:11,311 log Not Found: /ab2h
WARNING 2023-10-29 15:28:11,381 log Not Found: /t4
WARNING 2023-10-29 15:57:26,839 log Not Found: /.env
WARNING 2023-10-29 15:58:12,594 log Not Found: /actuator/health
WARNING 2023-10-29 16:07:54,518 log Not Found: /Core/Skin/Login.aspx
WARNING 2023-10-29 16:11:25,889 log Not Found: /owa/auth/x.js
WARNING 2023-10-29 16:20:08,603 log Not Found: /wp-content/themes/twentyseventeen/ALFA_DATA/alfacgiapi/
WARNING 2023-10-29 16:21:45,683 log Not Found: /robots.txt
WARNING 2023-10-29 16:22:22,744 log Not Found: /robots.txt
WARNING 2023-10-29 16:22:34,581 log Not Found: /shop/ko/product/남자를위한-moncler-acorus-euramerican-스타일-자켓/
WARNING 2023-10-29 16:49:11,774 log Not Found: /robots.txt
WARNING 2023-10-29 16:49:26,935 log Not Found: /.env
WARNING 2023-10-29 16:49:28,148 log Forbidden (Referer checking failed - no Referer.): /
WARNING 2023-10-29 16:53:04,295 log Not Found: /.env
WARNING 2023-10-29 16:59:57,619 log Not Found: /css.php
WARNING 2023-10-29 17:00:03,099 log Not Found: /_css.php
WARNING 2023-10-29 17:03:04,164 log Not Found: /robots.txt
WARNING 2023-10-29 17:44:30,579 log Not Found: /Core/Skin/Login.aspx
WARNING 2023-10-29 17:52:56,704 log Not Found: /robots.txt
WARNING 2023-10-29 17:53:20,554 log Not Found: /robots.txt
WARNING 2023-10-29 17:56:52,372 log Not Found: /.well-known/traffic-advice
WARNING 2023-10-29 17:56:53,485 log Not Found: /.well-known/traffic-advice
WARNING 2023-10-29 18:08:32,987 log Not Found: /home/wp-login.php
WARNING 2023-10-29 18:08:32,989 log Not Found: /wp-login.php
WARNING 2023-10-29 18:32:04,953 log Forbidden (Referer checking failed - no Referer.): /admin/login/
WARNING 2023-10-29 19:03:59,264 log Not Found: /.env
WARNING 2023-10-29 19:04:00,498 log Forbidden (Referer checking failed - no Referer.): /
