DEBUG 2023-12-27 16:53:13,310 base Exception while resolving variable 'email' in template 'basecamp/html_email-upcoming3.html'.
Traceback (most recent call last):
  File "/home/horeb/github/easygo/venv/lib/python3.11/site-packages/django/template/base.py", line 880, in _resolve_lookup
    current = current[bit]
              ~~~~~~~^^^^^
  File "/home/horeb/github/easygo/venv/lib/python3.11/site-packages/django/template/context.py", line 83, in __getitem__
    raise KeyError(key)
KeyError: 'email'

During handling of the above exception, another exception occurred:

Traceback (most recent call last):
  File "/home/horeb/github/easygo/venv/lib/python3.11/site-packages/django/template/base.py", line 886, in _resolve_lookup
    if isinstance(current, BaseContext) and getattr(
                                            ^^^^^^^^
AttributeError: type object 'Context' has no attribute 'email'

During handling of the above exception, another exception occurred:

Traceback (most recent call last):
  File "/home/horeb/github/easygo/venv/lib/python3.11/site-packages/django/template/base.py", line 896, in _resolve_lookup
    current = current[int(bit)]
                      ^^^^^^^^
ValueError: invalid literal for int() with base 10: 'email'

During handling of the above exception, another exception occurred:

Traceback (most recent call last):
  File "/home/horeb/github/easygo/venv/lib/python3.11/site-packages/django/template/base.py", line 903, in _resolve_lookup
    raise VariableDoesNotExist(
django.template.base.VariableDoesNotExist: Failed lookup for key [email] in [{'True': True, 'False': False, 'None': None}, {'name': 'Hau Wong', 'flight_date': datetime.date(2023, 12, 30), 'flight_number': 'TR21', 'flight_time': '21:00', 'direction': 'Drop off to Intl Airport', 'pickup_time': '16:30', 'street': '1 Rippon Avenue', 'suburb': 'Dundas', 'price': '100', 'meeting_point': None, 'driver_name': 'Sam', 'driver_contact': '0406783559', 'driver_plate': 'TV 8276', 'driver_car': 'White van (Toyota Hiace)'}]
DEBUG 2023-12-27 16:53:17,156 base Exception while resolving variable 'email' in template 'basecamp/html_email-upcoming3.html'.
Traceback (most recent call last):
  File "/home/horeb/github/easygo/venv/lib/python3.11/site-packages/django/template/base.py", line 880, in _resolve_lookup
    current = current[bit]
              ~~~~~~~^^^^^
  File "/home/horeb/github/easygo/venv/lib/python3.11/site-packages/django/template/context.py", line 83, in __getitem__
    raise KeyError(key)
KeyError: 'email'

During handling of the above exception, another exception occurred:

Traceback (most recent call last):
  File "/home/horeb/github/easygo/venv/lib/python3.11/site-packages/django/template/base.py", line 886, in _resolve_lookup
    if isinstance(current, BaseContext) and getattr(
                                            ^^^^^^^^
AttributeError: type object 'Context' has no attribute 'email'

During handling of the above exception, another exception occurred:

Traceback (most recent call last):
  File "/home/horeb/github/easygo/venv/lib/python3.11/site-packages/django/template/base.py", line 896, in _resolve_lookup
    current = current[int(bit)]
                      ^^^^^^^^
ValueError: invalid literal for int() with base 10: 'email'

During handling of the above exception, another exception occurred:

Traceback (most recent call last):
  File "/home/horeb/github/easygo/venv/lib/python3.11/site-packages/django/template/base.py", line 903, in _resolve_lookup
    raise VariableDoesNotExist(
django.template.base.VariableDoesNotExist: Failed lookup for key [email] in [{'True': True, 'False': False, 'None': None}, {'name': 'Priscilla Chow', 'flight_date': datetime.date(2023, 12, 30), 'flight_number': 'CX162', 'flight_time': '10:55', 'direction': 'Drop off to Intl Airport', 'pickup_time': '07:00', 'street': '20 Ganmain Road Pymble', 'suburb': 'Pymble', 'price': '90', 'meeting_point': None, 'driver_name': 'Sam', 'driver_contact': '0406783559', 'driver_plate': 'TV 8276', 'driver_car': 'White van (Toyota Hiace)'}]
DEBUG 2023-12-27 16:53:20,970 base Exception while resolving variable 'email' in template 'basecamp/html_email-upcoming3.html'.
Traceback (most recent call last):
  File "/home/horeb/github/easygo/venv/lib/python3.11/site-packages/django/template/base.py", line 880, in _resolve_lookup
    current = current[bit]
              ~~~~~~~^^^^^
  File "/home/horeb/github/easygo/venv/lib/python3.11/site-packages/django/template/context.py", line 83, in __getitem__
    raise KeyError(key)
KeyError: 'email'

During handling of the above exception, another exception occurred:

Traceback (most recent call last):
  File "/home/horeb/github/easygo/venv/lib/python3.11/site-packages/django/template/base.py", line 886, in _resolve_lookup
    if isinstance(current, BaseContext) and getattr(
                                            ^^^^^^^^
AttributeError: type object 'Context' has no attribute 'email'

During handling of the above exception, another exception occurred:

Traceback (most recent call last):
  File "/home/horeb/github/easygo/venv/lib/python3.11/site-packages/django/template/base.py", line 896, in _resolve_lookup
    current = current[int(bit)]
                      ^^^^^^^^
ValueError: invalid literal for int() with base 10: 'email'

During handling of the above exception, another exception occurred:

Traceback (most recent call last):
  File "/home/horeb/github/easygo/venv/lib/python3.11/site-packages/django/template/base.py", line 903, in _resolve_lookup
    raise VariableDoesNotExist(
django.template.base.VariableDoesNotExist: Failed lookup for key [email] in [{'True': True, 'False': False, 'None': None}, {'name': 'Lisa-Anne Savusa', 'flight_date': datetime.date(2023, 12, 30), 'flight_number': 'FJ916', 'flight_time': '15:40', 'direction': 'Drop off to Intl Airport', 'pickup_time': '07:15', 'street': '141 chestnut cres', 'suburb': 'Bidwill', 'price': '200', 'meeting_point': None, 'driver_name': 'Sam', 'driver_contact': '0406783559', 'driver_plate': 'TV 8276', 'driver_car': 'White van (Toyota Hiace)'}]
DEBUG 2023-12-27 16:53:24,904 base Exception while resolving variable 'email' in template 'basecamp/html_email-upcoming3.html'.
Traceback (most recent call last):
  File "/home/horeb/github/easygo/venv/lib/python3.11/site-packages/django/template/base.py", line 880, in _resolve_lookup
    current = current[bit]
              ~~~~~~~^^^^^
  File "/home/horeb/github/easygo/venv/lib/python3.11/site-packages/django/template/context.py", line 83, in __getitem__
    raise KeyError(key)
KeyError: 'email'

During handling of the above exception, another exception occurred:

Traceback (most recent call last):
  File "/home/horeb/github/easygo/venv/lib/python3.11/site-packages/django/template/base.py", line 886, in _resolve_lookup
    if isinstance(current, BaseContext) and getattr(
                                            ^^^^^^^^
AttributeError: type object 'Context' has no attribute 'email'

During handling of the above exception, another exception occurred:

Traceback (most recent call last):
  File "/home/horeb/github/easygo/venv/lib/python3.11/site-packages/django/template/base.py", line 896, in _resolve_lookup
    current = current[int(bit)]
                      ^^^^^^^^
ValueError: invalid literal for int() with base 10: 'email'

During handling of the above exception, another exception occurred:

Traceback (most recent call last):
  File "/home/horeb/github/easygo/venv/lib/python3.11/site-packages/django/template/base.py", line 903, in _resolve_lookup
    raise VariableDoesNotExist(
django.template.base.VariableDoesNotExist: Failed lookup for key [email] in [{'True': True, 'False': False, 'None': None}, {'name': 'Leo Cortez', 'flight_date': datetime.date(2023, 12, 30), 'flight_number': 'VA501', 'flight_time': '06:20', 'direction': 'Drop off to Domestic Airport', 'pickup_time': '04:50', 'street': '29 Crestview Dr', 'suburb': 'Glenwood', 'price': '360', 'meeting_point': None, 'driver_name': 'Sam', 'driver_contact': '0406783559', 'driver_plate': 'TV 8276', 'driver_car': 'White van (Toyota Hiace)'}]
