WARNING 2023-12-03 11:24:00,653 log Not Found: /inquiry3/
WARNING 2023-12-03 12:15:04,726 log Not Found: /.well-known/traffic-advice
WARNING 2023-12-03 12:27:28,177 log Not Found: /robots.txt
WARNING 2023-12-03 12:28:42,101 log Not Found: /robots.txt
WARNING 2023-12-03 12:29:58,916 log Not Found: /inquiry3/
DEBUG 2023-12-03 12:33:38,910 base Exception while resolving variable 'recaptcha_site_key' in template 'basecamp/inquiry1.html'.
Traceback (most recent call last):
  File "/home/horeb/github/easygo/venv/lib/python3.11/site-packages/django/template/base.py", line 880, in _resolve_lookup
    current = current[bit]
              ~~~~~~~^^^^^
  File "/home/horeb/github/easygo/venv/lib/python3.11/site-packages/django/template/context.py", line 83, in __getitem__
    raise KeyError(key)
KeyError: 'recaptcha_site_key'

During handling of the above exception, another exception occurred:

Traceback (most recent call last):
  File "/home/horeb/github/easygo/venv/lib/python3.11/site-packages/django/template/base.py", line 886, in _resolve_lookup
    if isinstance(current, BaseContext) and getattr(
                                            ^^^^^^^^
AttributeError: type object 'RequestContext' has no attribute 'recaptcha_site_key'

During handling of the above exception, another exception occurred:

Traceback (most recent call last):
  File "/home/horeb/github/easygo/venv/lib/python3.11/site-packages/django/template/base.py", line 896, in _resolve_lookup
    current = current[int(bit)]
                      ^^^^^^^^
ValueError: invalid literal for int() with base 10: 'recaptcha_site_key'

During handling of the above exception, another exception occurred:

Traceback (most recent call last):
  File "/home/horeb/github/easygo/venv/lib/python3.11/site-packages/django/template/base.py", line 903, in _resolve_lookup
    raise VariableDoesNotExist(
django.template.base.VariableDoesNotExist: Failed lookup for key [recaptcha_site_key] in [{'True': True, 'False': False, 'None': None}, {'csrf_token': <SimpleLazyObject: '5HRjvmot9moWCnt2buWWKSzQINE9Syax4WA3BJGcd1VpRgT6LvJp8OkbQq2OJUlV'>, 'request': <WSGIRequest: POST '/price_detail/'>, 'user': <SimpleLazyObject: <function AuthenticationMiddleware.process_request.<locals>.<lambda> at 0x7fb7dac07240>>, 'perms': PermWrapper(<SimpleLazyObject: <function AuthenticationMiddleware.process_request.<locals>.<lambda> at 0x7fb7dac07240>>), 'messages': <FallbackStorage: request=<WSGIRequest: POST '/price_detail/'>>, 'DEFAULT_MESSAGE_LEVELS': {'DEBUG': 10, 'INFO': 20, 'SUCCESS': 25, 'WARNING': 30, 'ERROR': 40}}, {}, {'flight_date': '2023-12-23', 'direction': 'Drop off to Intl Airport', 'suburb': 'Brookvale', 'no_of_passenger': '1'}, {'block': <Block Node: content. Contents: [<TextNode: '\n      <!-- Page content-'>, <Variable Node: flight_date>, <TextNode: '</a><br>\n\t\t\t  <a style="f'>, <Variable Node: direction>, <TextNode: '</a><br>\n\t\t\t  <a style="f'>, <Variable Node: suburb>, <TextNode: '</a><br>\n\t\t\t  <a style="f'>, <Variable Node: no_of_passenger>, <TextNode: '</a> -->\n\t\t\t  <br><br>\n  '>, <django.template.defaulttags.CsrfTokenNode object at 0x7fb7da852d90>, <TextNode: '\n\t\t\t\t<div class="mb3 pb-1'>, <Variable Node: direction>, <TextNode: '">'>, <Variable Node: direction>, <TextNode: '</option>\t\t\t\t\t\t          '>, <Variable Node: flight_date>, <TextNode: '" type="text" >\t\t\t\t  \n   '>, <IfNode>, <TextNode: '\n\t\t\t\t  <div class="mb-3 p'>, <Variable Node: suburb>, <TextNode: '</label>\t\t\t\t\t\n\t\t\t\t</div>\n'>, <Variable Node: suburb>, <TextNode: '">'>, <Variable Node: suburb>, <TextNode: '</option>\t\t\t\t\t\n\t\t\t\t  </se'>, <Variable Node: no_of_passenger>, <TextNode: '">'>, <Variable Node: no_of_passenger>, <TextNode: '</option>\t\t\t\t  \n         '>, <Variable Node: recaptcha_site_key>, <TextNode: '"></div>\n\t\t\t\t<div id="err'>]>}]
WARNING 2023-12-03 13:02:40,819 log Not Found: /robots.txt
WARNING 2023-12-03 13:10:12,019 log Not Found: /product/moncler-vest-for-women-smooth-shiny-fabric-black-2/
DEBUG 2023-12-03 13:16:51,840 base Exception while resolving variable 'recaptcha_site_key' in template 'basecamp/inquiry1.html'.
Traceback (most recent call last):
  File "/home/horeb/github/easygo/venv/lib/python3.11/site-packages/django/template/base.py", line 880, in _resolve_lookup
    current = current[bit]
              ~~~~~~~^^^^^
  File "/home/horeb/github/easygo/venv/lib/python3.11/site-packages/django/template/context.py", line 83, in __getitem__
    raise KeyError(key)
KeyError: 'recaptcha_site_key'

During handling of the above exception, another exception occurred:

Traceback (most recent call last):
  File "/home/horeb/github/easygo/venv/lib/python3.11/site-packages/django/template/base.py", line 886, in _resolve_lookup
    if isinstance(current, BaseContext) and getattr(
                                            ^^^^^^^^
AttributeError: type object 'RequestContext' has no attribute 'recaptcha_site_key'

During handling of the above exception, another exception occurred:

Traceback (most recent call last):
  File "/home/horeb/github/easygo/venv/lib/python3.11/site-packages/django/template/base.py", line 896, in _resolve_lookup
    current = current[int(bit)]
                      ^^^^^^^^
ValueError: invalid literal for int() with base 10: 'recaptcha_site_key'

During handling of the above exception, another exception occurred:

Traceback (most recent call last):
  File "/home/horeb/github/easygo/venv/lib/python3.11/site-packages/django/template/base.py", line 903, in _resolve_lookup
    raise VariableDoesNotExist(
django.template.base.VariableDoesNotExist: Failed lookup for key [recaptcha_site_key] in [{'True': True, 'False': False, 'None': None}, {'csrf_token': <SimpleLazyObject: 'zFxZxrIQd5E99fAgV6uFrHAztNjMPUSTZcdk7dJIWXYscoj1bZFH5UcRWTmxNfuB'>, 'request': <WSGIRequest: POST '/price_detail/'>, 'user': <SimpleLazyObject: <function AuthenticationMiddleware.process_request.<locals>.<lambda> at 0x7fb7dac618a0>>, 'perms': PermWrapper(<SimpleLazyObject: <function AuthenticationMiddleware.process_request.<locals>.<lambda> at 0x7fb7dac618a0>>), 'messages': <FallbackStorage: request=<WSGIRequest: POST '/price_detail/'>>, 'DEFAULT_MESSAGE_LEVELS': {'DEBUG': 10, 'INFO': 20, 'SUCCESS': 25, 'WARNING': 30, 'ERROR': 40}}, {}, {'flight_date': '2023-12-04', 'direction': 'Drop off to Domestic Airport', 'suburb': 'Surry Hills', 'no_of_passenger': '2'}, {'block': <Block Node: content. Contents: [<TextNode: '\n      <!-- Page content-'>, <Variable Node: flight_date>, <TextNode: '</a><br>\n\t\t\t  <a style="f'>, <Variable Node: direction>, <TextNode: '</a><br>\n\t\t\t  <a style="f'>, <Variable Node: suburb>, <TextNode: '</a><br>\n\t\t\t  <a style="f'>, <Variable Node: no_of_passenger>, <TextNode: '</a> -->\n\t\t\t  <br><br>\n  '>, <django.template.defaulttags.CsrfTokenNode object at 0x7fb7da5f8350>, <TextNode: '\n\t\t\t\t<div class="mb3 pb-1'>, <Variable Node: direction>, <TextNode: '">'>, <Variable Node: direction>, <TextNode: '</option>\t\t\t\t\t\t          '>, <Variable Node: flight_date>, <TextNode: '" type="text" >\t\t\t\t  \n   '>, <IfNode>, <TextNode: '\n\t\t\t\t  <div class="mb-3 p'>, <Variable Node: suburb>, <TextNode: '</label>\t\t\t\t\t\n\t\t\t\t</div>\n'>, <Variable Node: suburb>, <TextNode: '">'>, <Variable Node: suburb>, <TextNode: '</option>\t\t\t\t\t\n\t\t\t\t  </se'>, <Variable Node: no_of_passenger>, <TextNode: '">'>, <Variable Node: no_of_passenger>, <TextNode: '</option>\t\t\t\t  \n         '>, <Variable Node: recaptcha_site_key>, <TextNode: '"></div>\n\t\t\t\t<div id="err'>]>}]
WARNING 2023-12-03 13:55:30,219 log Not Found: /robots.txt
WARNING 2023-12-03 13:55:31,195 log Not Found: /shop/product/moncler-bady-2/
WARNING 2023-12-03 14:05:36,150 log Not Found: /RDWeb/Pages/en-US/login.aspx
WARNING 2023-12-03 14:18:58,968 log Not Found: /robots.txt
WARNING 2023-12-03 14:19:00,625 log Not Found: /sitemap.xml
WARNING 2023-12-03 14:19:04,304 log Not Found: /sitemap_index.xml
WARNING 2023-12-03 14:19:12,096 log Not Found: /sitemap1.xml
WARNING 2023-12-03 14:43:10,127 log Not Found: /wp-content/themes/famous/megaframe/megapanel/inc/functions.php
WARNING 2023-12-03 14:43:36,048 log Not Found: /robots.txt
WARNING 2023-12-03 14:44:15,720 log Not Found: /robots.txt
WARNING 2023-12-03 14:54:49,421 log Not Found: /robots.txt
WARNING 2023-12-03 14:58:25,140 log Not Found: /robots.txt
ERROR 2023-12-03 15:00:17,805 log Internal Server Error: /paypal_ipn/
DEBUG 2023-12-03 15:09:36,246 base Exception while resolving variable 'email1' in template 'basecamp/html_email-inquiry-response.html'.
Traceback (most recent call last):
  File "/home/horeb/github/easygo/venv/lib/python3.11/site-packages/django/template/base.py", line 880, in _resolve_lookup
    current = current[bit]
              ~~~~~~~^^^^^
  File "/home/horeb/github/easygo/venv/lib/python3.11/site-packages/django/template/context.py", line 83, in __getitem__
    raise KeyError(key)
KeyError: 'email1'

During handling of the above exception, another exception occurred:

Traceback (most recent call last):
  File "/home/horeb/github/easygo/venv/lib/python3.11/site-packages/django/template/base.py", line 886, in _resolve_lookup
    if isinstance(current, BaseContext) and getattr(
                                            ^^^^^^^^
AttributeError: type object 'Context' has no attribute 'email1'

During handling of the above exception, another exception occurred:

Traceback (most recent call last):
  File "/home/horeb/github/easygo/venv/lib/python3.11/site-packages/django/template/base.py", line 896, in _resolve_lookup
    current = current[int(bit)]
                      ^^^^^^^^
ValueError: invalid literal for int() with base 10: 'email1'

During handling of the above exception, another exception occurred:

Traceback (most recent call last):
  File "/home/horeb/github/easygo/venv/lib/python3.11/site-packages/django/template/base.py", line 903, in _resolve_lookup
    raise VariableDoesNotExist(
django.template.base.VariableDoesNotExist: Failed lookup for key [email1] in [{'True': True, 'False': False, 'None': None}, {'company_name': '', 'name': 'Sajid', 'contact': '0470334832', 'email': 'Sajidkv@gmail.com', 'flight_date': datetime.date(2023, 12, 19), 'flight_number': 'Sq233', 'flight_time': '12:15', 'pickup_time': '08:00', 'direction': 'Drop off to Intl Airport', 'street': '203/8 Hannah street', 'suburb': 'Westmead', 'no_of_passenger': '4', 'no_of_baggage': '4', 'return_direction': None, 'return_flight_date': None, 'return_flight_number': None, 'return_flight_time': None, 'return_pickup_time': None, 'message': '', 'price': '120', 'notice': '', 'private_ride': False}]
DEBUG 2023-12-03 15:10:31,820 base Exception while resolving variable 'email1' in template 'basecamp/html_email-inquiry-response.html'.
Traceback (most recent call last):
  File "/home/horeb/github/easygo/venv/lib/python3.11/site-packages/django/template/base.py", line 880, in _resolve_lookup
    current = current[bit]
              ~~~~~~~^^^^^
  File "/home/horeb/github/easygo/venv/lib/python3.11/site-packages/django/template/context.py", line 83, in __getitem__
    raise KeyError(key)
KeyError: 'email1'

During handling of the above exception, another exception occurred:

Traceback (most recent call last):
  File "/home/horeb/github/easygo/venv/lib/python3.11/site-packages/django/template/base.py", line 886, in _resolve_lookup
    if isinstance(current, BaseContext) and getattr(
                                            ^^^^^^^^
AttributeError: type object 'Context' has no attribute 'email1'

During handling of the above exception, another exception occurred:

Traceback (most recent call last):
  File "/home/horeb/github/easygo/venv/lib/python3.11/site-packages/django/template/base.py", line 896, in _resolve_lookup
    current = current[int(bit)]
                      ^^^^^^^^
ValueError: invalid literal for int() with base 10: 'email1'

During handling of the above exception, another exception occurred:

Traceback (most recent call last):
  File "/home/horeb/github/easygo/venv/lib/python3.11/site-packages/django/template/base.py", line 903, in _resolve_lookup
    raise VariableDoesNotExist(
django.template.base.VariableDoesNotExist: Failed lookup for key [email1] in [{'True': True, 'False': False, 'None': None}, {'company_name': '', 'name': 'Anna severino', 'contact': '0402015239', 'email': 'mentor2122@optusnet.com.au', 'flight_date': datetime.date(2023, 12, 31), 'flight_number': 'Qf101', 'flight_time': '08:35', 'pickup_time': '05:00', 'direction': 'Drop off to Intl Airport', 'street': '8 Darcy St', 'suburb': 'Marsfield', 'no_of_passenger': '7', 'no_of_baggage': '6', 'return_direction': 'Pickup from Intl Airport', 'return_flight_date': datetime.date(2024, 1, 7), 'return_flight_number': 'Qf5542', 'return_flight_time': '19:50', 'return_pickup_time': '19:50', 'message': 'Need a baby car seat for a 4 month', 'price': '300', 'notice': '', 'private_ride': False}]
DEBUG 2023-12-03 15:11:00,926 base Exception while resolving variable 'email1' in template 'basecamp/html_email-inquiry-response.html'.
Traceback (most recent call last):
  File "/home/horeb/github/easygo/venv/lib/python3.11/site-packages/django/template/base.py", line 880, in _resolve_lookup
    current = current[bit]
              ~~~~~~~^^^^^
  File "/home/horeb/github/easygo/venv/lib/python3.11/site-packages/django/template/context.py", line 83, in __getitem__
    raise KeyError(key)
KeyError: 'email1'

During handling of the above exception, another exception occurred:

Traceback (most recent call last):
  File "/home/horeb/github/easygo/venv/lib/python3.11/site-packages/django/template/base.py", line 886, in _resolve_lookup
    if isinstance(current, BaseContext) and getattr(
                                            ^^^^^^^^
AttributeError: type object 'Context' has no attribute 'email1'

During handling of the above exception, another exception occurred:

Traceback (most recent call last):
  File "/home/horeb/github/easygo/venv/lib/python3.11/site-packages/django/template/base.py", line 896, in _resolve_lookup
    current = current[int(bit)]
                      ^^^^^^^^
ValueError: invalid literal for int() with base 10: 'email1'

During handling of the above exception, another exception occurred:

Traceback (most recent call last):
  File "/home/horeb/github/easygo/venv/lib/python3.11/site-packages/django/template/base.py", line 903, in _resolve_lookup
    raise VariableDoesNotExist(
django.template.base.VariableDoesNotExist: Failed lookup for key [email1] in [{'True': True, 'False': False, 'None': None}, {'company_name': '', 'name': 'Gabriel', 'contact': '0402792982', 'email': 'gabriel.prasad@gmail.com', 'flight_date': datetime.date(2023, 12, 18), 'flight_number': 'Fj910', 'flight_time': '14:00', 'pickup_time': '10:00', 'direction': 'Drop off to Intl Airport', 'street': '29 Bardia road', 'suburb': 'Carlingford', 'no_of_passenger': '4', 'no_of_baggage': '4', 'return_direction': 'Pickup from Intl Airport', 'return_flight_date': datetime.date(2024, 1, 12), 'return_flight_number': 'FJ911', 'return_flight_time': '12:30', 'return_pickup_time': '13:00', 'message': '', 'price': '250', 'notice': '', 'private_ride': False}]
DEBUG 2023-12-03 15:11:59,916 base Exception while resolving variable 'email1' in template 'basecamp/html_email-inquiry-response.html'.
Traceback (most recent call last):
  File "/home/horeb/github/easygo/venv/lib/python3.11/site-packages/django/template/base.py", line 880, in _resolve_lookup
    current = current[bit]
              ~~~~~~~^^^^^
  File "/home/horeb/github/easygo/venv/lib/python3.11/site-packages/django/template/context.py", line 83, in __getitem__
    raise KeyError(key)
KeyError: 'email1'

During handling of the above exception, another exception occurred:

Traceback (most recent call last):
  File "/home/horeb/github/easygo/venv/lib/python3.11/site-packages/django/template/base.py", line 886, in _resolve_lookup
    if isinstance(current, BaseContext) and getattr(
                                            ^^^^^^^^
AttributeError: type object 'Context' has no attribute 'email1'

During handling of the above exception, another exception occurred:

Traceback (most recent call last):
  File "/home/horeb/github/easygo/venv/lib/python3.11/site-packages/django/template/base.py", line 896, in _resolve_lookup
    current = current[int(bit)]
                      ^^^^^^^^
ValueError: invalid literal for int() with base 10: 'email1'

During handling of the above exception, another exception occurred:

Traceback (most recent call last):
  File "/home/horeb/github/easygo/venv/lib/python3.11/site-packages/django/template/base.py", line 903, in _resolve_lookup
    raise VariableDoesNotExist(
django.template.base.VariableDoesNotExist: Failed lookup for key [email1] in [{'True': True, 'False': False, 'None': None}, {'company_name': '', 'name': 'Bobby', 'contact': '0431240784', 'email': 'daeibabak@yahoo.com', 'flight_date': datetime.date(2023, 12, 9), 'flight_number': 'jq27', 'flight_time': '15:05', 'pickup_time': '11:15', 'direction': 'Drop off to Intl Airport', 'street': '290 Burns Bay Rd', 'suburb': 'Lane Cove', 'no_of_passenger': '4', 'no_of_baggage': '4', 'return_direction': None, 'return_flight_date': None, 'return_flight_number': None, 'return_flight_time': None, 'return_pickup_time': None, 'message': 'Hi there,\r\nWe are two adult two kids and have 4 check-in luggage and 4 carry-on bag. Please provide us with a quotation\r\n\r\nRegards', 'price': '105', 'notice': '', 'private_ride': False}]
DEBUG 2023-12-03 15:12:46,159 base Exception while resolving variable 'email1' in template 'basecamp/html_email-inquiry-response.html'.
Traceback (most recent call last):
  File "/home/horeb/github/easygo/venv/lib/python3.11/site-packages/django/template/base.py", line 880, in _resolve_lookup
    current = current[bit]
              ~~~~~~~^^^^^
  File "/home/horeb/github/easygo/venv/lib/python3.11/site-packages/django/template/context.py", line 83, in __getitem__
    raise KeyError(key)
KeyError: 'email1'

During handling of the above exception, another exception occurred:

Traceback (most recent call last):
  File "/home/horeb/github/easygo/venv/lib/python3.11/site-packages/django/template/base.py", line 886, in _resolve_lookup
    if isinstance(current, BaseContext) and getattr(
                                            ^^^^^^^^
AttributeError: type object 'Context' has no attribute 'email1'

During handling of the above exception, another exception occurred:

Traceback (most recent call last):
  File "/home/horeb/github/easygo/venv/lib/python3.11/site-packages/django/template/base.py", line 896, in _resolve_lookup
    current = current[int(bit)]
                      ^^^^^^^^
ValueError: invalid literal for int() with base 10: 'email1'

During handling of the above exception, another exception occurred:

Traceback (most recent call last):
  File "/home/horeb/github/easygo/venv/lib/python3.11/site-packages/django/template/base.py", line 903, in _resolve_lookup
    raise VariableDoesNotExist(
django.template.base.VariableDoesNotExist: Failed lookup for key [email1] in [{'True': True, 'False': False, 'None': None}, {'company_name': '', 'name': 'Fed', 'contact': '0433222562', 'email': 'fedsnew@gmail.com', 'flight_date': datetime.date(2023, 12, 14), 'flight_number': 'Ga715', 'flight_time': '10:00', 'pickup_time': '07:00', 'direction': 'Drop off to Intl Airport', 'street': '10/42 cliff rd', 'suburb': 'Epping', 'no_of_passenger': '4', 'no_of_baggage': '5', 'return_direction': None, 'return_flight_date': None, 'return_flight_number': None, 'return_flight_time': None, 'return_pickup_time': None, 'message': 'Hi we have 3 large luggage\r\n3x small i need to be in airport by 8am', 'price': '120', 'notice': '', 'private_ride': False}]
DEBUG 2023-12-03 15:14:27,700 base Exception while resolving variable 'email1' in template 'basecamp/html_email-inquiry-response.html'.
Traceback (most recent call last):
  File "/home/horeb/github/easygo/venv/lib/python3.11/site-packages/django/template/base.py", line 880, in _resolve_lookup
    current = current[bit]
              ~~~~~~~^^^^^
  File "/home/horeb/github/easygo/venv/lib/python3.11/site-packages/django/template/context.py", line 83, in __getitem__
    raise KeyError(key)
KeyError: 'email1'

During handling of the above exception, another exception occurred:

Traceback (most recent call last):
  File "/home/horeb/github/easygo/venv/lib/python3.11/site-packages/django/template/base.py", line 886, in _resolve_lookup
    if isinstance(current, BaseContext) and getattr(
                                            ^^^^^^^^
AttributeError: type object 'Context' has no attribute 'email1'

During handling of the above exception, another exception occurred:

Traceback (most recent call last):
  File "/home/horeb/github/easygo/venv/lib/python3.11/site-packages/django/template/base.py", line 896, in _resolve_lookup
    current = current[int(bit)]
                      ^^^^^^^^
ValueError: invalid literal for int() with base 10: 'email1'

During handling of the above exception, another exception occurred:

Traceback (most recent call last):
  File "/home/horeb/github/easygo/venv/lib/python3.11/site-packages/django/template/base.py", line 903, in _resolve_lookup
    raise VariableDoesNotExist(
django.template.base.VariableDoesNotExist: Failed lookup for key [email1] in [{'True': True, 'False': False, 'None': None}, {'company_name': '', 'name': 'SUNG KAM', 'contact': '0406883355', 'email': 'sungkam718@gmail.com', 'flight_date': datetime.date(2023, 12, 15), 'flight_number': 'QF644', 'flight_time': '09:00', 'pickup_time': '14:00', 'direction': 'Drop off to Intl Airport', 'street': '1/6-12 SINCLAIR AVE', 'suburb': 'Thornleigh', 'no_of_passenger': '1', 'no_of_baggage': '2', 'return_direction': None, 'return_flight_date': None, 'return_flight_number': None, 'return_flight_time': None, 'return_pickup_time': None, 'message': '', 'price': '240', 'notice': '', 'private_ride': False}]
DEBUG 2023-12-03 15:16:21,641 base Exception while resolving variable 'email1' in template 'basecamp/html_email-inquiry-response.html'.
Traceback (most recent call last):
  File "/home/horeb/github/easygo/venv/lib/python3.11/site-packages/django/template/base.py", line 880, in _resolve_lookup
    current = current[bit]
              ~~~~~~~^^^^^
  File "/home/horeb/github/easygo/venv/lib/python3.11/site-packages/django/template/context.py", line 83, in __getitem__
    raise KeyError(key)
KeyError: 'email1'

During handling of the above exception, another exception occurred:

Traceback (most recent call last):
  File "/home/horeb/github/easygo/venv/lib/python3.11/site-packages/django/template/base.py", line 886, in _resolve_lookup
    if isinstance(current, BaseContext) and getattr(
                                            ^^^^^^^^
AttributeError: type object 'Context' has no attribute 'email1'

During handling of the above exception, another exception occurred:

Traceback (most recent call last):
  File "/home/horeb/github/easygo/venv/lib/python3.11/site-packages/django/template/base.py", line 896, in _resolve_lookup
    current = current[int(bit)]
                      ^^^^^^^^
ValueError: invalid literal for int() with base 10: 'email1'

During handling of the above exception, another exception occurred:

Traceback (most recent call last):
  File "/home/horeb/github/easygo/venv/lib/python3.11/site-packages/django/template/base.py", line 903, in _resolve_lookup
    raise VariableDoesNotExist(
django.template.base.VariableDoesNotExist: Failed lookup for key [email1] in [{'True': True, 'False': False, 'None': None}, {'company_name': '', 'name': 'Peter Kam', 'contact': '450035664', 'email': 'sungkam3@gmail.com', 'flight_date': datetime.date(2023, 12, 7), 'flight_number': 'Sq231', 'flight_time': '18:13', 'pickup_time': '19:30', 'direction': 'Drop off to Domestic Airport', 'street': 'Unit 715/15 Barton Road', 'suburb': 'Auburn', 'no_of_passenger': '1', 'no_of_baggage': '2', 'return_direction': 'Pickup from Intl Airport', 'return_flight_date': datetime.date(2023, 12, 30), 'return_flight_number': 'CX101', 'return_flight_time': '18:00', 'return_pickup_time': '20:00', 'message': '', 'price': '180', 'notice': '', 'private_ride': False}]
DEBUG 2023-12-03 15:16:43,420 base Exception while resolving variable 'email1' in template 'basecamp/html_email-inquiry-response.html'.
Traceback (most recent call last):
  File "/home/horeb/github/easygo/venv/lib/python3.11/site-packages/django/template/base.py", line 880, in _resolve_lookup
    current = current[bit]
              ~~~~~~~^^^^^
  File "/home/horeb/github/easygo/venv/lib/python3.11/site-packages/django/template/context.py", line 83, in __getitem__
    raise KeyError(key)
KeyError: 'email1'

During handling of the above exception, another exception occurred:

Traceback (most recent call last):
  File "/home/horeb/github/easygo/venv/lib/python3.11/site-packages/django/template/base.py", line 886, in _resolve_lookup
    if isinstance(current, BaseContext) and getattr(
                                            ^^^^^^^^
AttributeError: type object 'Context' has no attribute 'email1'

During handling of the above exception, another exception occurred:

Traceback (most recent call last):
  File "/home/horeb/github/easygo/venv/lib/python3.11/site-packages/django/template/base.py", line 896, in _resolve_lookup
    current = current[int(bit)]
                      ^^^^^^^^
ValueError: invalid literal for int() with base 10: 'email1'

During handling of the above exception, another exception occurred:

Traceback (most recent call last):
  File "/home/horeb/github/easygo/venv/lib/python3.11/site-packages/django/template/base.py", line 903, in _resolve_lookup
    raise VariableDoesNotExist(
django.template.base.VariableDoesNotExist: Failed lookup for key [email1] in [{'True': True, 'False': False, 'None': None}, {'company_name': '', 'name': 'Peter Kam', 'contact': '450035664', 'email': 'sungkam3@gmail.com', 'flight_date': datetime.date(2023, 12, 7), 'flight_number': 'Sq231', 'flight_time': '18:13', 'pickup_time': '19:30', 'direction': 'Drop off to Domestic Airport', 'street': 'Unit 715/15 Barton Road', 'suburb': 'Auburn', 'no_of_passenger': '1', 'no_of_baggage': '2', 'return_direction': 'Pickup from Intl Airport', 'return_flight_date': datetime.date(2023, 12, 30), 'return_flight_number': 'CX101', 'return_flight_time': '18:00', 'return_pickup_time': '20:00', 'message': '', 'price': '180', 'notice': '', 'private_ride': False}]
WARNING 2023-12-03 15:37:34,107 log Not Found: /.well-known/acme-challenge/0WEOJ87V-S89K-SAZJEBXPPMRN_G5HX9
WARNING 2023-12-03 15:37:35,077 log Not Found: /.well-known/acme-challenge/1A9LPJ1_MP4YDC7IHI56N9XM34NZ3613
WARNING 2023-12-03 15:40:23,644 log Not Found: /wp-content/themes/include.php
WARNING 2023-12-03 15:40:30,676 log Not Found: /wp-content/plugins/WordPressCore/include.php
WARNING 2023-12-03 15:40:35,486 log Not Found: /wp-content/themes/sketch/404.php
WARNING 2023-12-03 15:40:45,348 log Not Found: /wp-content/plugins/core-plugin/include.php
WARNING 2023-12-03 15:40:53,552 log Not Found: /wp-includes/widgets/include.php
WARNING 2023-12-03 15:40:59,222 log Not Found: /wp-content/include.php
WARNING 2023-12-03 15:41:08,862 log Not Found: /wp-content/themes/twentyfive/include.php
WARNING 2023-12-03 15:41:29,482 log Not Found: /wp-includes/images/include.php
WARNING 2023-12-03 15:41:36,442 log Not Found: /wp-content/plugins/include.php
DEBUG 2023-12-03 15:51:05,237 base Exception while resolving variable 'email1' in template 'basecamp/html_email-inquiry-response.html'.
Traceback (most recent call last):
  File "/home/horeb/github/easygo/venv/lib/python3.11/site-packages/django/template/base.py", line 880, in _resolve_lookup
    current = current[bit]
              ~~~~~~~^^^^^
  File "/home/horeb/github/easygo/venv/lib/python3.11/site-packages/django/template/context.py", line 83, in __getitem__
    raise KeyError(key)
KeyError: 'email1'

During handling of the above exception, another exception occurred:

Traceback (most recent call last):
  File "/home/horeb/github/easygo/venv/lib/python3.11/site-packages/django/template/base.py", line 886, in _resolve_lookup
    if isinstance(current, BaseContext) and getattr(
                                            ^^^^^^^^
AttributeError: type object 'Context' has no attribute 'email1'

During handling of the above exception, another exception occurred:

Traceback (most recent call last):
  File "/home/horeb/github/easygo/venv/lib/python3.11/site-packages/django/template/base.py", line 896, in _resolve_lookup
    current = current[int(bit)]
                      ^^^^^^^^
ValueError: invalid literal for int() with base 10: 'email1'

During handling of the above exception, another exception occurred:

Traceback (most recent call last):
  File "/home/horeb/github/easygo/venv/lib/python3.11/site-packages/django/template/base.py", line 903, in _resolve_lookup
    raise VariableDoesNotExist(
django.template.base.VariableDoesNotExist: Failed lookup for key [email1] in [{'True': True, 'False': False, 'None': None}, {'company_name': '', 'name': 'Nicki Burnett', 'contact': '406497934', 'email': 'nicki@burnett.com.au', 'flight_date': datetime.date(2024, 1, 17), 'flight_number': 'JL52', 'flight_time': '09:15', 'pickup_time': '05:15', 'direction': 'Drop off to Intl Airport', 'street': '2, Lawley Crescent', 'suburb': 'Pymble', 'no_of_passenger': '5', 'no_of_baggage': '3', 'return_direction': 'Pickup from Intl Airport', 'return_flight_date': datetime.date(2024, 2, 3), 'return_flight_number': 'JL51', 'return_flight_time': '06:20', 'return_pickup_time': '07:30', 'message': 'Could I get a quote please?', 'price': '270', 'notice': '', 'private_ride': False}]
DEBUG 2023-12-03 15:52:14,655 base Exception while resolving variable 'email1' in template 'basecamp/html_email-inquiry-response.html'.
Traceback (most recent call last):
  File "/home/horeb/github/easygo/venv/lib/python3.11/site-packages/django/template/base.py", line 880, in _resolve_lookup
    current = current[bit]
              ~~~~~~~^^^^^
  File "/home/horeb/github/easygo/venv/lib/python3.11/site-packages/django/template/context.py", line 83, in __getitem__
    raise KeyError(key)
KeyError: 'email1'

During handling of the above exception, another exception occurred:

Traceback (most recent call last):
  File "/home/horeb/github/easygo/venv/lib/python3.11/site-packages/django/template/base.py", line 886, in _resolve_lookup
    if isinstance(current, BaseContext) and getattr(
                                            ^^^^^^^^
AttributeError: type object 'Context' has no attribute 'email1'

During handling of the above exception, another exception occurred:

Traceback (most recent call last):
  File "/home/horeb/github/easygo/venv/lib/python3.11/site-packages/django/template/base.py", line 896, in _resolve_lookup
    current = current[int(bit)]
                      ^^^^^^^^
ValueError: invalid literal for int() with base 10: 'email1'

During handling of the above exception, another exception occurred:

Traceback (most recent call last):
  File "/home/horeb/github/easygo/venv/lib/python3.11/site-packages/django/template/base.py", line 903, in _resolve_lookup
    raise VariableDoesNotExist(
django.template.base.VariableDoesNotExist: Failed lookup for key [email1] in [{'True': True, 'False': False, 'None': None}, {'company_name': '', 'name': 'SUNG KAM', 'contact': '0406883355', 'email': 'sungkam718@gmail.com', 'flight_date': datetime.date(2023, 12, 15), 'flight_number': 'QF644', 'flight_time': '09:00', 'pickup_time': '14:00', 'direction': 'Drop off to Intl Airport', 'street': '1/6-12 SINCLAIR AVE', 'suburb': 'Thornleigh', 'no_of_passenger': '1', 'no_of_baggage': '2', 'return_direction': None, 'return_flight_date': None, 'return_flight_number': None, 'return_flight_time': None, 'return_pickup_time': None, 'message': '', 'price': '240', 'notice': '', 'private_ride': False}]
DEBUG 2023-12-03 15:52:29,115 base Exception while resolving variable 'email1' in template 'basecamp/html_email-inquiry-response.html'.
Traceback (most recent call last):
  File "/home/horeb/github/easygo/venv/lib/python3.11/site-packages/django/template/base.py", line 880, in _resolve_lookup
    current = current[bit]
              ~~~~~~~^^^^^
  File "/home/horeb/github/easygo/venv/lib/python3.11/site-packages/django/template/context.py", line 83, in __getitem__
    raise KeyError(key)
KeyError: 'email1'

During handling of the above exception, another exception occurred:

Traceback (most recent call last):
  File "/home/horeb/github/easygo/venv/lib/python3.11/site-packages/django/template/base.py", line 886, in _resolve_lookup
    if isinstance(current, BaseContext) and getattr(
                                            ^^^^^^^^
AttributeError: type object 'Context' has no attribute 'email1'

During handling of the above exception, another exception occurred:

Traceback (most recent call last):
  File "/home/horeb/github/easygo/venv/lib/python3.11/site-packages/django/template/base.py", line 896, in _resolve_lookup
    current = current[int(bit)]
                      ^^^^^^^^
ValueError: invalid literal for int() with base 10: 'email1'

During handling of the above exception, another exception occurred:

Traceback (most recent call last):
  File "/home/horeb/github/easygo/venv/lib/python3.11/site-packages/django/template/base.py", line 903, in _resolve_lookup
    raise VariableDoesNotExist(
django.template.base.VariableDoesNotExist: Failed lookup for key [email1] in [{'True': True, 'False': False, 'None': None}, {'company_name': '', 'name': 'Peter Kam', 'contact': '450035664', 'email': 'sungkam3@gmail.com', 'flight_date': datetime.date(2023, 12, 7), 'flight_number': 'Sq231', 'flight_time': '18:13', 'pickup_time': '19:30', 'direction': 'Drop off to Domestic Airport', 'street': 'Unit 715/15 Barton Road', 'suburb': 'Auburn', 'no_of_passenger': '1', 'no_of_baggage': '2', 'return_direction': 'Pickup from Intl Airport', 'return_flight_date': datetime.date(2023, 12, 30), 'return_flight_number': 'CX101', 'return_flight_time': '18:00', 'return_pickup_time': '20:00', 'message': '', 'price': '180', 'notice': '', 'private_ride': False}]
WARNING 2023-12-03 15:55:06,335 log Not Found: /robots.txt
DEBUG 2023-12-03 15:58:35,969 base Exception while resolving variable 'email1' in template 'basecamp/html_email-inquiry-response.html'.
Traceback (most recent call last):
  File "/home/horeb/github/easygo/venv/lib/python3.11/site-packages/django/template/base.py", line 880, in _resolve_lookup
    current = current[bit]
              ~~~~~~~^^^^^
  File "/home/horeb/github/easygo/venv/lib/python3.11/site-packages/django/template/context.py", line 83, in __getitem__
    raise KeyError(key)
KeyError: 'email1'

During handling of the above exception, another exception occurred:

Traceback (most recent call last):
  File "/home/horeb/github/easygo/venv/lib/python3.11/site-packages/django/template/base.py", line 886, in _resolve_lookup
    if isinstance(current, BaseContext) and getattr(
                                            ^^^^^^^^
AttributeError: type object 'Context' has no attribute 'email1'

During handling of the above exception, another exception occurred:

Traceback (most recent call last):
  File "/home/horeb/github/easygo/venv/lib/python3.11/site-packages/django/template/base.py", line 896, in _resolve_lookup
    current = current[int(bit)]
                      ^^^^^^^^
ValueError: invalid literal for int() with base 10: 'email1'

During handling of the above exception, another exception occurred:

Traceback (most recent call last):
  File "/home/horeb/github/easygo/venv/lib/python3.11/site-packages/django/template/base.py", line 903, in _resolve_lookup
    raise VariableDoesNotExist(
django.template.base.VariableDoesNotExist: Failed lookup for key [email1] in [{'True': True, 'False': False, 'None': None}, {'company_name': '', 'name': 'Peter Kam', 'contact': '450035664', 'email': 'sungkam3@gmail.com', 'flight_date': datetime.date(2023, 12, 7), 'flight_number': 'Sq231', 'flight_time': '18:13', 'pickup_time': '19:30', 'direction': 'Drop off to Domestic Airport', 'street': 'Unit 715/15 Barton Road', 'suburb': 'Auburn', 'no_of_passenger': '1', 'no_of_baggage': '2', 'return_direction': 'Pickup from Intl Airport', 'return_flight_date': datetime.date(2023, 12, 30), 'return_flight_number': 'CX101', 'return_flight_time': '18:00', 'return_pickup_time': '20:00', 'message': '', 'price': '180', 'notice': '', 'private_ride': False}]
DEBUG 2023-12-03 16:01:17,859 base Exception while resolving variable 'recaptcha_site_key' in template 'basecamp/inquiry1.html'.
Traceback (most recent call last):
  File "/home/horeb/github/easygo/venv/lib/python3.11/site-packages/django/template/base.py", line 880, in _resolve_lookup
    current = current[bit]
              ~~~~~~~^^^^^
  File "/home/horeb/github/easygo/venv/lib/python3.11/site-packages/django/template/context.py", line 83, in __getitem__
    raise KeyError(key)
KeyError: 'recaptcha_site_key'

During handling of the above exception, another exception occurred:

Traceback (most recent call last):
  File "/home/horeb/github/easygo/venv/lib/python3.11/site-packages/django/template/base.py", line 886, in _resolve_lookup
    if isinstance(current, BaseContext) and getattr(
                                            ^^^^^^^^
AttributeError: type object 'RequestContext' has no attribute 'recaptcha_site_key'

During handling of the above exception, another exception occurred:

Traceback (most recent call last):
  File "/home/horeb/github/easygo/venv/lib/python3.11/site-packages/django/template/base.py", line 896, in _resolve_lookup
    current = current[int(bit)]
                      ^^^^^^^^
ValueError: invalid literal for int() with base 10: 'recaptcha_site_key'

During handling of the above exception, another exception occurred:

Traceback (most recent call last):
  File "/home/horeb/github/easygo/venv/lib/python3.11/site-packages/django/template/base.py", line 903, in _resolve_lookup
    raise VariableDoesNotExist(
django.template.base.VariableDoesNotExist: Failed lookup for key [recaptcha_site_key] in [{'True': True, 'False': False, 'None': None}, {'csrf_token': <SimpleLazyObject: 'CYK2hnQeSfqDF7r9PmuntZ8UVB5obiJWE5f2ApoZpc49X7SR7aTlRgQbWtXsXZQq'>, 'request': <WSGIRequest: POST '/price_detail/'>, 'user': <SimpleLazyObject: <function AuthenticationMiddleware.process_request.<locals>.<lambda> at 0x7f1e1766dee0>>, 'perms': PermWrapper(<SimpleLazyObject: <function AuthenticationMiddleware.process_request.<locals>.<lambda> at 0x7f1e1766dee0>>), 'messages': <FallbackStorage: request=<WSGIRequest: POST '/price_detail/'>>, 'DEFAULT_MESSAGE_LEVELS': {'DEBUG': 10, 'INFO': 20, 'SUCCESS': 25, 'WARNING': 30, 'ERROR': 40}}, {}, {'flight_date': '2023-12-09', 'direction': 'Pickup from Intl Airport', 'suburb': 'Hotels in CBD', 'no_of_passenger': '2'}, {'block': <Block Node: content. Contents: [<TextNode: '\n      <!-- Page content-'>, <Variable Node: flight_date>, <TextNode: '</a><br>\n\t\t\t  <a style="f'>, <Variable Node: direction>, <TextNode: '</a><br>\n\t\t\t  <a style="f'>, <Variable Node: suburb>, <TextNode: '</a><br>\n\t\t\t  <a style="f'>, <Variable Node: no_of_passenger>, <TextNode: '</a> -->\n\t\t\t  <br><br>\n  '>, <django.template.defaulttags.CsrfTokenNode object at 0x7f1e176274d0>, <TextNode: '\n\t\t\t\t<div class="mb3 pb-1'>, <Variable Node: direction>, <TextNode: '">'>, <Variable Node: direction>, <TextNode: '</option>\t\t\t\t\t\t          '>, <Variable Node: flight_date>, <TextNode: '" type="text" >\t\t\t\t  \n   '>, <IfNode>, <TextNode: '\n\t\t\t\t  <div class="mb-3 p'>, <Variable Node: suburb>, <TextNode: '</label>\t\t\t\t\t\n\t\t\t\t</div>\n'>, <Variable Node: suburb>, <TextNode: '">'>, <Variable Node: suburb>, <TextNode: '</option>\t\t\t\t\t\n\t\t\t\t  </se'>, <Variable Node: no_of_passenger>, <TextNode: '">'>, <Variable Node: no_of_passenger>, <TextNode: '</option>\t\t\t\t  \n         '>, <Variable Node: recaptcha_site_key>, <TextNode: '"></div>\n\t\t\t\t<div id="err'>]>}]
DEBUG 2023-12-03 16:02:17,843 base Exception while resolving variable 'recaptcha_site_key' in template 'basecamp/inquiry1.html'.
Traceback (most recent call last):
  File "/home/horeb/github/easygo/venv/lib/python3.11/site-packages/django/template/base.py", line 880, in _resolve_lookup
    current = current[bit]
              ~~~~~~~^^^^^
  File "/home/horeb/github/easygo/venv/lib/python3.11/site-packages/django/template/context.py", line 83, in __getitem__
    raise KeyError(key)
KeyError: 'recaptcha_site_key'

During handling of the above exception, another exception occurred:

Traceback (most recent call last):
  File "/home/horeb/github/easygo/venv/lib/python3.11/site-packages/django/template/base.py", line 886, in _resolve_lookup
    if isinstance(current, BaseContext) and getattr(
                                            ^^^^^^^^
AttributeError: type object 'RequestContext' has no attribute 'recaptcha_site_key'

During handling of the above exception, another exception occurred:

Traceback (most recent call last):
  File "/home/horeb/github/easygo/venv/lib/python3.11/site-packages/django/template/base.py", line 896, in _resolve_lookup
    current = current[int(bit)]
                      ^^^^^^^^
ValueError: invalid literal for int() with base 10: 'recaptcha_site_key'

During handling of the above exception, another exception occurred:

Traceback (most recent call last):
  File "/home/horeb/github/easygo/venv/lib/python3.11/site-packages/django/template/base.py", line 903, in _resolve_lookup
    raise VariableDoesNotExist(
django.template.base.VariableDoesNotExist: Failed lookup for key [recaptcha_site_key] in [{'True': True, 'False': False, 'None': None}, {'csrf_token': <SimpleLazyObject: 'mcasPkXWmDEDuXYdecDKkgiiSlmeU79VojFs8mvHTAi9MXpVw02IIx0zTdeiGOgp'>, 'request': <WSGIRequest: POST '/price_detail/'>, 'user': <SimpleLazyObject: <function AuthenticationMiddleware.process_request.<locals>.<lambda> at 0x7f1e17a32a20>>, 'perms': PermWrapper(<SimpleLazyObject: <function AuthenticationMiddleware.process_request.<locals>.<lambda> at 0x7f1e17a32a20>>), 'messages': <FallbackStorage: request=<WSGIRequest: POST '/price_detail/'>>, 'DEFAULT_MESSAGE_LEVELS': {'DEBUG': 10, 'INFO': 20, 'SUCCESS': 25, 'WARNING': 30, 'ERROR': 40}}, {}, {'flight_date': '2023-12-09', 'direction': 'Pickup from Intl Airport', 'suburb': 'Hotels in CBD', 'no_of_passenger': '2'}, {'block': <Block Node: content. Contents: [<TextNode: '\n      <!-- Page content-'>, <Variable Node: flight_date>, <TextNode: '</a><br>\n\t\t\t  <a style="f'>, <Variable Node: direction>, <TextNode: '</a><br>\n\t\t\t  <a style="f'>, <Variable Node: suburb>, <TextNode: '</a><br>\n\t\t\t  <a style="f'>, <Variable Node: no_of_passenger>, <TextNode: '</a> -->\n\t\t\t  <br><br>\n  '>, <django.template.defaulttags.CsrfTokenNode object at 0x7f1e17162710>, <TextNode: '\n\t\t\t\t<div class="mb3 pb-1'>, <Variable Node: direction>, <TextNode: '">'>, <Variable Node: direction>, <TextNode: '</option>\t\t\t\t\t\t          '>, <Variable Node: flight_date>, <TextNode: '" type="text" >\t\t\t\t  \n   '>, <IfNode>, <TextNode: '\n\t\t\t\t  <div class="mb-3 p'>, <Variable Node: suburb>, <TextNode: '</label>\t\t\t\t\t\n\t\t\t\t</div>\n'>, <Variable Node: suburb>, <TextNode: '">'>, <Variable Node: suburb>, <TextNode: '</option>\t\t\t\t\t\n\t\t\t\t  </se'>, <Variable Node: no_of_passenger>, <TextNode: '">'>, <Variable Node: no_of_passenger>, <TextNode: '</option>\t\t\t\t  \n         '>, <Variable Node: recaptcha_site_key>, <TextNode: '"></div>\n\t\t\t\t<div id="err'>]>}]
WARNING 2023-12-03 16:24:50,682 log Not Found: /robots.txt
WARNING 2023-12-03 16:24:55,666 log Not Found: /wp-content/themes/easygo/images/Toyota-Hiace-small.png
WARNING 2023-12-03 16:31:30,582 log Not Found: /.env
WARNING 2023-12-03 16:55:02,904 log Not Found: /robots.txt
DEBUG 2023-12-03 17:06:59,308 base Exception while resolving variable 'recaptcha_site_key' in template 'basecamp/inquiry1.html'.
Traceback (most recent call last):
  File "/home/horeb/github/easygo/venv/lib/python3.11/site-packages/django/template/base.py", line 880, in _resolve_lookup
    current = current[bit]
              ~~~~~~~^^^^^
  File "/home/horeb/github/easygo/venv/lib/python3.11/site-packages/django/template/context.py", line 83, in __getitem__
    raise KeyError(key)
KeyError: 'recaptcha_site_key'

During handling of the above exception, another exception occurred:

Traceback (most recent call last):
  File "/home/horeb/github/easygo/venv/lib/python3.11/site-packages/django/template/base.py", line 886, in _resolve_lookup
    if isinstance(current, BaseContext) and getattr(
                                            ^^^^^^^^
AttributeError: type object 'RequestContext' has no attribute 'recaptcha_site_key'

During handling of the above exception, another exception occurred:

Traceback (most recent call last):
  File "/home/horeb/github/easygo/venv/lib/python3.11/site-packages/django/template/base.py", line 896, in _resolve_lookup
    current = current[int(bit)]
                      ^^^^^^^^
ValueError: invalid literal for int() with base 10: 'recaptcha_site_key'

During handling of the above exception, another exception occurred:

Traceback (most recent call last):
  File "/home/horeb/github/easygo/venv/lib/python3.11/site-packages/django/template/base.py", line 903, in _resolve_lookup
    raise VariableDoesNotExist(
django.template.base.VariableDoesNotExist: Failed lookup for key [recaptcha_site_key] in [{'True': True, 'False': False, 'None': None}, {'csrf_token': <SimpleLazyObject: 'RDtTlfDOqdRKhkpPskSdgLpDGyrUBEuTk5PvInucoEgpaLN1djgAlve3N7CfeNIM'>, 'request': <WSGIRequest: POST '/price_detail/'>, 'user': <SimpleLazyObject: <function AuthenticationMiddleware.process_request.<locals>.<lambda> at 0x7f1e176ea660>>, 'perms': PermWrapper(<SimpleLazyObject: <function AuthenticationMiddleware.process_request.<locals>.<lambda> at 0x7f1e176ea660>>), 'messages': <FallbackStorage: request=<WSGIRequest: POST '/price_detail/'>>, 'DEFAULT_MESSAGE_LEVELS': {'DEBUG': 10, 'INFO': 20, 'SUCCESS': 25, 'WARNING': 30, 'ERROR': 40}}, {}, {'flight_date': '2023-12-16', 'direction': 'Drop off to Intl Airport', 'suburb': 'Pennant Hills', 'no_of_passenger': '4'}, {'block': <Block Node: content. Contents: [<TextNode: '\n      <!-- Page content-'>, <Variable Node: flight_date>, <TextNode: '</a><br>\n\t\t\t  <a style="f'>, <Variable Node: direction>, <TextNode: '</a><br>\n\t\t\t  <a style="f'>, <Variable Node: suburb>, <TextNode: '</a><br>\n\t\t\t  <a style="f'>, <Variable Node: no_of_passenger>, <TextNode: '</a> -->\n\t\t\t  <br><br>\n  '>, <django.template.defaulttags.CsrfTokenNode object at 0x7f1e17162710>, <TextNode: '\n\t\t\t\t<div class="mb3 pb-1'>, <Variable Node: direction>, <TextNode: '">'>, <Variable Node: direction>, <TextNode: '</option>\t\t\t\t\t\t          '>, <Variable Node: flight_date>, <TextNode: '" type="text" >\t\t\t\t  \n   '>, <IfNode>, <TextNode: '\n\t\t\t\t  <div class="mb-3 p'>, <Variable Node: suburb>, <TextNode: '</label>\t\t\t\t\t\n\t\t\t\t</div>\n'>, <Variable Node: suburb>, <TextNode: '">'>, <Variable Node: suburb>, <TextNode: '</option>\t\t\t\t\t\n\t\t\t\t  </se'>, <Variable Node: no_of_passenger>, <TextNode: '">'>, <Variable Node: no_of_passenger>, <TextNode: '</option>\t\t\t\t  \n         '>, <Variable Node: recaptcha_site_key>, <TextNode: '"></div>\n\t\t\t\t<div id="err'>]>}]
WARNING 2023-12-03 17:15:18,789 log Not Found: /autodiscover/autodiscover.json
WARNING 2023-12-03 17:24:17,449 log Not Found: /robots.txt
WARNING 2023-12-03 17:24:39,199 log Not Found: /悉尼机场巴士/
WARNING 2023-12-03 17:25:02,967 log Not Found: /悉尼机场巴士/
WARNING 2023-12-03 17:25:27,992 log Not Found: /悉尼机场接送/
WARNING 2023-12-03 17:25:44,069 log Not Found: /悉尼机场接送/
WARNING 2023-12-03 17:26:03,815 log Not Found: /悉尼机场接送服务/
WARNING 2023-12-03 17:26:14,450 log Not Found: /悉尼机场接送服务/
WARNING 2023-12-03 17:26:37,649 log Not Found: /悉尼机场接送服务的最佳拍档/
WARNING 2023-12-03 17:26:43,683 log Not Found: /悉尼机场接送服务的最佳拍档/
WARNING 2023-12-03 17:27:11,005 log Not Found: /机场接送-悉尼/
WARNING 2023-12-03 17:27:20,577 log Not Found: /机场接送-悉尼/
WARNING 2023-12-03 17:29:27,547 log Not Found: /robots.txt
WARNING 2023-12-03 17:54:12,519 log Not Found: /robots.txt
WARNING 2023-12-03 17:54:21,199 log Not Found: /about-us/
WARNING 2023-12-03 18:00:49,864 log Not Found: /robots.txt
WARNING 2023-12-03 18:02:11,201 log Not Found: /robots.txt
WARNING 2023-12-03 18:21:33,852 log Not Found: /actuator/gateway/routes
WARNING 2023-12-03 18:29:12,801 log Not Found: /robots.txt
WARNING 2023-12-03 18:35:05,503 log Not Found: /retrieve_post/
WARNING 2023-12-03 18:37:21,340 log Not Found: /inquiry3/
WARNING 2023-12-03 18:38:24,226 log Not Found: /re_confirm/
WARNING 2023-12-03 18:39:25,779 log Not Found: /re_confirm_email/
WARNING 2023-12-03 18:40:26,886 log Not Found: /retrieve_inquiry/
WARNING 2023-12-03 19:04:56,846 log Not Found: /inquiry3/
WARNING 2023-12-03 19:05:28,395 log Not Found: /login
WARNING 2023-12-03 19:05:57,124 log Not Found: /re_confirm/
WARNING 2023-12-03 19:06:52,447 log Not Found: /re_confirm_email/
WARNING 2023-12-03 19:07:49,154 log Not Found: /retrieve_inquiry/
WARNING 2023-12-03 19:08:46,095 log Not Found: /retrieve_post/
DEBUG 2023-12-03 19:09:37,359 base Exception while resolving variable 'subtitle' in template 'admin_honeypot/login.html'.
Traceback (most recent call last):
  File "/home/horeb/github/easygo/venv/lib/python3.11/site-packages/django/template/base.py", line 880, in _resolve_lookup
    current = current[bit]
              ~~~~~~~^^^^^
  File "/home/horeb/github/easygo/venv/lib/python3.11/site-packages/django/template/context.py", line 83, in __getitem__
    raise KeyError(key)
KeyError: 'subtitle'

During handling of the above exception, another exception occurred:

Traceback (most recent call last):
  File "/home/horeb/github/easygo/venv/lib/python3.11/site-packages/django/template/base.py", line 886, in _resolve_lookup
    if isinstance(current, BaseContext) and getattr(
                                            ^^^^^^^^
AttributeError: type object 'RequestContext' has no attribute 'subtitle'

During handling of the above exception, another exception occurred:

Traceback (most recent call last):
  File "/home/horeb/github/easygo/venv/lib/python3.11/site-packages/django/template/base.py", line 896, in _resolve_lookup
    current = current[int(bit)]
                      ^^^^^^^^
ValueError: invalid literal for int() with base 10: 'subtitle'

During handling of the above exception, another exception occurred:

Traceback (most recent call last):
  File "/home/horeb/github/easygo/venv/lib/python3.11/site-packages/django/template/base.py", line 903, in _resolve_lookup
    raise VariableDoesNotExist(
django.template.base.VariableDoesNotExist: Failed lookup for key [subtitle] in [{'True': True, 'False': False, 'None': None}, {'csrf_token': <SimpleLazyObject: <function csrf.<locals>._get_val at 0x7f0a29ce9e40>>, 'request': <WSGIRequest: GET '/admin/login/?next=%2Fadmin%2F'>, 'user': <SimpleLazyObject: <function AuthenticationMiddleware.process_request.<locals>.<lambda> at 0x7f0a29ce9760>>, 'perms': PermWrapper(<SimpleLazyObject: <function AuthenticationMiddleware.process_request.<locals>.<lambda> at 0x7f0a29ce9760>>), 'messages': <FallbackStorage: request=<WSGIRequest: GET '/admin/login/?next=%2Fadmin%2F'>>, 'DEFAULT_MESSAGE_LEVELS': {'DEBUG': 10, 'INFO': 20, 'SUCCESS': 25, 'WARNING': 30, 'ERROR': 40}}, {}, {'form': <HoneypotLoginForm bound=False, valid=Unknown, fields=(username;password)>, 'view': <admin_honeypot.views.AdminHoneypot object at 0x7f0a29a293d0>, 'app_path': '/admin/login/?next=%2Fadmin%2F', 'next': '/admin/', 'title': 'Log in', 'LANGUAGE_CODE': 'en-us', 'LANGUAGE_BIDI': False}, {'block': <Block Node: title. Contents: [<IfNode>, <Variable Node: title>, <TextNode: ' | '>, <Variable Node: site_title|default:_('Django site admin')>]>}]
DEBUG 2023-12-03 19:09:37,360 base Exception while resolving variable 'site_title' in template 'admin_honeypot/login.html'.
Traceback (most recent call last):
  File "/home/horeb/github/easygo/venv/lib/python3.11/site-packages/django/template/base.py", line 880, in _resolve_lookup
    current = current[bit]
              ~~~~~~~^^^^^
  File "/home/horeb/github/easygo/venv/lib/python3.11/site-packages/django/template/context.py", line 83, in __getitem__
    raise KeyError(key)
KeyError: 'site_title'

During handling of the above exception, another exception occurred:

Traceback (most recent call last):
  File "/home/horeb/github/easygo/venv/lib/python3.11/site-packages/django/template/base.py", line 886, in _resolve_lookup
    if isinstance(current, BaseContext) and getattr(
                                            ^^^^^^^^
AttributeError: type object 'RequestContext' has no attribute 'site_title'

During handling of the above exception, another exception occurred:

Traceback (most recent call last):
  File "/home/horeb/github/easygo/venv/lib/python3.11/site-packages/django/template/base.py", line 896, in _resolve_lookup
    current = current[int(bit)]
                      ^^^^^^^^
ValueError: invalid literal for int() with base 10: 'site_title'

During handling of the above exception, another exception occurred:

Traceback (most recent call last):
  File "/home/horeb/github/easygo/venv/lib/python3.11/site-packages/django/template/base.py", line 903, in _resolve_lookup
    raise VariableDoesNotExist(
django.template.base.VariableDoesNotExist: Failed lookup for key [site_title] in [{'True': True, 'False': False, 'None': None}, {'csrf_token': <SimpleLazyObject: <function csrf.<locals>._get_val at 0x7f0a29ce9e40>>, 'request': <WSGIRequest: GET '/admin/login/?next=%2Fadmin%2F'>, 'user': <SimpleLazyObject: <function AuthenticationMiddleware.process_request.<locals>.<lambda> at 0x7f0a29ce9760>>, 'perms': PermWrapper(<SimpleLazyObject: <function AuthenticationMiddleware.process_request.<locals>.<lambda> at 0x7f0a29ce9760>>), 'messages': <FallbackStorage: request=<WSGIRequest: GET '/admin/login/?next=%2Fadmin%2F'>>, 'DEFAULT_MESSAGE_LEVELS': {'DEBUG': 10, 'INFO': 20, 'SUCCESS': 25, 'WARNING': 30, 'ERROR': 40}}, {}, {'form': <HoneypotLoginForm bound=False, valid=Unknown, fields=(username;password)>, 'view': <admin_honeypot.views.AdminHoneypot object at 0x7f0a29a293d0>, 'app_path': '/admin/login/?next=%2Fadmin%2F', 'next': '/admin/', 'title': 'Log in', 'LANGUAGE_CODE': 'en-us', 'LANGUAGE_BIDI': False}, {'block': <Block Node: title. Contents: [<IfNode>, <Variable Node: title>, <TextNode: ' | '>, <Variable Node: site_title|default:_('Django site admin')>]>}]
DEBUG 2023-12-03 19:09:37,361 base Exception while resolving variable 'is_popup' in template 'admin_honeypot/login.html'.
Traceback (most recent call last):
  File "/home/horeb/github/easygo/venv/lib/python3.11/site-packages/django/template/base.py", line 880, in _resolve_lookup
    current = current[bit]
              ~~~~~~~^^^^^
  File "/home/horeb/github/easygo/venv/lib/python3.11/site-packages/django/template/context.py", line 83, in __getitem__
    raise KeyError(key)
KeyError: 'is_popup'

During handling of the above exception, another exception occurred:

Traceback (most recent call last):
  File "/home/horeb/github/easygo/venv/lib/python3.11/site-packages/django/template/base.py", line 886, in _resolve_lookup
    if isinstance(current, BaseContext) and getattr(
                                            ^^^^^^^^
AttributeError: type object 'RequestContext' has no attribute 'is_popup'

During handling of the above exception, another exception occurred:

Traceback (most recent call last):
  File "/home/horeb/github/easygo/venv/lib/python3.11/site-packages/django/template/base.py", line 896, in _resolve_lookup
    current = current[int(bit)]
                      ^^^^^^^^
ValueError: invalid literal for int() with base 10: 'is_popup'

During handling of the above exception, another exception occurred:

Traceback (most recent call last):
  File "/home/horeb/github/easygo/venv/lib/python3.11/site-packages/django/template/base.py", line 903, in _resolve_lookup
    raise VariableDoesNotExist(
django.template.base.VariableDoesNotExist: Failed lookup for key [is_popup] in [{'True': True, 'False': False, 'None': None}, {'csrf_token': <SimpleLazyObject: <function csrf.<locals>._get_val at 0x7f0a29ce9e40>>, 'request': <WSGIRequest: GET '/admin/login/?next=%2Fadmin%2F'>, 'user': <SimpleLazyObject: <function AuthenticationMiddleware.process_request.<locals>.<lambda> at 0x7f0a29ce9760>>, 'perms': PermWrapper(<SimpleLazyObject: <function AuthenticationMiddleware.process_request.<locals>.<lambda> at 0x7f0a29ce9760>>), 'messages': <FallbackStorage: request=<WSGIRequest: GET '/admin/login/?next=%2Fadmin%2F'>>, 'DEFAULT_MESSAGE_LEVELS': {'DEBUG': 10, 'INFO': 20, 'SUCCESS': 25, 'WARNING': 30, 'ERROR': 40}}, {}, {'form': <HoneypotLoginForm bound=False, valid=Unknown, fields=(username;password)>, 'view': <admin_honeypot.views.AdminHoneypot object at 0x7f0a29a293d0>, 'app_path': '/admin/login/?next=%2Fadmin%2F', 'next': '/admin/', 'title': 'Log in', 'LANGUAGE_CODE': 'en-us', 'LANGUAGE_BIDI': False}]
DEBUG 2023-12-03 19:09:37,362 base Exception while resolving variable 'is_nav_sidebar_enabled' in template 'admin_honeypot/login.html'.
Traceback (most recent call last):
  File "/home/horeb/github/easygo/venv/lib/python3.11/site-packages/django/template/base.py", line 880, in _resolve_lookup
    current = current[bit]
              ~~~~~~~^^^^^
  File "/home/horeb/github/easygo/venv/lib/python3.11/site-packages/django/template/context.py", line 83, in __getitem__
    raise KeyError(key)
KeyError: 'is_nav_sidebar_enabled'

During handling of the above exception, another exception occurred:

Traceback (most recent call last):
  File "/home/horeb/github/easygo/venv/lib/python3.11/site-packages/django/template/base.py", line 886, in _resolve_lookup
    if isinstance(current, BaseContext) and getattr(
                                            ^^^^^^^^
AttributeError: type object 'RequestContext' has no attribute 'is_nav_sidebar_enabled'

During handling of the above exception, another exception occurred:

Traceback (most recent call last):
  File "/home/horeb/github/easygo/venv/lib/python3.11/site-packages/django/template/base.py", line 896, in _resolve_lookup
    current = current[int(bit)]
                      ^^^^^^^^
ValueError: invalid literal for int() with base 10: 'is_nav_sidebar_enabled'

During handling of the above exception, another exception occurred:

Traceback (most recent call last):
  File "/home/horeb/github/easygo/venv/lib/python3.11/site-packages/django/template/base.py", line 903, in _resolve_lookup
    raise VariableDoesNotExist(
django.template.base.VariableDoesNotExist: Failed lookup for key [is_nav_sidebar_enabled] in [{'True': True, 'False': False, 'None': None}, {'csrf_token': <SimpleLazyObject: <function csrf.<locals>._get_val at 0x7f0a29ce9e40>>, 'request': <WSGIRequest: GET '/admin/login/?next=%2Fadmin%2F'>, 'user': <SimpleLazyObject: <function AuthenticationMiddleware.process_request.<locals>.<lambda> at 0x7f0a29ce9760>>, 'perms': PermWrapper(<SimpleLazyObject: <function AuthenticationMiddleware.process_request.<locals>.<lambda> at 0x7f0a29ce9760>>), 'messages': <FallbackStorage: request=<WSGIRequest: GET '/admin/login/?next=%2Fadmin%2F'>>, 'DEFAULT_MESSAGE_LEVELS': {'DEBUG': 10, 'INFO': 20, 'SUCCESS': 25, 'WARNING': 30, 'ERROR': 40}}, {}, {'form': <HoneypotLoginForm bound=False, valid=Unknown, fields=(username;password)>, 'view': <admin_honeypot.views.AdminHoneypot object at 0x7f0a29a293d0>, 'app_path': '/admin/login/?next=%2Fadmin%2F', 'next': '/admin/', 'title': 'Log in', 'LANGUAGE_CODE': 'en-us', 'LANGUAGE_BIDI': False}]
DEBUG 2023-12-03 19:09:37,362 base Exception while resolving variable 'is_popup' in template 'admin_honeypot/login.html'.
Traceback (most recent call last):
  File "/home/horeb/github/easygo/venv/lib/python3.11/site-packages/django/template/base.py", line 880, in _resolve_lookup
    current = current[bit]
              ~~~~~~~^^^^^
  File "/home/horeb/github/easygo/venv/lib/python3.11/site-packages/django/template/context.py", line 83, in __getitem__
    raise KeyError(key)
KeyError: 'is_popup'

During handling of the above exception, another exception occurred:

Traceback (most recent call last):
  File "/home/horeb/github/easygo/venv/lib/python3.11/site-packages/django/template/base.py", line 886, in _resolve_lookup
    if isinstance(current, BaseContext) and getattr(
                                            ^^^^^^^^
AttributeError: type object 'RequestContext' has no attribute 'is_popup'

During handling of the above exception, another exception occurred:

Traceback (most recent call last):
  File "/home/horeb/github/easygo/venv/lib/python3.11/site-packages/django/template/base.py", line 896, in _resolve_lookup
    current = current[int(bit)]
                      ^^^^^^^^
ValueError: invalid literal for int() with base 10: 'is_popup'

During handling of the above exception, another exception occurred:

Traceback (most recent call last):
  File "/home/horeb/github/easygo/venv/lib/python3.11/site-packages/django/template/base.py", line 903, in _resolve_lookup
    raise VariableDoesNotExist(
django.template.base.VariableDoesNotExist: Failed lookup for key [is_popup] in [{'True': True, 'False': False, 'None': None}, {'csrf_token': <SimpleLazyObject: <function csrf.<locals>._get_val at 0x7f0a29ce9e40>>, 'request': <WSGIRequest: GET '/admin/login/?next=%2Fadmin%2F'>, 'user': <SimpleLazyObject: <function AuthenticationMiddleware.process_request.<locals>.<lambda> at 0x7f0a29ce9760>>, 'perms': PermWrapper(<SimpleLazyObject: <function AuthenticationMiddleware.process_request.<locals>.<lambda> at 0x7f0a29ce9760>>), 'messages': <FallbackStorage: request=<WSGIRequest: GET '/admin/login/?next=%2Fadmin%2F'>>, 'DEFAULT_MESSAGE_LEVELS': {'DEBUG': 10, 'INFO': 20, 'SUCCESS': 25, 'WARNING': 30, 'ERROR': 40}}, {}, {'form': <HoneypotLoginForm bound=False, valid=Unknown, fields=(username;password)>, 'view': <admin_honeypot.views.AdminHoneypot object at 0x7f0a29a293d0>, 'app_path': '/admin/login/?next=%2Fadmin%2F', 'next': '/admin/', 'title': 'Log in', 'LANGUAGE_CODE': 'en-us', 'LANGUAGE_BIDI': False}]
DEBUG 2023-12-03 19:09:37,363 base Exception while resolving variable 'is_popup' in template 'admin_honeypot/login.html'.
Traceback (most recent call last):
  File "/home/horeb/github/easygo/venv/lib/python3.11/site-packages/django/template/base.py", line 880, in _resolve_lookup
    current = current[bit]
              ~~~~~~~^^^^^
  File "/home/horeb/github/easygo/venv/lib/python3.11/site-packages/django/template/context.py", line 83, in __getitem__
    raise KeyError(key)
KeyError: 'is_popup'

During handling of the above exception, another exception occurred:

Traceback (most recent call last):
  File "/home/horeb/github/easygo/venv/lib/python3.11/site-packages/django/template/base.py", line 886, in _resolve_lookup
    if isinstance(current, BaseContext) and getattr(
                                            ^^^^^^^^
AttributeError: type object 'RequestContext' has no attribute 'is_popup'

During handling of the above exception, another exception occurred:

Traceback (most recent call last):
  File "/home/horeb/github/easygo/venv/lib/python3.11/site-packages/django/template/base.py", line 896, in _resolve_lookup
    current = current[int(bit)]
                      ^^^^^^^^
ValueError: invalid literal for int() with base 10: 'is_popup'

During handling of the above exception, another exception occurred:

Traceback (most recent call last):
  File "/home/horeb/github/easygo/venv/lib/python3.11/site-packages/django/template/base.py", line 903, in _resolve_lookup
    raise VariableDoesNotExist(
django.template.base.VariableDoesNotExist: Failed lookup for key [is_popup] in [{'True': True, 'False': False, 'None': None}, {'csrf_token': <SimpleLazyObject: <function csrf.<locals>._get_val at 0x7f0a29ce9e40>>, 'request': <WSGIRequest: GET '/admin/login/?next=%2Fadmin%2F'>, 'user': <SimpleLazyObject: <function AuthenticationMiddleware.process_request.<locals>.<lambda> at 0x7f0a29ce9760>>, 'perms': PermWrapper(<SimpleLazyObject: <function AuthenticationMiddleware.process_request.<locals>.<lambda> at 0x7f0a29ce9760>>), 'messages': <FallbackStorage: request=<WSGIRequest: GET '/admin/login/?next=%2Fadmin%2F'>>, 'DEFAULT_MESSAGE_LEVELS': {'DEBUG': 10, 'INFO': 20, 'SUCCESS': 25, 'WARNING': 30, 'ERROR': 40}}, {}, {'form': <HoneypotLoginForm bound=False, valid=Unknown, fields=(username;password)>, 'view': <admin_honeypot.views.AdminHoneypot object at 0x7f0a29a293d0>, 'app_path': '/admin/login/?next=%2Fadmin%2F', 'next': '/admin/', 'title': 'Log in', 'LANGUAGE_CODE': 'en-us', 'LANGUAGE_BIDI': False}]
DEBUG 2023-12-03 19:09:37,364 base Exception while resolving variable 'site_header' in template 'admin_honeypot/login.html'.
Traceback (most recent call last):
  File "/home/horeb/github/easygo/venv/lib/python3.11/site-packages/django/template/base.py", line 880, in _resolve_lookup
    current = current[bit]
              ~~~~~~~^^^^^
  File "/home/horeb/github/easygo/venv/lib/python3.11/site-packages/django/template/context.py", line 83, in __getitem__
    raise KeyError(key)
KeyError: 'site_header'

During handling of the above exception, another exception occurred:

Traceback (most recent call last):
  File "/home/horeb/github/easygo/venv/lib/python3.11/site-packages/django/template/base.py", line 886, in _resolve_lookup
    if isinstance(current, BaseContext) and getattr(
                                            ^^^^^^^^
AttributeError: type object 'RequestContext' has no attribute 'site_header'

During handling of the above exception, another exception occurred:

Traceback (most recent call last):
  File "/home/horeb/github/easygo/venv/lib/python3.11/site-packages/django/template/base.py", line 896, in _resolve_lookup
    current = current[int(bit)]
                      ^^^^^^^^
ValueError: invalid literal for int() with base 10: 'site_header'

During handling of the above exception, another exception occurred:

Traceback (most recent call last):
  File "/home/horeb/github/easygo/venv/lib/python3.11/site-packages/django/template/base.py", line 903, in _resolve_lookup
    raise VariableDoesNotExist(
django.template.base.VariableDoesNotExist: Failed lookup for key [site_header] in [{'True': True, 'False': False, 'None': None}, {'csrf_token': <SimpleLazyObject: <function csrf.<locals>._get_val at 0x7f0a29ce9e40>>, 'request': <WSGIRequest: GET '/admin/login/?next=%2Fadmin%2F'>, 'user': <SimpleLazyObject: <function AuthenticationMiddleware.process_request.<locals>.<lambda> at 0x7f0a29ce9760>>, 'perms': PermWrapper(<SimpleLazyObject: <function AuthenticationMiddleware.process_request.<locals>.<lambda> at 0x7f0a29ce9760>>), 'messages': <FallbackStorage: request=<WSGIRequest: GET '/admin/login/?next=%2Fadmin%2F'>>, 'DEFAULT_MESSAGE_LEVELS': {'DEBUG': 10, 'INFO': 20, 'SUCCESS': 25, 'WARNING': 30, 'ERROR': 40}}, {}, {'form': <HoneypotLoginForm bound=False, valid=Unknown, fields=(username;password)>, 'view': <admin_honeypot.views.AdminHoneypot object at 0x7f0a29a293d0>, 'app_path': '/admin/login/?next=%2Fadmin%2F', 'next': '/admin/', 'title': 'Log in', 'LANGUAGE_CODE': 'en-us', 'LANGUAGE_BIDI': False}, {'block': <Block Node: header. Contents: [<TextNode: '\n    <div id="header">\n  '>, <Block Node: branding. Contents: []>, <TextNode: '\n        </div>\n        '>, <Block Node: usertools. Contents: [<TextNode: '\n        '>, <IfNode>, <TextNode: '\n        '>]>, <TextNode: '\n        '>, <Block Node: nav-global. Contents: []>, <TextNode: '\n    </div>\n    '>]>}, {'block': <Block Node: branding. Contents: [<TextNode: '\n<h1 id="site-name"><a hr'>, <URLNode view_name=''admin_honeypot:index'' args=[] kwargs={} as=None>, <TextNode: '">'>, <Variable Node: site_header|default:_('Django administration')>, <TextNode: '</a></h1>\n'>]>}]
DEBUG 2023-12-03 19:09:37,364 base Exception while resolving variable 'is_popup' in template 'admin_honeypot/login.html'.
Traceback (most recent call last):
  File "/home/horeb/github/easygo/venv/lib/python3.11/site-packages/django/template/base.py", line 880, in _resolve_lookup
    current = current[bit]
              ~~~~~~~^^^^^
  File "/home/horeb/github/easygo/venv/lib/python3.11/site-packages/django/template/context.py", line 83, in __getitem__
    raise KeyError(key)
KeyError: 'is_popup'

During handling of the above exception, another exception occurred:

Traceback (most recent call last):
  File "/home/horeb/github/easygo/venv/lib/python3.11/site-packages/django/template/base.py", line 886, in _resolve_lookup
    if isinstance(current, BaseContext) and getattr(
                                            ^^^^^^^^
AttributeError: type object 'RequestContext' has no attribute 'is_popup'

During handling of the above exception, another exception occurred:

Traceback (most recent call last):
  File "/home/horeb/github/easygo/venv/lib/python3.11/site-packages/django/template/base.py", line 896, in _resolve_lookup
    current = current[int(bit)]
                      ^^^^^^^^
ValueError: invalid literal for int() with base 10: 'is_popup'

During handling of the above exception, another exception occurred:

Traceback (most recent call last):
  File "/home/horeb/github/easygo/venv/lib/python3.11/site-packages/django/template/base.py", line 903, in _resolve_lookup
    raise VariableDoesNotExist(
django.template.base.VariableDoesNotExist: Failed lookup for key [is_popup] in [{'True': True, 'False': False, 'None': None}, {'csrf_token': <SimpleLazyObject: <function csrf.<locals>._get_val at 0x7f0a29ce9e40>>, 'request': <WSGIRequest: GET '/admin/login/?next=%2Fadmin%2F'>, 'user': <SimpleLazyObject: <function AuthenticationMiddleware.process_request.<locals>.<lambda> at 0x7f0a29ce9760>>, 'perms': PermWrapper(<SimpleLazyObject: <function AuthenticationMiddleware.process_request.<locals>.<lambda> at 0x7f0a29ce9760>>), 'messages': <FallbackStorage: request=<WSGIRequest: GET '/admin/login/?next=%2Fadmin%2F'>>, 'DEFAULT_MESSAGE_LEVELS': {'DEBUG': 10, 'INFO': 20, 'SUCCESS': 25, 'WARNING': 30, 'ERROR': 40}}, {}, {'form': <HoneypotLoginForm bound=False, valid=Unknown, fields=(username;password)>, 'view': <admin_honeypot.views.AdminHoneypot object at 0x7f0a29a293d0>, 'app_path': '/admin/login/?next=%2Fadmin%2F', 'next': '/admin/', 'title': 'Log in', 'LANGUAGE_CODE': 'en-us', 'LANGUAGE_BIDI': False}]
DEBUG 2023-12-03 19:09:37,365 base Exception while resolving variable 'is_nav_sidebar_enabled' in template 'admin_honeypot/login.html'.
Traceback (most recent call last):
  File "/home/horeb/github/easygo/venv/lib/python3.11/site-packages/django/template/base.py", line 880, in _resolve_lookup
    current = current[bit]
              ~~~~~~~^^^^^
  File "/home/horeb/github/easygo/venv/lib/python3.11/site-packages/django/template/context.py", line 83, in __getitem__
    raise KeyError(key)
KeyError: 'is_nav_sidebar_enabled'

During handling of the above exception, another exception occurred:

Traceback (most recent call last):
  File "/home/horeb/github/easygo/venv/lib/python3.11/site-packages/django/template/base.py", line 886, in _resolve_lookup
    if isinstance(current, BaseContext) and getattr(
                                            ^^^^^^^^
AttributeError: type object 'RequestContext' has no attribute 'is_nav_sidebar_enabled'

During handling of the above exception, another exception occurred:

Traceback (most recent call last):
  File "/home/horeb/github/easygo/venv/lib/python3.11/site-packages/django/template/base.py", line 896, in _resolve_lookup
    current = current[int(bit)]
                      ^^^^^^^^
ValueError: invalid literal for int() with base 10: 'is_nav_sidebar_enabled'

During handling of the above exception, another exception occurred:

Traceback (most recent call last):
  File "/home/horeb/github/easygo/venv/lib/python3.11/site-packages/django/template/base.py", line 903, in _resolve_lookup
    raise VariableDoesNotExist(
django.template.base.VariableDoesNotExist: Failed lookup for key [is_nav_sidebar_enabled] in [{'True': True, 'False': False, 'None': None}, {'csrf_token': <SimpleLazyObject: <function csrf.<locals>._get_val at 0x7f0a29ce9e40>>, 'request': <WSGIRequest: GET '/admin/login/?next=%2Fadmin%2F'>, 'user': <SimpleLazyObject: <function AuthenticationMiddleware.process_request.<locals>.<lambda> at 0x7f0a29ce9760>>, 'perms': PermWrapper(<SimpleLazyObject: <function AuthenticationMiddleware.process_request.<locals>.<lambda> at 0x7f0a29ce9760>>), 'messages': <FallbackStorage: request=<WSGIRequest: GET '/admin/login/?next=%2Fadmin%2F'>>, 'DEFAULT_MESSAGE_LEVELS': {'DEBUG': 10, 'INFO': 20, 'SUCCESS': 25, 'WARNING': 30, 'ERROR': 40}}, {}, {'form': <HoneypotLoginForm bound=False, valid=Unknown, fields=(username;password)>, 'view': <admin_honeypot.views.AdminHoneypot object at 0x7f0a29a293d0>, 'app_path': '/admin/login/?next=%2Fadmin%2F', 'next': '/admin/', 'title': 'Log in', 'LANGUAGE_CODE': 'en-us', 'LANGUAGE_BIDI': False}]
DEBUG 2023-12-03 19:09:37,365 base Exception while resolving variable 'subtitle' in template 'admin_honeypot/login.html'.
Traceback (most recent call last):
  File "/home/horeb/github/easygo/venv/lib/python3.11/site-packages/django/template/base.py", line 880, in _resolve_lookup
    current = current[bit]
              ~~~~~~~^^^^^
  File "/home/horeb/github/easygo/venv/lib/python3.11/site-packages/django/template/context.py", line 83, in __getitem__
    raise KeyError(key)
KeyError: 'subtitle'

During handling of the above exception, another exception occurred:

Traceback (most recent call last):
  File "/home/horeb/github/easygo/venv/lib/python3.11/site-packages/django/template/base.py", line 886, in _resolve_lookup
    if isinstance(current, BaseContext) and getattr(
                                            ^^^^^^^^
AttributeError: type object 'RequestContext' has no attribute 'subtitle'

During handling of the above exception, another exception occurred:

Traceback (most recent call last):
  File "/home/horeb/github/easygo/venv/lib/python3.11/site-packages/django/template/base.py", line 896, in _resolve_lookup
    current = current[int(bit)]
                      ^^^^^^^^
ValueError: invalid literal for int() with base 10: 'subtitle'

During handling of the above exception, another exception occurred:

Traceback (most recent call last):
  File "/home/horeb/github/easygo/venv/lib/python3.11/site-packages/django/template/base.py", line 903, in _resolve_lookup
    raise VariableDoesNotExist(
django.template.base.VariableDoesNotExist: Failed lookup for key [subtitle] in [{'True': True, 'False': False, 'None': None}, {'csrf_token': <SimpleLazyObject: <function csrf.<locals>._get_val at 0x7f0a29ce9e40>>, 'request': <WSGIRequest: GET '/admin/login/?next=%2Fadmin%2F'>, 'user': <SimpleLazyObject: <function AuthenticationMiddleware.process_request.<locals>.<lambda> at 0x7f0a29ce9760>>, 'perms': PermWrapper(<SimpleLazyObject: <function AuthenticationMiddleware.process_request.<locals>.<lambda> at 0x7f0a29ce9760>>), 'messages': <FallbackStorage: request=<WSGIRequest: GET '/admin/login/?next=%2Fadmin%2F'>>, 'DEFAULT_MESSAGE_LEVELS': {'DEBUG': 10, 'INFO': 20, 'SUCCESS': 25, 'WARNING': 30, 'ERROR': 40}}, {}, {'form': <HoneypotLoginForm bound=False, valid=Unknown, fields=(username;password)>, 'view': <admin_honeypot.views.AdminHoneypot object at 0x7f0a29a293d0>, 'app_path': '/admin/login/?next=%2Fadmin%2F', 'next': '/admin/', 'title': 'Log in', 'LANGUAGE_CODE': 'en-us', 'LANGUAGE_BIDI': False}, {'block': <Block Node: content_subtitle. Contents: [<IfNode>]>}]
WARNING 2023-12-03 19:13:46,012 log Not Found: /RDWeb
WARNING 2023-12-03 19:18:10,374 log Not Found: /about-us/
WARNING 2023-12-03 19:25:42,219 log Not Found: /.env
DEBUG 2023-12-03 19:35:13,210 base Exception while resolving variable 'subtitle' in template 'admin_honeypot/login.html'.
Traceback (most recent call last):
  File "/home/horeb/github/easygo/venv/lib/python3.11/site-packages/django/template/base.py", line 880, in _resolve_lookup
    current = current[bit]
              ~~~~~~~^^^^^
  File "/home/horeb/github/easygo/venv/lib/python3.11/site-packages/django/template/context.py", line 83, in __getitem__
    raise KeyError(key)
KeyError: 'subtitle'

During handling of the above exception, another exception occurred:

Traceback (most recent call last):
  File "/home/horeb/github/easygo/venv/lib/python3.11/site-packages/django/template/base.py", line 886, in _resolve_lookup
    if isinstance(current, BaseContext) and getattr(
                                            ^^^^^^^^
AttributeError: type object 'RequestContext' has no attribute 'subtitle'

During handling of the above exception, another exception occurred:

Traceback (most recent call last):
  File "/home/horeb/github/easygo/venv/lib/python3.11/site-packages/django/template/base.py", line 896, in _resolve_lookup
    current = current[int(bit)]
                      ^^^^^^^^
ValueError: invalid literal for int() with base 10: 'subtitle'

During handling of the above exception, another exception occurred:

Traceback (most recent call last):
  File "/home/horeb/github/easygo/venv/lib/python3.11/site-packages/django/template/base.py", line 903, in _resolve_lookup
    raise VariableDoesNotExist(
django.template.base.VariableDoesNotExist: Failed lookup for key [subtitle] in [{'True': True, 'False': False, 'None': None}, {'csrf_token': <SimpleLazyObject: <function csrf.<locals>._get_val at 0x7f31550c4f40>>, 'request': <WSGIRequest: GET '/admin/login/?next=%2Fadmin%2F'>, 'user': <SimpleLazyObject: <function AuthenticationMiddleware.process_request.<locals>.<lambda> at 0x7f315577f1a0>>, 'perms': PermWrapper(<SimpleLazyObject: <function AuthenticationMiddleware.process_request.<locals>.<lambda> at 0x7f315577f1a0>>), 'messages': <FallbackStorage: request=<WSGIRequest: GET '/admin/login/?next=%2Fadmin%2F'>>, 'DEFAULT_MESSAGE_LEVELS': {'DEBUG': 10, 'INFO': 20, 'SUCCESS': 25, 'WARNING': 30, 'ERROR': 40}}, {}, {'form': <HoneypotLoginForm bound=False, valid=Unknown, fields=(username;password)>, 'view': <admin_honeypot.views.AdminHoneypot object at 0x7f3154f6a450>, 'app_path': '/admin/login/?next=%2Fadmin%2F', 'next': '/admin/', 'title': 'Log in', 'LANGUAGE_CODE': 'en-us', 'LANGUAGE_BIDI': False}, {'block': <Block Node: title. Contents: [<IfNode>, <Variable Node: title>, <TextNode: ' | '>, <Variable Node: site_title|default:_('Django site admin')>]>}]
DEBUG 2023-12-03 19:35:13,211 base Exception while resolving variable 'site_title' in template 'admin_honeypot/login.html'.
Traceback (most recent call last):
  File "/home/horeb/github/easygo/venv/lib/python3.11/site-packages/django/template/base.py", line 880, in _resolve_lookup
    current = current[bit]
              ~~~~~~~^^^^^
  File "/home/horeb/github/easygo/venv/lib/python3.11/site-packages/django/template/context.py", line 83, in __getitem__
    raise KeyError(key)
KeyError: 'site_title'

During handling of the above exception, another exception occurred:

Traceback (most recent call last):
  File "/home/horeb/github/easygo/venv/lib/python3.11/site-packages/django/template/base.py", line 886, in _resolve_lookup
    if isinstance(current, BaseContext) and getattr(
                                            ^^^^^^^^
AttributeError: type object 'RequestContext' has no attribute 'site_title'

During handling of the above exception, another exception occurred:

Traceback (most recent call last):
  File "/home/horeb/github/easygo/venv/lib/python3.11/site-packages/django/template/base.py", line 896, in _resolve_lookup
    current = current[int(bit)]
                      ^^^^^^^^
ValueError: invalid literal for int() with base 10: 'site_title'

During handling of the above exception, another exception occurred:

Traceback (most recent call last):
  File "/home/horeb/github/easygo/venv/lib/python3.11/site-packages/django/template/base.py", line 903, in _resolve_lookup
    raise VariableDoesNotExist(
django.template.base.VariableDoesNotExist: Failed lookup for key [site_title] in [{'True': True, 'False': False, 'None': None}, {'csrf_token': <SimpleLazyObject: <function csrf.<locals>._get_val at 0x7f31550c4f40>>, 'request': <WSGIRequest: GET '/admin/login/?next=%2Fadmin%2F'>, 'user': <SimpleLazyObject: <function AuthenticationMiddleware.process_request.<locals>.<lambda> at 0x7f315577f1a0>>, 'perms': PermWrapper(<SimpleLazyObject: <function AuthenticationMiddleware.process_request.<locals>.<lambda> at 0x7f315577f1a0>>), 'messages': <FallbackStorage: request=<WSGIRequest: GET '/admin/login/?next=%2Fadmin%2F'>>, 'DEFAULT_MESSAGE_LEVELS': {'DEBUG': 10, 'INFO': 20, 'SUCCESS': 25, 'WARNING': 30, 'ERROR': 40}}, {}, {'form': <HoneypotLoginForm bound=False, valid=Unknown, fields=(username;password)>, 'view': <admin_honeypot.views.AdminHoneypot object at 0x7f3154f6a450>, 'app_path': '/admin/login/?next=%2Fadmin%2F', 'next': '/admin/', 'title': 'Log in', 'LANGUAGE_CODE': 'en-us', 'LANGUAGE_BIDI': False}, {'block': <Block Node: title. Contents: [<IfNode>, <Variable Node: title>, <TextNode: ' | '>, <Variable Node: site_title|default:_('Django site admin')>]>}]
DEBUG 2023-12-03 19:35:13,212 base Exception while resolving variable 'is_popup' in template 'admin_honeypot/login.html'.
Traceback (most recent call last):
  File "/home/horeb/github/easygo/venv/lib/python3.11/site-packages/django/template/base.py", line 880, in _resolve_lookup
    current = current[bit]
              ~~~~~~~^^^^^
  File "/home/horeb/github/easygo/venv/lib/python3.11/site-packages/django/template/context.py", line 83, in __getitem__
    raise KeyError(key)
KeyError: 'is_popup'

During handling of the above exception, another exception occurred:

Traceback (most recent call last):
  File "/home/horeb/github/easygo/venv/lib/python3.11/site-packages/django/template/base.py", line 886, in _resolve_lookup
    if isinstance(current, BaseContext) and getattr(
                                            ^^^^^^^^
AttributeError: type object 'RequestContext' has no attribute 'is_popup'

During handling of the above exception, another exception occurred:

Traceback (most recent call last):
  File "/home/horeb/github/easygo/venv/lib/python3.11/site-packages/django/template/base.py", line 896, in _resolve_lookup
    current = current[int(bit)]
                      ^^^^^^^^
ValueError: invalid literal for int() with base 10: 'is_popup'

During handling of the above exception, another exception occurred:

Traceback (most recent call last):
  File "/home/horeb/github/easygo/venv/lib/python3.11/site-packages/django/template/base.py", line 903, in _resolve_lookup
    raise VariableDoesNotExist(
django.template.base.VariableDoesNotExist: Failed lookup for key [is_popup] in [{'True': True, 'False': False, 'None': None}, {'csrf_token': <SimpleLazyObject: <function csrf.<locals>._get_val at 0x7f31550c4f40>>, 'request': <WSGIRequest: GET '/admin/login/?next=%2Fadmin%2F'>, 'user': <SimpleLazyObject: <function AuthenticationMiddleware.process_request.<locals>.<lambda> at 0x7f315577f1a0>>, 'perms': PermWrapper(<SimpleLazyObject: <function AuthenticationMiddleware.process_request.<locals>.<lambda> at 0x7f315577f1a0>>), 'messages': <FallbackStorage: request=<WSGIRequest: GET '/admin/login/?next=%2Fadmin%2F'>>, 'DEFAULT_MESSAGE_LEVELS': {'DEBUG': 10, 'INFO': 20, 'SUCCESS': 25, 'WARNING': 30, 'ERROR': 40}}, {}, {'form': <HoneypotLoginForm bound=False, valid=Unknown, fields=(username;password)>, 'view': <admin_honeypot.views.AdminHoneypot object at 0x7f3154f6a450>, 'app_path': '/admin/login/?next=%2Fadmin%2F', 'next': '/admin/', 'title': 'Log in', 'LANGUAGE_CODE': 'en-us', 'LANGUAGE_BIDI': False}]
DEBUG 2023-12-03 19:35:13,212 base Exception while resolving variable 'is_nav_sidebar_enabled' in template 'admin_honeypot/login.html'.
Traceback (most recent call last):
  File "/home/horeb/github/easygo/venv/lib/python3.11/site-packages/django/template/base.py", line 880, in _resolve_lookup
    current = current[bit]
              ~~~~~~~^^^^^
  File "/home/horeb/github/easygo/venv/lib/python3.11/site-packages/django/template/context.py", line 83, in __getitem__
    raise KeyError(key)
KeyError: 'is_nav_sidebar_enabled'

During handling of the above exception, another exception occurred:

Traceback (most recent call last):
  File "/home/horeb/github/easygo/venv/lib/python3.11/site-packages/django/template/base.py", line 886, in _resolve_lookup
    if isinstance(current, BaseContext) and getattr(
                                            ^^^^^^^^
AttributeError: type object 'RequestContext' has no attribute 'is_nav_sidebar_enabled'

During handling of the above exception, another exception occurred:

Traceback (most recent call last):
  File "/home/horeb/github/easygo/venv/lib/python3.11/site-packages/django/template/base.py", line 896, in _resolve_lookup
    current = current[int(bit)]
                      ^^^^^^^^
ValueError: invalid literal for int() with base 10: 'is_nav_sidebar_enabled'

During handling of the above exception, another exception occurred:

Traceback (most recent call last):
  File "/home/horeb/github/easygo/venv/lib/python3.11/site-packages/django/template/base.py", line 903, in _resolve_lookup
    raise VariableDoesNotExist(
django.template.base.VariableDoesNotExist: Failed lookup for key [is_nav_sidebar_enabled] in [{'True': True, 'False': False, 'None': None}, {'csrf_token': <SimpleLazyObject: <function csrf.<locals>._get_val at 0x7f31550c4f40>>, 'request': <WSGIRequest: GET '/admin/login/?next=%2Fadmin%2F'>, 'user': <SimpleLazyObject: <function AuthenticationMiddleware.process_request.<locals>.<lambda> at 0x7f315577f1a0>>, 'perms': PermWrapper(<SimpleLazyObject: <function AuthenticationMiddleware.process_request.<locals>.<lambda> at 0x7f315577f1a0>>), 'messages': <FallbackStorage: request=<WSGIRequest: GET '/admin/login/?next=%2Fadmin%2F'>>, 'DEFAULT_MESSAGE_LEVELS': {'DEBUG': 10, 'INFO': 20, 'SUCCESS': 25, 'WARNING': 30, 'ERROR': 40}}, {}, {'form': <HoneypotLoginForm bound=False, valid=Unknown, fields=(username;password)>, 'view': <admin_honeypot.views.AdminHoneypot object at 0x7f3154f6a450>, 'app_path': '/admin/login/?next=%2Fadmin%2F', 'next': '/admin/', 'title': 'Log in', 'LANGUAGE_CODE': 'en-us', 'LANGUAGE_BIDI': False}]
DEBUG 2023-12-03 19:35:13,213 base Exception while resolving variable 'is_popup' in template 'admin_honeypot/login.html'.
Traceback (most recent call last):
  File "/home/horeb/github/easygo/venv/lib/python3.11/site-packages/django/template/base.py", line 880, in _resolve_lookup
    current = current[bit]
              ~~~~~~~^^^^^
  File "/home/horeb/github/easygo/venv/lib/python3.11/site-packages/django/template/context.py", line 83, in __getitem__
    raise KeyError(key)
KeyError: 'is_popup'

During handling of the above exception, another exception occurred:

Traceback (most recent call last):
  File "/home/horeb/github/easygo/venv/lib/python3.11/site-packages/django/template/base.py", line 886, in _resolve_lookup
    if isinstance(current, BaseContext) and getattr(
                                            ^^^^^^^^
AttributeError: type object 'RequestContext' has no attribute 'is_popup'

During handling of the above exception, another exception occurred:

Traceback (most recent call last):
  File "/home/horeb/github/easygo/venv/lib/python3.11/site-packages/django/template/base.py", line 896, in _resolve_lookup
    current = current[int(bit)]
                      ^^^^^^^^
ValueError: invalid literal for int() with base 10: 'is_popup'

During handling of the above exception, another exception occurred:

Traceback (most recent call last):
  File "/home/horeb/github/easygo/venv/lib/python3.11/site-packages/django/template/base.py", line 903, in _resolve_lookup
    raise VariableDoesNotExist(
django.template.base.VariableDoesNotExist: Failed lookup for key [is_popup] in [{'True': True, 'False': False, 'None': None}, {'csrf_token': <SimpleLazyObject: <function csrf.<locals>._get_val at 0x7f31550c4f40>>, 'request': <WSGIRequest: GET '/admin/login/?next=%2Fadmin%2F'>, 'user': <SimpleLazyObject: <function AuthenticationMiddleware.process_request.<locals>.<lambda> at 0x7f315577f1a0>>, 'perms': PermWrapper(<SimpleLazyObject: <function AuthenticationMiddleware.process_request.<locals>.<lambda> at 0x7f315577f1a0>>), 'messages': <FallbackStorage: request=<WSGIRequest: GET '/admin/login/?next=%2Fadmin%2F'>>, 'DEFAULT_MESSAGE_LEVELS': {'DEBUG': 10, 'INFO': 20, 'SUCCESS': 25, 'WARNING': 30, 'ERROR': 40}}, {}, {'form': <HoneypotLoginForm bound=False, valid=Unknown, fields=(username;password)>, 'view': <admin_honeypot.views.AdminHoneypot object at 0x7f3154f6a450>, 'app_path': '/admin/login/?next=%2Fadmin%2F', 'next': '/admin/', 'title': 'Log in', 'LANGUAGE_CODE': 'en-us', 'LANGUAGE_BIDI': False}]
DEBUG 2023-12-03 19:35:13,213 base Exception while resolving variable 'is_popup' in template 'admin_honeypot/login.html'.
Traceback (most recent call last):
  File "/home/horeb/github/easygo/venv/lib/python3.11/site-packages/django/template/base.py", line 880, in _resolve_lookup
    current = current[bit]
              ~~~~~~~^^^^^
  File "/home/horeb/github/easygo/venv/lib/python3.11/site-packages/django/template/context.py", line 83, in __getitem__
    raise KeyError(key)
KeyError: 'is_popup'

During handling of the above exception, another exception occurred:

Traceback (most recent call last):
  File "/home/horeb/github/easygo/venv/lib/python3.11/site-packages/django/template/base.py", line 886, in _resolve_lookup
    if isinstance(current, BaseContext) and getattr(
                                            ^^^^^^^^
AttributeError: type object 'RequestContext' has no attribute 'is_popup'

During handling of the above exception, another exception occurred:

Traceback (most recent call last):
  File "/home/horeb/github/easygo/venv/lib/python3.11/site-packages/django/template/base.py", line 896, in _resolve_lookup
    current = current[int(bit)]
                      ^^^^^^^^
ValueError: invalid literal for int() with base 10: 'is_popup'

During handling of the above exception, another exception occurred:

Traceback (most recent call last):
  File "/home/horeb/github/easygo/venv/lib/python3.11/site-packages/django/template/base.py", line 903, in _resolve_lookup
    raise VariableDoesNotExist(
django.template.base.VariableDoesNotExist: Failed lookup for key [is_popup] in [{'True': True, 'False': False, 'None': None}, {'csrf_token': <SimpleLazyObject: <function csrf.<locals>._get_val at 0x7f31550c4f40>>, 'request': <WSGIRequest: GET '/admin/login/?next=%2Fadmin%2F'>, 'user': <SimpleLazyObject: <function AuthenticationMiddleware.process_request.<locals>.<lambda> at 0x7f315577f1a0>>, 'perms': PermWrapper(<SimpleLazyObject: <function AuthenticationMiddleware.process_request.<locals>.<lambda> at 0x7f315577f1a0>>), 'messages': <FallbackStorage: request=<WSGIRequest: GET '/admin/login/?next=%2Fadmin%2F'>>, 'DEFAULT_MESSAGE_LEVELS': {'DEBUG': 10, 'INFO': 20, 'SUCCESS': 25, 'WARNING': 30, 'ERROR': 40}}, {}, {'form': <HoneypotLoginForm bound=False, valid=Unknown, fields=(username;password)>, 'view': <admin_honeypot.views.AdminHoneypot object at 0x7f3154f6a450>, 'app_path': '/admin/login/?next=%2Fadmin%2F', 'next': '/admin/', 'title': 'Log in', 'LANGUAGE_CODE': 'en-us', 'LANGUAGE_BIDI': False}]
DEBUG 2023-12-03 19:35:13,214 base Exception while resolving variable 'site_header' in template 'admin_honeypot/login.html'.
Traceback (most recent call last):
  File "/home/horeb/github/easygo/venv/lib/python3.11/site-packages/django/template/base.py", line 880, in _resolve_lookup
    current = current[bit]
              ~~~~~~~^^^^^
  File "/home/horeb/github/easygo/venv/lib/python3.11/site-packages/django/template/context.py", line 83, in __getitem__
    raise KeyError(key)
KeyError: 'site_header'

During handling of the above exception, another exception occurred:

Traceback (most recent call last):
  File "/home/horeb/github/easygo/venv/lib/python3.11/site-packages/django/template/base.py", line 886, in _resolve_lookup
    if isinstance(current, BaseContext) and getattr(
                                            ^^^^^^^^
AttributeError: type object 'RequestContext' has no attribute 'site_header'

During handling of the above exception, another exception occurred:

Traceback (most recent call last):
  File "/home/horeb/github/easygo/venv/lib/python3.11/site-packages/django/template/base.py", line 896, in _resolve_lookup
    current = current[int(bit)]
                      ^^^^^^^^
ValueError: invalid literal for int() with base 10: 'site_header'

During handling of the above exception, another exception occurred:

Traceback (most recent call last):
  File "/home/horeb/github/easygo/venv/lib/python3.11/site-packages/django/template/base.py", line 903, in _resolve_lookup
    raise VariableDoesNotExist(
django.template.base.VariableDoesNotExist: Failed lookup for key [site_header] in [{'True': True, 'False': False, 'None': None}, {'csrf_token': <SimpleLazyObject: <function csrf.<locals>._get_val at 0x7f31550c4f40>>, 'request': <WSGIRequest: GET '/admin/login/?next=%2Fadmin%2F'>, 'user': <SimpleLazyObject: <function AuthenticationMiddleware.process_request.<locals>.<lambda> at 0x7f315577f1a0>>, 'perms': PermWrapper(<SimpleLazyObject: <function AuthenticationMiddleware.process_request.<locals>.<lambda> at 0x7f315577f1a0>>), 'messages': <FallbackStorage: request=<WSGIRequest: GET '/admin/login/?next=%2Fadmin%2F'>>, 'DEFAULT_MESSAGE_LEVELS': {'DEBUG': 10, 'INFO': 20, 'SUCCESS': 25, 'WARNING': 30, 'ERROR': 40}}, {}, {'form': <HoneypotLoginForm bound=False, valid=Unknown, fields=(username;password)>, 'view': <admin_honeypot.views.AdminHoneypot object at 0x7f3154f6a450>, 'app_path': '/admin/login/?next=%2Fadmin%2F', 'next': '/admin/', 'title': 'Log in', 'LANGUAGE_CODE': 'en-us', 'LANGUAGE_BIDI': False}, {'block': <Block Node: header. Contents: [<TextNode: '\n    <div id="header">\n  '>, <Block Node: branding. Contents: []>, <TextNode: '\n        </div>\n        '>, <Block Node: usertools. Contents: [<TextNode: '\n        '>, <IfNode>, <TextNode: '\n        '>]>, <TextNode: '\n        '>, <Block Node: nav-global. Contents: []>, <TextNode: '\n    </div>\n    '>]>}, {'block': <Block Node: branding. Contents: [<TextNode: '\n<h1 id="site-name"><a hr'>, <URLNode view_name=''admin_honeypot:index'' args=[] kwargs={} as=None>, <TextNode: '">'>, <Variable Node: site_header|default:_('Django administration')>, <TextNode: '</a></h1>\n'>]>}]
DEBUG 2023-12-03 19:35:13,214 base Exception while resolving variable 'is_popup' in template 'admin_honeypot/login.html'.
Traceback (most recent call last):
  File "/home/horeb/github/easygo/venv/lib/python3.11/site-packages/django/template/base.py", line 880, in _resolve_lookup
    current = current[bit]
              ~~~~~~~^^^^^
  File "/home/horeb/github/easygo/venv/lib/python3.11/site-packages/django/template/context.py", line 83, in __getitem__
    raise KeyError(key)
KeyError: 'is_popup'

During handling of the above exception, another exception occurred:

Traceback (most recent call last):
  File "/home/horeb/github/easygo/venv/lib/python3.11/site-packages/django/template/base.py", line 886, in _resolve_lookup
    if isinstance(current, BaseContext) and getattr(
                                            ^^^^^^^^
AttributeError: type object 'RequestContext' has no attribute 'is_popup'

During handling of the above exception, another exception occurred:

Traceback (most recent call last):
  File "/home/horeb/github/easygo/venv/lib/python3.11/site-packages/django/template/base.py", line 896, in _resolve_lookup
    current = current[int(bit)]
                      ^^^^^^^^
ValueError: invalid literal for int() with base 10: 'is_popup'

During handling of the above exception, another exception occurred:

Traceback (most recent call last):
  File "/home/horeb/github/easygo/venv/lib/python3.11/site-packages/django/template/base.py", line 903, in _resolve_lookup
    raise VariableDoesNotExist(
django.template.base.VariableDoesNotExist: Failed lookup for key [is_popup] in [{'True': True, 'False': False, 'None': None}, {'csrf_token': <SimpleLazyObject: <function csrf.<locals>._get_val at 0x7f31550c4f40>>, 'request': <WSGIRequest: GET '/admin/login/?next=%2Fadmin%2F'>, 'user': <SimpleLazyObject: <function AuthenticationMiddleware.process_request.<locals>.<lambda> at 0x7f315577f1a0>>, 'perms': PermWrapper(<SimpleLazyObject: <function AuthenticationMiddleware.process_request.<locals>.<lambda> at 0x7f315577f1a0>>), 'messages': <FallbackStorage: request=<WSGIRequest: GET '/admin/login/?next=%2Fadmin%2F'>>, 'DEFAULT_MESSAGE_LEVELS': {'DEBUG': 10, 'INFO': 20, 'SUCCESS': 25, 'WARNING': 30, 'ERROR': 40}}, {}, {'form': <HoneypotLoginForm bound=False, valid=Unknown, fields=(username;password)>, 'view': <admin_honeypot.views.AdminHoneypot object at 0x7f3154f6a450>, 'app_path': '/admin/login/?next=%2Fadmin%2F', 'next': '/admin/', 'title': 'Log in', 'LANGUAGE_CODE': 'en-us', 'LANGUAGE_BIDI': False}]
DEBUG 2023-12-03 19:35:13,215 base Exception while resolving variable 'is_nav_sidebar_enabled' in template 'admin_honeypot/login.html'.
Traceback (most recent call last):
  File "/home/horeb/github/easygo/venv/lib/python3.11/site-packages/django/template/base.py", line 880, in _resolve_lookup
    current = current[bit]
              ~~~~~~~^^^^^
  File "/home/horeb/github/easygo/venv/lib/python3.11/site-packages/django/template/context.py", line 83, in __getitem__
    raise KeyError(key)
KeyError: 'is_nav_sidebar_enabled'

During handling of the above exception, another exception occurred:

Traceback (most recent call last):
  File "/home/horeb/github/easygo/venv/lib/python3.11/site-packages/django/template/base.py", line 886, in _resolve_lookup
    if isinstance(current, BaseContext) and getattr(
                                            ^^^^^^^^
AttributeError: type object 'RequestContext' has no attribute 'is_nav_sidebar_enabled'

During handling of the above exception, another exception occurred:

Traceback (most recent call last):
  File "/home/horeb/github/easygo/venv/lib/python3.11/site-packages/django/template/base.py", line 896, in _resolve_lookup
    current = current[int(bit)]
                      ^^^^^^^^
ValueError: invalid literal for int() with base 10: 'is_nav_sidebar_enabled'

During handling of the above exception, another exception occurred:

Traceback (most recent call last):
  File "/home/horeb/github/easygo/venv/lib/python3.11/site-packages/django/template/base.py", line 903, in _resolve_lookup
    raise VariableDoesNotExist(
django.template.base.VariableDoesNotExist: Failed lookup for key [is_nav_sidebar_enabled] in [{'True': True, 'False': False, 'None': None}, {'csrf_token': <SimpleLazyObject: <function csrf.<locals>._get_val at 0x7f31550c4f40>>, 'request': <WSGIRequest: GET '/admin/login/?next=%2Fadmin%2F'>, 'user': <SimpleLazyObject: <function AuthenticationMiddleware.process_request.<locals>.<lambda> at 0x7f315577f1a0>>, 'perms': PermWrapper(<SimpleLazyObject: <function AuthenticationMiddleware.process_request.<locals>.<lambda> at 0x7f315577f1a0>>), 'messages': <FallbackStorage: request=<WSGIRequest: GET '/admin/login/?next=%2Fadmin%2F'>>, 'DEFAULT_MESSAGE_LEVELS': {'DEBUG': 10, 'INFO': 20, 'SUCCESS': 25, 'WARNING': 30, 'ERROR': 40}}, {}, {'form': <HoneypotLoginForm bound=False, valid=Unknown, fields=(username;password)>, 'view': <admin_honeypot.views.AdminHoneypot object at 0x7f3154f6a450>, 'app_path': '/admin/login/?next=%2Fadmin%2F', 'next': '/admin/', 'title': 'Log in', 'LANGUAGE_CODE': 'en-us', 'LANGUAGE_BIDI': False}]
DEBUG 2023-12-03 19:35:13,215 base Exception while resolving variable 'subtitle' in template 'admin_honeypot/login.html'.
Traceback (most recent call last):
  File "/home/horeb/github/easygo/venv/lib/python3.11/site-packages/django/template/base.py", line 880, in _resolve_lookup
    current = current[bit]
              ~~~~~~~^^^^^
  File "/home/horeb/github/easygo/venv/lib/python3.11/site-packages/django/template/context.py", line 83, in __getitem__
    raise KeyError(key)
KeyError: 'subtitle'

During handling of the above exception, another exception occurred:

Traceback (most recent call last):
  File "/home/horeb/github/easygo/venv/lib/python3.11/site-packages/django/template/base.py", line 886, in _resolve_lookup
    if isinstance(current, BaseContext) and getattr(
                                            ^^^^^^^^
AttributeError: type object 'RequestContext' has no attribute 'subtitle'

During handling of the above exception, another exception occurred:

Traceback (most recent call last):
  File "/home/horeb/github/easygo/venv/lib/python3.11/site-packages/django/template/base.py", line 896, in _resolve_lookup
    current = current[int(bit)]
                      ^^^^^^^^
ValueError: invalid literal for int() with base 10: 'subtitle'

During handling of the above exception, another exception occurred:

Traceback (most recent call last):
  File "/home/horeb/github/easygo/venv/lib/python3.11/site-packages/django/template/base.py", line 903, in _resolve_lookup
    raise VariableDoesNotExist(
django.template.base.VariableDoesNotExist: Failed lookup for key [subtitle] in [{'True': True, 'False': False, 'None': None}, {'csrf_token': <SimpleLazyObject: <function csrf.<locals>._get_val at 0x7f31550c4f40>>, 'request': <WSGIRequest: GET '/admin/login/?next=%2Fadmin%2F'>, 'user': <SimpleLazyObject: <function AuthenticationMiddleware.process_request.<locals>.<lambda> at 0x7f315577f1a0>>, 'perms': PermWrapper(<SimpleLazyObject: <function AuthenticationMiddleware.process_request.<locals>.<lambda> at 0x7f315577f1a0>>), 'messages': <FallbackStorage: request=<WSGIRequest: GET '/admin/login/?next=%2Fadmin%2F'>>, 'DEFAULT_MESSAGE_LEVELS': {'DEBUG': 10, 'INFO': 20, 'SUCCESS': 25, 'WARNING': 30, 'ERROR': 40}}, {}, {'form': <HoneypotLoginForm bound=False, valid=Unknown, fields=(username;password)>, 'view': <admin_honeypot.views.AdminHoneypot object at 0x7f3154f6a450>, 'app_path': '/admin/login/?next=%2Fadmin%2F', 'next': '/admin/', 'title': 'Log in', 'LANGUAGE_CODE': 'en-us', 'LANGUAGE_BIDI': False}, {'block': <Block Node: content_subtitle. Contents: [<IfNode>]>}]
WARNING 2023-12-03 19:39:46,442 log Not Found: /re_confirm_email/
WARNING 2023-12-03 19:40:32,148 log Not Found: /wp-login.php
WARNING 2023-12-03 19:41:20,112 log Not Found: /retrieve_inquiry/
WARNING 2023-12-03 19:41:49,501 log Not Found: /vendor/phpunit/phpunit/src/Util/PHP/eval-stdin.php
WARNING 2023-12-03 19:41:58,745 log Not Found: /.env
WARNING 2023-12-03 19:42:26,947 log Not Found: /inquiry3/
WARNING 2023-12-03 19:43:27,992 log Not Found: /retrieve_post/
WARNING 2023-12-03 19:44:30,388 log Not Found: /re_confirm/
WARNING 2023-12-03 19:47:17,715 log Not Found: /.env
WARNING 2023-12-03 19:49:03,183 log Not Found: /.env
WARNING 2023-12-03 19:49:04,080 log Forbidden (Referer checking failed - no Referer.): /
DEBUG 2023-12-03 19:49:34,746 base Exception while resolving variable 'email1' in template 'basecamp/html_email-inquiry-response.html'.
Traceback (most recent call last):
  File "/home/horeb/github/easygo/venv/lib/python3.11/site-packages/django/template/base.py", line 880, in _resolve_lookup
    current = current[bit]
              ~~~~~~~^^^^^
  File "/home/horeb/github/easygo/venv/lib/python3.11/site-packages/django/template/context.py", line 83, in __getitem__
    raise KeyError(key)
KeyError: 'email1'

During handling of the above exception, another exception occurred:

Traceback (most recent call last):
  File "/home/horeb/github/easygo/venv/lib/python3.11/site-packages/django/template/base.py", line 886, in _resolve_lookup
    if isinstance(current, BaseContext) and getattr(
                                            ^^^^^^^^
AttributeError: type object 'Context' has no attribute 'email1'

During handling of the above exception, another exception occurred:

Traceback (most recent call last):
  File "/home/horeb/github/easygo/venv/lib/python3.11/site-packages/django/template/base.py", line 896, in _resolve_lookup
    current = current[int(bit)]
                      ^^^^^^^^
ValueError: invalid literal for int() with base 10: 'email1'

During handling of the above exception, another exception occurred:

Traceback (most recent call last):
  File "/home/horeb/github/easygo/venv/lib/python3.11/site-packages/django/template/base.py", line 903, in _resolve_lookup
    raise VariableDoesNotExist(
django.template.base.VariableDoesNotExist: Failed lookup for key [email1] in [{'True': True, 'False': False, 'None': None}, {'company_name': '', 'name': 'Sandrine Ellis', 'contact': '+64272520707', 'email': 'sandrine.v.c.ellis@gmail.com', 'flight_date': datetime.date(2023, 12, 9), 'flight_number': 'NZ 103', 'flight_time': '10:25', 'pickup_time': '11:30', 'direction': 'Pickup from Intl Airport', 'street': '161 Sussex Street', 'suburb': 'Hotels in CBD', 'no_of_passenger': '2', 'no_of_baggage': '4', 'return_direction': 'Drop off to Intl Airport', 'return_flight_date': datetime.date(2023, 12, 14), 'return_flight_number': 'NZ 112', 'return_flight_time': '19:15', 'return_pickup_time': '15:15', 'message': '', 'price': '140', 'notice': '', 'private_ride': True}]
DEBUG 2023-12-03 19:50:48,639 base Exception while resolving variable 'email1' in template 'basecamp/html_email-inquiry-response.html'.
Traceback (most recent call last):
  File "/home/horeb/github/easygo/venv/lib/python3.11/site-packages/django/template/base.py", line 880, in _resolve_lookup
    current = current[bit]
              ~~~~~~~^^^^^
  File "/home/horeb/github/easygo/venv/lib/python3.11/site-packages/django/template/context.py", line 83, in __getitem__
    raise KeyError(key)
KeyError: 'email1'

During handling of the above exception, another exception occurred:

Traceback (most recent call last):
  File "/home/horeb/github/easygo/venv/lib/python3.11/site-packages/django/template/base.py", line 886, in _resolve_lookup
    if isinstance(current, BaseContext) and getattr(
                                            ^^^^^^^^
AttributeError: type object 'Context' has no attribute 'email1'

During handling of the above exception, another exception occurred:

Traceback (most recent call last):
  File "/home/horeb/github/easygo/venv/lib/python3.11/site-packages/django/template/base.py", line 896, in _resolve_lookup
    current = current[int(bit)]
                      ^^^^^^^^
ValueError: invalid literal for int() with base 10: 'email1'

During handling of the above exception, another exception occurred:

Traceback (most recent call last):
  File "/home/horeb/github/easygo/venv/lib/python3.11/site-packages/django/template/base.py", line 903, in _resolve_lookup
    raise VariableDoesNotExist(
django.template.base.VariableDoesNotExist: Failed lookup for key [email1] in [{'True': True, 'False': False, 'None': None}, {'company_name': '', 'name': 'Leica Jamcotchian', 'contact': '0410282648', 'email': 'leicajam@hotmail.com', 'flight_date': datetime.date(2024, 1, 1), 'flight_number': 'Va477', 'flight_time': '08:10', 'pickup_time': '06:30', 'direction': 'Drop off to Domestic Airport', 'street': '37 Faulkner st', 'suburb': 'Old Toongabbie', 'no_of_passenger': '5', 'no_of_baggage': '2', 'return_direction': None, 'return_flight_date': None, 'return_flight_number': None, 'return_flight_time': None, 'return_pickup_time': None, 'message': '2 adult \r\n3kids (5/2/4 months', 'price': '185 (inc tolls)', 'notice': '3 car seats required', 'private_ride': False}]
DEBUG 2023-12-03 19:51:35,663 base Exception while resolving variable 'email1' in template 'basecamp/html_email-inquiry-response.html'.
Traceback (most recent call last):
  File "/home/horeb/github/easygo/venv/lib/python3.11/site-packages/django/template/base.py", line 880, in _resolve_lookup
    current = current[bit]
              ~~~~~~~^^^^^
  File "/home/horeb/github/easygo/venv/lib/python3.11/site-packages/django/template/context.py", line 83, in __getitem__
    raise KeyError(key)
KeyError: 'email1'

During handling of the above exception, another exception occurred:

Traceback (most recent call last):
  File "/home/horeb/github/easygo/venv/lib/python3.11/site-packages/django/template/base.py", line 886, in _resolve_lookup
    if isinstance(current, BaseContext) and getattr(
                                            ^^^^^^^^
AttributeError: type object 'Context' has no attribute 'email1'

During handling of the above exception, another exception occurred:

Traceback (most recent call last):
  File "/home/horeb/github/easygo/venv/lib/python3.11/site-packages/django/template/base.py", line 896, in _resolve_lookup
    current = current[int(bit)]
                      ^^^^^^^^
ValueError: invalid literal for int() with base 10: 'email1'

During handling of the above exception, another exception occurred:

Traceback (most recent call last):
  File "/home/horeb/github/easygo/venv/lib/python3.11/site-packages/django/template/base.py", line 903, in _resolve_lookup
    raise VariableDoesNotExist(
django.template.base.VariableDoesNotExist: Failed lookup for key [email1] in [{'True': True, 'False': False, 'None': None}, {'company_name': '', 'name': 'Sev Lapuz', 'contact': '0400969777', 'email': 'srlapuz@gmail.com', 'flight_date': datetime.date(2023, 12, 18), 'flight_number': 'PR212', 'flight_time': '11:35', 'pickup_time': '07:00', 'direction': 'Drop off to Intl Airport', 'street': '3/149 Toongabbie Road', 'suburb': 'Toongabbie', 'no_of_passenger': '2', 'no_of_baggage': '4', 'return_direction': 'Pickup from Intl Airport', 'return_flight_date': datetime.date(2024, 1, 19), 'return_flight_number': 'PR211', 'return_flight_time': '10:15', 'return_pickup_time': '11:30', 'message': 'Pls. email quote first', 'price': '140', 'notice': '', 'private_ride': False}]
DEBUG 2023-12-03 19:51:50,797 base Exception while resolving variable 'email1' in template 'basecamp/html_email-inquiry-response.html'.
Traceback (most recent call last):
  File "/home/horeb/github/easygo/venv/lib/python3.11/site-packages/django/template/base.py", line 880, in _resolve_lookup
    current = current[bit]
              ~~~~~~~^^^^^
  File "/home/horeb/github/easygo/venv/lib/python3.11/site-packages/django/template/context.py", line 83, in __getitem__
    raise KeyError(key)
KeyError: 'email1'

During handling of the above exception, another exception occurred:

Traceback (most recent call last):
  File "/home/horeb/github/easygo/venv/lib/python3.11/site-packages/django/template/base.py", line 886, in _resolve_lookup
    if isinstance(current, BaseContext) and getattr(
                                            ^^^^^^^^
AttributeError: type object 'Context' has no attribute 'email1'

During handling of the above exception, another exception occurred:

Traceback (most recent call last):
  File "/home/horeb/github/easygo/venv/lib/python3.11/site-packages/django/template/base.py", line 896, in _resolve_lookup
    current = current[int(bit)]
                      ^^^^^^^^
ValueError: invalid literal for int() with base 10: 'email1'

During handling of the above exception, another exception occurred:

Traceback (most recent call last):
  File "/home/horeb/github/easygo/venv/lib/python3.11/site-packages/django/template/base.py", line 903, in _resolve_lookup
    raise VariableDoesNotExist(
django.template.base.VariableDoesNotExist: Failed lookup for key [email1] in [{'True': True, 'False': False, 'None': None}, {'company_name': '', 'name': 'Sev Lapuz', 'contact': '0400969777', 'email': 'srlapuz@gmail.com', 'flight_date': datetime.date(2023, 12, 18), 'flight_number': 'PR212', 'flight_time': '11:35', 'pickup_time': '07:00', 'direction': 'Drop off to Intl Airport', 'street': '3/149 Toongabbie Road', 'suburb': 'Toongabbie', 'no_of_passenger': '2', 'no_of_baggage': '4', 'return_direction': 'Pickup from Intl Airport', 'return_flight_date': datetime.date(2024, 1, 19), 'return_flight_number': 'PR211', 'return_flight_time': '10:15', 'return_pickup_time': '11:30', 'message': 'Pls. email quote first', 'price': '280', 'notice': '', 'private_ride': False}]
WARNING 2023-12-03 19:54:23,105 log Not Found: /.env
WARNING 2023-12-03 19:54:24,096 log Forbidden (Referer checking failed - no Referer.): /
WARNING 2023-12-03 20:01:21,613 log Not Found: /.env
WARNING 2023-12-03 20:04:02,158 log Not Found: /.env
WARNING 2023-12-03 20:04:35,925 log Not Found: /.well-known/traffic-advice
WARNING 2023-12-03 20:06:47,231 log Not Found: /retrieve_post/
WARNING 2023-12-03 20:08:03,037 log Not Found: /retrieve_inquiry/
WARNING 2023-12-03 20:08:56,571 log Not Found: /re_confirm_email/
WARNING 2023-12-03 20:09:53,760 log Not Found: /re_confirm/
WARNING 2023-12-03 20:10:47,615 log Not Found: /inquiry3/
WARNING 2023-12-03 20:13:03,990 log Not Found: /.env
WARNING 2023-12-03 20:15:57,475 log Not Found: /robots.txt
WARNING 2023-12-03 20:26:42,853 log Not Found: /.env
