WARNING 2024-01-18 12:38:47,478 log Not Found: /ads.txt
DEBUG 2024-01-18 12:47:11,198 base Exception while resolving variable 'subtitle' in template 'admin_honeypot/login.html'.
Traceback (most recent call last):
  File "/home/horeb/github/easygo/venv/lib/python3.11/site-packages/django/template/base.py", line 880, in _resolve_lookup
    current = current[bit]
              ~~~~~~~^^^^^
  File "/home/horeb/github/easygo/venv/lib/python3.11/site-packages/django/template/context.py", line 83, in __getitem__
    raise KeyError(key)
KeyError: 'subtitle'

During handling of the above exception, another exception occurred:

Traceback (most recent call last):
  File "/home/horeb/github/easygo/venv/lib/python3.11/site-packages/django/template/base.py", line 886, in _resolve_lookup
    if isinstance(current, BaseContext) and getattr(
                                            ^^^^^^^^
AttributeError: type object 'RequestContext' has no attribute 'subtitle'

During handling of the above exception, another exception occurred:

Traceback (most recent call last):
  File "/home/horeb/github/easygo/venv/lib/python3.11/site-packages/django/template/base.py", line 896, in _resolve_lookup
    current = current[int(bit)]
                      ^^^^^^^^
ValueError: invalid literal for int() with base 10: 'subtitle'

During handling of the above exception, another exception occurred:

Traceback (most recent call last):
  File "/home/horeb/github/easygo/venv/lib/python3.11/site-packages/django/template/base.py", line 903, in _resolve_lookup
    raise VariableDoesNotExist(
django.template.base.VariableDoesNotExist: Failed lookup for key [subtitle] in [{'True': True, 'False': False, 'None': None}, {'csrf_token': <SimpleLazyObject: <function csrf.<locals>._get_val at 0x7fdddfc5b2e0>>, 'request': <WSGIRequest: GET '/admin/login/?next=/admin/'>, 'user': <SimpleLazyObject: <function AuthenticationMiddleware.process_request.<locals>.<lambda> at 0x7fdddfc5bf60>>, 'perms': PermWrapper(<SimpleLazyObject: <function AuthenticationMiddleware.process_request.<locals>.<lambda> at 0x7fdddfc5bf60>>), 'messages': <FallbackStorage: request=<WSGIRequest: GET '/admin/login/?next=/admin/'>>, 'DEFAULT_MESSAGE_LEVELS': {'DEBUG': 10, 'INFO': 20, 'SUCCESS': 25, 'WARNING': 30, 'ERROR': 40}}, {}, {'form': <HoneypotLoginForm bound=False, valid=Unknown, fields=(username;password)>, 'view': <admin_honeypot.views.AdminHoneypot object at 0x7fdddf194110>, 'app_path': '/admin/login/?next=/admin/', 'next': '/admin/', 'title': 'Log in', 'LANGUAGE_CODE': 'en-us', 'LANGUAGE_BIDI': False}, {'block': <Block Node: title. Contents: [<IfNode>, <Variable Node: title>, <TextNode: ' | '>, <Variable Node: site_title|default:_('Django site admin')>]>}]
DEBUG 2024-01-18 12:47:11,204 base Exception while resolving variable 'site_title' in template 'admin_honeypot/login.html'.
Traceback (most recent call last):
  File "/home/horeb/github/easygo/venv/lib/python3.11/site-packages/django/template/base.py", line 880, in _resolve_lookup
    current = current[bit]
              ~~~~~~~^^^^^
  File "/home/horeb/github/easygo/venv/lib/python3.11/site-packages/django/template/context.py", line 83, in __getitem__
    raise KeyError(key)
KeyError: 'site_title'

During handling of the above exception, another exception occurred:

Traceback (most recent call last):
  File "/home/horeb/github/easygo/venv/lib/python3.11/site-packages/django/template/base.py", line 886, in _resolve_lookup
    if isinstance(current, BaseContext) and getattr(
                                            ^^^^^^^^
AttributeError: type object 'RequestContext' has no attribute 'site_title'

During handling of the above exception, another exception occurred:

Traceback (most recent call last):
  File "/home/horeb/github/easygo/venv/lib/python3.11/site-packages/django/template/base.py", line 896, in _resolve_lookup
    current = current[int(bit)]
                      ^^^^^^^^
ValueError: invalid literal for int() with base 10: 'site_title'

During handling of the above exception, another exception occurred:

Traceback (most recent call last):
  File "/home/horeb/github/easygo/venv/lib/python3.11/site-packages/django/template/base.py", line 903, in _resolve_lookup
    raise VariableDoesNotExist(
django.template.base.VariableDoesNotExist: Failed lookup for key [site_title] in [{'True': True, 'False': False, 'None': None}, {'csrf_token': <SimpleLazyObject: <function csrf.<locals>._get_val at 0x7fdddfc5b2e0>>, 'request': <WSGIRequest: GET '/admin/login/?next=/admin/'>, 'user': <SimpleLazyObject: <function AuthenticationMiddleware.process_request.<locals>.<lambda> at 0x7fdddfc5bf60>>, 'perms': PermWrapper(<SimpleLazyObject: <function AuthenticationMiddleware.process_request.<locals>.<lambda> at 0x7fdddfc5bf60>>), 'messages': <FallbackStorage: request=<WSGIRequest: GET '/admin/login/?next=/admin/'>>, 'DEFAULT_MESSAGE_LEVELS': {'DEBUG': 10, 'INFO': 20, 'SUCCESS': 25, 'WARNING': 30, 'ERROR': 40}}, {}, {'form': <HoneypotLoginForm bound=False, valid=Unknown, fields=(username;password)>, 'view': <admin_honeypot.views.AdminHoneypot object at 0x7fdddf194110>, 'app_path': '/admin/login/?next=/admin/', 'next': '/admin/', 'title': 'Log in', 'LANGUAGE_CODE': 'en-us', 'LANGUAGE_BIDI': False}, {'block': <Block Node: title. Contents: [<IfNode>, <Variable Node: title>, <TextNode: ' | '>, <Variable Node: site_title|default:_('Django site admin')>]>}]
DEBUG 2024-01-18 12:47:11,205 base Exception while resolving variable 'is_popup' in template 'admin_honeypot/login.html'.
Traceback (most recent call last):
  File "/home/horeb/github/easygo/venv/lib/python3.11/site-packages/django/template/base.py", line 880, in _resolve_lookup
    current = current[bit]
              ~~~~~~~^^^^^
  File "/home/horeb/github/easygo/venv/lib/python3.11/site-packages/django/template/context.py", line 83, in __getitem__
    raise KeyError(key)
KeyError: 'is_popup'

During handling of the above exception, another exception occurred:

Traceback (most recent call last):
  File "/home/horeb/github/easygo/venv/lib/python3.11/site-packages/django/template/base.py", line 886, in _resolve_lookup
    if isinstance(current, BaseContext) and getattr(
                                            ^^^^^^^^
AttributeError: type object 'RequestContext' has no attribute 'is_popup'

During handling of the above exception, another exception occurred:

Traceback (most recent call last):
  File "/home/horeb/github/easygo/venv/lib/python3.11/site-packages/django/template/base.py", line 896, in _resolve_lookup
    current = current[int(bit)]
                      ^^^^^^^^
ValueError: invalid literal for int() with base 10: 'is_popup'

During handling of the above exception, another exception occurred:

Traceback (most recent call last):
  File "/home/horeb/github/easygo/venv/lib/python3.11/site-packages/django/template/base.py", line 903, in _resolve_lookup
    raise VariableDoesNotExist(
django.template.base.VariableDoesNotExist: Failed lookup for key [is_popup] in [{'True': True, 'False': False, 'None': None}, {'csrf_token': <SimpleLazyObject: <function csrf.<locals>._get_val at 0x7fdddfc5b2e0>>, 'request': <WSGIRequest: GET '/admin/login/?next=/admin/'>, 'user': <SimpleLazyObject: <function AuthenticationMiddleware.process_request.<locals>.<lambda> at 0x7fdddfc5bf60>>, 'perms': PermWrapper(<SimpleLazyObject: <function AuthenticationMiddleware.process_request.<locals>.<lambda> at 0x7fdddfc5bf60>>), 'messages': <FallbackStorage: request=<WSGIRequest: GET '/admin/login/?next=/admin/'>>, 'DEFAULT_MESSAGE_LEVELS': {'DEBUG': 10, 'INFO': 20, 'SUCCESS': 25, 'WARNING': 30, 'ERROR': 40}}, {}, {'form': <HoneypotLoginForm bound=False, valid=Unknown, fields=(username;password)>, 'view': <admin_honeypot.views.AdminHoneypot object at 0x7fdddf194110>, 'app_path': '/admin/login/?next=/admin/', 'next': '/admin/', 'title': 'Log in', 'LANGUAGE_CODE': 'en-us', 'LANGUAGE_BIDI': False}]
DEBUG 2024-01-18 12:47:11,205 base Exception while resolving variable 'is_nav_sidebar_enabled' in template 'admin_honeypot/login.html'.
Traceback (most recent call last):
  File "/home/horeb/github/easygo/venv/lib/python3.11/site-packages/django/template/base.py", line 880, in _resolve_lookup
    current = current[bit]
              ~~~~~~~^^^^^
  File "/home/horeb/github/easygo/venv/lib/python3.11/site-packages/django/template/context.py", line 83, in __getitem__
    raise KeyError(key)
KeyError: 'is_nav_sidebar_enabled'

During handling of the above exception, another exception occurred:

Traceback (most recent call last):
  File "/home/horeb/github/easygo/venv/lib/python3.11/site-packages/django/template/base.py", line 886, in _resolve_lookup
    if isinstance(current, BaseContext) and getattr(
                                            ^^^^^^^^
AttributeError: type object 'RequestContext' has no attribute 'is_nav_sidebar_enabled'

During handling of the above exception, another exception occurred:

Traceback (most recent call last):
  File "/home/horeb/github/easygo/venv/lib/python3.11/site-packages/django/template/base.py", line 896, in _resolve_lookup
    current = current[int(bit)]
                      ^^^^^^^^
ValueError: invalid literal for int() with base 10: 'is_nav_sidebar_enabled'

During handling of the above exception, another exception occurred:

Traceback (most recent call last):
  File "/home/horeb/github/easygo/venv/lib/python3.11/site-packages/django/template/base.py", line 903, in _resolve_lookup
    raise VariableDoesNotExist(
django.template.base.VariableDoesNotExist: Failed lookup for key [is_nav_sidebar_enabled] in [{'True': True, 'False': False, 'None': None}, {'csrf_token': <SimpleLazyObject: <function csrf.<locals>._get_val at 0x7fdddfc5b2e0>>, 'request': <WSGIRequest: GET '/admin/login/?next=/admin/'>, 'user': <SimpleLazyObject: <function AuthenticationMiddleware.process_request.<locals>.<lambda> at 0x7fdddfc5bf60>>, 'perms': PermWrapper(<SimpleLazyObject: <function AuthenticationMiddleware.process_request.<locals>.<lambda> at 0x7fdddfc5bf60>>), 'messages': <FallbackStorage: request=<WSGIRequest: GET '/admin/login/?next=/admin/'>>, 'DEFAULT_MESSAGE_LEVELS': {'DEBUG': 10, 'INFO': 20, 'SUCCESS': 25, 'WARNING': 30, 'ERROR': 40}}, {}, {'form': <HoneypotLoginForm bound=False, valid=Unknown, fields=(username;password)>, 'view': <admin_honeypot.views.AdminHoneypot object at 0x7fdddf194110>, 'app_path': '/admin/login/?next=/admin/', 'next': '/admin/', 'title': 'Log in', 'LANGUAGE_CODE': 'en-us', 'LANGUAGE_BIDI': False}]
DEBUG 2024-01-18 12:47:11,206 base Exception while resolving variable 'is_popup' in template 'admin_honeypot/login.html'.
Traceback (most recent call last):
  File "/home/horeb/github/easygo/venv/lib/python3.11/site-packages/django/template/base.py", line 880, in _resolve_lookup
    current = current[bit]
              ~~~~~~~^^^^^
  File "/home/horeb/github/easygo/venv/lib/python3.11/site-packages/django/template/context.py", line 83, in __getitem__
    raise KeyError(key)
KeyError: 'is_popup'

During handling of the above exception, another exception occurred:

Traceback (most recent call last):
  File "/home/horeb/github/easygo/venv/lib/python3.11/site-packages/django/template/base.py", line 886, in _resolve_lookup
    if isinstance(current, BaseContext) and getattr(
                                            ^^^^^^^^
AttributeError: type object 'RequestContext' has no attribute 'is_popup'

During handling of the above exception, another exception occurred:

Traceback (most recent call last):
  File "/home/horeb/github/easygo/venv/lib/python3.11/site-packages/django/template/base.py", line 896, in _resolve_lookup
    current = current[int(bit)]
                      ^^^^^^^^
ValueError: invalid literal for int() with base 10: 'is_popup'

During handling of the above exception, another exception occurred:

Traceback (most recent call last):
  File "/home/horeb/github/easygo/venv/lib/python3.11/site-packages/django/template/base.py", line 903, in _resolve_lookup
    raise VariableDoesNotExist(
django.template.base.VariableDoesNotExist: Failed lookup for key [is_popup] in [{'True': True, 'False': False, 'None': None}, {'csrf_token': <SimpleLazyObject: <function csrf.<locals>._get_val at 0x7fdddfc5b2e0>>, 'request': <WSGIRequest: GET '/admin/login/?next=/admin/'>, 'user': <SimpleLazyObject: <function AuthenticationMiddleware.process_request.<locals>.<lambda> at 0x7fdddfc5bf60>>, 'perms': PermWrapper(<SimpleLazyObject: <function AuthenticationMiddleware.process_request.<locals>.<lambda> at 0x7fdddfc5bf60>>), 'messages': <FallbackStorage: request=<WSGIRequest: GET '/admin/login/?next=/admin/'>>, 'DEFAULT_MESSAGE_LEVELS': {'DEBUG': 10, 'INFO': 20, 'SUCCESS': 25, 'WARNING': 30, 'ERROR': 40}}, {}, {'form': <HoneypotLoginForm bound=False, valid=Unknown, fields=(username;password)>, 'view': <admin_honeypot.views.AdminHoneypot object at 0x7fdddf194110>, 'app_path': '/admin/login/?next=/admin/', 'next': '/admin/', 'title': 'Log in', 'LANGUAGE_CODE': 'en-us', 'LANGUAGE_BIDI': False}]
DEBUG 2024-01-18 12:47:11,207 base Exception while resolving variable 'is_popup' in template 'admin_honeypot/login.html'.
Traceback (most recent call last):
  File "/home/horeb/github/easygo/venv/lib/python3.11/site-packages/django/template/base.py", line 880, in _resolve_lookup
    current = current[bit]
              ~~~~~~~^^^^^
  File "/home/horeb/github/easygo/venv/lib/python3.11/site-packages/django/template/context.py", line 83, in __getitem__
    raise KeyError(key)
KeyError: 'is_popup'

During handling of the above exception, another exception occurred:

Traceback (most recent call last):
  File "/home/horeb/github/easygo/venv/lib/python3.11/site-packages/django/template/base.py", line 886, in _resolve_lookup
    if isinstance(current, BaseContext) and getattr(
                                            ^^^^^^^^
AttributeError: type object 'RequestContext' has no attribute 'is_popup'

During handling of the above exception, another exception occurred:

Traceback (most recent call last):
  File "/home/horeb/github/easygo/venv/lib/python3.11/site-packages/django/template/base.py", line 896, in _resolve_lookup
    current = current[int(bit)]
                      ^^^^^^^^
ValueError: invalid literal for int() with base 10: 'is_popup'

During handling of the above exception, another exception occurred:

Traceback (most recent call last):
  File "/home/horeb/github/easygo/venv/lib/python3.11/site-packages/django/template/base.py", line 903, in _resolve_lookup
    raise VariableDoesNotExist(
django.template.base.VariableDoesNotExist: Failed lookup for key [is_popup] in [{'True': True, 'False': False, 'None': None}, {'csrf_token': <SimpleLazyObject: <function csrf.<locals>._get_val at 0x7fdddfc5b2e0>>, 'request': <WSGIRequest: GET '/admin/login/?next=/admin/'>, 'user': <SimpleLazyObject: <function AuthenticationMiddleware.process_request.<locals>.<lambda> at 0x7fdddfc5bf60>>, 'perms': PermWrapper(<SimpleLazyObject: <function AuthenticationMiddleware.process_request.<locals>.<lambda> at 0x7fdddfc5bf60>>), 'messages': <FallbackStorage: request=<WSGIRequest: GET '/admin/login/?next=/admin/'>>, 'DEFAULT_MESSAGE_LEVELS': {'DEBUG': 10, 'INFO': 20, 'SUCCESS': 25, 'WARNING': 30, 'ERROR': 40}}, {}, {'form': <HoneypotLoginForm bound=False, valid=Unknown, fields=(username;password)>, 'view': <admin_honeypot.views.AdminHoneypot object at 0x7fdddf194110>, 'app_path': '/admin/login/?next=/admin/', 'next': '/admin/', 'title': 'Log in', 'LANGUAGE_CODE': 'en-us', 'LANGUAGE_BIDI': False}]
DEBUG 2024-01-18 12:47:11,208 base Exception while resolving variable 'site_header' in template 'admin_honeypot/login.html'.
Traceback (most recent call last):
  File "/home/horeb/github/easygo/venv/lib/python3.11/site-packages/django/template/base.py", line 880, in _resolve_lookup
    current = current[bit]
              ~~~~~~~^^^^^
  File "/home/horeb/github/easygo/venv/lib/python3.11/site-packages/django/template/context.py", line 83, in __getitem__
    raise KeyError(key)
KeyError: 'site_header'

During handling of the above exception, another exception occurred:

Traceback (most recent call last):
  File "/home/horeb/github/easygo/venv/lib/python3.11/site-packages/django/template/base.py", line 886, in _resolve_lookup
    if isinstance(current, BaseContext) and getattr(
                                            ^^^^^^^^
AttributeError: type object 'RequestContext' has no attribute 'site_header'

During handling of the above exception, another exception occurred:

Traceback (most recent call last):
  File "/home/horeb/github/easygo/venv/lib/python3.11/site-packages/django/template/base.py", line 896, in _resolve_lookup
    current = current[int(bit)]
                      ^^^^^^^^
ValueError: invalid literal for int() with base 10: 'site_header'

During handling of the above exception, another exception occurred:

Traceback (most recent call last):
  File "/home/horeb/github/easygo/venv/lib/python3.11/site-packages/django/template/base.py", line 903, in _resolve_lookup
    raise VariableDoesNotExist(
django.template.base.VariableDoesNotExist: Failed lookup for key [site_header] in [{'True': True, 'False': False, 'None': None}, {'csrf_token': <SimpleLazyObject: <function csrf.<locals>._get_val at 0x7fdddfc5b2e0>>, 'request': <WSGIRequest: GET '/admin/login/?next=/admin/'>, 'user': <SimpleLazyObject: <function AuthenticationMiddleware.process_request.<locals>.<lambda> at 0x7fdddfc5bf60>>, 'perms': PermWrapper(<SimpleLazyObject: <function AuthenticationMiddleware.process_request.<locals>.<lambda> at 0x7fdddfc5bf60>>), 'messages': <FallbackStorage: request=<WSGIRequest: GET '/admin/login/?next=/admin/'>>, 'DEFAULT_MESSAGE_LEVELS': {'DEBUG': 10, 'INFO': 20, 'SUCCESS': 25, 'WARNING': 30, 'ERROR': 40}}, {}, {'form': <HoneypotLoginForm bound=False, valid=Unknown, fields=(username;password)>, 'view': <admin_honeypot.views.AdminHoneypot object at 0x7fdddf194110>, 'app_path': '/admin/login/?next=/admin/', 'next': '/admin/', 'title': 'Log in', 'LANGUAGE_CODE': 'en-us', 'LANGUAGE_BIDI': False}, {'block': <Block Node: header. Contents: [<TextNode: '\n    <div id="header">\n  '>, <Block Node: branding. Contents: []>, <TextNode: '\n        </div>\n        '>, <Block Node: usertools. Contents: [<TextNode: '\n        '>, <IfNode>, <TextNode: '\n        '>]>, <TextNode: '\n        '>, <Block Node: nav-global. Contents: []>, <TextNode: '\n    </div>\n    '>]>}, {'block': <Block Node: branding. Contents: [<TextNode: '\n<h1 id="site-name"><a hr'>, <URLNode view_name=''admin_honeypot:index'' args=[] kwargs={} as=None>, <TextNode: '">'>, <Variable Node: site_header|default:_('Django administration')>, <TextNode: '</a></h1>\n'>]>}]
DEBUG 2024-01-18 12:47:11,209 base Exception while resolving variable 'is_popup' in template 'admin_honeypot/login.html'.
Traceback (most recent call last):
  File "/home/horeb/github/easygo/venv/lib/python3.11/site-packages/django/template/base.py", line 880, in _resolve_lookup
    current = current[bit]
              ~~~~~~~^^^^^
  File "/home/horeb/github/easygo/venv/lib/python3.11/site-packages/django/template/context.py", line 83, in __getitem__
    raise KeyError(key)
KeyError: 'is_popup'

During handling of the above exception, another exception occurred:

Traceback (most recent call last):
  File "/home/horeb/github/easygo/venv/lib/python3.11/site-packages/django/template/base.py", line 886, in _resolve_lookup
    if isinstance(current, BaseContext) and getattr(
                                            ^^^^^^^^
AttributeError: type object 'RequestContext' has no attribute 'is_popup'

During handling of the above exception, another exception occurred:

Traceback (most recent call last):
  File "/home/horeb/github/easygo/venv/lib/python3.11/site-packages/django/template/base.py", line 896, in _resolve_lookup
    current = current[int(bit)]
                      ^^^^^^^^
ValueError: invalid literal for int() with base 10: 'is_popup'

During handling of the above exception, another exception occurred:

Traceback (most recent call last):
  File "/home/horeb/github/easygo/venv/lib/python3.11/site-packages/django/template/base.py", line 903, in _resolve_lookup
    raise VariableDoesNotExist(
django.template.base.VariableDoesNotExist: Failed lookup for key [is_popup] in [{'True': True, 'False': False, 'None': None}, {'csrf_token': <SimpleLazyObject: <function csrf.<locals>._get_val at 0x7fdddfc5b2e0>>, 'request': <WSGIRequest: GET '/admin/login/?next=/admin/'>, 'user': <SimpleLazyObject: <function AuthenticationMiddleware.process_request.<locals>.<lambda> at 0x7fdddfc5bf60>>, 'perms': PermWrapper(<SimpleLazyObject: <function AuthenticationMiddleware.process_request.<locals>.<lambda> at 0x7fdddfc5bf60>>), 'messages': <FallbackStorage: request=<WSGIRequest: GET '/admin/login/?next=/admin/'>>, 'DEFAULT_MESSAGE_LEVELS': {'DEBUG': 10, 'INFO': 20, 'SUCCESS': 25, 'WARNING': 30, 'ERROR': 40}}, {}, {'form': <HoneypotLoginForm bound=False, valid=Unknown, fields=(username;password)>, 'view': <admin_honeypot.views.AdminHoneypot object at 0x7fdddf194110>, 'app_path': '/admin/login/?next=/admin/', 'next': '/admin/', 'title': 'Log in', 'LANGUAGE_CODE': 'en-us', 'LANGUAGE_BIDI': False}]
DEBUG 2024-01-18 12:47:11,209 base Exception while resolving variable 'is_nav_sidebar_enabled' in template 'admin_honeypot/login.html'.
Traceback (most recent call last):
  File "/home/horeb/github/easygo/venv/lib/python3.11/site-packages/django/template/base.py", line 880, in _resolve_lookup
    current = current[bit]
              ~~~~~~~^^^^^
  File "/home/horeb/github/easygo/venv/lib/python3.11/site-packages/django/template/context.py", line 83, in __getitem__
    raise KeyError(key)
KeyError: 'is_nav_sidebar_enabled'

During handling of the above exception, another exception occurred:

Traceback (most recent call last):
  File "/home/horeb/github/easygo/venv/lib/python3.11/site-packages/django/template/base.py", line 886, in _resolve_lookup
    if isinstance(current, BaseContext) and getattr(
                                            ^^^^^^^^
AttributeError: type object 'RequestContext' has no attribute 'is_nav_sidebar_enabled'

During handling of the above exception, another exception occurred:

Traceback (most recent call last):
  File "/home/horeb/github/easygo/venv/lib/python3.11/site-packages/django/template/base.py", line 896, in _resolve_lookup
    current = current[int(bit)]
                      ^^^^^^^^
ValueError: invalid literal for int() with base 10: 'is_nav_sidebar_enabled'

During handling of the above exception, another exception occurred:

Traceback (most recent call last):
  File "/home/horeb/github/easygo/venv/lib/python3.11/site-packages/django/template/base.py", line 903, in _resolve_lookup
    raise VariableDoesNotExist(
django.template.base.VariableDoesNotExist: Failed lookup for key [is_nav_sidebar_enabled] in [{'True': True, 'False': False, 'None': None}, {'csrf_token': <SimpleLazyObject: <function csrf.<locals>._get_val at 0x7fdddfc5b2e0>>, 'request': <WSGIRequest: GET '/admin/login/?next=/admin/'>, 'user': <SimpleLazyObject: <function AuthenticationMiddleware.process_request.<locals>.<lambda> at 0x7fdddfc5bf60>>, 'perms': PermWrapper(<SimpleLazyObject: <function AuthenticationMiddleware.process_request.<locals>.<lambda> at 0x7fdddfc5bf60>>), 'messages': <FallbackStorage: request=<WSGIRequest: GET '/admin/login/?next=/admin/'>>, 'DEFAULT_MESSAGE_LEVELS': {'DEBUG': 10, 'INFO': 20, 'SUCCESS': 25, 'WARNING': 30, 'ERROR': 40}}, {}, {'form': <HoneypotLoginForm bound=False, valid=Unknown, fields=(username;password)>, 'view': <admin_honeypot.views.AdminHoneypot object at 0x7fdddf194110>, 'app_path': '/admin/login/?next=/admin/', 'next': '/admin/', 'title': 'Log in', 'LANGUAGE_CODE': 'en-us', 'LANGUAGE_BIDI': False}]
DEBUG 2024-01-18 12:47:11,210 base Exception while resolving variable 'subtitle' in template 'admin_honeypot/login.html'.
Traceback (most recent call last):
  File "/home/horeb/github/easygo/venv/lib/python3.11/site-packages/django/template/base.py", line 880, in _resolve_lookup
    current = current[bit]
              ~~~~~~~^^^^^
  File "/home/horeb/github/easygo/venv/lib/python3.11/site-packages/django/template/context.py", line 83, in __getitem__
    raise KeyError(key)
KeyError: 'subtitle'

During handling of the above exception, another exception occurred:

Traceback (most recent call last):
  File "/home/horeb/github/easygo/venv/lib/python3.11/site-packages/django/template/base.py", line 886, in _resolve_lookup
    if isinstance(current, BaseContext) and getattr(
                                            ^^^^^^^^
AttributeError: type object 'RequestContext' has no attribute 'subtitle'

During handling of the above exception, another exception occurred:

Traceback (most recent call last):
  File "/home/horeb/github/easygo/venv/lib/python3.11/site-packages/django/template/base.py", line 896, in _resolve_lookup
    current = current[int(bit)]
                      ^^^^^^^^
ValueError: invalid literal for int() with base 10: 'subtitle'

During handling of the above exception, another exception occurred:

Traceback (most recent call last):
  File "/home/horeb/github/easygo/venv/lib/python3.11/site-packages/django/template/base.py", line 903, in _resolve_lookup
    raise VariableDoesNotExist(
django.template.base.VariableDoesNotExist: Failed lookup for key [subtitle] in [{'True': True, 'False': False, 'None': None}, {'csrf_token': <SimpleLazyObject: <function csrf.<locals>._get_val at 0x7fdddfc5b2e0>>, 'request': <WSGIRequest: GET '/admin/login/?next=/admin/'>, 'user': <SimpleLazyObject: <function AuthenticationMiddleware.process_request.<locals>.<lambda> at 0x7fdddfc5bf60>>, 'perms': PermWrapper(<SimpleLazyObject: <function AuthenticationMiddleware.process_request.<locals>.<lambda> at 0x7fdddfc5bf60>>), 'messages': <FallbackStorage: request=<WSGIRequest: GET '/admin/login/?next=/admin/'>>, 'DEFAULT_MESSAGE_LEVELS': {'DEBUG': 10, 'INFO': 20, 'SUCCESS': 25, 'WARNING': 30, 'ERROR': 40}}, {}, {'form': <HoneypotLoginForm bound=False, valid=Unknown, fields=(username;password)>, 'view': <admin_honeypot.views.AdminHoneypot object at 0x7fdddf194110>, 'app_path': '/admin/login/?next=/admin/', 'next': '/admin/', 'title': 'Log in', 'LANGUAGE_CODE': 'en-us', 'LANGUAGE_BIDI': False}, {'block': <Block Node: content_subtitle. Contents: [<IfNode>]>}]
WARNING 2024-01-18 12:54:35,481 log Not Found: /robots.txt
WARNING 2024-01-18 12:56:29,425 log Not Found: /.well-known/apple-app-site-association
WARNING 2024-01-18 12:57:56,048 log Not Found: /.well-known/traffic-advice
DEBUG 2024-01-18 13:03:51,328 base Exception while resolving variable 'recaptcha_site_key' in template 'basecamp/inquiry1.html'.
Traceback (most recent call last):
  File "/home/horeb/github/easygo/venv/lib/python3.11/site-packages/django/template/base.py", line 880, in _resolve_lookup
    current = current[bit]
              ~~~~~~~^^^^^
  File "/home/horeb/github/easygo/venv/lib/python3.11/site-packages/django/template/context.py", line 83, in __getitem__
    raise KeyError(key)
KeyError: 'recaptcha_site_key'

During handling of the above exception, another exception occurred:

Traceback (most recent call last):
  File "/home/horeb/github/easygo/venv/lib/python3.11/site-packages/django/template/base.py", line 886, in _resolve_lookup
    if isinstance(current, BaseContext) and getattr(
                                            ^^^^^^^^
AttributeError: type object 'RequestContext' has no attribute 'recaptcha_site_key'

During handling of the above exception, another exception occurred:

Traceback (most recent call last):
  File "/home/horeb/github/easygo/venv/lib/python3.11/site-packages/django/template/base.py", line 896, in _resolve_lookup
    current = current[int(bit)]
                      ^^^^^^^^
ValueError: invalid literal for int() with base 10: 'recaptcha_site_key'

During handling of the above exception, another exception occurred:

Traceback (most recent call last):
  File "/home/horeb/github/easygo/venv/lib/python3.11/site-packages/django/template/base.py", line 903, in _resolve_lookup
    raise VariableDoesNotExist(
django.template.base.VariableDoesNotExist: Failed lookup for key [recaptcha_site_key] in [{'True': True, 'False': False, 'None': None}, {'csrf_token': <SimpleLazyObject: 'jFmPguwmb1O1wsdMuL9ANqAPmaGtNQHck9OszFsvdPDhcnXsHHSdtmnianVVri3j'>, 'request': <WSGIRequest: POST '/price_detail/'>, 'user': <SimpleLazyObject: <function AuthenticationMiddleware.process_request.<locals>.<lambda> at 0x7fdddf9363e0>>, 'perms': PermWrapper(<SimpleLazyObject: <function AuthenticationMiddleware.process_request.<locals>.<lambda> at 0x7fdddf9363e0>>), 'messages': <FallbackStorage: request=<WSGIRequest: POST '/price_detail/'>>, 'DEFAULT_MESSAGE_LEVELS': {'DEBUG': 10, 'INFO': 20, 'SUCCESS': 25, 'WARNING': 30, 'ERROR': 40}}, {}, {'flight_date': '2024-02-15', 'direction': 'Drop off to Intl Airport', 'suburb': 'Peakhurst', 'no_of_passenger': '1'}, {'block': <Block Node: content. Contents: [<TextNode: '\n      <!-- Page content-'>, <Variable Node: flight_date>, <TextNode: '</a><br>\n\t\t\t  <a style="f'>, <Variable Node: direction>, <TextNode: '</a><br>\n\t\t\t  <a style="f'>, <Variable Node: suburb>, <TextNode: '</a><br>\n\t\t\t  <a style="f'>, <Variable Node: no_of_passenger>, <TextNode: '</a> -->\n\t\t\t  <br><br>\n  '>, <django.template.defaulttags.CsrfTokenNode object at 0x7fdddf548290>, <TextNode: '\n\t\t\t\t<div class="mb3 pb-1'>, <Variable Node: direction>, <TextNode: '">'>, <Variable Node: direction>, <TextNode: '</option>\t\t\t\t\t\t          '>, <Variable Node: flight_date>, <TextNode: '" type="text" >\t\t\t\t  \n   '>, <IfNode>, <TextNode: '\n\t\t\t\t  <div class="mb-3 p'>, <Variable Node: suburb>, <TextNode: '</label>\t\t\t\t\t\n\t\t\t\t</div>\n'>, <Variable Node: suburb>, <TextNode: '">'>, <Variable Node: suburb>, <TextNode: '</option>\t\t\t\t\t\n\t\t\t\t  </se'>, <Variable Node: no_of_passenger>, <TextNode: '">'>, <Variable Node: no_of_passenger>, <TextNode: '</option>\t\t\t\t  \n         '>, <Variable Node: recaptcha_site_key>, <TextNode: '"></div>\n\t\t\t\t<div id="err'>]>}]
WARNING 2024-01-18 13:04:33,712 log Not Found: /apple-app-site-association
WARNING 2024-01-18 13:08:47,468 log Not Found: /robots.txt
DEBUG 2024-01-18 13:09:16,938 base Exception while resolving variable 'recaptcha_site_key' in template 'basecamp/inquiry1.html'.
Traceback (most recent call last):
  File "/home/horeb/github/easygo/venv/lib/python3.11/site-packages/django/template/base.py", line 880, in _resolve_lookup
    current = current[bit]
              ~~~~~~~^^^^^
  File "/home/horeb/github/easygo/venv/lib/python3.11/site-packages/django/template/context.py", line 83, in __getitem__
    raise KeyError(key)
KeyError: 'recaptcha_site_key'

During handling of the above exception, another exception occurred:

Traceback (most recent call last):
  File "/home/horeb/github/easygo/venv/lib/python3.11/site-packages/django/template/base.py", line 886, in _resolve_lookup
    if isinstance(current, BaseContext) and getattr(
                                            ^^^^^^^^
AttributeError: type object 'RequestContext' has no attribute 'recaptcha_site_key'

During handling of the above exception, another exception occurred:

Traceback (most recent call last):
  File "/home/horeb/github/easygo/venv/lib/python3.11/site-packages/django/template/base.py", line 896, in _resolve_lookup
    current = current[int(bit)]
                      ^^^^^^^^
ValueError: invalid literal for int() with base 10: 'recaptcha_site_key'

During handling of the above exception, another exception occurred:

Traceback (most recent call last):
  File "/home/horeb/github/easygo/venv/lib/python3.11/site-packages/django/template/base.py", line 903, in _resolve_lookup
    raise VariableDoesNotExist(
django.template.base.VariableDoesNotExist: Failed lookup for key [recaptcha_site_key] in [{'True': True, 'False': False, 'None': None}, {'csrf_token': <SimpleLazyObject: '8V8laRtYPBeppy3jhrERywOPkSvxtiho20Z9GO9e7AMiIO2HCKVPMLZIZz43nQ0t'>, 'request': <WSGIRequest: POST '/price_detail/'>, 'user': <SimpleLazyObject: <function AuthenticationMiddleware.process_request.<locals>.<lambda> at 0x7fdddf8b4680>>, 'perms': PermWrapper(<SimpleLazyObject: <function AuthenticationMiddleware.process_request.<locals>.<lambda> at 0x7fdddf8b4680>>), 'messages': <FallbackStorage: request=<WSGIRequest: POST '/price_detail/'>>, 'DEFAULT_MESSAGE_LEVELS': {'DEBUG': 10, 'INFO': 20, 'SUCCESS': 25, 'WARNING': 30, 'ERROR': 40}}, {}, {'flight_date': '2024-01-19', 'direction': 'Drop off to Domestic Airport', 'suburb': 'Artarmon', 'no_of_passenger': '4'}, {'block': <Block Node: content. Contents: [<TextNode: '\n      <!-- Page content-'>, <Variable Node: flight_date>, <TextNode: '</a><br>\n\t\t\t  <a style="f'>, <Variable Node: direction>, <TextNode: '</a><br>\n\t\t\t  <a style="f'>, <Variable Node: suburb>, <TextNode: '</a><br>\n\t\t\t  <a style="f'>, <Variable Node: no_of_passenger>, <TextNode: '</a> -->\n\t\t\t  <br><br>\n  '>, <django.template.defaulttags.CsrfTokenNode object at 0x7fdddfe09dd0>, <TextNode: '\n\t\t\t\t<div class="mb3 pb-1'>, <Variable Node: direction>, <TextNode: '">'>, <Variable Node: direction>, <TextNode: '</option>\t\t\t\t\t\t          '>, <Variable Node: flight_date>, <TextNode: '" type="text" >\t\t\t\t  \n   '>, <IfNode>, <TextNode: '\n\t\t\t\t  <div class="mb-3 p'>, <Variable Node: suburb>, <TextNode: '</label>\t\t\t\t\t\n\t\t\t\t</div>\n'>, <Variable Node: suburb>, <TextNode: '">'>, <Variable Node: suburb>, <TextNode: '</option>\t\t\t\t\t\n\t\t\t\t  </se'>, <Variable Node: no_of_passenger>, <TextNode: '">'>, <Variable Node: no_of_passenger>, <TextNode: '</option>\t\t\t\t  \n         '>, <Variable Node: recaptcha_site_key>, <TextNode: '"></div>\n\t\t\t\t<div id="err'>]>}]
WARNING 2024-01-18 13:22:18,999 log Not Found: /robots.txt
WARNING 2024-01-18 13:45:06,121 log Not Found: /robots.txt
WARNING 2024-01-18 13:52:25,535 log Not Found: /robots.txt
WARNING 2024-01-18 14:02:55,700 log Not Found: /shop/de/product/moncler-jacken-kids-daim-rose/
WARNING 2024-01-18 14:34:36,004 log Not Found: /shop/fi/product-category/moncler-saappaat/
WARNING 2024-01-18 14:35:22,772 log Not Found: /robots.txt
WARNING 2024-01-18 14:37:13,007 log Not Found: /inquiry3/
WARNING 2024-01-18 15:08:15,187 log Not Found: /robots.txt
WARNING 2024-01-18 15:14:25,981 log Not Found: /shop/fi/product/halpa-moncler-alus-hihaton-liivi-naisten-zip-musta/
WARNING 2024-01-18 15:26:54,273 log Not Found: /shop/nl/product/moncler-sanglante-eider-donsjack-dames-zwart/
DEBUG 2024-01-18 15:28:52,404 base Exception while resolving variable 'email' in template 'basecamp/html_email-upcoming3.html'.
Traceback (most recent call last):
  File "/home/horeb/github/easygo/venv/lib/python3.11/site-packages/django/template/base.py", line 880, in _resolve_lookup
    current = current[bit]
              ~~~~~~~^^^^^
  File "/home/horeb/github/easygo/venv/lib/python3.11/site-packages/django/template/context.py", line 83, in __getitem__
    raise KeyError(key)
KeyError: 'email'

During handling of the above exception, another exception occurred:

Traceback (most recent call last):
  File "/home/horeb/github/easygo/venv/lib/python3.11/site-packages/django/template/base.py", line 886, in _resolve_lookup
    if isinstance(current, BaseContext) and getattr(
                                            ^^^^^^^^
AttributeError: type object 'Context' has no attribute 'email'

During handling of the above exception, another exception occurred:

Traceback (most recent call last):
  File "/home/horeb/github/easygo/venv/lib/python3.11/site-packages/django/template/base.py", line 896, in _resolve_lookup
    current = current[int(bit)]
                      ^^^^^^^^
ValueError: invalid literal for int() with base 10: 'email'

During handling of the above exception, another exception occurred:

Traceback (most recent call last):
  File "/home/horeb/github/easygo/venv/lib/python3.11/site-packages/django/template/base.py", line 903, in _resolve_lookup
    raise VariableDoesNotExist(
django.template.base.VariableDoesNotExist: Failed lookup for key [email] in [{'True': True, 'False': False, 'None': None}, {'name': 'Tia Clark', 'flight_date': datetime.date(2024, 1, 21), 'flight_number': 'ID5337', 'flight_time': '06:15', 'direction': 'Pickup from Intl Airport', 'pickup_time': '06:45', 'street': '28a Morrell Crescent', 'suburb': 'Quakers hill', 'price': '320', 'meeting_point': None, 'driver_name': 'Sam', 'driver_contact': '0406783559', 'driver_plate': 'TV 8276', 'driver_car': 'White van (Toyota Hiace)'}]
DEBUG 2024-01-18 15:28:56,268 base Exception while resolving variable 'email' in template 'basecamp/html_email-upcoming3.html'.
Traceback (most recent call last):
  File "/home/horeb/github/easygo/venv/lib/python3.11/site-packages/django/template/base.py", line 880, in _resolve_lookup
    current = current[bit]
              ~~~~~~~^^^^^
  File "/home/horeb/github/easygo/venv/lib/python3.11/site-packages/django/template/context.py", line 83, in __getitem__
    raise KeyError(key)
KeyError: 'email'

During handling of the above exception, another exception occurred:

Traceback (most recent call last):
  File "/home/horeb/github/easygo/venv/lib/python3.11/site-packages/django/template/base.py", line 886, in _resolve_lookup
    if isinstance(current, BaseContext) and getattr(
                                            ^^^^^^^^
AttributeError: type object 'Context' has no attribute 'email'

During handling of the above exception, another exception occurred:

Traceback (most recent call last):
  File "/home/horeb/github/easygo/venv/lib/python3.11/site-packages/django/template/base.py", line 896, in _resolve_lookup
    current = current[int(bit)]
                      ^^^^^^^^
ValueError: invalid literal for int() with base 10: 'email'

During handling of the above exception, another exception occurred:

Traceback (most recent call last):
  File "/home/horeb/github/easygo/venv/lib/python3.11/site-packages/django/template/base.py", line 903, in _resolve_lookup
    raise VariableDoesNotExist(
django.template.base.VariableDoesNotExist: Failed lookup for key [email] in [{'True': True, 'False': False, 'None': None}, {'name': 'ZOLTAN UJ-TOZSA', 'flight_date': datetime.date(2024, 1, 21), 'flight_number': 'THE TANK STREAM HOTEL', 'flight_time': '08:00', 'direction': 'Point to Point', 'pickup_time': '08:00', 'street': 'Featherdale Wildlife Park and Blue Mountains', 'suburb': 'Artarmon', 'price': '800', 'meeting_point': None, 'driver_name': 'Sam', 'driver_contact': '0406783559', 'driver_plate': 'TV 8276', 'driver_car': 'White van (Toyota Hiace)'}]
DEBUG 2024-01-18 15:29:00,077 base Exception while resolving variable 'email' in template 'basecamp/html_email-upcoming3.html'.
Traceback (most recent call last):
  File "/home/horeb/github/easygo/venv/lib/python3.11/site-packages/django/template/base.py", line 880, in _resolve_lookup
    current = current[bit]
              ~~~~~~~^^^^^
  File "/home/horeb/github/easygo/venv/lib/python3.11/site-packages/django/template/context.py", line 83, in __getitem__
    raise KeyError(key)
KeyError: 'email'

During handling of the above exception, another exception occurred:

Traceback (most recent call last):
  File "/home/horeb/github/easygo/venv/lib/python3.11/site-packages/django/template/base.py", line 886, in _resolve_lookup
    if isinstance(current, BaseContext) and getattr(
                                            ^^^^^^^^
AttributeError: type object 'Context' has no attribute 'email'

During handling of the above exception, another exception occurred:

Traceback (most recent call last):
  File "/home/horeb/github/easygo/venv/lib/python3.11/site-packages/django/template/base.py", line 896, in _resolve_lookup
    current = current[int(bit)]
                      ^^^^^^^^
ValueError: invalid literal for int() with base 10: 'email'

During handling of the above exception, another exception occurred:

Traceback (most recent call last):
  File "/home/horeb/github/easygo/venv/lib/python3.11/site-packages/django/template/base.py", line 903, in _resolve_lookup
    raise VariableDoesNotExist(
django.template.base.VariableDoesNotExist: Failed lookup for key [email] in [{'True': True, 'False': False, 'None': None}, {'name': 'Katie Jackson', 'flight_date': datetime.date(2024, 1, 21), 'flight_number': 'JQ40', 'flight_time': '20:25', 'direction': 'Pickup from Intl Airport', 'pickup_time': '21:25', 'street': '1 Cranbrook Street', 'suburb': 'Botany', 'price': '120', 'meeting_point': None, 'driver_name': 'Sam', 'driver_contact': '0406783559', 'driver_plate': 'TV 8276', 'driver_car': 'White van (Toyota Hiace)'}]
WARNING 2024-01-18 15:38:36,137 log Not Found: /.well-known/acme-challenge/76OKCLI16B1XPQ5O1HQJFI1LGI1LAQ0D
WARNING 2024-01-18 15:38:37,111 log Not Found: /.well-known/acme-challenge/ZI-3G0_9S422LJLQRAYH741LNU6M7KW_
DEBUG 2024-01-18 15:39:57,638 base Exception while resolving variable 'recaptcha_site_key' in template 'basecamp/inquiry1.html'.
Traceback (most recent call last):
  File "/home/horeb/github/easygo/venv/lib/python3.11/site-packages/django/template/base.py", line 880, in _resolve_lookup
    current = current[bit]
              ~~~~~~~^^^^^
  File "/home/horeb/github/easygo/venv/lib/python3.11/site-packages/django/template/context.py", line 83, in __getitem__
    raise KeyError(key)
KeyError: 'recaptcha_site_key'

During handling of the above exception, another exception occurred:

Traceback (most recent call last):
  File "/home/horeb/github/easygo/venv/lib/python3.11/site-packages/django/template/base.py", line 886, in _resolve_lookup
    if isinstance(current, BaseContext) and getattr(
                                            ^^^^^^^^
AttributeError: type object 'RequestContext' has no attribute 'recaptcha_site_key'

During handling of the above exception, another exception occurred:

Traceback (most recent call last):
  File "/home/horeb/github/easygo/venv/lib/python3.11/site-packages/django/template/base.py", line 896, in _resolve_lookup
    current = current[int(bit)]
                      ^^^^^^^^
ValueError: invalid literal for int() with base 10: 'recaptcha_site_key'

During handling of the above exception, another exception occurred:

Traceback (most recent call last):
  File "/home/horeb/github/easygo/venv/lib/python3.11/site-packages/django/template/base.py", line 903, in _resolve_lookup
    raise VariableDoesNotExist(
django.template.base.VariableDoesNotExist: Failed lookup for key [recaptcha_site_key] in [{'True': True, 'False': False, 'None': None}, {'csrf_token': <SimpleLazyObject: 'pehl6vHYUfCcZKwuaSQOI6u3WIRseIHU5DYQ2fIzEkP4EjIx9pZNIZr8oxWJmLnH'>, 'request': <WSGIRequest: POST '/price_detail/'>, 'user': <SimpleLazyObject: <function AuthenticationMiddleware.process_request.<locals>.<lambda> at 0x7f4b1fab72e0>>, 'perms': PermWrapper(<SimpleLazyObject: <function AuthenticationMiddleware.process_request.<locals>.<lambda> at 0x7f4b1fab72e0>>), 'messages': <FallbackStorage: request=<WSGIRequest: POST '/price_detail/'>>, 'DEFAULT_MESSAGE_LEVELS': {'DEBUG': 10, 'INFO': 20, 'SUCCESS': 25, 'WARNING': 30, 'ERROR': 40}}, {}, {'flight_date': '2024-01-19', 'direction': 'Drop off to Intl Airport', 'suburb': 'Mosman', 'no_of_passenger': '5'}, {'block': <Block Node: content. Contents: [<TextNode: '\n      <!-- Page content-'>, <Variable Node: flight_date>, <TextNode: '</a><br>\n\t\t\t  <a style="f'>, <Variable Node: direction>, <TextNode: '</a><br>\n\t\t\t  <a style="f'>, <Variable Node: suburb>, <TextNode: '</a><br>\n\t\t\t  <a style="f'>, <Variable Node: no_of_passenger>, <TextNode: '</a> -->\n\t\t\t  <br><br>\n  '>, <django.template.defaulttags.CsrfTokenNode object at 0x7f4b1fb09e10>, <TextNode: '\n\t\t\t\t<div class="mb3 pb-1'>, <Variable Node: direction>, <TextNode: '">'>, <Variable Node: direction>, <TextNode: '</option>\t\t\t\t\t\t          '>, <Variable Node: flight_date>, <TextNode: '" type="text" >\t\t\t\t  \n   '>, <IfNode>, <TextNode: '\n\t\t\t\t  <div class="mb-3 p'>, <Variable Node: suburb>, <TextNode: '</label>\t\t\t\t\t\n\t\t\t\t</div>\n'>, <Variable Node: suburb>, <TextNode: '">'>, <Variable Node: suburb>, <TextNode: '</option>\t\t\t\t\t\n\t\t\t\t  </se'>, <Variable Node: no_of_passenger>, <TextNode: '">'>, <Variable Node: no_of_passenger>, <TextNode: '</option>\t\t\t\t  \n         '>, <Variable Node: recaptcha_site_key>, <TextNode: '"></div>\n\t\t\t\t<div id="err'>]>}]
WARNING 2024-01-18 15:42:32,821 log Not Found: /version
DEBUG 2024-01-18 15:58:34,993 base Exception while resolving variable 'recaptcha_site_key' in template 'basecamp/inquiry1.html'.
Traceback (most recent call last):
  File "/home/horeb/github/easygo/venv/lib/python3.11/site-packages/django/template/base.py", line 880, in _resolve_lookup
    current = current[bit]
              ~~~~~~~^^^^^
  File "/home/horeb/github/easygo/venv/lib/python3.11/site-packages/django/template/context.py", line 83, in __getitem__
    raise KeyError(key)
KeyError: 'recaptcha_site_key'

During handling of the above exception, another exception occurred:

Traceback (most recent call last):
  File "/home/horeb/github/easygo/venv/lib/python3.11/site-packages/django/template/base.py", line 886, in _resolve_lookup
    if isinstance(current, BaseContext) and getattr(
                                            ^^^^^^^^
AttributeError: type object 'RequestContext' has no attribute 'recaptcha_site_key'

During handling of the above exception, another exception occurred:

Traceback (most recent call last):
  File "/home/horeb/github/easygo/venv/lib/python3.11/site-packages/django/template/base.py", line 896, in _resolve_lookup
    current = current[int(bit)]
                      ^^^^^^^^
ValueError: invalid literal for int() with base 10: 'recaptcha_site_key'

During handling of the above exception, another exception occurred:

Traceback (most recent call last):
  File "/home/horeb/github/easygo/venv/lib/python3.11/site-packages/django/template/base.py", line 903, in _resolve_lookup
    raise VariableDoesNotExist(
django.template.base.VariableDoesNotExist: Failed lookup for key [recaptcha_site_key] in [{'True': True, 'False': False, 'None': None}, {'csrf_token': <SimpleLazyObject: 'gw9kDVA8sXUqBPCQPnvoOdn9pdzEcHqag8XvX0iYA8VcmLj8T0iiCSACTRUd7uJO'>, 'request': <WSGIRequest: POST '/price_detail/'>, 'user': <SimpleLazyObject: <function AuthenticationMiddleware.process_request.<locals>.<lambda> at 0x7f4b1f95ee80>>, 'perms': PermWrapper(<SimpleLazyObject: <function AuthenticationMiddleware.process_request.<locals>.<lambda> at 0x7f4b1f95ee80>>), 'messages': <FallbackStorage: request=<WSGIRequest: POST '/price_detail/'>>, 'DEFAULT_MESSAGE_LEVELS': {'DEBUG': 10, 'INFO': 20, 'SUCCESS': 25, 'WARNING': 30, 'ERROR': 40}}, {}, {'flight_date': '2024-02-23', 'direction': 'Pickup from Intl Airport', 'suburb': 'Turramurra', 'no_of_passenger': '3'}, {'block': <Block Node: content. Contents: [<TextNode: '\n      <!-- Page content-'>, <Variable Node: flight_date>, <TextNode: '</a><br>\n\t\t\t  <a style="f'>, <Variable Node: direction>, <TextNode: '</a><br>\n\t\t\t  <a style="f'>, <Variable Node: suburb>, <TextNode: '</a><br>\n\t\t\t  <a style="f'>, <Variable Node: no_of_passenger>, <TextNode: '</a> -->\n\t\t\t  <br><br>\n  '>, <django.template.defaulttags.CsrfTokenNode object at 0x7f4b1f559b50>, <TextNode: '\n\t\t\t\t<div class="mb3 pb-1'>, <Variable Node: direction>, <TextNode: '">'>, <Variable Node: direction>, <TextNode: '</option>\t\t\t\t\t\t          '>, <Variable Node: flight_date>, <TextNode: '" type="text" >\t\t\t\t  \n   '>, <IfNode>, <TextNode: '\n\t\t\t\t  <div class="mb-3 p'>, <Variable Node: suburb>, <TextNode: '</label>\t\t\t\t\t\n\t\t\t\t</div>\n'>, <Variable Node: suburb>, <TextNode: '">'>, <Variable Node: suburb>, <TextNode: '</option>\t\t\t\t\t\n\t\t\t\t  </se'>, <Variable Node: no_of_passenger>, <TextNode: '">'>, <Variable Node: no_of_passenger>, <TextNode: '</option>\t\t\t\t  \n         '>, <Variable Node: recaptcha_site_key>, <TextNode: '"></div>\n\t\t\t\t<div id="err'>]>}]
DEBUG 2024-01-18 15:59:31,397 base Exception while resolving variable 'email' in template 'basecamp/html_email-upcoming3.html'.
Traceback (most recent call last):
  File "/home/horeb/github/easygo/venv/lib/python3.11/site-packages/django/template/base.py", line 880, in _resolve_lookup
    current = current[bit]
              ~~~~~~~^^^^^
  File "/home/horeb/github/easygo/venv/lib/python3.11/site-packages/django/template/context.py", line 83, in __getitem__
    raise KeyError(key)
KeyError: 'email'

During handling of the above exception, another exception occurred:

Traceback (most recent call last):
  File "/home/horeb/github/easygo/venv/lib/python3.11/site-packages/django/template/base.py", line 886, in _resolve_lookup
    if isinstance(current, BaseContext) and getattr(
                                            ^^^^^^^^
AttributeError: type object 'Context' has no attribute 'email'

During handling of the above exception, another exception occurred:

Traceback (most recent call last):
  File "/home/horeb/github/easygo/venv/lib/python3.11/site-packages/django/template/base.py", line 896, in _resolve_lookup
    current = current[int(bit)]
                      ^^^^^^^^
ValueError: invalid literal for int() with base 10: 'email'

During handling of the above exception, another exception occurred:

Traceback (most recent call last):
  File "/home/horeb/github/easygo/venv/lib/python3.11/site-packages/django/template/base.py", line 903, in _resolve_lookup
    raise VariableDoesNotExist(
django.template.base.VariableDoesNotExist: Failed lookup for key [email] in [{'True': True, 'False': False, 'None': None}, {'name': 'Tia Clark', 'flight_date': datetime.date(2024, 1, 21), 'flight_number': 'ID5337', 'flight_time': '06:15', 'direction': 'Pickup from Intl Airport', 'pickup_time': '06:45', 'street': '28a Morrell Crescent', 'suburb': 'Quakers hill', 'price': '320', 'meeting_point': None, 'driver_name': 'Sam', 'driver_contact': '0406783559', 'driver_plate': 'TV 8276', 'driver_car': 'White van (Toyota Hiace)'}]
DEBUG 2024-01-18 15:59:35,325 base Exception while resolving variable 'email' in template 'basecamp/html_email-upcoming3.html'.
Traceback (most recent call last):
  File "/home/horeb/github/easygo/venv/lib/python3.11/site-packages/django/template/base.py", line 880, in _resolve_lookup
    current = current[bit]
              ~~~~~~~^^^^^
  File "/home/horeb/github/easygo/venv/lib/python3.11/site-packages/django/template/context.py", line 83, in __getitem__
    raise KeyError(key)
KeyError: 'email'

During handling of the above exception, another exception occurred:

Traceback (most recent call last):
  File "/home/horeb/github/easygo/venv/lib/python3.11/site-packages/django/template/base.py", line 886, in _resolve_lookup
    if isinstance(current, BaseContext) and getattr(
                                            ^^^^^^^^
AttributeError: type object 'Context' has no attribute 'email'

During handling of the above exception, another exception occurred:

Traceback (most recent call last):
  File "/home/horeb/github/easygo/venv/lib/python3.11/site-packages/django/template/base.py", line 896, in _resolve_lookup
    current = current[int(bit)]
                      ^^^^^^^^
ValueError: invalid literal for int() with base 10: 'email'

During handling of the above exception, another exception occurred:

Traceback (most recent call last):
  File "/home/horeb/github/easygo/venv/lib/python3.11/site-packages/django/template/base.py", line 903, in _resolve_lookup
    raise VariableDoesNotExist(
django.template.base.VariableDoesNotExist: Failed lookup for key [email] in [{'True': True, 'False': False, 'None': None}, {'name': 'ZOLTAN UJ-TOZSA', 'flight_date': datetime.date(2024, 1, 21), 'flight_number': 'THE TANK STREAM HOTEL', 'flight_time': '08:00', 'direction': 'Point to Point', 'pickup_time': '08:00', 'street': 'Featherdale Wildlife Park and Blue Mountains', 'suburb': 'Artarmon', 'price': '800', 'meeting_point': None, 'driver_name': 'Sam', 'driver_contact': '0406783559', 'driver_plate': 'TV 8276', 'driver_car': 'White van (Toyota Hiace)'}]
DEBUG 2024-01-18 15:59:39,200 base Exception while resolving variable 'email' in template 'basecamp/html_email-upcoming3.html'.
Traceback (most recent call last):
  File "/home/horeb/github/easygo/venv/lib/python3.11/site-packages/django/template/base.py", line 880, in _resolve_lookup
    current = current[bit]
              ~~~~~~~^^^^^
  File "/home/horeb/github/easygo/venv/lib/python3.11/site-packages/django/template/context.py", line 83, in __getitem__
    raise KeyError(key)
KeyError: 'email'

During handling of the above exception, another exception occurred:

Traceback (most recent call last):
  File "/home/horeb/github/easygo/venv/lib/python3.11/site-packages/django/template/base.py", line 886, in _resolve_lookup
    if isinstance(current, BaseContext) and getattr(
                                            ^^^^^^^^
AttributeError: type object 'Context' has no attribute 'email'

During handling of the above exception, another exception occurred:

Traceback (most recent call last):
  File "/home/horeb/github/easygo/venv/lib/python3.11/site-packages/django/template/base.py", line 896, in _resolve_lookup
    current = current[int(bit)]
                      ^^^^^^^^
ValueError: invalid literal for int() with base 10: 'email'

During handling of the above exception, another exception occurred:

Traceback (most recent call last):
  File "/home/horeb/github/easygo/venv/lib/python3.11/site-packages/django/template/base.py", line 903, in _resolve_lookup
    raise VariableDoesNotExist(
django.template.base.VariableDoesNotExist: Failed lookup for key [email] in [{'True': True, 'False': False, 'None': None}, {'name': 'Katie Jackson', 'flight_date': datetime.date(2024, 1, 21), 'flight_number': 'JQ40', 'flight_time': '20:25', 'direction': 'Pickup from Intl Airport', 'pickup_time': '21:25', 'street': '1 Cranbrook Street', 'suburb': 'Botany', 'price': '120', 'meeting_point': None, 'driver_name': 'Sam', 'driver_contact': '0406783559', 'driver_plate': 'TV 8276', 'driver_car': 'White van (Toyota Hiace)'}]
DEBUG 2024-01-18 16:16:16,603 base Exception while resolving variable 'recaptcha_site_key' in template 'basecamp/inquiry1.html'.
Traceback (most recent call last):
  File "/home/horeb/github/easygo/venv/lib/python3.11/site-packages/django/template/base.py", line 880, in _resolve_lookup
    current = current[bit]
              ~~~~~~~^^^^^
  File "/home/horeb/github/easygo/venv/lib/python3.11/site-packages/django/template/context.py", line 83, in __getitem__
    raise KeyError(key)
KeyError: 'recaptcha_site_key'

During handling of the above exception, another exception occurred:

Traceback (most recent call last):
  File "/home/horeb/github/easygo/venv/lib/python3.11/site-packages/django/template/base.py", line 886, in _resolve_lookup
    if isinstance(current, BaseContext) and getattr(
                                            ^^^^^^^^
AttributeError: type object 'RequestContext' has no attribute 'recaptcha_site_key'

During handling of the above exception, another exception occurred:

Traceback (most recent call last):
  File "/home/horeb/github/easygo/venv/lib/python3.11/site-packages/django/template/base.py", line 896, in _resolve_lookup
    current = current[int(bit)]
                      ^^^^^^^^
ValueError: invalid literal for int() with base 10: 'recaptcha_site_key'

During handling of the above exception, another exception occurred:

Traceback (most recent call last):
  File "/home/horeb/github/easygo/venv/lib/python3.11/site-packages/django/template/base.py", line 903, in _resolve_lookup
    raise VariableDoesNotExist(
django.template.base.VariableDoesNotExist: Failed lookup for key [recaptcha_site_key] in [{'True': True, 'False': False, 'None': None}, {'csrf_token': <SimpleLazyObject: 'Lqd04n0knNMP6SSORgwY1npEszhk7TcOoNbb3OEkLzdppcvzfRoj7kSvqVBEFXZ0'>, 'request': <WSGIRequest: POST '/price_detail/'>, 'user': <SimpleLazyObject: <function AuthenticationMiddleware.process_request.<locals>.<lambda> at 0x7fe519093a60>>, 'perms': PermWrapper(<SimpleLazyObject: <function AuthenticationMiddleware.process_request.<locals>.<lambda> at 0x7fe519093a60>>), 'messages': <FallbackStorage: request=<WSGIRequest: POST '/price_detail/'>>, 'DEFAULT_MESSAGE_LEVELS': {'DEBUG': 10, 'INFO': 20, 'SUCCESS': 25, 'WARNING': 30, 'ERROR': 40}}, {}, {'flight_date': '2024-02-06', 'direction': 'Drop off to Intl Airport', 'suburb': 'Hornsby', 'no_of_passenger': '2'}, {'block': <Block Node: content. Contents: [<TextNode: '\n      <!-- Page content-'>, <Variable Node: flight_date>, <TextNode: '</a><br>\n\t\t\t  <a style="f'>, <Variable Node: direction>, <TextNode: '</a><br>\n\t\t\t  <a style="f'>, <Variable Node: suburb>, <TextNode: '</a><br>\n\t\t\t  <a style="f'>, <Variable Node: no_of_passenger>, <TextNode: '</a> -->\n\t\t\t  <br><br>\n  '>, <django.template.defaulttags.CsrfTokenNode object at 0x7fe51877fb50>, <TextNode: '\n\t\t\t\t<div class="mb3 pb-1'>, <Variable Node: direction>, <TextNode: '">'>, <Variable Node: direction>, <TextNode: '</option>\t\t\t\t\t\t          '>, <Variable Node: flight_date>, <TextNode: '" type="text" >\t\t\t\t  \n   '>, <IfNode>, <TextNode: '\n\t\t\t\t  <div class="mb-3 p'>, <Variable Node: suburb>, <TextNode: '</label>\t\t\t\t\t\n\t\t\t\t</div>\n'>, <Variable Node: suburb>, <TextNode: '">'>, <Variable Node: suburb>, <TextNode: '</option>\t\t\t\t\t\n\t\t\t\t  </se'>, <Variable Node: no_of_passenger>, <TextNode: '">'>, <Variable Node: no_of_passenger>, <TextNode: '</option>\t\t\t\t  \n         '>, <Variable Node: recaptcha_site_key>, <TextNode: '"></div>\n\t\t\t\t<div id="err'>]>}]
DEBUG 2024-01-18 16:16:29,761 base Exception while resolving variable 'recaptcha_site_key' in template 'basecamp/inquiry1.html'.
Traceback (most recent call last):
  File "/home/horeb/github/easygo/venv/lib/python3.11/site-packages/django/template/base.py", line 880, in _resolve_lookup
    current = current[bit]
              ~~~~~~~^^^^^
  File "/home/horeb/github/easygo/venv/lib/python3.11/site-packages/django/template/context.py", line 83, in __getitem__
    raise KeyError(key)
KeyError: 'recaptcha_site_key'

During handling of the above exception, another exception occurred:

Traceback (most recent call last):
  File "/home/horeb/github/easygo/venv/lib/python3.11/site-packages/django/template/base.py", line 886, in _resolve_lookup
    if isinstance(current, BaseContext) and getattr(
                                            ^^^^^^^^
AttributeError: type object 'RequestContext' has no attribute 'recaptcha_site_key'

During handling of the above exception, another exception occurred:

Traceback (most recent call last):
  File "/home/horeb/github/easygo/venv/lib/python3.11/site-packages/django/template/base.py", line 896, in _resolve_lookup
    current = current[int(bit)]
                      ^^^^^^^^
ValueError: invalid literal for int() with base 10: 'recaptcha_site_key'

During handling of the above exception, another exception occurred:

Traceback (most recent call last):
  File "/home/horeb/github/easygo/venv/lib/python3.11/site-packages/django/template/base.py", line 903, in _resolve_lookup
    raise VariableDoesNotExist(
django.template.base.VariableDoesNotExist: Failed lookup for key [recaptcha_site_key] in [{'True': True, 'False': False, 'None': None}, {'csrf_token': <SimpleLazyObject: 'iGaiGE9vorVYqQAzHFnXdK38uiOJPX4qV38tF5NvMdmyJadk5gfijHwZsE83n1RC'>, 'request': <WSGIRequest: POST '/price_detail/'>, 'user': <SimpleLazyObject: <function AuthenticationMiddleware.process_request.<locals>.<lambda> at 0x7fd84a712200>>, 'perms': PermWrapper(<SimpleLazyObject: <function AuthenticationMiddleware.process_request.<locals>.<lambda> at 0x7fd84a712200>>), 'messages': <FallbackStorage: request=<WSGIRequest: POST '/price_detail/'>>, 'DEFAULT_MESSAGE_LEVELS': {'DEBUG': 10, 'INFO': 20, 'SUCCESS': 25, 'WARNING': 30, 'ERROR': 40}}, {}, {'flight_date': '2024-02-06', 'direction': 'Drop off to Intl Airport', 'suburb': 'Hornsby', 'no_of_passenger': '4'}, {'block': <Block Node: content. Contents: [<TextNode: '\n      <!-- Page content-'>, <Variable Node: flight_date>, <TextNode: '</a><br>\n\t\t\t  <a style="f'>, <Variable Node: direction>, <TextNode: '</a><br>\n\t\t\t  <a style="f'>, <Variable Node: suburb>, <TextNode: '</a><br>\n\t\t\t  <a style="f'>, <Variable Node: no_of_passenger>, <TextNode: '</a> -->\n\t\t\t  <br><br>\n  '>, <django.template.defaulttags.CsrfTokenNode object at 0x7fd8473df010>, <TextNode: '\n\t\t\t\t<div class="mb3 pb-1'>, <Variable Node: direction>, <TextNode: '">'>, <Variable Node: direction>, <TextNode: '</option>\t\t\t\t\t\t          '>, <Variable Node: flight_date>, <TextNode: '" type="text" >\t\t\t\t  \n   '>, <IfNode>, <TextNode: '\n\t\t\t\t  <div class="mb-3 p'>, <Variable Node: suburb>, <TextNode: '</label>\t\t\t\t\t\n\t\t\t\t</div>\n'>, <Variable Node: suburb>, <TextNode: '">'>, <Variable Node: suburb>, <TextNode: '</option>\t\t\t\t\t\n\t\t\t\t  </se'>, <Variable Node: no_of_passenger>, <TextNode: '">'>, <Variable Node: no_of_passenger>, <TextNode: '</option>\t\t\t\t  \n         '>, <Variable Node: recaptcha_site_key>, <TextNode: '"></div>\n\t\t\t\t<div id="err'>]>}]
WARNING 2024-01-18 16:33:10,662 log Not Found: /.env
WARNING 2024-01-18 16:33:11,684 log Forbidden (Referer checking failed - no Referer.): /
WARNING 2024-01-18 16:33:21,592 log Not Found: /vendor/phpunit/phpunit/src/Util/PHP/eval-stdin.php
WARNING 2024-01-18 16:46:11,194 log Not Found: /robots.txt
WARNING 2024-01-18 16:55:45,529 log Not Found: /inquiry3/
